Workbook

Sheet 1_README
A1: FOMA CER–COD–Paris — T5 results workbook (Block D: publication-bias battery D1/D2/D4/D5 + D6 draft)
A2: Template: docs/results_workbook_template.md (binding) · Output schema: T2 36-column
A3: Run 2026-07-19 13:37:05 CEST · Verifier R/05_verify_outputs.R: 27/27 PASS · Run basis @ 6bf40b1
A5: Item | B5: Value
A6: Version | B6: v1 (2026-07-19, post-run build)
A7: Method (one line) | B7: Publication-bias battery on the 3L-RVE spine (PET/PEESE, CR2/Satterthwaite) and on one-effect-per-cluster aggregates (3PSM, p-uniform*), plus grey-literature panel; pre/post-Paris split per DEC-031a.5.
A8: Scope | B8: D1 FAT-PET-PEESE (full set) · D2 selection models (full aggregates) · D4 pre/post split (both engines) · D5 grey-literature panel · D6 triangulation FINAL (RoBMA line cited from TH-b/H2a per the resolved gate [DEC-047]); D3 executes in the H-session [DEC-031g].
A9: Repository | B9: rwitte-wu-research/FOMA-CER-COD-Paris (main)
A10: Computational stack | B10: R 4.6.1 · metafor 5.0-1 · clubSandwich 0.7.0 · puniform 0.2.8 · renv lockfile (F64)
A11: Scripts | B11: R/05_bias.R (run) · R/05_verify_outputs.R (paired verifier, O1–O27)
A12: Decision basis | B12: DEC-031g (execution pins P-T5-1..5, F63/F64/F65) · DEC-031f/A.11 (ladder) · DEC-031a.4/.5 · DEC-016 · DEC-010 · DEC-042a/b · plan §8 + A.12
A13: Result framing | B13: Language per the resolved gate [DEC-044 → DEC-047]; Tier-2 register for the pooled effect (claim wording fixed by DEC-047).
A15: TAB-INDEX | B15: Content
A16: 1_README | B16: This tab
A17: 2_Methodology | B17: Quantity | Formula / Construction | Reference
... A28: Manuscript_Text_Blocks | B28: TB-30..TB-35 (continues from T8 = TB-28; TB-29 never assigned — documented gap)

Sheet 2_Methodology
A1: T5 methodology — construction of every reported quantity
A2: Source pointers in project notation ([DEC-nnn], [F-nn], [plan §x], literature).
A3: Spine: rma.mv REML · V = impute_covariance_matrix(vi, cluster_id, r = 0.6) · random = ~1|cluster_id/study/esid · CR2 + Satterthwaite on cluster_id [D31.1/A.2].
A5: Quantity | B5: Formula / Construction | C5: Reference
A6: PET (intercept) / FAT (slope) | B6: Spine + mods = ~ sez, sez = sqrt(vi) derived in-script; intercept = selection-adjusted mean at SE→0; slope = Egger-type small-study test; two-sided CR2/Satterthwaite p. | C6: [DEC-010][DEC-031g P-T5-2][plan §8.1][Stanley & Doucouliagos 2013][Egger et al. 1997]
A7: PEESE (intercept) | B7: Spine + mods = ~ I(sez^2) (≡ vi); quadratic small-study approximation. | C7: [DEC-010][Stanley & Doucouliagos 2013]
A8: PET→PEESE rule flag | B8: value = 1{PET intercept p < .05, two-sided, CR2/Satterthwaite}; both models always reported; rule identical in every subgroup. | C8: [DEC-010][DEC-031g P-T5-1]
A9: One-per-cluster aggregates | B9: metafor aggregate.escalc, cluster = cluster_id, struct = "CS", rho = 0.6 → k = 114 (full) / 82 (pre) / 31 (post). | C9: [DEC-031g/F65][Borenstein et al. 2009][T1/A5 convention]
A10: 3PSM {mu, tau2, delta} | B10: rma(yi, vi, method="ML") → selmodel(type="stepfun", steps=0.025, alternative="less"); delta = relative publication probability of one-sided p > .025 results; LRT vs delta = 1. | C10: [DEC-016][DEC-031g/F63][Vevea & Hedges 1995][Carter et al. 2019]
A11: p-uniform* | B11: puni_star(yi, vi, side="left", method="ML"); estimate, CI, L.0 test, tau2. | C11: [DEC-016][van Aert & van Assen][DEC-031g P-T5-2]
A12: Grey-literature panel | B12: Spine cell-means zi ~ 0 + q_status (levels 0_published / 1_not published); contrast (−1, +1); between-group Wald HTZ. | C12: [DEC-031a.1][DEC-031g Q2/F60-pattern pins]
A13: Convergence protocol | B13: Continuous-regressor fits: ladder nlminb → optim/BFGS → optim/Nelder-Mead, first metafor-certified wins; fallback rows note-flagged; one BFGS control re-fit |Δβ| < 1e-5 (R6); factor-only cell-means default. | C13: [DEC-031f][plan A.11]
A14: Off-spine failure handling | B14: Pinned non-convergence signatures {converg, opposite sign} → not_estimable rows; any other condition = S5 stop. | C14: [DEC-031g P-T5-4]
A15: SESOI bands (read-out only) | B15: |r| = 0.070 primary (F27v2), |Δr| = 0.05 secondary — verdict read-outs per the resolved gate [DEC-044/DEC-047]. | C15: [DEC-031 Block E]

Sheet 3_Interpretation_Guide
A1: How to read the T5 quantities
A2: Decision rules with citations; claim-carrying verdicts per the resolved gate [DEC-044/DEC-047].
A3: df convention: Satterthwaite; Tipton df ≥ 4 for full inference [Tipton & Pustejovsky 2015].
A5: Quantity | B5: Meaning | C5: Decision rule
A6: FAT slope | B6: Association between effect size and its SE; negative = smaller studies report more negative effects. | C6: Two-sided p < .05 flags small-study asymmetry; direction pinned a priori (negative) [P-T5-2].
A7: PET intercept | B7: Regression-corrected mean at SE→0 (linear). | C7: p < .05 (two-sided, CR2/Satt) → rule selects PEESE as the claim-carrying corrected estimate [DEC-010].
A8: PEESE intercept | B8: Regression-corrected mean (quadratic); preferred when a genuine nonzero effect is plausible. | C8: Claim-carrying when the rule fires; reported alongside PET regardless [P-T5-1].
A9: 3PSM delta | B9: Relative publication probability of nonsignificant (one-sided p > .025) results; 1 = no selection. | C9: LRT vs delta = 1, alpha .05; delta < 1 indicates selection against nonsignificant results.
A10: 3PSM / p-uniform* mu | B10: Selection-adjusted mean effects (z scale) under two distinct selection mechanisms. | C10: Read jointly (concordance check); z-tests, no cluster df (aggregate level).
A11: Grey contrast (NP − P) | B11: Direct selection check: not-published minus published mean. | C11: Read against SESOI band; inference full (both cells ≥ 3 clusters [DEC-031g pin]).
A12: Realized df | B12: CR2/Satterthwaite df per coefficient; small df flag disclosed, not suppressed. | C12: df ≥ 4 full inference; smaller = descriptive read [Tipton & Pustejovsky 2015].
A13: Verdict lines | B13: Mechanical statements of estimates vs pre-registered rules. | C13: A-vs-C framing resolved → A [DEC-044]; wording register per DEC-047.

Sheet 4_Formula_Reference
A1: Exact R calls as implemented (R/05_bias.R @ 6bf40b1)
A2: Frozen constants: RHO 0.6 · STEPS_3PSM 0.025 · SEL_ALT "less" · PUNI_SIDE "left" · ALPHA_RULE .05 · TOL_R6 1e-5.
A3: Verifier re-fit (anchor): independent duplicate of the aggregation + rma.uni call [DEC-031g/F65].
A5: Quantity | B5: R call | C5: Script section
A6: Spine fit (ladder) | B6: rma.mv(yi=zi, V=impute_covariance_matrix(vi, cluster_id, r=0.6), mods=fml, random=~1|cluster_id/study/esid, sparse=TRUE, method="REML", control=list(optimizer=...)) | C6: fit3l(), §2
A7: CR2 tests / CIs | B7: coef_test(m, vcov=vcovCR(m, cluster, "CR2"), test="Satterthwaite"); conf_int(...); linear_contrast(...); Wald_test(..., constrain_equal(1:2), test="HTZ") | C7: §5 / §7
A8: Aggregates | B8: escalc(measure="GEN", yi, vi) |> aggregate(cluster=cluster_id, struct="CS", rho=0.6) | C8: make_agg(), §4
A9: 3PSM | B9: rma(yi, vi, method="ML") |> selmodel(type="stepfun", steps=0.025, alternative="less") | C9: selection_block(), §6
A10: p-uniform* | B10: puni_star(yi=agg$yi, vi=agg$vi, side="left", method="ML") | C10: selection_block(), §6
A11: T1/A5 anchor | B11: rma(yi, vi, data=agg, method="REML", test="knha") — df = k − 1 = 113 | C11: selection_block(), §6
A12: R6 control fit | B12: re-fit first nlminb spine fit under control=list(optimizer="optim", optmethod="BFGS"); assert max|Δβ| < 1e-5 | C12: §5

Sheet 5_Data_Provenance
A1: Data provenance and run certification — T5
A2: All domain quantities re-derived and verifier-asserted; design constants pinned ex ante (result-blind).
A3: Spot verification (post-recalc): 6_D1 est_z(PET intercept) = -0.0432 · 7_D2 est_z(mu_3psm) = +0.0117 · 9_D5 p(contrast) = 0.9279.
A5: Item | B5: Value | C5: Source
A6: Estimation set (D1/D2/D5) | B6: 2,713 ES / 115 studies / 114 clusters | C6: [DEC-042a]; verifier O9
A7: Period cells (D4) | B7: pre 1,994 ES / 83 studies / 82 clusters · post 711 / 31 / 31 · NA 8 ES / 2 studies (listwise from period cells only) | C7: [DEC-042b]; run_meta; O9
A8: Aggregates | B8: full 114 · pre 82 · post 31 (one-effect-per-cluster, CS rho = 0.6) | C8: [DEC-031g/F65]; O9/O14
A9: q_status cells (pinned ex ante) | B9: 0_published = 2,033 / 101 / 100 · 1_not published = 680 / 14 / 14; corpus raw 106/14, usable 103/14 (q_VHB raw 76/30/14, usable 74/29/14) | C9: [DEC-031g F60-pattern]; O10/O11
A10: Input contract | B10: output/dat_prep.rds md5 = 6702ef3dc45fe0b693b13f50ebd1576b (hard assert); pr$n = 2713; seed = 20260710 | C10: R/05_bias.R §1; O8
A11: Run stamp | B11: 2026-07-19 13:37:05 CEST · R 4.6.1 (Windows 11) · run basis @ 6bf40b1 | C11: output/T5_run_meta.txt
A12: Verifier | B12: 27/27 PASS, exit 0; anchor row value-located in T1_results.csv: 'A5 || one_effect_per_cluster'; frozen-constant canary 1e-9; independent re-fit 1e-6, df 113 | C12: R/05_verify_outputs.R; CC report 2026-07-19
A13: Convergence | B13: 7 certificates, all nlminb ladder rung 1/3 (no fallbacks); R6 control fit PASS, max|Δβ| = 5.665e-06 | C13: run_meta [DEC-031f]
A14: Direction pins | B14: selmodel alternative = "less" ≡ puni_star side = "left" (selection favors significant negative effects) | C14: [DEC-031g P-T5-2]; O16
A15: Known warnings | B15: clubSandwich deprecation of impute_covariance_matrix() (→ vcalc()): identical committed T8/T1 spine call, metafor-certified fits; migration = on-demand register candidate, no action in T5 | C15: CC transcript
A16: Absences (asserted) | B16: no D3/RoBMA rows (→ H2) · no bp rows [P-T5-5] · no trim-and-fill [DEC-031a.4] · no not_estimable rows this run | C16: O25/O20

Sheet 6_D1_FAT_PET_PEESE
A1: D1 — FAT-PET-PEESE on the full estimation set (2,713 ES / 115 studies / 114 clusters)
A2: Spine + mods ~sez (PET/FAT) and ~I(sez^2) (PEESE); CR2/Satterthwaite; ladder-certified (nlminb, rung 1).
A3: Rule [P-T5-1]: PET intercept p < .05 → PEESE carries the corrected-estimate claim; both reported.
A5: Term | B5: k (ES/St/Cl) | C5: est_z | D5: ci_lb_z | E5: ci_ub_z | F5: est_r | G5: ci_lb_r | H5: ci_ub_r | I5: df | J5: p
A6: PET intercept (corrected mean) | B6: =Results_Long!H2&" / "&Results_Long!I2&" / "&Results_Long!J2 -> 2713 / 115 / 114 | C6: =Results_Long!K2 -> -0.043157943 | D6: =Results_Long!P2 -> -0.076041494 | E6: =Results_Long!Q2 -> -0.010274392 | F6: =Results_Long!T2 -> -0.043131168 | G6: =Results_Long!U2 -> -0.075895267 | H6: =Results_Long!V2 -> -0.010274031 | I6: =Results_Long!N2 -> 100.32798 | J6: =Results_Long!O2 -> 0.010619718
A7: FAT slope (sez) | B7: =Results_Long!H3&" / "&Results_Long!I3&" / "&Results_Long!J3 -> 2713 / 115 / 114 | C7: =Results_Long!K3 -> -0.64221439 | D7: =Results_Long!P3 -> -1.2845269 | E7: =Results_Long!Q3 -> 9.8085614e-05 | F7: z-only | I7: =Results_Long!N3 -> 35.301112 | J7: =Results_Long!O3 -> 0.050033138
A8: PEESE intercept (corrected mean) | B8: =Results_Long!H4&" / "&Results_Long!I4&" / "&Results_Long!J4 -> 2713 / 115 / 114 | C8: =Results_Long!K4 -> -0.055198903 | D8: =Results_Long!P4 -> -0.083619272 | E8: =Results_Long!Q4 -> -0.026778534 | F8: =Results_Long!T4 -> -0.055142909 | G8: =Results_Long!U4 -> -0.083424922 | H8: =Results_Long!V4 -> -0.026772135 | I8: =Results_Long!N4 -> 109.9044 | J8: =Results_Long!O4 -> 0.00019947959
A9: PEESE slope (sez^2) | B9: =Results_Long!H5&" / "&Results_Long!I5&" / "&Results_Long!J5 -> 2713 / 115 / 114 | C9: =Results_Long!K5 -> -3.8704188 | D9: =Results_Long!P5 -> -10.694086 | E9: =Results_Long!Q5 -> 2.953248 | F9: z-only | I9: =Results_Long!N5 -> 6.3913416 | J9: =Results_Long!O5 -> 0.21759026
A11: Rule flag (1 = PEESE claim-carrying) | B11: =Results_Long!AG6 -> 1 | C11: ="PET intercept p = "&(IF(Results_Long!O2<0,"-","")&INT(ABS(ROUND(Results_Long!O2,4)))&"."&RIGHT("0000"&ROUND(MOD(ABS(ROUND(Results_Long!O2,4)),1)*10000,0),4))&" < 0.05 -> PEESE" -> PET intercept p = 0.0106 < 0.05 -> PEESE
A13: Interpretation
A14: Mechanical read: the PET intercept is significant at the pre-registered two-sided .05 (CR2/Satterthwaite), so the alignment rule selects PEESE as the claim-carrying corrected estimate; PET remains reported side by side [DEC-010]. The FAT slope is negative with p at the .05 boundary — small-study asymmetry evidence sits exactly at the conventional threshold (see Q&A).
A15: Corrected estimates (PET, PEESE) are smaller in magnitude than the unadjusted pooled mean (T1 headline r = −0,059; D2 tab, unadjusted aggregate −0,062) and retain the negative sign. Assessment against the SESOI band follows the resolved gate [DEC-044/DEC-047].
A17: Question | B17: Answer
A18: The FAT p-value is exactly 0.050 — is asymmetry 'significant'? | B18: The two-sided CR2/Satterthwaite p rounds to 0.0500 with the CI upper bound at +0.0001; the test sits on the boundary. No dichotomous claim is made; the corrected estimates (PET/PEESE) are the operative quantities [DEC-010], and the selection-model evidence (D2: LRT p = .025) is read jointly in D6.
A19: Why is PEESE claim-carrying if FAT is only borderline? | B19: The pre-registered rule conditions on the PET intercept (p = .011), not on FAT [DEC-010; P-T5-1]. The rule is mechanical and identical in every subgroup; no post hoc selection.
A20: The PEESE sez^2 slope has df = 6.4 — inference concern? | B20: The realized Satterthwaite df on the quadratic term is small and disclosed; the claim cell is the PEESE intercept (df = 109.9). Slope rows are diagnostic, not claim-carrying.
A22: =CONCATENATE("VERDICT (mechanical): Rule selects PEESE — corrected mean z = ",(IF(Results_Long!K4<0,"-","+")&INT(ABS(ROUND(Results_Long!K4,4)))&"."&RIGHT("0000"&ROUND(MOD(ABS(ROUND(Results_Long!K4,4)),1)*10000,0),4))," [",(IF(Results_Long!P4<0,"-","+")&INT(ABS(ROUND(Results_Long!P4,4)))&"."&RIGHT("0000"&ROUND(MOD(ABS(ROUND(Results_Long!P4,4)),1)*10000,0),4)),"; ",(IF(Results_Long!Q4<0,"-","+")&INT(ABS(ROUND(Results_Long!Q4,4)))&"."&RIGHT("0000"&ROUND(MOD(ABS(ROUND(Results_Long!Q4,4)),1)*10000,0),4)),"]; FAT p = ",(IF(Results_Long!O3<0,"-","")&INT(ABS(ROUND(Results_Long!O3,4)))&"."&RIGHT("0000"&ROUND(MOD(ABS(ROUND(Results_Long!O3,4)),1)*10000,0),4)),". Assessment: wording per the resolved gate [DEC-044/DEC-047].") -> VERDICT (mechanical): Rule selects PEESE — corrected mean z = -0.0552 [-0.0836; -0.0268]; FAT p = 0.0500. Assessment: wording per the resolved gate [DEC-044/DEC-047].

Sheet 7_D2_Selection_Models
A1: D2 — Selection models on one-effect-per-cluster aggregates (k = 114 from 2,713 ES)
A2: Base rma(ML) → 3PSM (stepfun, steps .025, alternative "less") · p-uniform* (side "left", ML) · T1/A5 anchor (REML, KnHa).
A3: Aggregation: metafor aggregate.escalc, struct "CS", rho 0.6 [DEC-031g/F63/F65].
A5: Term | B5: k (ES/St/Cl) | C5: est_z | D5: ci_lb_z | E5: ci_ub_z | F5: est_r | G5: ci_lb_r | H5: ci_ub_r | I5: df | J5: p
A6: Unadjusted RE/ML mean (base model) | B6: =Results_Long!H17&" / "&Results_Long!I17&" / "&Results_Long!J17 -> 2713 / 115 / 114 | C6: =Results_Long!K17 -> -0.061660035 | D6: =Results_Long!P17 -> -0.10914692 | E6: =Results_Long!Q17 -> -0.014173146 | F6: =Results_Long!T17 -> -0.06158201 | G6: =Results_Long!U17 -> -0.10871556 | H6: =Results_Long!V17 -> -0.014172197 | I6: =Results_Long!N17 -> 0 | J6: =Results_Long!O17 -> 0.010929544
A7: 3PSM adjusted mean | B7: =Results_Long!H19&" / "&Results_Long!I19&" / "&Results_Long!J19 -> 2713 / 115 / 114 | C7: =Results_Long!K19 -> 0.011689851 | D7: =Results_Long!P19 -> -0.070799372 | E7: =Results_Long!Q19 -> 0.094179075 | F7: =Results_Long!T19 -> 0.011689319 | G7: =Results_Long!U19 -> -0.070681314 | H7: =Results_Long!V19 -> 0.093901613 | I7: =Results_Long!N19 -> 0 | J7: =Results_Long!O19 -> 0.78120143
A8: p-uniform* adjusted mean | B8: =Results_Long!H23&" / "&Results_Long!I23&" / "&Results_Long!J23 -> 2713 / 115 / 114 | C8: =Results_Long!K23 -> 0.011840186 | D8: =Results_Long!P23 -> -0.068584635 | E8: =Results_Long!Q23 -> 0.097802261 | F8: =Results_Long!T23 -> 0.011839632 | G8: =Results_Long!U23 -> -0.0684773 | H8: =Results_Long!V23 -> 0.097491614 | I8: =Results_Long!N23 -> 0 | J8: =Results_Long!O23 -> 0.77760619
A9: T1/A5 anchor (REML, KnHa) | B9: =Results_Long!H25&" / "&Results_Long!I25&" / "&Results_Long!J25 -> 2713 / 115 / 114 | C9: =Results_Long!K25 -> -0.061660839 | D9: =Results_Long!P25 -> -0.10986426 | E9: =Results_Long!Q25 -> -0.013457412 | F9: =Results_Long!T25 -> -0.061582811 | G9: =Results_Long!U25 -> -0.10942436 | H9: =Results_Long!V25 -> -0.0134566 | I9: =Results_Long!N25 -> 113 | J9: =Results_Long!O25 -> 0.012636764
A11: Scalar | B11: Value | C11: Note
A12: tau2 unadjusted | B12: =Results_Long!AG18 -> 0.066435911
A13: tau2 3PSM | B13: =Results_Long!AG20 -> 0.068922443
A14: delta (3PSM) | B14: =Results_Long!AG21 -> 0.49144361
A15: tau2 p-uniform* | B15: =Results_Long!AG24 -> 0.069045623
A16: LRT delta = 1 (3PSM) | B16: =Results_Long!M22 -> 5.0525159 | C16: ="chi-square, df = 1, p = "&(IF(Results_Long!O22<0,"-","")&INT(ABS(ROUND(Results_Long!O22,4)))&"."&RIGHT("0000"&ROUND(MOD(ABS(ROUND(Results_Long!O22,4)),1)*10000,0),4)) -> chi-square, df = 1, p = 0.0246
A18: Interpretation
A19: Both selection models shift the adjusted mean from the unadjusted −0,062 to approximately +0,01 (z scale) with confidence intervals spanning zero; the two mechanisms agree to the third decimal. The 3PSM weight delta = 0,49 with LRT p = ,025 indicates selection against nonsignificant results in the aggregate corpus. tau2 is essentially unchanged across models (~0,067–0,069).
A20: The anchor row replicates the committed T1/A5 one-per-cluster estimate (df = 113) — verifier O13–O15 confirm identity at 1e-6 against the frozen full-precision constants. Cross-method assessment: D6 / TB-35, per the resolved gate [DEC-044/DEC-047].
A22: Question | B22: Answer
A23: Why z-tests (no df) on the selection-model rows? | B23: selmodel and puni_star inference is Wald-z / likelihood-based at the aggregate level; cluster-robust df do not apply. The df column is intentionally empty [schema convention].
A24: 3PSM and p-uniform* nearly coincide — expected? | B24: Both model one-sided selection at the .025 cutpoint in the pinned direction; concordance under a common mechanism is informative but not guaranteed. It is reported as a robustness observation, not pooled.
A25: Do the regression-based (D1) and selection-based (D2) corrections disagree? | B25: PET/PEESE retain a small negative corrected mean; 3PSM/p-uniform* move to ~0 with wide CIs. Method divergence of this kind is documented in Carter et al. (2019); the joint reading is staged in D6 and finalized in TB-35 per the resolved gate [DEC-044/DEC-047].
A27: =CONCATENATE("VERDICT (mechanical): 3PSM mu = ",(IF(Results_Long!K19<0,"-","+")&INT(ABS(ROUND(Results_Long!K19,4)))&"."&RIGHT("0000"&ROUND(MOD(ABS(ROUND(Results_Long!K19,4)),1)*10000,0),4))," [",(IF(Results_Long!P19<0,"-","+")&INT(ABS(ROUND(Results_Long!P19,4)))&"."&RIGHT("0000"&ROUND(MOD(ABS(ROUND(Results_Long!P19,4)),1)*10000,0),4)),"; ",(IF(Results_Long!Q19<0,"-","+")&INT(ABS(ROUND(Results_Long!Q19,4)))&"."&RIGHT("0000"&ROUND(MOD(ABS(ROUND(Results_Long!Q19,4)),1)*10000,0),4)),"], LRT p = ",(IF(Results_Long!O22<0,"-","")&INT(ABS(ROUND(Results_Long!O22,4)))&"."&RIGHT("0000"&ROUND(MOD(ABS(ROUND(Results_Long!O22,4)),1)*10000,0),4)),"; p-uniform* concordant. Assessment: wording per the resolved gate [DEC-044/DEC-047].") -> VERDICT (mechanical): 3PSM mu = +0.0117 [-0.0708; +0.0942], LRT p = 0.0246; p-uniform* concordant. Assessment: wording per the resolved gate [DEC-044/DEC-047].

Sheet 8_D4_Period_Split
A1: D4 — Pre/post-Paris publication-bias split (period domain 2,705; pre 1,994/83/82 · post 711/31/31)
A2: FAT-PET-PEESE per period (spine, ladder-certified) + selection models per period (upgrade FIRED [DEC-031a.5]: post cell 31 ≥ 20 studies).
A3: Identical rule and direction pins in both cells [P-T5-1/2]; appendix panel per plan §8.
A5: Pre-Paris cell (subset defined_pre)
A6: Term | B6: k (ES/St/Cl) | C6: est_z | D6: ci_lb_z | E6: ci_ub_z | F6: est_r | G6: ci_lb_r | H6: ci_ub_r | I6: df | J6: p
A7: PET intercept (pre) | B7: =Results_Long!H7&" / "&Results_Long!I7&" / "&Results_Long!J7 -> 1994 / 83 / 82 | C7: =Results_Long!K7 -> -0.045707923 | D7: =Results_Long!P7 -> -0.091360219 | E7: =Results_Long!Q7 -> -5.562832e-05 | F7: =Results_Long!T7 -> -0.045676119 | G7: =Results_Long!U7 -> -0.091106879 | H7: =Results_Long!V7 -> -5.562832e-05 | I7: =Results_Long!N7 -> 75.068685 | J7: =Results_Long!O7 -> 0.049728529
A8: FAT slope (pre) | B8: =Results_Long!H8&" / "&Results_Long!I8&" / "&Results_Long!J8 -> 1994 / 83 / 82 | C8: =Results_Long!K8 -> -0.58958191 | D8: =Results_Long!P8 -> -1.4302531 | E8: =Results_Long!Q8 -> 0.2510893 | F8: z-only | I8: =Results_Long!N8 -> 29.223934 | J8: =Results_Long!O8 -> 0.16221796
A9: PEESE intercept (pre) | B9: =Results_Long!H9&" / "&Results_Long!I9&" / "&Results_Long!J9 -> 1994 / 83 / 82 | C9: =Results_Long!K9 -> -0.057844862 | D9: =Results_Long!P9 -> -0.097907632 | E9: =Results_Long!Q9 -> -0.017782092 | F9: =Results_Long!T9 -> -0.057780431 | G9: =Results_Long!U9 -> -0.097595983 | H9: =Results_Long!V9 -> -0.017780218 | I9: =Results_Long!N9 -> 79.26547 | J9: =Results_Long!O9 -> 0.0052041753
A10: PEESE slope sez^2 (pre) | B10: =Results_Long!H10&" / "&Results_Long!I10&" / "&Results_Long!J10 -> 1994 / 83 / 82 | C10: =Results_Long!K10 -> -2.5200945 | D10: =Results_Long!P10 -> -12.83511 | E10: =Results_Long!Q10 -> 7.7949207 | F10: z-only | I10: =Results_Long!N10 -> 4.9667294 | J10: =Results_Long!O10 -> 0.55696236
A11: Unadjusted RE/ML mean (pre agg, k=82) | B11: =Results_Long!H26&" / "&Results_Long!I26&" / "&Results_Long!J26 -> 1994 / 83 / 82 | C11: =Results_Long!K26 -> -0.066681317 | D11: =Results_Long!P26 -> -0.13145732 | E11: =Results_Long!Q26 -> -0.0019053104 | F11: =Results_Long!T26 -> -0.066582662 | G11: =Results_Long!U26 -> -0.13070528 | H11: =Results_Long!V26 -> -0.0019053081 | I11: =Results_Long!N26 -> 0 | J11: =Results_Long!O26 -> 0.043631475
A12: 3PSM adjusted mean (pre) | B12: =Results_Long!H28&" / "&Results_Long!I28&" / "&Results_Long!J28 -> 1994 / 83 / 82 | C12: =Results_Long!K28 -> -0.021873758 | D12: =Results_Long!P28 -> -0.13151955 | E12: =Results_Long!Q28 -> 0.087772029 | F12: =Results_Long!T28 -> -0.021870271 | G12: =Results_Long!U28 -> -0.13076644 | H12: =Results_Long!V28 -> 0.087547325 | I12: =Results_Long!N28 -> 0 | J12: =Results_Long!O28 -> 0.69579538
A13: p-uniform* adjusted mean (pre) | B13: =Results_Long!H32&" / "&Results_Long!I32&" / "&Results_Long!J32 -> 1994 / 83 / 82 | C13: =Results_Long!K32 -> -0.02163994 | D13: =Results_Long!P32 -> -0.12909249 | E13: =Results_Long!Q32 -> 0.092718602 | F13: =Results_Long!T32 -> -0.021636562 | G13: =Results_Long!U32 -> -0.12838014 | H13: =Results_Long!V32 -> 0.09245382 | I13: =Results_Long!N32 -> 0 | J13: =Results_Long!O32 -> 0.70095639
A15: Post-Paris cell (subset defined_post)
A16: Term | B16: k (ES/St/Cl) | C16: est_z | D16: ci_lb_z | E16: ci_ub_z | F16: est_r | G16: ci_lb_r | H16: ci_ub_r | I16: df | J16: p
A17: PET intercept (post) | B17: =Results_Long!H12&" / "&Results_Long!I12&" / "&Results_Long!J12 -> 711 / 31 / 31 | C17: =Results_Long!K12 -> -0.02450192 | D17: =Results_Long!P12 -> -0.042210933 | E17: =Results_Long!Q12 -> -0.0067929062 | F17: =Results_Long!T12 -> -0.024497018 | G17: =Results_Long!U12 -> -0.042185881 | H17: =Results_Long!V12 -> -0.0067928017 | I17: =Results_Long!N12 -> 15.559826 | J17: =Results_Long!O12 -> 0.0098348328
A18: FAT slope (post) | B18: =Results_Long!H13&" / "&Results_Long!I13&" / "&Results_Long!J13 -> 711 / 31 / 31 | C18: =Results_Long!K13 -> -1.2375786 | D18: =Results_Long!P13 -> -2.0152655 | E18: =Results_Long!Q13 -> -0.45989172 | F18: z-only | I18: =Results_Long!N13 -> 11.829404 | J18: =Results_Long!O13 -> 0.004700619
A19: PEESE intercept (post) | B19: =Results_Long!H14&" / "&Results_Long!I14&" / "&Results_Long!J14 -> 711 / 31 / 31 | C19: =Results_Long!K14 -> -0.044590387 | D19: =Results_Long!P14 -> -0.06075909 | E19: =Results_Long!Q14 -> -0.028421683 | F19: =Results_Long!T14 -> -0.044560857 | G19: =Results_Long!U14 -> -0.060684433 | H19: =Results_Long!V14 -> -0.028414033 | I19: =Results_Long!N14 -> 25.39607 | J19: =Results_Long!O14 -> 6.2099503e-06
A20: PEESE slope sez^2 (post) | B20: =Results_Long!H15&" / "&Results_Long!I15&" / "&Results_Long!J15 -> 711 / 31 / 31 | C20: =Results_Long!K15 -> -8.4735243 | D20: =Results_Long!P15 -> -24.783574 | E20: =Results_Long!Q15 -> 7.8365254 | F20: z-only | I20: =Results_Long!N15 -> 1.9652601 | J20: =Results_Long!O15 -> 0.15309131
A21: Unadjusted RE/ML mean (post agg, k=31) | B21: =Results_Long!H34&" / "&Results_Long!I34&" / "&Results_Long!J34 -> 711 / 31 / 31 | C21: =Results_Long!K34 -> -0.045907401 | D21: =Results_Long!P34 -> -0.078771174 | E21: =Results_Long!Q34 -> -0.013043629 | F21: =Results_Long!T34 -> -0.045875179 | G21: =Results_Long!U34 -> -0.078608655 | H21: =Results_Long!V34 -> -0.013042889 | I21: =Results_Long!N34 -> 0 | J21: =Results_Long!O34 -> 0.006183785
A22: 3PSM adjusted mean (post) | B22: =Results_Long!H36&" / "&Results_Long!I36&" / "&Results_Long!J36 -> 711 / 31 / 31 | C22: =Results_Long!K36 -> -0.0060590998 | D22: =Results_Long!P36 -> -0.066252942 | E22: =Results_Long!Q36 -> 0.054134743 | F22: =Results_Long!T36 -> -0.0060590257 | G22: =Results_Long!U36 -> -0.066156174 | H22: =Results_Long!V36 -> 0.054081923 | I22: =Results_Long!N36 -> 0 | J22: =Results_Long!O36 -> 0.84360094
A23: p-uniform* adjusted mean (post) | B23: =Results_Long!H40&" / "&Results_Long!I40&" / "&Results_Long!J40 -> 711 / 31 / 31 | C23: =Results_Long!K40 -> -0.0080891642 | D23: =Results_Long!P40 -> -0.063585809 | E23: =Results_Long!Q40 -> 0.059763132 | F23: =Results_Long!T40 -> -0.0080889878 | G23: =Results_Long!U40 -> -0.063500252 | H23: =Results_Long!V40 -> 0.059692083 | I23: =Results_Long!N40 -> 0 | J23: =Results_Long!O40 -> 0.79318553
A25: Scalar (per period) | B25: pre | C25: post
A26: delta (3PSM) | B26: =Results_Long!AG30 -> 0.6857153 | C26: =Results_Long!AG38 -> 0.33803946
A27: LRT p (3PSM) | B27: =Results_Long!O31 -> 0.30845922 | C27: =Results_Long!O39 -> 0.079921547
A28: tau2 3PSM | B28: =Results_Long!AG29 -> 0.090846743 | C28: =Results_Long!AG37 -> 0.0091862318
A29: Rule flag (1 = PEESE) | B29: =Results_Long!AG11 -> 1 | C29: =Results_Long!AG16 -> 1
A31: Interpretation
A32: The rule selects PEESE in both cells (PET p = ,0497 pre · ,0098 post). FAT: no significant asymmetry pre (p = ,162); pronounced negative asymmetry post (slope −1,24, p = ,0047). Selection models attenuate toward zero in both periods (pre −0,022, post −0,006), with the 3PSM LRT nonsignificant pre (p = ,309) and marginal post (p = ,080). Realized df on the post sez^2 slope is 2,0 — disclosed; slope rows are diagnostic only.
A34: Question | B34: Answer
A35: Pre-cell PET p = 0.0497 — knife-edge rule firing? | B35: Yes, and disclosed: the rule fires by 0.0003. Both PET and PEESE are reported either way [P-T5-1]; the knife-edge is flagged for the D6 joint reading rather than resolved by relabeling.
A36: Post cell has only 31 studies / 31 clusters — are selection models admissible? | B36: The pre-registered upgrade fired at the ≥ 20-study threshold [DEC-031a.5]; k = 31 aggregates meets the van Aert & van Assen minimum. Wide CIs are expected and shown.
A37: Can pre/post bias parameters be compared inferentially? | B37: No formal pre-vs-post test of bias parameters is pre-registered; the split is an appendix disclosure panel [plan §8]. Differences are described, not tested.
A39: =CONCATENATE("VERDICT (mechanical): Rule → PEESE in both periods (pre ",(IF(Results_Long!K9<0,"-","+")&INT(ABS(ROUND(Results_Long!K9,4)))&"."&RIGHT("0000"&ROUND(MOD(ABS(ROUND(Results_Long!K9,4)),1)*10000,0),4))," · post ",(IF(Results_Long!K14<0,"-","+")&INT(ABS(ROUND(Results_Long!K14,4)))&"."&RIGHT("0000"&ROUND(MOD(ABS(ROUND(Results_Long!K14,4)),1)*10000,0),4)),"); FAT significant post only (p = ",(IF(Results_Long!O13<0,"-","")&INT(ABS(ROUND(Results_Long!O13,4)))&"."&RIGHT("0000"&ROUND(MOD(ABS(ROUND(Results_Long!O13,4)),1)*10000,0),4)),"). Assessment: wording per the resolved gate [DEC-044/DEC-047].") -> VERDICT (mechanical): Rule → PEESE in both periods (pre -0.0578 · post -0.0446); FAT significant post only (p = 0.0047). Assessment: wording per the resolved gate [DEC-044/DEC-047].

Sheet 9_D5_Grey_Literature
A1: D5 — Grey-literature panel (q_status), full estimation set 2,713 / 115 / 114
A2: Spine cell-means zi ~ 0 + q_status; CR2/Satterthwaite; contrast (−1, +1); between-group Wald HTZ.
A3: Cells pinned ex ante [DEC-031g F60-pattern]: 0_published = 2,033/101/100 · 1_not published = 680/14/14 (≥ 3 clusters → full inference).
A5: Term | B5: k (ES/St/Cl) | C5: est_z | D5: ci_lb_z | E5: ci_ub_z | F5: est_r | G5: ci_lb_r | H5: ci_ub_r | I5: df | J5: p
A6: Cell mean: published | B6: =Results_Long!H42&" / "&Results_Long!I42&" / "&Results_Long!J42 -> 2713 / 115 / 114 | C6: =Results_Long!K42 -> -0.059010252 | D6: =Results_Long!P42 -> -0.090092042 | E6: =Results_Long!Q42 -> -0.027928462 | F6: =Results_Long!T42 -> -0.058941852 | G6: =Results_Long!U42 -> -0.089849085 | H6: =Results_Long!V42 -> -0.027921202 | I6: =Results_Long!N42 -> 97.760757 | J6: =Results_Long!O42 -> 0.00028171285
A7: Cell mean: not published (WP/grey) | B7: =Results_Long!H43&" / "&Results_Long!I43&" / "&Results_Long!J43 -> 2713 / 115 / 114 | C7: =Results_Long!K43 -> -0.056539989 | D7: =Results_Long!P43 -> -0.10381833 | E7: =Results_Long!Q43 -> -0.0092616474 | F7: =Results_Long!T43 -> -0.056479817 | G7: =Results_Long!U43 -> -0.10344694 | H7: =Results_Long!V43 -> -0.0092613826 | I7: =Results_Long!N43 -> 12.987695 | J7: =Results_Long!O43 -> 0.022705427
A8: Contrast NP − P (z-only) | B8: =Results_Long!H44&" / "&Results_Long!I44&" / "&Results_Long!J44 -> 2713 / 115 / 114 | C8: =Results_Long!K44 -> 0.0024702629 | D8: =Results_Long!P44 -> -0.054267993 | E8: =Results_Long!Q44 -> 0.059208518 | F8: z-only | I8: =Results_Long!N44 -> 17.14411 | J8: =Results_Long!O44 -> 0.92792258
A10: Wald between groups (HTZ) | B10: =Results_Long!M45 -> 0.0084268904 | C10: ="F; df = "&(IF(Results_Long!N45<0,"-","")&INT(ABS(ROUND(Results_Long!N45,1)))&"."&RIGHT("0"&ROUND(MOD(ABS(ROUND(Results_Long!N45,1)),1)*10,0),1))&"; p = "&(IF(Results_Long!O45<0,"-","")&INT(ABS(ROUND(Results_Long!O45,4)))&"."&RIGHT("0000"&ROUND(MOD(ABS(ROUND(Results_Long!O45,4)),1)*10000,0),4))&"; num_df = 1" -> F; df = 17.1; p = 0.9279; num_df = 1
A12: Interpretation
A13: Published and not-published cells are nearly identical (−0,059 vs −0,057, z scale); the contrast is +0,0025 with a CI of [−0,054; +0,059] and p = ,928 — a precise null on the direct selection check, with full inference (Satterthwaite df = 17,1). This panel complements the model-based corrections: within the retrieved corpus, publication status does not stratify effect size.
A14: Scope note: the panel conditions on retrieval — it speaks to published-vs-grey differences inside the corpus, not to unretrieved studies; the model-based estimators (D1/D2) address the latter. Joint reading: D6 / TB-35, per the resolved gate [DEC-044/DEC-047].
A16: Question | B16: Answer
A17: Only 14 not-published studies — is the null informative? | B17: The CI [−0,054; +0,059] is the informativeness statement: it excludes |Δz| beyond ~0,06, inside the secondary SESOI band edge (0,05) on one side. The cell exceeds the 3-cluster inference floor [DEC-031g]; df = 17,1 supports full inference.
A18: Does a null grey-literature contrast contradict the 3PSM selection signal (LRT p = .025)? | B18: Not mechanically: D5 compares retrieved published vs retrieved grey; 3PSM models selection relative to the significance threshold irrespective of outlet. Both facts enter the D6 triangulation.
A20: =CONCATENATE("VERDICT (mechanical): Grey contrast = ",(IF(Results_Long!K44<0,"-","+")&INT(ABS(ROUND(Results_Long!K44,4)))&"."&RIGHT("0000"&ROUND(MOD(ABS(ROUND(Results_Long!K44,4)),1)*10000,0),4))," [",(IF(Results_Long!P44<0,"-","+")&INT(ABS(ROUND(Results_Long!P44,4)))&"."&RIGHT("0000"&ROUND(MOD(ABS(ROUND(Results_Long!P44,4)),1)*10000,0),4)),"; ",(IF(Results_Long!Q44<0,"-","+")&INT(ABS(ROUND(Results_Long!Q44,4)))&"."&RIGHT("0000"&ROUND(MOD(ABS(ROUND(Results_Long!Q44,4)),1)*10000,0),4)),"], p = ",(IF(Results_Long!O44<0,"-","")&INT(ABS(ROUND(Results_Long!O44,4)))&"."&RIGHT("0000"&ROUND(MOD(ABS(ROUND(Results_Long!O44,4)),1)*10000,0),4))," — precise null on the direct check. Assessment: wording per the resolved gate [DEC-044/DEC-047].") -> VERDICT (mechanical): Grey contrast = +0.0025 [-0.0543; +0.0592], p = 0.9279 — precise null on the direct check. Assessment: wording per the resolved gate [DEC-044/DEC-047].

Sheet 10_D6_Triangulation
A1: D6 — Triangulation across bias methods — STATUS: FINAL (post-gate sync 2026-07-29)
A2: Fed the A-vs-C framing decision → resolved A [DEC-044]; finalized after TH-b delivered the RoBMA line; end version references DEC-047 [DEC-031g].
A3: Mechanical convergence table; no claim-carrying language in this tab.
A5: FINAL — RoBMA row cited from TH-b/H2a (single home); wording per the resolved gate [DEC-044/DEC-047]
A7: Method | B7: est_z | C7: ci_lb_z | D7: ci_ub_z | E7: Status / note
A8: Unadjusted 3L-RVE headline (T1, r-scale −0,059) | E8: reference [T1 @ ce5d80b]
A9: Unadjusted RE/ML on aggregates | B9: =Results_Long!K17 -> -0.061660035 | C9: =Results_Long!P17 -> -0.10914692 | D9: =Results_Long!Q17 -> -0.014173146 | E9: base model
A10: PET (regression-corrected) | B10: =Results_Long!K2 -> -0.043157943 | C10: =Results_Long!P2 -> -0.076041494 | D10: =Results_Long!Q2 -> -0.010274392 | E10: rule: not claim-carrying (PEESE selected)
A11: PEESE (regression-corrected) | B11: =Results_Long!K4 -> -0.055198903 | C11: =Results_Long!P4 -> -0.083619272 | D11: =Results_Long!Q4 -> -0.026778534 | E11: claim-carrying per rule [P-T5-1]
A12: 3PSM (selection-adjusted) | B12: =Results_Long!K19 -> 0.011689851 | C12: =Results_Long!P19 -> -0.070799372 | D12: =Results_Long!Q19 -> 0.094179075 | E12: delta = 0,49; LRT p = ,025
A13: p-uniform* (selection-adjusted) | B13: =Results_Long!K23 -> 0.011840186 | C13: =Results_Long!P23 -> -0.068584635 | D13: =Results_Long!Q23 -> 0.097802261 | E13: concordant with 3PSM
A14: Grey-literature contrast (NP − P) | B14: =Results_Long!K44 -> 0.0024702629 | C14: =Results_Long!P44 -> -0.054267993 | D14: =Results_Long!Q44 -> 0.059208518 | E14: direct check: precise null
A15: RoBMA (Bayesian model averaging) | E15: per TH-b/H2a [single home; DEC-047]: model-averaged mean spike-bounded between −0.009 and +0.008 (95% CIs); BF01(effect) = 7.03 / 2.38 / 1.69; bias-block BF10 = 94.7 / 11.1 / 16.8; priors per DEC-031b
A17: Synthesis (mechanical; final per DEC-047)
A18: Regression-based corrections (PET/PEESE) retain a small negative mean (−0,04 to −0,06 z); selection-model corrections (3PSM, p-uniform*) move to ~0 with CIs spanning zero; the direct grey-literature check is a precise null; the 3PSM LRT indicates selection against nonsignificant results. All corrected point estimates lie inside the primary SESOI band (|r| = 0,070). RoBMA (cited from TH-b/H2a) brackets the model-averaged mean between −0.009 and +0.008 with strong selection-component inclusion — a prior-sensitivity complement, not a null verdict. The joint characterization is TB-35, per the resolved gate [DEC-044/DEC-047].
A20: VERDICT — Mechanical outcome: corrected estimates split by estimator family (regression −0.04 to −0.06 z vs selection ≈ 0), all inside the primary SESOI band (|r| = 0.070); RoBMA complements without a null verdict; wording per the resolved gate [DEC-044/DEC-047].

Sheet Results_Long
A1: analysis_id | B1: spec | C1: subset | D1: term | E1: metric | F1: estimator | G1: rho | H1: k_es | I1: k_study | J1: k_cluster | K1: est_z | L1: se_z | M1: t_stat | N1: df | O1: p | P1: ci_lb_z | Q1: ci_ub_z | R1: pi_lb_z | S1: pi_ub_z | T1: est_r | U1: ci_lb_r | V1: ci_ub_r | W1: pi_lb_r | X1: pi_ub_r | Y1: sigma2_cluster | Z1: sigma2_study | AA1: sigma2_esid | AB1: pct_cluster | AC1: pct_study | AD1: pct_esid | AE1: pct_sampling | AF1: typical_v | AG1: value | AH1: ms_input | AI1: ms_label | AJ1: note
A2: D1 | B2: pet | C2: full | D2: intercept | E2: Fisher_z | F2: 3LMA-RVE_CR2 | G2: 0.6 | H2: 2713 | I2: 115 | J2: 114 | K2: -0.043157943 | L2: 0.016575272 | M2: -2.6037548 | N2: 100.32798 | O2: 0.010619718 | P2: -0.076041494 | Q2: -0.010274392 | T2: -0.043131168 | U2: -0.075895267 | V2: -0.010274031 | Y2: 0.019328304 | Z2: 1.4504953e-09 | AA2: 0.011867155 | AH2: =TRUE() -> TRUE | AI2: pet_full | AJ2: rma.mv mods=~ sez (sez = sqrt(vi), in-script [P-T5-2]); random ~1|cluster_id/study/esid; V blocks within cluster_id, rho=0.6; CR2/Satterthwaite on cluster_id [D31.1/A.2]; domain 2,713/115/114 [DEC-042a]; intercept = PET estimate of the selection-adjusted mean, slope = FAT (Egger-type small-study test) [DEC-010; plan Section 8.1]
A3: D1 | B3: pet | C3: full | D3: sez | E3: Fisher_z | F3: 3LMA-RVE_CR2 | G3: 0.6 | H3: 2713 | I3: 115 | J3: 114 | K3: -0.64221439 | L3: 0.31648974 | M3: -2.0291792 | N3: 35.301112 | O3: 0.050033138 | P3: -1.2845269 | Q3: 9.8085614e-05 | Y3: 0.019328304 | Z3: 1.4504953e-09 | AA3: 0.011867155 | AH3: =TRUE() -> TRUE | AI3: fat_full | AJ3: rma.mv mods=~ sez (sez = sqrt(vi), in-script [P-T5-2]); random ~1|cluster_id/study/esid; V blocks within cluster_id, rho=0.6; CR2/Satterthwaite on cluster_id [D31.1/A.2]; domain 2,713/115/114 [DEC-042a]; intercept = PET estimate of the selection-adjusted mean, slope = FAT (Egger-type small-study test) [DEC-010; plan Section 8.1]
A4: D1 | B4: peese | C4: full | D4: intercept | E4: Fisher_z | F4: 3LMA-RVE_CR2 | G4: 0.6 | H4: 2713 | I4: 115 | J4: 114 | K4: -0.055198903 | L4: 0.014340797 | M4: -3.8490819 | N4: 109.9044 | O4: 0.00019947959 | P4: -0.083619272 | Q4: -0.026778534 | T4: -0.055142909 | U4: -0.083424922 | V4: -0.026772135 | Y4: 0.019647042 | Z4: 2.9652894e-09 | AA4: 0.01186788 | AH4: =TRUE() -> TRUE | AI4: peese_full | AJ4: rma.mv mods=~ I(sez^2) (== vi [P-T5-2]); random ~1|cluster_id/study/esid; V blocks within cluster_id, rho=0.6; CR2/Satterthwaite on cluster_id [D31.1/A.2]; domain 2,713/115/114 [DEC-042a]; intercept = PEESE estimate; computed and reported unconditionally, side by side [DEC-010; P-T5-1]
A5: D1 | B5: peese | C5: full | D5: sez_sq | E5: Fisher_z | F5: 3LMA-RVE_CR2 | G5: 0.6 | H5: 2713 | I5: 115 | J5: 114 | K5: -3.8704188 | L5: 2.8301653 | M5: -1.3675593 | N5: 6.3913416 | O5: 0.21759026 | P5: -10.694086 | Q5: 2.953248 | Y5: 0.019647042 | Z5: 2.9652894e-09 | AA5: 0.01186788 | AH5: =FALSE() -> FALSE | AJ5: rma.mv mods=~ I(sez^2) (== vi [P-T5-2]); random ~1|cluster_id/study/esid; V blocks within cluster_id, rho=0.6; CR2/Satterthwaite on cluster_id [D31.1/A.2]; domain 2,713/115/114 [DEC-042a]; intercept = PEESE estimate; computed and reported unconditionally, side by side [DEC-010; P-T5-1]
A6: D1 | B6: rule | C6: full | D6: pet_peese_rule | E6: flag | F6: rule | H6: 2713 | I6: 115 | J6: 114 | AG6: 1 | AH6: =TRUE() -> TRUE | AI6: pet_peese_rule_full | AJ6: conditional PET->PEESE alignment [DEC-010; DEC-031g P-T5-1]: value 1 = PEESE carries the corrected-estimate claim (PET intercept p = 0.010620 < 0.05, two-sided, CR2/Satterthwaite), value 0 = PET carries it; both models reported side by side regardless; identical rule in every subgroup
A7: D4 | B7: pet_pre | C7: defined_pre | D7: intercept | E7: Fisher_z | F7: 3LMA-RVE_CR2 | G7: 0.6 | H7: 1994 | I7: 83 | J7: 82 | K7: -0.045707923 | L7: 0.022916987 | M7: -1.9944997 | N7: 75.068685 | O7: 0.049728529 | P7: -0.091360219 | Q7: -5.562832e-05 | T7: -0.045676119 | U7: -0.091106879 | V7: -5.562832e-05 | Y7: 0.027897221 | Z7: 1.657482e-09 | AA7: 0.014243315 | AH7: =TRUE() -> TRUE | AI7: pet_pre | AJ7: rma.mv mods=~ sez (sez = sqrt(vi), in-script [P-T5-2]); random ~1|cluster_id/study/esid; V blocks within cluster_id, rho=0.6; CR2/Satterthwaite on cluster_id [D31.1/A.2]; domain pre cell 1,994/83/82 [DEC-042b]; intercept = PET estimate of the selection-adjusted mean, slope = FAT (Egger-type small-study test) [DEC-010; plan Section 8.1]
A8: D4 | B8: pet_pre | C8: defined_pre | D8: sez | E8: Fisher_z | F8: 3LMA-RVE_CR2 | G8: 0.6 | H8: 1994 | I8: 83 | J8: 82 | K8: -0.58958191 | L8: 0.41117682 | M8: -1.433889 | N8: 29.223934 | O8: 0.16221796 | P8: -1.4302531 | Q8: 0.2510893 | Y8: 0.027897221 | Z8: 1.657482e-09 | AA8: 0.014243315 | AH8: =FALSE() -> FALSE | AJ8: rma.mv mods=~ sez (sez = sqrt(vi), in-script [P-T5-2]); random ~1|cluster_id/study/esid; V blocks within cluster_id, rho=0.6; CR2/Satterthwaite on cluster_id [D31.1/A.2]; domain pre cell 1,994/83/82 [DEC-042b]; intercept = PET estimate of the selection-adjusted mean, slope = FAT (Egger-type small-study test) [DEC-010; plan Section 8.1]
A9: D4 | B9: peese_pre | C9: defined_pre | D9: intercept | E9: Fisher_z | F9: 3LMA-RVE_CR2 | G9: 0.6 | H9: 1994 | I9: 83 | J9: 82 | K9: -0.057844862 | L9: 0.02012854 | M9: -2.8737734 | N9: 79.26547 | O9: 0.0052041753 | P9: -0.097907632 | Q9: -0.017782092 | T9: -0.057780431 | U9: -0.097595983 | V9: -0.017780218 | Y9: 0.028155496 | Z9: 1.7684629e-09 | AA9: 0.014253443 | AH9: =FALSE() -> FALSE | AJ9: rma.mv mods=~ I(sez^2) (== vi [P-T5-2]); random ~1|cluster_id/study/esid; V blocks within cluster_id, rho=0.6; CR2/Satterthwaite on cluster_id [D31.1/A.2]; domain pre cell 1,994/83/82 [DEC-042b]; intercept = PEESE estimate; computed and reported unconditionally, side by side [DEC-010; P-T5-1]
A10: D4 | B10: peese_pre | C10: defined_pre | D10: sez_sq | E10: Fisher_z | F10: 3LMA-RVE_CR2 | G10: 0.6 | H10: 1994 | I10: 83 | J10: 82 | K10: -2.5200945 | L10: 4.0046341 | M10: -0.62929456 | N10: 4.9667294 | O10: 0.55696236 | P10: -12.83511 | Q10: 7.7949207 | Y10: 0.028155496 | Z10: 1.7684629e-09 | AA10: 0.014253443 | AH10: =FALSE() -> FALSE | AJ10: rma.mv mods=~ I(sez^2) (== vi [P-T5-2]); random ~1|cluster_id/study/esid; V blocks within cluster_id, rho=0.6; CR2/Satterthwaite on cluster_id [D31.1/A.2]; domain pre cell 1,994/83/82 [DEC-042b]; intercept = PEESE estimate; computed and reported unconditionally, side by side [DEC-010; P-T5-1]
A11: D4 | B11: rule_pre | C11: defined_pre | D11: pet_peese_rule | E11: flag | F11: rule | H11: 1994 | I11: 83 | J11: 82 | AG11: 1 | AH11: =FALSE() -> FALSE | AJ11: conditional PET->PEESE alignment [DEC-010; DEC-031g P-T5-1]: value 1 = PEESE carries the corrected-estimate claim (PET intercept p = 0.049729 < 0.05, two-sided, CR2/Satterthwaite), value 0 = PET carries it; both models reported side by side regardless; identical rule in every subgroup
A12: D4 | B12: pet_post | C12: defined_post | D12: intercept | E12: Fisher_z | F12: 3LMA-RVE_CR2 | G12: 0.6 | H12: 711 | I12: 31 | J12: 31 | K12: -0.02450192 | L12: 0.0083344782 | M12: -2.9398265 | N12: 15.559826 | O12: 0.0098348328 | P12: -0.042210933 | Q12: -0.0067929062 | T12: -0.024497018 | U12: -0.042185881 | V12: -0.0067928017 | Y12: 0.00033634103 | Z12: 0.00033634085 | AA12: 0.0047503377 | AH12: =TRUE() -> TRUE | AI12: pet_post | AJ12: rma.mv mods=~ sez (sez = sqrt(vi), in-script [P-T5-2]); random ~1|cluster_id/study/esid; V blocks within cluster_id, rho=0.6; CR2/Satterthwaite on cluster_id [D31.1/A.2]; domain post cell 711/31/31 [DEC-042b]; intercept = PET estimate of the selection-adjusted mean, slope = FAT (Egger-type small-study test) [DEC-010; plan Section 8.1]
A13: D4 | B13: pet_post | C13: defined_post | D13: sez | E13: Fisher_z | F13: 3LMA-RVE_CR2 | G13: 0.6 | H13: 711 | I13: 31 | J13: 31 | K13: -1.2375786 | L13: 0.35636066 | M13: -3.4728261 | N13: 11.829404 | O13: 0.004700619 | P13: -2.0152655 | Q13: -0.45989172 | Y13: 0.00033634103 | Z13: 0.00033634085 | AA13: 0.0047503377 | AH13: =FALSE() -> FALSE | AJ13: rma.mv mods=~ sez (sez = sqrt(vi), in-script [P-T5-2]); random ~1|cluster_id/study/esid; V blocks within cluster_id, rho=0.6; CR2/Satterthwaite on cluster_id [D31.1/A.2]; domain post cell 711/31/31 [DEC-042b]; intercept = PET estimate of the selection-adjusted mean, slope = FAT (Egger-type small-study test) [DEC-010; plan Section 8.1]
A14: D4 | B14: peese_post | C14: defined_post | D14: intercept | E14: Fisher_z | F14: 3LMA-RVE_CR2 | G14: 0.6 | H14: 711 | I14: 31 | J14: 31 | K14: -0.044590387 | L14: 0.0078568522 | M14: -5.6753501 | N14: 25.39607 | O14: 6.2099503e-06 | P14: -0.06075909 | Q14: -0.028421683 | T14: -0.044560857 | U14: -0.060684433 | V14: -0.028414033 | Y14: 0.00053781451 | Z14: 0.00053781451 | AA14: 0.0047224718 | AH14: =FALSE() -> FALSE | AJ14: rma.mv mods=~ I(sez^2) (== vi [P-T5-2]); random ~1|cluster_id/study/esid; V blocks within cluster_id, rho=0.6; CR2/Satterthwaite on cluster_id [D31.1/A.2]; domain post cell 711/31/31 [DEC-042b]; intercept = PEESE estimate; computed and reported unconditionally, side by side [DEC-010; P-T5-1]
A15: D4 | B15: peese_post | C15: defined_post | D15: sez_sq | E15: Fisher_z | F15: 3LMA-RVE_CR2 | G15: 0.6 | H15: 711 | I15: 31 | J15: 31 | K15: -8.4735243 | L15: 3.7268473 | M15: -2.2736441 | N15: 1.9652601 | O15: 0.15309131 | P15: -24.783574 | Q15: 7.8365254 | Y15: 0.00053781451 | Z15: 0.00053781451 | AA15: 0.0047224718 | AH15: =FALSE() -> FALSE | AJ15: rma.mv mods=~ I(sez^2) (== vi [P-T5-2]); random ~1|cluster_id/study/esid; V blocks within cluster_id, rho=0.6; CR2/Satterthwaite on cluster_id [D31.1/A.2]; domain post cell 711/31/31 [DEC-042b]; intercept = PEESE estimate; computed and reported unconditionally, side by side [DEC-010; P-T5-1]
A16: D4 | B16: rule_post | C16: defined_post | D16: pet_peese_rule | E16: flag | F16: rule | H16: 711 | I16: 31 | J16: 31 | AG16: 1 | AH16: =FALSE() -> FALSE | AJ16: conditional PET->PEESE alignment [DEC-010; DEC-031g P-T5-1]: value 1 = PEESE carries the corrected-estimate claim (PET intercept p = 0.009835 < 0.05, two-sided, CR2/Satterthwaite), value 0 = PET carries it; both models reported side by side regardless; identical rule in every subgroup
A17: D2 | B17: selection_full | C17: full | D17: mu_unadjusted_ML | E17: Fisher_z | F17: RE_ML_cluster_agg | G17: 0.6 | H17: 2713 | I17: 115 | J17: 114 | K17: -0.061660035 | L17: 0.02422845 | M17: -2.5449435 | O17: 0.010929544 | P17: -0.10914692 | Q17: -0.014173146 | T17: -0.06158201 | U17: -0.10871556 | V17: -0.014172197 | AH17: =FALSE() -> FALSE | AJ17: one-effect-per-cluster aggregates: metafor aggregate.escalc, struct="CS", rho=0.6 (T1/A5 convention [DEC-031g/F65]); domain 2,713/115/114 [DEC-042a]; k = 114 aggregates from 2713 ES; rma.uni method="ML" (selmodel base [DEC-031g/F63]); z-test
A18: D2 | B18: selection_full | C18: full | D18: tau2_unadjusted | E18: tau2 | F18: RE_ML_cluster_agg | G18: 0.6 | H18: 2713 | I18: 115 | J18: 114 | AG18: 0.066435911 | AH18: =FALSE() -> FALSE | AJ18: one-effect-per-cluster aggregates: metafor aggregate.escalc, struct="CS", rho=0.6 (T1/A5 convention [DEC-031g/F65]); domain 2,713/115/114 [DEC-042a]; k = 114 aggregates from 2713 ES; between-aggregate tau2, ML
A19: D2 | B19: selection_full | C19: full | D19: mu_3psm | E19: Fisher_z | F19: selmodel_3PSM_ML | G19: 0.6 | H19: 2713 | I19: 115 | J19: 114 | K19: 0.011689851 | L19: 0.042087112 | M19: 0.27775371 | O19: 0.78120143 | P19: -0.070799372 | Q19: 0.094179075 | T19: 0.011689319 | U19: -0.070681314 | V19: 0.093901613 | AH19: =TRUE() -> TRUE | AI19: mu_3psm_full | AJ19: one-effect-per-cluster aggregates: metafor aggregate.escalc, struct="CS", rho=0.6 (T1/A5 convention [DEC-031g/F65]); domain 2,713/115/114 [DEC-042a]; k = 114 aggregates from 2713 ES; selmodel(type="stepfun", steps=0.025, alternative="less") on the ML base -> 3PSM {mu, tau2, delta} [DEC-016; DEC-031g/F63; P-T5-2: selection favors significant negative effects]
A20: D2 | B20: selection_full | C20: full | D20: tau2_3psm | E20: tau2 | F20: selmodel_3PSM_ML | G20: 0.6 | H20: 2713 | I20: 115 | J20: 114 | AG20: 0.068922443 | AH20: =FALSE() -> FALSE | AJ20: one-effect-per-cluster aggregates: metafor aggregate.escalc, struct="CS", rho=0.6 (T1/A5 convention [DEC-031g/F65]); domain 2,713/115/114 [DEC-042a]; k = 114 aggregates from 2713 ES; selmodel(type="stepfun", steps=0.025, alternative="less") on the ML base -> 3PSM {mu, tau2, delta} [DEC-016; DEC-031g/F63; P-T5-2: selection favors significant negative effects]
A21: D2 | B21: selection_full | C21: full | D21: delta_3psm | E21: delta | F21: selmodel_3PSM_ML | G21: 0.6 | H21: 2713 | I21: 115 | J21: 114 | AG21: 0.49144361 | AH21: =FALSE() -> FALSE | AJ21: one-effect-per-cluster aggregates: metafor aggregate.escalc, struct="CS", rho=0.6 (T1/A5 convention [DEC-031g/F65]); domain 2,713/115/114 [DEC-042a]; k = 114 aggregates from 2713 ES; selmodel(type="stepfun", steps=0.025, alternative="less") on the ML base -> 3PSM {mu, tau2, delta} [DEC-016; DEC-031g/F63; P-T5-2: selection favors significant negative effects]; relative publication probability of one-sided p > 0.025 results (reference interval weight = 1)
A22: D2 | B22: selection_full | C22: full | D22: lrt_3psm | E22: LRT_test | F22: selmodel_3PSM_ML | G22: 0.6 | H22: 2713 | I22: 115 | J22: 114 | M22: 5.0525159 | N22: 1 | O22: 0.024590207 | AH22: =FALSE() -> FALSE | AJ22: one-effect-per-cluster aggregates: metafor aggregate.escalc, struct="CS", rho=0.6 (T1/A5 convention [DEC-031g/F65]); domain 2,713/115/114 [DEC-042a]; k = 114 aggregates from 2713 ES; selmodel(type="stepfun", steps=0.025, alternative="less") on the ML base -> 3PSM {mu, tau2, delta} [DEC-016; DEC-031g/F63; P-T5-2: selection favors significant negative effects]; LRT of H0: delta = 1 (no selection); chi-square stat in t_stat, df in df
A23: D2 | B23: selection_full | C23: full | D23: mu_punistar | E23: Fisher_z | F23: puni_star_ML | G23: 0.6 | H23: 2713 | I23: 115 | J23: 114 | K23: 0.011840186 | M23: 0.07977232 | O23: 0.77760619 | P23: -0.068584635 | Q23: 0.097802261 | T23: 0.011839632 | U23: -0.0684773 | V23: 0.097491614 | AH23: =TRUE() -> TRUE | AI23: mu_punistar_full | AJ23: one-effect-per-cluster aggregates: metafor aggregate.escalc, struct="CS", rho=0.6 (T1/A5 convention [DEC-031g/F65]); domain 2,713/115/114 [DEC-042a]; k = 114 aggregates from 2713 ES; puni_star(side="left", method="ML") [DEC-016; van Aert & van Assen; P-T5-2 direction pin, jointly with selmodel alternative="less"]; test statistic (L.0) in t_stat; SE not part of the p-uniform* output
A24: D2 | B24: selection_full | C24: full | D24: tau2_punistar | E24: tau2 | F24: puni_star_ML | G24: 0.6 | H24: 2713 | I24: 115 | J24: 114 | AG24: 0.069045623 | AH24: =FALSE() -> FALSE | AJ24: one-effect-per-cluster aggregates: metafor aggregate.escalc, struct="CS", rho=0.6 (T1/A5 convention [DEC-031g/F65]); domain 2,713/115/114 [DEC-042a]; k = 114 aggregates from 2713 ES; puni_star(side="left", method="ML") [DEC-016; van Aert & van Assen; P-T5-2 direction pin, jointly with selmodel alternative="less"]
A25: D2 | B25: selection_full | C25: full | D25: mu_anchor_reml_knha | E25: Fisher_z | F25: RE_REML_knha_cluster_agg | G25: 0.6 | H25: 2713 | I25: 115 | J25: 114 | K25: -0.061660839 | L25: 0.02433066 | M25: -2.5342855 | N25: 113 | O25: 0.012636764 | P25: -0.10986426 | Q25: -0.013457412 | T25: -0.061582811 | U25: -0.10942436 | V25: -0.0134566 | AH25: =FALSE() -> FALSE | AJ25: one-effect-per-cluster aggregates: metafor aggregate.escalc, struct="CS", rho=0.6 (T1/A5 convention [DEC-031g/F65]); domain 2,713/115/114 [DEC-042a]; k = 114 aggregates from 2713 ES; rma.uni method="REML", test="knha" == T1/A5 one-per-cluster identity anchor [DEC-031g/F65]; verifier re-fits independently and checks against committed output/T1_results.csv
A26: D4 | B26: selection_pre | C26: defined_pre | D26: mu_unadjusted_ML | E26: Fisher_z | F26: RE_ML_cluster_agg | G26: 0.6 | H26: 1994 | I26: 83 | J26: 82 | K26: -0.066681317 | L26: 0.03304959 | M26: -2.017614 | O26: 0.043631475 | P26: -0.13145732 | Q26: -0.0019053104 | T26: -0.066582662 | U26: -0.13070528 | V26: -0.0019053081 | AH26: =FALSE() -> FALSE | AJ26: one-effect-per-cluster aggregates: metafor aggregate.escalc, struct="CS", rho=0.6 (T1/A5 convention [DEC-031g/F65]); domain pre cell 1,994/83/82 [DEC-042b]; k = 82 aggregates from 1994 ES; rma.uni method="ML" (selmodel base [DEC-031g/F63]); z-test
A27: D4 | B27: selection_pre | C27: defined_pre | D27: tau2_unadjusted | E27: tau2 | F27: RE_ML_cluster_agg | G27: 0.6 | H27: 1994 | I27: 83 | J27: 82 | AG27: 0.089076092 | AH27: =FALSE() -> FALSE | AJ27: one-effect-per-cluster aggregates: metafor aggregate.escalc, struct="CS", rho=0.6 (T1/A5 convention [DEC-031g/F65]); domain pre cell 1,994/83/82 [DEC-042b]; k = 82 aggregates from 1994 ES; between-aggregate tau2, ML
A28: D4 | B28: selection_pre | C28: defined_pre | D28: mu_3psm | E28: Fisher_z | F28: selmodel_3PSM_ML | G28: 0.6 | H28: 1994 | I28: 83 | J28: 82 | K28: -0.021873758 | L28: 0.055942756 | M28: -0.39100252 | O28: 0.69579538 | P28: -0.13151955 | Q28: 0.087772029 | T28: -0.021870271 | U28: -0.13076644 | V28: 0.087547325 | AH28: =FALSE() -> FALSE | AJ28: one-effect-per-cluster aggregates: metafor aggregate.escalc, struct="CS", rho=0.6 (T1/A5 convention [DEC-031g/F65]); domain pre cell 1,994/83/82 [DEC-042b]; k = 82 aggregates from 1994 ES; selmodel(type="stepfun", steps=0.025, alternative="less") on the ML base -> 3PSM {mu, tau2, delta} [DEC-016; DEC-031g/F63; P-T5-2: selection favors significant negative effects]
A29: D4 | B29: selection_pre | C29: defined_pre | D29: tau2_3psm | E29: tau2 | F29: selmodel_3PSM_ML | G29: 0.6 | H29: 1994 | I29: 83 | J29: 82 | AG29: 0.090846743 | AH29: =FALSE() -> FALSE | AJ29: one-effect-per-cluster aggregates: metafor aggregate.escalc, struct="CS", rho=0.6 (T1/A5 convention [DEC-031g/F65]); domain pre cell 1,994/83/82 [DEC-042b]; k = 82 aggregates from 1994 ES; selmodel(type="stepfun", steps=0.025, alternative="less") on the ML base -> 3PSM {mu, tau2, delta} [DEC-016; DEC-031g/F63; P-T5-2: selection favors significant negative effects]
A30: D4 | B30: selection_pre | C30: defined_pre | D30: delta_3psm | E30: delta | F30: selmodel_3PSM_ML | G30: 0.6 | H30: 1994 | I30: 83 | J30: 82 | AG30: 0.6857153 | AH30: =FALSE() -> FALSE | AJ30: one-effect-per-cluster aggregates: metafor aggregate.escalc, struct="CS", rho=0.6 (T1/A5 convention [DEC-031g/F65]); domain pre cell 1,994/83/82 [DEC-042b]; k = 82 aggregates from 1994 ES; selmodel(type="stepfun", steps=0.025, alternative="less") on the ML base -> 3PSM {mu, tau2, delta} [DEC-016; DEC-031g/F63; P-T5-2: selection favors significant negative effects]; relative publication probability of one-sided p > 0.025 results (reference interval weight = 1)
A31: D4 | B31: selection_pre | C31: defined_pre | D31: lrt_3psm | E31: LRT_test | F31: selmodel_3PSM_ML | G31: 0.6 | H31: 1994 | I31: 83 | J31: 82 | M31: 1.0372615 | N31: 1 | O31: 0.30845922 | AH31: =FALSE() -> FALSE | AJ31: one-effect-per-cluster aggregates: metafor aggregate.escalc, struct="CS", rho=0.6 (T1/A5 convention [DEC-031g/F65]); domain pre cell 1,994/83/82 [DEC-042b]; k = 82 aggregates from 1994 ES; selmodel(type="stepfun", steps=0.025, alternative="less") on the ML base -> 3PSM {mu, tau2, delta} [DEC-016; DEC-031g/F63; P-T5-2: selection favors significant negative effects]; LRT of H0: delta = 1 (no selection); chi-square stat in t_stat, df in df
A32: D4 | B32: selection_pre | C32: defined_pre | D32: mu_punistar | E32: Fisher_z | F32: puni_star_ML | G32: 0.6 | H32: 1994 | I32: 83 | J32: 82 | K32: -0.02163994 | M32: 0.14747886 | O32: 0.70095639 | P32: -0.12909249 | Q32: 0.092718602 | T32: -0.021636562 | U32: -0.12838014 | V32: 0.09245382 | AH32: =FALSE() -> FALSE | AJ32: one-effect-per-cluster aggregates: metafor aggregate.escalc, struct="CS", rho=0.6 (T1/A5 convention [DEC-031g/F65]); domain pre cell 1,994/83/82 [DEC-042b]; k = 82 aggregates from 1994 ES; puni_star(side="left", method="ML") [DEC-016; van Aert & van Assen; P-T5-2 direction pin, jointly with selmodel alternative="less"]; test statistic (L.0) in t_stat; SE not part of the p-uniform* output
A33: D4 | B33: selection_pre | C33: defined_pre | D33: tau2_punistar | E33: tau2 | F33: puni_star_ML | G33: 0.6 | H33: 1994 | I33: 83 | J33: 82 | AG33: 0.091119111 | AH33: =FALSE() -> FALSE | AJ33: one-effect-per-cluster aggregates: metafor aggregate.escalc, struct="CS", rho=0.6 (T1/A5 convention [DEC-031g/F65]); domain pre cell 1,994/83/82 [DEC-042b]; k = 82 aggregates from 1994 ES; puni_star(side="left", method="ML") [DEC-016; van Aert & van Assen; P-T5-2 direction pin, jointly with selmodel alternative="less"]
A34: D4 | B34: selection_post | C34: defined_post | D34: mu_unadjusted_ML | E34: Fisher_z | F34: RE_ML_cluster_agg | G34: 0.6 | H34: 711 | I34: 31 | J34: 31 | K34: -0.045907401 | L34: 0.016767539 | M34: -2.7378735 | O34: 0.006183785 | P34: -0.078771174 | Q34: -0.013043629 | T34: -0.045875179 | U34: -0.078608655 | V34: -0.013042889 | AH34: =FALSE() -> FALSE | AJ34: one-effect-per-cluster aggregates: metafor aggregate.escalc, struct="CS", rho=0.6 (T1/A5 convention [DEC-031g/F65]); domain post cell 711/31/31 [DEC-042b; upgrade FIRED per DEC-031a.5: post cell 31 >= 20 studies]; k = 31 aggregates from 711 ES; rma.uni method="ML" (selmodel base [DEC-031g/F63]); z-test
A35: D4 | B35: selection_post | C35: defined_post | D35: tau2_unadjusted | E35: tau2 | F35: RE_ML_cluster_agg | G35: 0.6 | H35: 711 | I35: 31 | J35: 31 | AG35: 0.0084306052 | AH35: =FALSE() -> FALSE | AJ35: one-effect-per-cluster aggregates: metafor aggregate.escalc, struct="CS", rho=0.6 (T1/A5 convention [DEC-031g/F65]); domain post cell 711/31/31 [DEC-042b; upgrade FIRED per DEC-031a.5: post cell 31 >= 20 studies]; k = 31 aggregates from 711 ES; between-aggregate tau2, ML
A36: D4 | B36: selection_post | C36: defined_post | D36: mu_3psm | E36: Fisher_z | F36: selmodel_3PSM_ML | G36: 0.6 | H36: 711 | I36: 31 | J36: 31 | K36: -0.0060590998 | L36: 0.030711709 | M36: -0.19728957 | O36: 0.84360094 | P36: -0.066252942 | Q36: 0.054134743 | T36: -0.0060590257 | U36: -0.066156174 | V36: 0.054081923 | AH36: =FALSE() -> FALSE | AJ36: one-effect-per-cluster aggregates: metafor aggregate.escalc, struct="CS", rho=0.6 (T1/A5 convention [DEC-031g/F65]); domain post cell 711/31/31 [DEC-042b; upgrade FIRED per DEC-031a.5: post cell 31 >= 20 studies]; k = 31 aggregates from 711 ES; selmodel(type="stepfun", steps=0.025, alternative="less") on the ML base -> 3PSM {mu, tau2, delta} [DEC-016; DEC-031g/F63; P-T5-2: selection favors significant negative effects]
A37: D4 | B37: selection_post | C37: defined_post | D37: tau2_3psm | E37: tau2 | F37: selmodel_3PSM_ML | G37: 0.6 | H37: 711 | I37: 31 | J37: 31 | AG37: 0.0091862318 | AH37: =FALSE() -> FALSE | AJ37: one-effect-per-cluster aggregates: metafor aggregate.escalc, struct="CS", rho=0.6 (T1/A5 convention [DEC-031g/F65]); domain post cell 711/31/31 [DEC-042b; upgrade FIRED per DEC-031a.5: post cell 31 >= 20 studies]; k = 31 aggregates from 711 ES; selmodel(type="stepfun", steps=0.025, alternative="less") on the ML base -> 3PSM {mu, tau2, delta} [DEC-016; DEC-031g/F63; P-T5-2: selection favors significant negative effects]
A38: D4 | B38: selection_post | C38: defined_post | D38: delta_3psm | E38: delta | F38: selmodel_3PSM_ML | G38: 0.6 | H38: 711 | I38: 31 | J38: 31 | AG38: 0.33803946 | AH38: =FALSE() -> FALSE | AJ38: one-effect-per-cluster aggregates: metafor aggregate.escalc, struct="CS", rho=0.6 (T1/A5 convention [DEC-031g/F65]); domain post cell 711/31/31 [DEC-042b; upgrade FIRED per DEC-031a.5: post cell 31 >= 20 studies]; k = 31 aggregates from 711 ES; selmodel(type="stepfun", steps=0.025, alternative="less") on the ML base -> 3PSM {mu, tau2, delta} [DEC-016; DEC-031g/F63; P-T5-2: selection favors significant negative effects]; relative publication probability of one-sided p > 0.025 results (reference interval weight = 1)
