Workbook

Sheet 1_README
A1: FOMA CER–COD–Paris — T7 / Block C results workbook (narrative moderators C0–C9)
A2: Template: docs/results_workbook_template.md (binding) · one workbook per run
A3: Run 7 · 2026-07-29 09:30:52 · HEAD 6e7ce03 · verifier R/10_verify_outputs.R: 27/27 PASS, exit 0
A5: Item | B5: Value
A6: Data version | B6: CERCOD v12 — estimation set 2,713 ES / 115 studies / 114 clusters
A7: Method (one line) | B7: random ~1|cluster_id/study/esid; V blocks within cluster_id, rho=0.6; CR2/Satterthwaite on cluster_id [D31.1/A.2]
A8: Scope | B8: Block C: eight univariate moderator panels (M_A/M_B), M-pre guards, any-with sensitivity, unified models V1/V2, C0 background (separate file)
A9: Repository | B9: github.com/rwitte-wu-research/FOMA-CER-COD-Paris (public, main)
A10: Computational stack | B10: R 4.6.1 · metafor 5.0-1 · clubSandwich 0.7.0 · seed 20260710
A11: Scripts | B11: R/10_moderators.R + R/10_verify_outputs.R @ 6e7ce03
A12: Decision basis | B12: DEC-043 · DEC-048 · DEC-049 · DEC-049a · analysis_plan A.14; language regime per DEC-044/DEC-047
A14: TAB-INDEX
A15: 1_README
A16: 2_Methodology
A17: 3_Interpretation_Guide
A18: 4_Formula_Reference
A19: 5_Data_Provenance
A20: 6_Moderation_Overview
A21: 7_Featured_Panels
A22: 8_Other_Panels
A23: 9_C9_Unified
A24: 10_Guards_Sensitivity
A25: Results_Long
... A27: Manuscript_Text_Blocks

Sheet 2_Methodology
A1: Methodology — constructions as implemented
A2: All quantities computed by R/10_moderators.R @ 6e7ce03
A3: Source pointers in project notation
A5: Quantity | B5: Formula / Construction | C5: Reference
A6: M_A level means | B6: rma.mv: zi ~ 0 + moderator (cell means, NCE excluded); CR2/Satterthwaite per level | C6: [DEC-048; DEC-031e]
A7: M_B period cells | B7: zi ~ 0 + cell(moderator × pp_mid_lag0), nonempty cells; domain = period ∩ classified | C7: [DEC-048; K1]
A8: Prediction interval (levels) | B8: b ± t(df_Satt)·sqrt(SE_CR2² + σ²_cluster + σ²_study + ω²_esid) | C8: [A.8 extension, DEC-048]
A9: Pairwise level contrasts | B9: c'b with CR2 var; t = sign·sqrt(F_HTZ), df = Satterthwaite denominator | C9: [DEC-048]
A10: Moderation test (per panel) | B10: HTZ Wald on the difference-in-differences block across levels with both period cells | C10: [D31.5; DEC-048]
A11: Multiplicity | B11: Unadjusted primary + one Holm line over the eight interaction-HTZ p-values | C11: [DEC-048 R7]
A12: M-pre guards (C3/C4) | B12: zi ~ 0 + exposure + exposure:ts_knot, ts_knot = sample_mid − 2015.5, pre domain; HTZ on slope block | C12: [DEC-031c]
A13: regulation3 | B13: end-anchored: = regulation_sample_end; run-time gate post clusters 14/6/11 | C13: [DEC-048 Q11a]
A14: Any-with sensitivity | B14: single C4-M_B refit under ever-treated coding; appendix, descriptive | C14: [DEC-048 Q11b]
A15: Unified V1/V2 | B15: reference coding (refs per DEC-043); interaction blocks admitted by mechanical rule | C15: [DEC-043]
A16: Design-df rule | B16: synthetic-outcome FE fit (sin index; df outcome-invariant under FE/V weights); block df_denom ≥ 5 AND ≥2 post-supported levels | C16: [DEC-043; DEC-049a]
... A19: Identity gates | B19: F65: A5 row by value (1e-9) + pinned aggregate refit (1e-6, df 113); verifier: 3L headline refit vs T1_results (1e-6) | C19: [DEC-031g; DEC-048]

Sheet 3_Interpretation_Guide
A1: Interpretation guide
A2: How to read the reported quantities
A3: Thresholds with citations
A5: Quantity | B5: Meaning | C5: Decision rule
A6: Interaction HTZ p | B6: Does the Paris-period contrast differ across moderator levels? | C6: α = 0.05 unadjusted primary; Holm line disclosed [DEC-048]
A7: descriptive flag | B7: Estimate + CI + df shown; p and t suppressed | C7: cell < 3 clusters [Battery C] or df_Satt < 5 [DEC-024 echo; cf. Tipton & Pustejovsky df guidance]
A8: not_estimable (n.e.) | B8: Planned quantity without support; triggering condition in the note | C8: [P-T5-4; DEC-049]
A9: PI per level | B9: Range for a single new study-level true effect at that level | C9: wider than CI by construction [A.8]
A10: q_planned / q_eff | B10: Interaction columns planned vs. carried by the fit on the CC domain | C10: drops disclosed per block [DEC-043/#27]
A11: Verdict lines | B11: Mechanical outcome only | C11: wording per the resolved gate [DEC-044/DEC-047]

Sheet 4_Formula_Reference
A1: Formula reference — exact calls
A2: As implemented in R/10_moderators.R @ 6e7ce03
A3: Documented template deviation listed below
A5: Quantity | B5: R call / construction | C5: Reference
A6: 3L fit | B6: rma.mv(yi=zi, V=build_V, mods=X, intercept=FALSE, random=~1|cluster_id/study/esid, method="REML", sparse=TRUE, control=ladder) | C6: S6; DEC-031f/A.11
A7: CR2 vcov | B7: vcovCR(fit, cluster=cluster_id, type="CR2") | C7: clubSandwich 0.7.0
A8: Per-coef inference | B8: coef_test(fit, vcov=Vc, test="Satterthwaite") — fields beta/SE/df_Satt/p_Satt | C8: run_meta accessor echo
A9: Block tests | B9: Wald_test(fit, constraints=C, vcov=Vc, test="HTZ") — Fstat/df_num/df_denom/p_val | C9: safe_wald wrapper [DEC-049]
A10: F65 aggregate | B10: aggregate(escalc(...), cluster=cluster_id, struct="CS", rho=0.6) → rma.uni(method="REML", test="knha") | C10: [DEC-031g]
A11: Holm | B11: p.adjust(p_HTZ, "holm") over the finite family | C11: [DEC-048 R7]
A12: Design-df probe | B12: FE fit with yi = sin(1:n); df_denom harvested, F/p never read | C12: [DEC-049a]
A13: TEMPLATE DEVIATION (documented) | B13: Manuscript_Inputs strings are built locale-neutrally via sign/INT/frac/REPT arithmetic instead of TEXT() — robust under LC-independent recalc | C13: C-session pin [§4]

Sheet 5_Data_Provenance
A1: Data provenance & run record
A2: Run 7 (canonical) — seven runs total, six pre-canonical stops, all gate-caught
A3: ERROR_LOG #23–#28; nothing entered committed bytes
A5: Item | B5: Value | C5: Source
A6: Estimation set | B6: 2,713 ES / 115 studies / 114 clusters; period 2,705/113/112; post 711/31/31 | C6: dat_prep.rds; gates
A7: dat_prep md5 | B7: 6702ef3dc45fe0b693b13f50ebd1576b | C7: run_meta
A8: Seed / rho | B8: 20260710 / 0.6 | C8: FROZEN ZONE
A9: Run stamp | B9: 2026-07-29 09:30:52 · elapsed 7.9 min · 24 convergence certificates (all nlminb rung 1) | C9: T7_run_meta.txt
A10: Verifier | B10: V01–V27 all PASS (schema parity to T8, budget 200, 4-key unique, domain pins, F65, 3L identity, single-home, C0 separation) | C10: R/10_verify_outputs.R
A11: Known warnings | B11: three "Redundant predictors dropped" = the exact identity pp = pp:Europe + pp:AsiaPac on the US-free V1 CC post cell (fit, hardening, design probe); mapped, disclosed | C11: [#27/#28]
A12: Hardening refits | B12: V1 max|Δβ| = 3.3e-08 · V2 = 5.1e-07 (< 1e-5) | C12: [A.11]
A13: C0 background | B13: output/T7_background_C0.csv — 56 rows, background-only, absent from results (verifier check) | C13: [r15; K5]
A14: Canonical HEAD | B14: 6e7ce03 (fix 6); canonical bytes = author machine output/ | C14: CC report run 7

Sheet 6_Moderation_Overview
A1: Moderation overview — the eight pre-registered interaction tests
A2: HTZ Wald on the difference-in-differences block per panel [DEC-048]
A3: Unadjusted primary + Holm family line; flags per the small-cell double rule
A5: Panel | B5: F (HTZ) | C5: df | D5: p | E5: Flag | F5: Moderator
A6: C1 | B6: =IF(ISBLANK(INDEX(Results_Long!$M$2:$M$201,MATCH("C1|paris_mid|defined_classified|interaction_HTZ",Results_Long!$AK$2:$AK$201,0))),"n.e.",INDEX(Results_Long!$M$2:$M$201,MATCH("C1|paris_mid|defined_classified|interaction_HTZ",Results_Long!$AK$2:$AK$201,0))) -> 4.5435597 | C6: =IF(ISBLANK(INDEX(Results_Long!$N$2:$N$201,MATCH("C1|paris_mid|defined_classified|interaction_HTZ",Results_Long!$AK$2:$AK$201,0))),"n.e.",INDEX(Results_Long!$N$2:$N$201,MATCH("C1|paris_mid|defined_classified|interaction_HTZ",Results_Long!$AK$2:$AK$201,0))) -> 6.0016344 | D6: =IF(ISBLANK(INDEX(Results_Long!$O$2:$O$201,MATCH("C1|paris_mid|defined_classified|interaction_HTZ",Results_Long!$AK$2:$AK$201,0))),"—",INDEX(Results_Long!$O$2:$O$201,MATCH("C1|paris_mid|defined_classified|interaction_HTZ",Results_Long!$AK$2:$AK$201,0))) -> 0.07703039 | E6: =IF(ISNUMBER(SEARCH("<3-cluster",INDEX(Results_Long!$AJ$2:$AJ$201,MATCH("C1|paris_mid|defined_classified|interaction_HTZ",Results_Long!$AK$2:$AK$201,0)))),"touches <3-cluster cell","") | F6: CER_measure
A7: C2 | B7: =IF(ISBLANK(INDEX(Results_Long!$M$2:$M$201,MATCH("C2|paris_mid|defined_classified|interaction_HTZ",Results_Long!$AK$2:$AK$201,0))),"n.e.",INDEX(Results_Long!$M$2:$M$201,MATCH("C2|paris_mid|defined_classified|interaction_HTZ",Results_Long!$AK$2:$AK$201,0))) -> 0.38881646 | C7: =IF(ISBLANK(INDEX(Results_Long!$N$2:$N$201,MATCH("C2|paris_mid|defined_classified|interaction_HTZ",Results_Long!$AK$2:$AK$201,0))),"n.e.",INDEX(Results_Long!$N$2:$N$201,MATCH("C2|paris_mid|defined_classified|interaction_HTZ",Results_Long!$AK$2:$AK$201,0))) -> 3.0916267 | D7: =IF(ISBLANK(INDEX(Results_Long!$O$2:$O$201,MATCH("C2|paris_mid|defined_classified|interaction_HTZ",Results_Long!$AK$2:$AK$201,0))),"—",INDEX(Results_Long!$O$2:$O$201,MATCH("C2|paris_mid|defined_classified|interaction_HTZ",Results_Long!$AK$2:$AK$201,0))) -> 0.70692718 | E7: =IF(ISNUMBER(SEARCH("<3-cluster",INDEX(Results_Long!$AJ$2:$AJ$201,MATCH("C2|paris_mid|defined_classified|interaction_HTZ",Results_Long!$AK$2:$AK$201,0)))),"touches <3-cluster cell","") | F7: COD_instrument
A8: C3 | B8: =IF(ISBLANK(INDEX(Results_Long!$M$2:$M$201,MATCH("C3|paris_mid|defined_classified|interaction_HTZ",Results_Long!$AK$2:$AK$201,0))),"n.e.",INDEX(Results_Long!$M$2:$M$201,MATCH("C3|paris_mid|defined_classified|interaction_HTZ",Results_Long!$AK$2:$AK$201,0))) -> 0.15811514 | C8: =IF(ISBLANK(INDEX(Results_Long!$N$2:$N$201,MATCH("C3|paris_mid|defined_classified|interaction_HTZ",Results_Long!$AK$2:$AK$201,0))),"n.e.",INDEX(Results_Long!$N$2:$N$201,MATCH("C3|paris_mid|defined_classified|interaction_HTZ",Results_Long!$AK$2:$AK$201,0))) -> 8.7855308 | D8: =IF(ISBLANK(INDEX(Results_Long!$O$2:$O$201,MATCH("C3|paris_mid|defined_classified|interaction_HTZ",Results_Long!$AK$2:$AK$201,0))),"—",INDEX(Results_Long!$O$2:$O$201,MATCH("C3|paris_mid|defined_classified|interaction_HTZ",Results_Long!$AK$2:$AK$201,0))) -> 0.70038592 | E8: =IF(ISNUMBER(SEARCH("<3-cluster",INDEX(Results_Long!$AJ$2:$AJ$201,MATCH("C3|paris_mid|defined_classified|interaction_HTZ",Results_Long!$AK$2:$AK$201,0)))),"touches <3-cluster cell","") | F8: industry
A9: C4 | B9: =IF(ISBLANK(INDEX(Results_Long!$M$2:$M$201,MATCH("C4|paris_mid|defined_classified|interaction_HTZ",Results_Long!$AK$2:$AK$201,0))),"n.e.",INDEX(Results_Long!$M$2:$M$201,MATCH("C4|paris_mid|defined_classified|interaction_HTZ",Results_Long!$AK$2:$AK$201,0))) -> 0.83663292 | C9: =IF(ISBLANK(INDEX(Results_Long!$N$2:$N$201,MATCH("C4|paris_mid|defined_classified|interaction_HTZ",Results_Long!$AK$2:$AK$201,0))),"n.e.",INDEX(Results_Long!$N$2:$N$201,MATCH("C4|paris_mid|defined_classified|interaction_HTZ",Results_Long!$AK$2:$AK$201,0))) -> 9.4938297 | D9: =IF(ISBLANK(INDEX(Results_Long!$O$2:$O$201,MATCH("C4|paris_mid|defined_classified|interaction_HTZ",Results_Long!$AK$2:$AK$201,0))),"—",INDEX(Results_Long!$O$2:$O$201,MATCH("C4|paris_mid|defined_classified|interaction_HTZ",Results_Long!$AK$2:$AK$201,0))) -> 0.38300481 | E9: =IF(ISNUMBER(SEARCH("<3-cluster",INDEX(Results_Long!$AJ$2:$AJ$201,MATCH("C4|paris_mid|defined_classified|interaction_HTZ",Results_Long!$AK$2:$AK$201,0)))),"touches <3-cluster cell","") | F9: regulation3
A10: C5 | B10: =IF(ISBLANK(INDEX(Results_Long!$M$2:$M$201,MATCH("C5|paris_mid|defined_classified|interaction_HTZ",Results_Long!$AK$2:$AK$201,0))),"n.e.",INDEX(Results_Long!$M$2:$M$201,MATCH("C5|paris_mid|defined_classified|interaction_HTZ",Results_Long!$AK$2:$AK$201,0))) -> 0.46062069 | C10: =IF(ISBLANK(INDEX(Results_Long!$N$2:$N$201,MATCH("C5|paris_mid|defined_classified|interaction_HTZ",Results_Long!$AK$2:$AK$201,0))),"n.e.",INDEX(Results_Long!$N$2:$N$201,MATCH("C5|paris_mid|defined_classified|interaction_HTZ",Results_Long!$AK$2:$AK$201,0))) -> 3.3629019 | D10: =IF(ISBLANK(INDEX(Results_Long!$O$2:$O$201,MATCH("C5|paris_mid|defined_classified|interaction_HTZ",Results_Long!$AK$2:$AK$201,0))),"—",INDEX(Results_Long!$O$2:$O$201,MATCH("C5|paris_mid|defined_classified|interaction_HTZ",Results_Long!$AK$2:$AK$201,0))) -> 0.66557314 | E10: =IF(ISNUMBER(SEARCH("<3-cluster",INDEX(Results_Long!$AJ$2:$AJ$201,MATCH("C5|paris_mid|defined_classified|interaction_HTZ",Results_Long!$AK$2:$AK$201,0)))),"touches <3-cluster cell","") -> touches <3-cluster cell | F10: country_region
A11: C6 | B11: =IF(ISBLANK(INDEX(Results_Long!$M$2:$M$201,MATCH("C6|paris_mid|defined_classified|interaction_HTZ",Results_Long!$AK$2:$AK$201,0))),"n.e.",INDEX(Results_Long!$M$2:$M$201,MATCH("C6|paris_mid|defined_classified|interaction_HTZ",Results_Long!$AK$2:$AK$201,0))) -> 3.4928388 | C11: =IF(ISBLANK(INDEX(Results_Long!$N$2:$N$201,MATCH("C6|paris_mid|defined_classified|interaction_HTZ",Results_Long!$AK$2:$AK$201,0))),"n.e.",INDEX(Results_Long!$N$2:$N$201,MATCH("C6|paris_mid|defined_classified|interaction_HTZ",Results_Long!$AK$2:$AK$201,0))) -> 2.2032508 | D11: =IF(ISBLANK(INDEX(Results_Long!$O$2:$O$201,MATCH("C6|paris_mid|defined_classified|interaction_HTZ",Results_Long!$AK$2:$AK$201,0))),"—",INDEX(Results_Long!$O$2:$O$201,MATCH("C6|paris_mid|defined_classified|interaction_HTZ",Results_Long!$AK$2:$AK$201,0))) -> 0.19073471 | E11: =IF(ISNUMBER(SEARCH("<3-cluster",INDEX(Results_Long!$AJ$2:$AJ$201,MATCH("C6|paris_mid|defined_classified|interaction_HTZ",Results_Long!$AK$2:$AK$201,0)))),"touches <3-cluster cell","") | F11: country_econ
A12: C7 | B12: =IF(ISBLANK(INDEX(Results_Long!$M$2:$M$201,MATCH("C7|paris_mid|defined_classified|interaction_HTZ",Results_Long!$AK$2:$AK$201,0))),"n.e.",INDEX(Results_Long!$M$2:$M$201,MATCH("C7|paris_mid|defined_classified|interaction_HTZ",Results_Long!$AK$2:$AK$201,0))) -> 0.067668187 | C12: =IF(ISBLANK(INDEX(Results_Long!$N$2:$N$201,MATCH("C7|paris_mid|defined_classified|interaction_HTZ",Results_Long!$AK$2:$AK$201,0))),"n.e.",INDEX(Results_Long!$N$2:$N$201,MATCH("C7|paris_mid|defined_classified|interaction_HTZ",Results_Long!$AK$2:$AK$201,0))) -> 13.146308 | D12: =IF(ISBLANK(INDEX(Results_Long!$O$2:$O$201,MATCH("C7|paris_mid|defined_classified|interaction_HTZ",Results_Long!$AK$2:$AK$201,0))),"—",INDEX(Results_Long!$O$2:$O$201,MATCH("C7|paris_mid|defined_classified|interaction_HTZ",Results_Long!$AK$2:$AK$201,0))) -> 0.79879242 | E12: =IF(ISNUMBER(SEARCH("<3-cluster",INDEX(Results_Long!$AJ$2:$AJ$201,MATCH("C7|paris_mid|defined_classified|interaction_HTZ",Results_Long!$AK$2:$AK$201,0)))),"touches <3-cluster cell","") | F12: country_culture
A13: C8 | B13: =IF(ISBLANK(INDEX(Results_Long!$M$2:$M$201,MATCH("C8|paris_mid|defined_classified|interaction_HTZ",Results_Long!$AK$2:$AK$201,0))),"n.e.",INDEX(Results_Long!$M$2:$M$201,MATCH("C8|paris_mid|defined_classified|interaction_HTZ",Results_Long!$AK$2:$AK$201,0))) -> 0.44248965 | C13: =IF(ISBLANK(INDEX(Results_Long!$N$2:$N$201,MATCH("C8|paris_mid|defined_classified|interaction_HTZ",Results_Long!$AK$2:$AK$201,0))),"n.e.",INDEX(Results_Long!$N$2:$N$201,MATCH("C8|paris_mid|defined_classified|interaction_HTZ",Results_Long!$AK$2:$AK$201,0))) -> 1.214221 | D13: =IF(ISBLANK(INDEX(Results_Long!$O$2:$O$201,MATCH("C8|paris_mid|defined_classified|interaction_HTZ",Results_Long!$AK$2:$AK$201,0))),"—",INDEX(Results_Long!$O$2:$O$201,MATCH("C8|paris_mid|defined_classified|interaction_HTZ",Results_Long!$AK$2:$AK$201,0))) -> 0.60963825 | E13: =IF(ISNUMBER(SEARCH("<3-cluster",INDEX(Results_Long!$AJ$2:$AJ$201,MATCH("C8|paris_mid|defined_classified|interaction_HTZ",Results_Long!$AK$2:$AK$201,0)))),"touches <3-cluster cell","") -> touches <3-cluster cell | F13: country_legal
A15: Holm (family of 8) | D15: =IF(ISBLANK(INDEX(Results_Long!$AG$2:$AG$201,MATCH("C_family|multiplicity|defined_classified|interaction_HTZ_holm",Results_Long!$AK$2:$AK$201,0))),"n.e.",INDEX(Results_Long!$AG$2:$AG$201,MATCH("C_family|multiplicity|defined_classified|interaction_HTZ_holm",Results_Long!$AK$2:$AK$201,0))) -> 0.61624312 | E15: minimum Holm-adjusted p; per-panel adjusted values in the Results_Long note
A17: Interpretation
A18: No panel reaches the 0.05 level, unadjusted or Holm-adjusted; the closest value is the CER-measurement panel (see 7_Featured_Panels).
A19: Two tests carry the disclosed small-cell flag (C5, C8); both are reported with their own Satterthwaite df.
A20: Under the null-claim framing, unadjusted testing maximises the claim exposure; the Holm line is the pre-registered safeguard [DEC-048].
A22: Question | B22: Answer
A23: Why report unadjusted p-values as primary? | B23: Any chance rejection works against the null claim; unadjusted testing is therefore the stricter presentation, with the Holm family line disclosed alongside [DEC-048 R7].
A24: Why are two tests flagged? | B24: Their difference-in-differences blocks touch a period cell with fewer than three clusters (US x post; common-law x post); HTZ tests are always reported with the flag naming the cell [R6].
A25: Where are the underlying cells? | B25: Per-panel tables in 7_Featured_Panels / 8_Other_Panels; every quantity is formula-linked to Results_Long.
A27: Mechanical outcome: none of the eight pre-registered panel interaction tests is significant at the 0.05 level, unadjusted or Holm-adjusted; wording per the resolved gate [DEC-044/DEC-047].

Sheet 7_Featured_Panels
A1: Featured panels — CER measure, debt instrument, carbon regulation, region
A2: Featured set == V1 moderator set [DEC-043; R1]
A3: All cells formula-linked to Results_Long
A5: C1 — CER_measure
A6: Level (M_A) | B6: r | C6: CI_r low | D6: CI_r high | E6: PI_r low | F6: PI_r high | G6: df
A7: performance | B7: =IF(ISBLANK(INDEX(Results_Long!$T$2:$T$201,MATCH("C1|levels|classified|lvl::performance",Results_Long!$AK$2:$AK$201,0))),"n.e.",INDEX(Results_Long!$T$2:$T$201,MATCH("C1|levels|classified|lvl::performance",Results_Long!$AK$2:$AK$201,0))) -> -0.055821677 | C7: =IF(ISBLANK(INDEX(Results_Long!$U$2:$U$201,MATCH("C1|levels|classified|lvl::performance",Results_Long!$AK$2:$AK$201,0))),"n.e.",INDEX(Results_Long!$U$2:$U$201,MATCH("C1|levels|classified|lvl::performance",Results_Long!$AK$2:$AK$201,0))) -> -0.084626723 | D7: =IF(ISBLANK(INDEX(Results_Long!$V$2:$V$201,MATCH("C1|levels|classified|lvl::performance",Results_Long!$AK$2:$AK$201,0))),"n.e.",INDEX(Results_Long!$V$2:$V$201,MATCH("C1|levels|classified|lvl::performance",Results_Long!$AK$2:$AK$201,0))) -> -0.026923406 | E7: =IF(ISBLANK(INDEX(Results_Long!$W$2:$W$201,MATCH("C1|levels|classified|lvl::performance",Results_Long!$AK$2:$AK$201,0))),"n.e.",INDEX(Results_Long!$W$2:$W$201,MATCH("C1|levels|classified|lvl::performance",Results_Long!$AK$2:$AK$201,0))) -> -0.38826484 | F7: =IF(ISBLANK(INDEX(Results_Long!$X$2:$X$201,MATCH("C1|levels|classified|lvl::performance",Results_Long!$AK$2:$AK$201,0))),"n.e.",INDEX(Results_Long!$X$2:$X$201,MATCH("C1|levels|classified|lvl::performance",Results_Long!$AK$2:$AK$201,0))) -> 0.28947734 | G7: =IF(ISBLANK(INDEX(Results_Long!$N$2:$N$201,MATCH("C1|levels|classified|lvl::performance",Results_Long!$AK$2:$AK$201,0))),"n.e.",INDEX(Results_Long!$N$2:$N$201,MATCH("C1|levels|classified|lvl::performance",Results_Long!$AK$2:$AK$201,0))) -> 109.55901
A8: disclosure | B8: =IF(ISBLANK(INDEX(Results_Long!$T$2:$T$201,MATCH("C1|levels|classified|lvl::disclosure",Results_Long!$AK$2:$AK$201,0))),"n.e.",INDEX(Results_Long!$T$2:$T$201,MATCH("C1|levels|classified|lvl::disclosure",Results_Long!$AK$2:$AK$201,0))) -> -0.068460526 | C8: =IF(ISBLANK(INDEX(Results_Long!$U$2:$U$201,MATCH("C1|levels|classified|lvl::disclosure",Results_Long!$AK$2:$AK$201,0))),"n.e.",INDEX(Results_Long!$U$2:$U$201,MATCH("C1|levels|classified|lvl::disclosure",Results_Long!$AK$2:$AK$201,0))) -> -0.10283801 | D8: =IF(ISBLANK(INDEX(Results_Long!$V$2:$V$201,MATCH("C1|levels|classified|lvl::disclosure",Results_Long!$AK$2:$AK$201,0))),"n.e.",INDEX(Results_Long!$V$2:$V$201,MATCH("C1|levels|classified|lvl::disclosure",Results_Long!$AK$2:$AK$201,0))) -> -0.033919694 | E8: =IF(ISBLANK(INDEX(Results_Long!$W$2:$W$201,MATCH("C1|levels|classified|lvl::disclosure",Results_Long!$AK$2:$AK$201,0))),"n.e.",INDEX(Results_Long!$W$2:$W$201,MATCH("C1|levels|classified|lvl::disclosure",Results_Long!$AK$2:$AK$201,0))) -> -0.40271441 | F8: =IF(ISBLANK(INDEX(Results_Long!$X$2:$X$201,MATCH("C1|levels|classified|lvl::disclosure",Results_Long!$AK$2:$AK$201,0))),"n.e.",INDEX(Results_Long!$X$2:$X$201,MATCH("C1|levels|classified|lvl::disclosure",Results_Long!$AK$2:$AK$201,0))) -> 0.28190377 | G8: =IF(ISBLANK(INDEX(Results_Long!$N$2:$N$201,MATCH("C1|levels|classified|lvl::disclosure",Results_Long!$AK$2:$AK$201,0))),"n.e.",INDEX(Results_Long!$N$2:$N$201,MATCH("C1|levels|classified|lvl::disclosure",Results_Long!$AK$2:$AK$201,0))) -> 54.996246
A10: Paris shift (M_B) | B10: dz (post-pre) | C10: CI_z low | D10: CI_z high | E10: df | F10: p | G10: status
A11: performance | B11: =IF(ISBLANK(INDEX(Results_Long!$K$2:$K$201,MATCH("C1|paris_mid|defined_classified|diff::performance",Results_Long!$AK$2:$AK$201,0))),"n.e.",INDEX(Results_Long!$K$2:$K$201,MATCH("C1|paris_mid|defined_classified|diff::performance",Results_Long!$AK$2:$AK$201,0))) -> 0.021593762 | C11: =IF(ISBLANK(INDEX(Results_Long!$P$2:$P$201,MATCH("C1|paris_mid|defined_classified|diff::performance",Results_Long!$AK$2:$AK$201,0))),"n.e.",INDEX(Results_Long!$P$2:$P$201,MATCH("C1|paris_mid|defined_classified|diff::performance",Results_Long!$AK$2:$AK$201,0))) -> -0.016820001 | D11: =IF(ISBLANK(INDEX(Results_Long!$Q$2:$Q$201,MATCH("C1|paris_mid|defined_classified|diff::performance",Results_Long!$AK$2:$AK$201,0))),"n.e.",INDEX(Results_Long!$Q$2:$Q$201,MATCH("C1|paris_mid|defined_classified|diff::performance",Results_Long!$AK$2:$AK$201,0))) -> 0.060007525 | E11: =IF(ISBLANK(INDEX(Results_Long!$N$2:$N$201,MATCH("C1|paris_mid|defined_classified|diff::performance",Results_Long!$AK$2:$AK$201,0))),"n.e.",INDEX(Results_Long!$N$2:$N$201,MATCH("C1|paris_mid|defined_classified|diff::performance",Results_Long!$AK$2:$AK$201,0))) -> 14.348492 | F11: =IF(ISBLANK(INDEX(Results_Long!$O$2:$O$201,MATCH("C1|paris_mid|defined_classified|diff::performance",Results_Long!$AK$2:$AK$201,0))),"—",INDEX(Results_Long!$O$2:$O$201,MATCH("C1|paris_mid|defined_classified|diff::performance",Results_Long!$AK$2:$AK$201,0))) -> 0.2484811 | G11: =INDEX(Results_Long!$F$2:$F$201,MATCH("C1|paris_mid|defined_classified|diff::performance",Results_Long!$AK$2:$AK$201,0)) -> 3LMA-RVE_CR2
A12: disclosure | B12: =IF(ISBLANK(INDEX(Results_Long!$K$2:$K$201,MATCH("C1|paris_mid|defined_classified|diff::disclosure",Results_Long!$AK$2:$AK$201,0))),"n.e.",INDEX(Results_Long!$K$2:$K$201,MATCH("C1|paris_mid|defined_classified|diff::disclosure",Results_Long!$AK$2:$AK$201,0))) -> -0.036452479 | C12: =IF(ISBLANK(INDEX(Results_Long!$P$2:$P$201,MATCH("C1|paris_mid|defined_classified|diff::disclosure",Results_Long!$AK$2:$AK$201,0))),"n.e.",INDEX(Results_Long!$P$2:$P$201,MATCH("C1|paris_mid|defined_classified|diff::disclosure",Results_Long!$AK$2:$AK$201,0))) -> -0.094282611 | D12: =IF(ISBLANK(INDEX(Results_Long!$Q$2:$Q$201,MATCH("C1|paris_mid|defined_classified|diff::disclosure",Results_Long!$AK$2:$AK$201,0))),"n.e.",INDEX(Results_Long!$Q$2:$Q$201,MATCH("C1|paris_mid|defined_classified|diff::disclosure",Results_Long!$AK$2:$AK$201,0))) -> 0.021377654 | E12: =IF(ISBLANK(INDEX(Results_Long!$N$2:$N$201,MATCH("C1|paris_mid|defined_classified|diff::disclosure",Results_Long!$AK$2:$AK$201,0))),"n.e.",INDEX(Results_Long!$N$2:$N$201,MATCH("C1|paris_mid|defined_classified|diff::disclosure",Results_Long!$AK$2:$AK$201,0))) -> 22.075179 | F12: =IF(ISBLANK(INDEX(Results_Long!$O$2:$O$201,MATCH("C1|paris_mid|defined_classified|diff::disclosure",Results_Long!$AK$2:$AK$201,0))),"—",INDEX(Results_Long!$O$2:$O$201,MATCH("C1|paris_mid|defined_classified|diff::disclosure",Results_Long!$AK$2:$AK$201,0))) -> 0.20467077 | G12: =INDEX(Results_Long!$F$2:$F$201,MATCH("C1|paris_mid|defined_classified|diff::disclosure",Results_Long!$AK$2:$AK$201,0)) -> 3LMA-RVE_CR2
A14: Level contrasts (M_A) | B14: dz | C14: df | D14: p
A15: performance vs disclosure | B15: =IF(ISBLANK(INDEX(Results_Long!$K$2:$K$201,MATCH("C1|levels|classified|pair::performance - disclosure",Results_Long!$AK$2:$AK$201,0))),"n.e.",INDEX(Results_Long!$K$2:$K$201,MATCH("C1|levels|classified|pair::performance - disclosure",Results_Long!$AK$2:$AK$201,0))) -> 0.012688016 | C15: =IF(ISBLANK(INDEX(Results_Long!$N$2:$N$201,MATCH("C1|levels|classified|pair::performance - disclosure",Results_Long!$AK$2:$AK$201,0))),"n.e.",INDEX(Results_Long!$N$2:$N$201,MATCH("C1|levels|classified|pair::performance - disclosure",Results_Long!$AK$2:$AK$201,0))) -> 8.7257163 | D15: =IF(ISBLANK(INDEX(Results_Long!$O$2:$O$201,MATCH("C1|levels|classified|pair::performance - disclosure",Results_Long!$AK$2:$AK$201,0))),"—",INDEX(Results_Long!$O$2:$O$201,MATCH("C1|levels|classified|pair::performance - disclosure",Results_Long!$AK$2:$AK$201,0))) -> 0.42751159
A17: Levels equal (HTZ) | B17: =IF(ISBLANK(INDEX(Results_Long!$M$2:$M$201,MATCH("C1|levels|classified|levels_HTZ",Results_Long!$AK$2:$AK$201,0))),"n.e.",INDEX(Results_Long!$M$2:$M$201,MATCH("C1|levels|classified|levels_HTZ",Results_Long!$AK$2:$AK$201,0))) -> 0.69247038 | C17: =IF(ISBLANK(INDEX(Results_Long!$N$2:$N$201,MATCH("C1|levels|classified|levels_HTZ",Results_Long!$AK$2:$AK$201,0))),"n.e.",INDEX(Results_Long!$N$2:$N$201,MATCH("C1|levels|classified|levels_HTZ",Results_Long!$AK$2:$AK$201,0))) -> 8.7257163 | D17: =IF(ISBLANK(INDEX(Results_Long!$O$2:$O$201,MATCH("C1|levels|classified|levels_HTZ",Results_Long!$AK$2:$AK$201,0))),"—",INDEX(Results_Long!$O$2:$O$201,MATCH("C1|levels|classified|levels_HTZ",Results_Long!$AK$2:$AK$201,0))) -> 0.42751159 | E17: =IF(ISNUMBER(SEARCH("<3-cluster",INDEX(Results_Long!$AJ$2:$AJ$201,MATCH("C1|levels|classified|levels_HTZ",Results_Long!$AK$2:$AK$201,0)))),"touches <3-cluster cell","")
A18: Moderation test (interaction HTZ) | B18: =IF(ISBLANK(INDEX(Results_Long!$M$2:$M$201,MATCH("C1|paris_mid|defined_classified|interaction_HTZ",Results_Long!$AK$2:$AK$201,0))),"n.e.",INDEX(Results_Long!$M$2:$M$201,MATCH("C1|paris_mid|defined_classified|interaction_HTZ",Results_Long!$AK$2:$AK$201,0))) -> 4.5435597 | C18: =IF(ISBLANK(INDEX(Results_Long!$N$2:$N$201,MATCH("C1|paris_mid|defined_classified|interaction_HTZ",Results_Long!$AK$2:$AK$201,0))),"n.e.",INDEX(Results_Long!$N$2:$N$201,MATCH("C1|paris_mid|defined_classified|interaction_HTZ",Results_Long!$AK$2:$AK$201,0))) -> 6.0016344 | D18: =IF(ISBLANK(INDEX(Results_Long!$O$2:$O$201,MATCH("C1|paris_mid|defined_classified|interaction_HTZ",Results_Long!$AK$2:$AK$201,0))),"—",INDEX(Results_Long!$O$2:$O$201,MATCH("C1|paris_mid|defined_classified|interaction_HTZ",Results_Long!$AK$2:$AK$201,0))) -> 0.07703039 | E18: =IF(ISNUMBER(SEARCH("<3-cluster",INDEX(Results_Long!$AJ$2:$AJ$201,MATCH("C1|paris_mid|defined_classified|interaction_HTZ",Results_Long!$AK$2:$AK$201,0)))),"touches <3-cluster cell","")
A21: C2 — COD_instrument
A22: Level (M_A) | B22: r | C22: CI_r low | D22: CI_r high | E22: PI_r low | F22: PI_r high | G22: df
A23: loan (interest rate) | B23: =IF(ISBLANK(INDEX(Results_Long!$T$2:$T$201,MATCH("C2|levels|classified|lvl::loan (interest rate)",Results_Long!$AK$2:$AK$201,0))),"n.e.",INDEX(Results_Long!$T$2:$T$201,MATCH("C2|levels|classified|lvl::loan (interest rate)",Results_Long!$AK$2:$AK$201,0))) -> -0.038311071 | C23: =IF(ISBLANK(INDEX(Results_Long!$U$2:$U$201,MATCH("C2|levels|classified|lvl::loan (interest rate)",Results_Long!$AK$2:$AK$201,0))),"n.e.",INDEX(Results_Long!$U$2:$U$201,MATCH("C2|levels|classified|lvl::loan (interest rate)",Results_Long!$AK$2:$AK$201,0))) -> -0.05728833 | D23: =IF(ISBLANK(INDEX(Results_Long!$V$2:$V$201,MATCH("C2|levels|classified|lvl::loan (interest rate)",Results_Long!$AK$2:$AK$201,0))),"n.e.",INDEX(Results_Long!$V$2:$V$201,MATCH("C2|levels|classified|lvl::loan (interest rate)",Results_Long!$AK$2:$AK$201,0))) -> -0.019306136 | E23: =IF(ISBLANK(INDEX(Results_Long!$W$2:$W$201,MATCH("C2|levels|classified|lvl::loan (interest rate)",Results_Long!$AK$2:$AK$201,0))),"n.e.",INDEX(Results_Long!$W$2:$W$201,MATCH("C2|levels|classified|lvl::loan (interest rate)",Results_Long!$AK$2:$AK$201,0))) -> -0.37381703 | F23: =IF(ISBLANK(INDEX(Results_Long!$X$2:$X$201,MATCH("C2|levels|classified|lvl::loan (interest rate)",Results_Long!$AK$2:$AK$201,0))),"n.e.",INDEX(Results_Long!$X$2:$X$201,MATCH("C2|levels|classified|lvl::loan (interest rate)",Results_Long!$AK$2:$AK$201,0))) -> 0.30606073 | G23: =IF(ISBLANK(INDEX(Results_Long!$N$2:$N$201,MATCH("C2|levels|classified|lvl::loan (interest rate)",Results_Long!$AK$2:$AK$201,0))),"n.e.",INDEX(Results_Long!$N$2:$N$201,MATCH("C2|levels|classified|lvl::loan (interest rate)",Results_Long!$AK$2:$AK$201,0))) -> 64.656366
A24: bond (yield) | B24: =IF(ISBLANK(INDEX(Results_Long!$T$2:$T$201,MATCH("C2|levels|classified|lvl::bond (yield)",Results_Long!$AK$2:$AK$201,0))),"n.e.",INDEX(Results_Long!$T$2:$T$201,MATCH("C2|levels|classified|lvl::bond (yield)",Results_Long!$AK$2:$AK$201,0))) -> -0.09123577 | C24: =IF(ISBLANK(INDEX(Results_Long!$U$2:$U$201,MATCH("C2|levels|classified|lvl::bond (yield)",Results_Long!$AK$2:$AK$201,0))),"n.e.",INDEX(Results_Long!$U$2:$U$201,MATCH("C2|levels|classified|lvl::bond (yield)",Results_Long!$AK$2:$AK$201,0))) -> -0.12164395 | D24: =IF(ISBLANK(INDEX(Results_Long!$V$2:$V$201,MATCH("C2|levels|classified|lvl::bond (yield)",Results_Long!$AK$2:$AK$201,0))),"n.e.",INDEX(Results_Long!$V$2:$V$201,MATCH("C2|levels|classified|lvl::bond (yield)",Results_Long!$AK$2:$AK$201,0))) -> -0.060656497 | E24: =IF(ISBLANK(INDEX(Results_Long!$W$2:$W$201,MATCH("C2|levels|classified|lvl::bond (yield)",Results_Long!$AK$2:$AK$201,0))),"n.e.",INDEX(Results_Long!$W$2:$W$201,MATCH("C2|levels|classified|lvl::bond (yield)",Results_Long!$AK$2:$AK$201,0))) -> -0.4323466 | F24: =IF(ISBLANK(INDEX(Results_Long!$X$2:$X$201,MATCH("C2|levels|classified|lvl::bond (yield)",Results_Long!$AK$2:$AK$201,0))),"n.e.",INDEX(Results_Long!$X$2:$X$201,MATCH("C2|levels|classified|lvl::bond (yield)",Results_Long!$AK$2:$AK$201,0))) -> 0.27271884 | G24: =IF(ISBLANK(INDEX(Results_Long!$N$2:$N$201,MATCH("C2|levels|classified|lvl::bond (yield)",Results_Long!$AK$2:$AK$201,0))),"n.e.",INDEX(Results_Long!$N$2:$N$201,MATCH("C2|levels|classified|lvl::bond (yield)",Results_Long!$AK$2:$AK$201,0))) -> 19.756484
A25: rating | B25: =IF(ISBLANK(INDEX(Results_Long!$T$2:$T$201,MATCH("C2|levels|classified|lvl::rating",Results_Long!$AK$2:$AK$201,0))),"n.e.",INDEX(Results_Long!$T$2:$T$201,MATCH("C2|levels|classified|lvl::rating",Results_Long!$AK$2:$AK$201,0))) -> -0.058177669 | C25: =IF(ISBLANK(INDEX(Results_Long!$U$2:$U$201,MATCH("C2|levels|classified|lvl::rating",Results_Long!$AK$2:$AK$201,0))),"n.e.",INDEX(Results_Long!$U$2:$U$201,MATCH("C2|levels|classified|lvl::rating",Results_Long!$AK$2:$AK$201,0))) -> -0.092042513 | D25: =IF(ISBLANK(INDEX(Results_Long!$V$2:$V$201,MATCH("C2|levels|classified|lvl::rating",Results_Long!$AK$2:$AK$201,0))),"n.e.",INDEX(Results_Long!$V$2:$V$201,MATCH("C2|levels|classified|lvl::rating",Results_Long!$AK$2:$AK$201,0))) -> -0.0241784 | E25: =IF(ISBLANK(INDEX(Results_Long!$W$2:$W$201,MATCH("C2|levels|classified|lvl::rating",Results_Long!$AK$2:$AK$201,0))),"n.e.",INDEX(Results_Long!$W$2:$W$201,MATCH("C2|levels|classified|lvl::rating",Results_Long!$AK$2:$AK$201,0))) -> -0.40044371 | F25: =IF(ISBLANK(INDEX(Results_Long!$X$2:$X$201,MATCH("C2|levels|classified|lvl::rating",Results_Long!$AK$2:$AK$201,0))),"n.e.",INDEX(Results_Long!$X$2:$X$201,MATCH("C2|levels|classified|lvl::rating",Results_Long!$AK$2:$AK$201,0))) -> 0.29833451 | G25: =IF(ISBLANK(INDEX(Results_Long!$N$2:$N$201,MATCH("C2|levels|classified|lvl::rating",Results_Long!$AK$2:$AK$201,0))),"n.e.",INDEX(Results_Long!$N$2:$N$201,MATCH("C2|levels|classified|lvl::rating",Results_Long!$AK$2:$AK$201,0))) -> 25.971986
A26: derivativ (CDS spread) | B26: =IF(ISBLANK(INDEX(Results_Long!$T$2:$T$201,MATCH("C2|levels|classified|lvl::derivativ (CDS spread)",Results_Long!$AK$2:$AK$201,0))),"n.e.",INDEX(Results_Long!$T$2:$T$201,MATCH("C2|levels|classified|lvl::derivativ (CDS spread)",Results_Long!$AK$2:$AK$201,0))) -> -0.12182373 | C26: =IF(ISBLANK(INDEX(Results_Long!$U$2:$U$201,MATCH("C2|levels|classified|lvl::derivativ (CDS spread)",Results_Long!$AK$2:$AK$201,0))),"n.e.",INDEX(Results_Long!$U$2:$U$201,MATCH("C2|levels|classified|lvl::derivativ (CDS spread)",Results_Long!$AK$2:$AK$201,0))) -> -0.30435397 | D26: =IF(ISBLANK(INDEX(Results_Long!$V$2:$V$201,MATCH("C2|levels|classified|lvl::derivativ (CDS spread)",Results_Long!$AK$2:$AK$201,0))),"n.e.",INDEX(Results_Long!$V$2:$V$201,MATCH("C2|levels|classified|lvl::derivativ (CDS spread)",Results_Long!$AK$2:$AK$201,0))) -> 0.069336026 | E26: =IF(ISBLANK(INDEX(Results_Long!$W$2:$W$201,MATCH("C2|levels|classified|lvl::derivativ (CDS spread)",Results_Long!$AK$2:$AK$201,0))),"n.e.",INDEX(Results_Long!$W$2:$W$201,MATCH("C2|levels|classified|lvl::derivativ (CDS spread)",Results_Long!$AK$2:$AK$201,0))) -> -0.52798216 | F26: =IF(ISBLANK(INDEX(Results_Long!$X$2:$X$201,MATCH("C2|levels|classified|lvl::derivativ (CDS spread)",Results_Long!$AK$2:$AK$201,0))),"n.e.",INDEX(Results_Long!$X$2:$X$201,MATCH("C2|levels|classified|lvl::derivativ (CDS spread)",Results_Long!$AK$2:$AK$201,0))) -> 0.32968929 | G26: =IF(ISBLANK(INDEX(Results_Long!$N$2:$N$201,MATCH("C2|levels|classified|lvl::derivativ (CDS spread)",Results_Long!$AK$2:$AK$201,0))),"n.e.",INDEX(Results_Long!$N$2:$N$201,MATCH("C2|levels|classified|lvl::derivativ (CDS spread)",Results_Long!$AK$2:$AK$201,0))) -> 6.6614305
A28: Paris shift (M_B) | B28: dz (post-pre) | C28: CI_z low | D28: CI_z high | E28: df | F28: p | G28: status
A29: loan (interest rate) | B29: =IF(ISBLANK(INDEX(Results_Long!$K$2:$K$201,MATCH("C2|paris_mid|defined_classified|diff::loan (interest rate)",Results_Long!$AK$2:$AK$201,0))),"n.e.",INDEX(Results_Long!$K$2:$K$201,MATCH("C2|paris_mid|defined_classified|diff::loan (interest rate)",Results_Long!$AK$2:$AK$201,0))) -> 0.016284304 | C29: =IF(ISBLANK(INDEX(Results_Long!$P$2:$P$201,MATCH("C2|paris_mid|defined_classified|diff::loan (interest rate)",Results_Long!$AK$2:$AK$201,0))),"n.e.",INDEX(Results_Long!$P$2:$P$201,MATCH("C2|paris_mid|defined_classified|diff::loan (interest rate)",Results_Long!$AK$2:$AK$201,0))) -> -0.039353919 | D29: =IF(ISBLANK(INDEX(Results_Long!$Q$2:$Q$201,MATCH("C2|paris_mid|defined_classified|diff::loan (interest rate)",Results_Long!$AK$2:$AK$201,0))),"n.e.",INDEX(Results_Long!$Q$2:$Q$201,MATCH("C2|paris_mid|defined_classified|diff::loan (interest rate)",Results_Long!$AK$2:$AK$201,0))) -> 0.071922526 | E29: =IF(ISBLANK(INDEX(Results_Long!$N$2:$N$201,MATCH("C2|paris_mid|defined_classified|diff::loan (interest rate)",Results_Long!$AK$2:$AK$201,0))),"n.e.",INDEX(Results_Long!$N$2:$N$201,MATCH("C2|paris_mid|defined_classified|diff::loan (interest rate)",Results_Long!$AK$2:$AK$201,0))) -> 10.296624 | F29: =IF(ISBLANK(INDEX(Results_Long!$O$2:$O$201,MATCH("C2|paris_mid|defined_classified|diff::loan (interest rate)",Results_Long!$AK$2:$AK$201,0))),"—",INDEX(Results_Long!$O$2:$O$201,MATCH("C2|paris_mid|defined_classified|diff::loan (interest rate)",Results_Long!$AK$2:$AK$201,0))) -> 0.53017574 | G29: =INDEX(Results_Long!$F$2:$F$201,MATCH("C2|paris_mid|defined_classified|diff::loan (interest rate)",Results_Long!$AK$2:$AK$201,0)) -> 3LMA-RVE_CR2
A30: bond (yield) | B30: =IF(ISBLANK(INDEX(Results_Long!$K$2:$K$201,MATCH("C2|paris_mid|defined_classified|diff::bond (yield)",Results_Long!$AK$2:$AK$201,0))),"n.e.",INDEX(Results_Long!$K$2:$K$201,MATCH("C2|paris_mid|defined_classified|diff::bond (yield)",Results_Long!$AK$2:$AK$201,0))) -> -0.050736876 | C30: =IF(ISBLANK(INDEX(Results_Long!$P$2:$P$201,MATCH("C2|paris_mid|defined_classified|diff::bond (yield)",Results_Long!$AK$2:$AK$201,0))),"n.e.",INDEX(Results_Long!$P$2:$P$201,MATCH("C2|paris_mid|defined_classified|diff::bond (yield)",Results_Long!$AK$2:$AK$201,0))) -> -0.20339482 | D30: =IF(ISBLANK(INDEX(Results_Long!$Q$2:$Q$201,MATCH("C2|paris_mid|defined_classified|diff::bond (yield)",Results_Long!$AK$2:$AK$201,0))),"n.e.",INDEX(Results_Long!$Q$2:$Q$201,MATCH("C2|paris_mid|defined_classified|diff::bond (yield)",Results_Long!$AK$2:$AK$201,0))) -> 0.10192107 | E30: =IF(ISBLANK(INDEX(Results_Long!$N$2:$N$201,MATCH("C2|paris_mid|defined_classified|diff::bond (yield)",Results_Long!$AK$2:$AK$201,0))),"n.e.",INDEX(Results_Long!$N$2:$N$201,MATCH("C2|paris_mid|defined_classified|diff::bond (yield)",Results_Long!$AK$2:$AK$201,0))) -> 9.127122 | F30: =IF(ISBLANK(INDEX(Results_Long!$O$2:$O$201,MATCH("C2|paris_mid|defined_classified|diff::bond (yield)",Results_Long!$AK$2:$AK$201,0))),"—",INDEX(Results_Long!$O$2:$O$201,MATCH("C2|paris_mid|defined_classified|diff::bond (yield)",Results_Long!$AK$2:$AK$201,0))) -> 0.47200107 | G30: =INDEX(Results_Long!$F$2:$F$201,MATCH("C2|paris_mid|defined_classified|diff::bond (yield)",Results_Long!$AK$2:$AK$201,0)) -> 3LMA-RVE_CR2
A31: rating | B31: =IF(ISBLANK(INDEX(Results_Long!$K$2:$K$201,MATCH("C2|paris_mid|defined_classified|diff::rating",Results_Long!$AK$2:$AK$201,0))),"n.e.",INDEX(Results_Long!$K$2:$K$201,MATCH("C2|paris_mid|defined_classified|diff::rating",Results_Long!$AK$2:$AK$201,0))) -> 0.052570446 | C31: =IF(ISBLANK(INDEX(Results_Long!$P$2:$P$201,MATCH("C2|paris_mid|defined_classified|diff::rating",Results_Long!$AK$2:$AK$201,0))),"n.e.",INDEX(Results_Long!$P$2:$P$201,MATCH("C2|paris_mid|defined_classified|diff::rating",Results_Long!$AK$2:$AK$201,0))) -> -0.2828952 | D31: =IF(ISBLANK(INDEX(Results_Long!$Q$2:$Q$201,MATCH("C2|paris_mid|defined_classified|diff::rating",Results_Long!$AK$2:$AK$201,0))),"n.e.",INDEX(Results_Long!$Q$2:$Q$201,MATCH("C2|paris_mid|defined_classified|diff::rating",Results_Long!$AK$2:$AK$201,0))) -> 0.38803609 | E31: =IF(ISBLANK(INDEX(Results_Long!$N$2:$N$201,MATCH("C2|paris_mid|defined_classified|diff::rating",Results_Long!$AK$2:$AK$201,0))),"n.e.",INDEX(Results_Long!$N$2:$N$201,MATCH("C2|paris_mid|defined_classified|diff::rating",Results_Long!$AK$2:$AK$201,0))) -> 4.1545139 | F31: =IF(ISBLANK(INDEX(Results_Long!$O$2:$O$201,MATCH("C2|paris_mid|defined_classified|diff::rating",Results_Long!$AK$2:$AK$201,0))),"—",INDEX(Results_Long!$O$2:$O$201,MATCH("C2|paris_mid|defined_classified|diff::rating",Results_Long!$AK$2:$AK$201,0))) -> — | G31: =INDEX(Results_Long!$F$2:$F$201,MATCH("C2|paris_mid|defined_classified|diff::rating",Results_Long!$AK$2:$AK$201,0)) -> 3LMA-RVE_CR2
A32: derivativ (CDS spread) | B32: =IF(ISBLANK(INDEX(Results_Long!$K$2:$K$201,MATCH("C2|paris_mid|defined_classified|diff::derivativ (CDS spread)",Results_Long!$AK$2:$AK$201,0))),"n.e.",INDEX(Results_Long!$K$2:$K$201,MATCH("C2|paris_mid|defined_classified|diff::derivativ (CDS spread)",Results_Long!$AK$2:$AK$201,0))) -> n.e. | C32: =IF(ISBLANK(INDEX(Results_Long!$P$2:$P$201,MATCH("C2|paris_mid|defined_classified|diff::derivativ (CDS spread)",Results_Long!$AK$2:$AK$201,0))),"n.e.",INDEX(Results_Long!$P$2:$P$201,MATCH("C2|paris_mid|defined_classified|diff::derivativ (CDS spread)",Results_Long!$AK$2:$AK$201,0))) -> n.e. | D32: =IF(ISBLANK(INDEX(Results_Long!$Q$2:$Q$201,MATCH("C2|paris_mid|defined_classified|diff::derivativ (CDS spread)",Results_Long!$AK$2:$AK$201,0))),"n.e.",INDEX(Results_Long!$Q$2:$Q$201,MATCH("C2|paris_mid|defined_classified|diff::derivativ (CDS spread)",Results_Long!$AK$2:$AK$201,0))) -> n.e. | E32: =IF(ISBLANK(INDEX(Results_Long!$N$2:$N$201,MATCH("C2|paris_mid|defined_classified|diff::derivativ (CDS spread)",Results_Long!$AK$2:$AK$201,0))),"n.e.",INDEX(Results_Long!$N$2:$N$201,MATCH("C2|paris_mid|defined_classified|diff::derivativ (CDS spread)",Results_Long!$AK$2:$AK$201,0))) -> n.e. | F32: =IF(ISBLANK(INDEX(Results_Long!$O$2:$O$201,MATCH("C2|paris_mid|defined_classified|diff::derivativ (CDS spread)",Results_Long!$AK$2:$AK$201,0))),"—",INDEX(Results_Long!$O$2:$O$201,MATCH("C2|paris_mid|defined_classified|diff::derivativ (CDS spread)",Results_Long!$AK$2:$AK$201,0))) -> — | G32: =INDEX(Results_Long!$F$2:$F$201,MATCH("C2|paris_mid|defined_classified|diff::derivativ (CDS spread)",Results_Long!$AK$2:$AK$201,0)) -> not_estimable
A34: Level contrasts (M_A) | B34: dz | C34: df | D34: p
A35: loan (interest rate) vs bond (yield) | B35: =IF(ISBLANK(INDEX(Results_Long!$K$2:$K$201,MATCH("C2|levels|classified|pair::loan (interest rate) - bond (yield)",Results_Long!$AK$2:$AK$201,0))),"n.e.",INDEX(Results_Long!$K$2:$K$201,MATCH("C2|levels|classified|pair::loan (interest rate) - bond (yield)",Results_Long!$AK$2:$AK$201,0))) -> 0.053160359 | C35: =IF(ISBLANK(INDEX(Results_Long!$N$2:$N$201,MATCH("C2|levels|classified|pair::loan (interest rate) - bond (yield)",Results_Long!$AK$2:$AK$201,0))),"n.e.",INDEX(Results_Long!$N$2:$N$201,MATCH("C2|levels|classified|pair::loan (interest rate) - bond (yield)",Results_Long!$AK$2:$AK$201,0))) -> 7.6978478 | D35: =IF(ISBLANK(INDEX(Results_Long!$O$2:$O$201,MATCH("C2|levels|classified|pair::loan (interest rate) - bond (yield)",Results_Long!$AK$2:$AK$201,0))),"—",INDEX(Results_Long!$O$2:$O$201,MATCH("C2|levels|classified|pair::loan (interest rate) - bond (yield)",Results_Long!$AK$2:$AK$201,0))) -> 0.0090785143
A36: loan (interest rate) vs rating | B36: =IF(ISBLANK(INDEX(Results_Long!$K$2:$K$201,MATCH("C2|levels|classified|pair::loan (interest rate) - rating",Results_Long!$AK$2:$AK$201,0))),"n.e.",INDEX(Results_Long!$K$2:$K$201,MATCH("C2|levels|classified|pair::loan (interest rate) - rating",Results_Long!$AK$2:$AK$201,0))) -> 0.019913609 | C36: =IF(ISBLANK(INDEX(Results_Long!$N$2:$N$201,MATCH("C2|levels|classified|pair::loan (interest rate) - rating",Results_Long!$AK$2:$AK$201,0))),"n.e.",INDEX(Results_Long!$N$2:$N$201,MATCH("C2|levels|classified|pair::loan (interest rate) - rating",Results_Long!$AK$2:$AK$201,0))) -> 6.6077537 | D36: =IF(ISBLANK(INDEX(Results_Long!$O$2:$O$201,MATCH("C2|levels|classified|pair::loan (interest rate) - rating",Results_Long!$AK$2:$AK$201,0))),"—",INDEX(Results_Long!$O$2:$O$201,MATCH("C2|levels|classified|pair::loan (interest rate) - rating",Results_Long!$AK$2:$AK$201,0))) -> 0.25366692
A37: loan (interest rate) vs derivativ (CDS spread) | B37: =IF(ISBLANK(INDEX(Results_Long!$K$2:$K$201,MATCH("C2|levels|classified|pair::loan (interest rate) - derivativ (CDS spread)",Results_Long!$AK$2:$AK$201,0))),"n.e.",INDEX(Results_Long!$K$2:$K$201,MATCH("C2|levels|classified|pair::loan (interest rate) - derivativ (CDS spread)",Results_Long!$AK$2:$AK$201,0))) -> 0.084101991 | C37: =IF(ISBLANK(INDEX(Results_Long!$N$2:$N$201,MATCH("C2|levels|classified|pair::loan (interest rate) - derivativ (CDS spread)",Results_Long!$AK$2:$AK$201,0))),"n.e.",INDEX(Results_Long!$N$2:$N$201,MATCH("C2|levels|classified|pair::loan (interest rate) - derivativ (CDS spread)",Results_Long!$AK$2:$AK$201,0))) -> 6.734945 | D37: =IF(ISBLANK(INDEX(Results_Long!$O$2:$O$201,MATCH("C2|levels|classified|pair::loan (interest rate) - derivativ (CDS spread)",Results_Long!$AK$2:$AK$201,0))),"—",INDEX(Results_Long!$O$2:$O$201,MATCH("C2|levels|classified|pair::loan (interest rate) - derivativ (CDS spread)",Results_Long!$AK$2:$AK$201,0))) -> 0.30907587
A38: bond (yield) vs rating | B38: =IF(ISBLANK(INDEX(Results_Long!$K$2:$K$201,MATCH("C2|levels|classified|pair::bond (yield) - rating",Results_Long!$AK$2:$AK$201,0))),"n.e.",INDEX(Results_Long!$K$2:$K$201,MATCH("C2|levels|classified|pair::bond (yield) - rating",Results_Long!$AK$2:$AK$201,0))) -> -0.03324675 | C38: =IF(ISBLANK(INDEX(Results_Long!$N$2:$N$201,MATCH("C2|levels|classified|pair::bond (yield) - rating",Results_Long!$AK$2:$AK$201,0))),"n.e.",INDEX(Results_Long!$N$2:$N$201,MATCH("C2|levels|classified|pair::bond (yield) - rating",Results_Long!$AK$2:$AK$201,0))) -> 2.1134522 | D38: =IF(ISBLANK(INDEX(Results_Long!$O$2:$O$201,MATCH("C2|levels|classified|pair::bond (yield) - rating",Results_Long!$AK$2:$AK$201,0))),"—",INDEX(Results_Long!$O$2:$O$201,MATCH("C2|levels|classified|pair::bond (yield) - rating",Results_Long!$AK$2:$AK$201,0))) -> —
A39: bond (yield) vs derivativ (CDS spread) | B39: =IF(ISBLANK(INDEX(Results_Long!$K$2:$K$201,MATCH("C2|levels|classified|pair::bond (yield) - derivativ (CDS spread)",Results_Long!$AK$2:$AK$201,0))),"n.e.",INDEX(Results_Long!$K$2:$K$201,MATCH("C2|levels|classified|pair::bond (yield) - derivativ (CDS spread)",Results_Long!$AK$2:$AK$201,0))) -> 0.030941632 | C39: =IF(ISBLANK(INDEX(Results_Long!$N$2:$N$201,MATCH("C2|levels|classified|pair::bond (yield) - derivativ (CDS spread)",Results_Long!$AK$2:$AK$201,0))),"n.e.",INDEX(Results_Long!$N$2:$N$201,MATCH("C2|levels|classified|pair::bond (yield) - derivativ (CDS spread)",Results_Long!$AK$2:$AK$201,0))) -> 5.9932112 | D39: =IF(ISBLANK(INDEX(Results_Long!$O$2:$O$201,MATCH("C2|levels|classified|pair::bond (yield) - derivativ (CDS spread)",Results_Long!$AK$2:$AK$201,0))),"—",INDEX(Results_Long!$O$2:$O$201,MATCH("C2|levels|classified|pair::bond (yield) - derivativ (CDS spread)",Results_Long!$AK$2:$AK$201,0))) -> 0.68748068
A40: rating vs derivativ (CDS spread) | B40: =IF(ISBLANK(INDEX(Results_Long!$K$2:$K$201,MATCH("C2|levels|classified|pair::rating - derivativ (CDS spread)",Results_Long!$AK$2:$AK$201,0))),"n.e.",INDEX(Results_Long!$K$2:$K$201,MATCH("C2|levels|classified|pair::rating - derivativ (CDS spread)",Results_Long!$AK$2:$AK$201,0))) -> 0.064188382 | C40: =IF(ISBLANK(INDEX(Results_Long!$N$2:$N$201,MATCH("C2|levels|classified|pair::rating - derivativ (CDS spread)",Results_Long!$AK$2:$AK$201,0))),"n.e.",INDEX(Results_Long!$N$2:$N$201,MATCH("C2|levels|classified|pair::rating - derivativ (CDS spread)",Results_Long!$AK$2:$AK$201,0))) -> 4.5405051 | D40: =IF(ISBLANK(INDEX(Results_Long!$O$2:$O$201,MATCH("C2|levels|classified|pair::rating - derivativ (CDS spread)",Results_Long!$AK$2:$AK$201,0))),"—",INDEX(Results_Long!$O$2:$O$201,MATCH("C2|levels|classified|pair::rating - derivativ (CDS spread)",Results_Long!$AK$2:$AK$201,0))) -> —
A42: Levels equal (HTZ) | B42: =IF(ISBLANK(INDEX(Results_Long!$M$2:$M$201,MATCH("C2|levels|classified|levels_HTZ",Results_Long!$AK$2:$AK$201,0))),"n.e.",INDEX(Results_Long!$M$2:$M$201,MATCH("C2|levels|classified|levels_HTZ",Results_Long!$AK$2:$AK$201,0))) -> 3.4289985 | C42: =IF(ISBLANK(INDEX(Results_Long!$N$2:$N$201,MATCH("C2|levels|classified|levels_HTZ",Results_Long!$AK$2:$AK$201,0))),"n.e.",INDEX(Results_Long!$N$2:$N$201,MATCH("C2|levels|classified|levels_HTZ",Results_Long!$AK$2:$AK$201,0))) -> 4.7796082 | D42: =IF(ISBLANK(INDEX(Results_Long!$O$2:$O$201,MATCH("C2|levels|classified|levels_HTZ",Results_Long!$AK$2:$AK$201,0))),"—",INDEX(Results_Long!$O$2:$O$201,MATCH("C2|levels|classified|levels_HTZ",Results_Long!$AK$2:$AK$201,0))) -> 0.11339224 | E42: =IF(ISNUMBER(SEARCH("<3-cluster",INDEX(Results_Long!$AJ$2:$AJ$201,MATCH("C2|levels|classified|levels_HTZ",Results_Long!$AK$2:$AK$201,0)))),"touches <3-cluster cell","")
A43: Moderation test (interaction HTZ) | B43: =IF(ISBLANK(INDEX(Results_Long!$M$2:$M$201,MATCH("C2|paris_mid|defined_classified|interaction_HTZ",Results_Long!$AK$2:$AK$201,0))),"n.e.",INDEX(Results_Long!$M$2:$M$201,MATCH("C2|paris_mid|defined_classified|interaction_HTZ",Results_Long!$AK$2:$AK$201,0))) -> 0.38881646 | C43: =IF(ISBLANK(INDEX(Results_Long!$N$2:$N$201,MATCH("C2|paris_mid|defined_classified|interaction_HTZ",Results_Long!$AK$2:$AK$201,0))),"n.e.",INDEX(Results_Long!$N$2:$N$201,MATCH("C2|paris_mid|defined_classified|interaction_HTZ",Results_Long!$AK$2:$AK$201,0))) -> 3.0916267 | D43: =IF(ISBLANK(INDEX(Results_Long!$O$2:$O$201,MATCH("C2|paris_mid|defined_classified|interaction_HTZ",Results_Long!$AK$2:$AK$201,0))),"—",INDEX(Results_Long!$O$2:$O$201,MATCH("C2|paris_mid|defined_classified|interaction_HTZ",Results_Long!$AK$2:$AK$201,0))) -> 0.70692718 | E43: =IF(ISNUMBER(SEARCH("<3-cluster",INDEX(Results_Long!$AJ$2:$AJ$201,MATCH("C2|paris_mid|defined_classified|interaction_HTZ",Results_Long!$AK$2:$AK$201,0)))),"touches <3-cluster cell","")
A46: C4 — regulation3
A47: Level (M_A) | B47: r | C47: CI_r low | D47: CI_r high | E47: PI_r low | F47: PI_r high | G47: df
A48: without ETS/CT | B48: =IF(ISBLANK(INDEX(Results_Long!$T$2:$T$201,MATCH("C4|levels|classified|lvl::without ETS/CT",Results_Long!$AK$2:$AK$201,0))),"n.e.",INDEX(Results_Long!$T$2:$T$201,MATCH("C4|levels|classified|lvl::without ETS/CT",Results_Long!$AK$2:$AK$201,0))) -> -0.063156914 | C48: =IF(ISBLANK(INDEX(Results_Long!$U$2:$U$201,MATCH("C4|levels|classified|lvl::without ETS/CT",Results_Long!$AK$2:$AK$201,0))),"n.e.",INDEX(Results_Long!$U$2:$U$201,MATCH("C4|levels|classified|lvl::without ETS/CT",Results_Long!$AK$2:$AK$201,0))) -> -0.093044155 | D48: =IF(ISBLANK(INDEX(Results_Long!$V$2:$V$201,MATCH("C4|levels|classified|lvl::without ETS/CT",Results_Long!$AK$2:$AK$201,0))),"n.e.",INDEX(Results_Long!$V$2:$V$201,MATCH("C4|levels|classified|lvl::without ETS/CT",Results_Long!$AK$2:$AK$201,0))) -> -0.033155961 | E48: =IF(ISBLANK(INDEX(Results_Long!$W$2:$W$201,MATCH("C4|levels|classified|lvl::without ETS/CT",Results_Long!$AK$2:$AK$201,0))),"n.e.",INDEX(Results_Long!$W$2:$W$201,MATCH("C4|levels|classified|lvl::without ETS/CT",Results_Long!$AK$2:$AK$201,0))) -> -0.43565115 | F48: =IF(ISBLANK(INDEX(Results_Long!$X$2:$X$201,MATCH("C4|levels|classified|lvl::without ETS/CT",Results_Long!$AK$2:$AK$201,0))),"n.e.",INDEX(Results_Long!$X$2:$X$201,MATCH("C4|levels|classified|lvl::without ETS/CT",Results_Long!$AK$2:$AK$201,0))) -> 0.32780626 | G48: =IF(ISBLANK(INDEX(Results_Long!$N$2:$N$201,MATCH("C4|levels|classified|lvl::without ETS/CT",Results_Long!$AK$2:$AK$201,0))),"n.e.",INDEX(Results_Long!$N$2:$N$201,MATCH("C4|levels|classified|lvl::without ETS/CT",Results_Long!$AK$2:$AK$201,0))) -> 48.487822
A49: with ETS/CT | B49: =IF(ISBLANK(INDEX(Results_Long!$T$2:$T$201,MATCH("C4|levels|classified|lvl::with ETS/CT",Results_Long!$AK$2:$AK$201,0))),"n.e.",INDEX(Results_Long!$T$2:$T$201,MATCH("C4|levels|classified|lvl::with ETS/CT",Results_Long!$AK$2:$AK$201,0))) -> -0.068100162 | C49: =IF(ISBLANK(INDEX(Results_Long!$U$2:$U$201,MATCH("C4|levels|classified|lvl::with ETS/CT",Results_Long!$AK$2:$AK$201,0))),"n.e.",INDEX(Results_Long!$U$2:$U$201,MATCH("C4|levels|classified|lvl::with ETS/CT",Results_Long!$AK$2:$AK$201,0))) -> -0.14287093 | D49: =IF(ISBLANK(INDEX(Results_Long!$V$2:$V$201,MATCH("C4|levels|classified|lvl::with ETS/CT",Results_Long!$AK$2:$AK$201,0))),"n.e.",INDEX(Results_Long!$V$2:$V$201,MATCH("C4|levels|classified|lvl::with ETS/CT",Results_Long!$AK$2:$AK$201,0))) -> 0.007443518 | E49: =IF(ISBLANK(INDEX(Results_Long!$W$2:$W$201,MATCH("C4|levels|classified|lvl::with ETS/CT",Results_Long!$AK$2:$AK$201,0))),"n.e.",INDEX(Results_Long!$W$2:$W$201,MATCH("C4|levels|classified|lvl::with ETS/CT",Results_Long!$AK$2:$AK$201,0))) -> -0.46104593 | F49: =IF(ISBLANK(INDEX(Results_Long!$X$2:$X$201,MATCH("C4|levels|classified|lvl::with ETS/CT",Results_Long!$AK$2:$AK$201,0))),"n.e.",INDEX(Results_Long!$X$2:$X$201,MATCH("C4|levels|classified|lvl::with ETS/CT",Results_Long!$AK$2:$AK$201,0))) -> 0.34717438 | G49: =IF(ISBLANK(INDEX(Results_Long!$N$2:$N$201,MATCH("C4|levels|classified|lvl::with ETS/CT",Results_Long!$AK$2:$AK$201,0))),"n.e.",INDEX(Results_Long!$N$2:$N$201,MATCH("C4|levels|classified|lvl::with ETS/CT",Results_Long!$AK$2:$AK$201,0))) -> 16.35057
A51: Paris shift (M_B) | B51: dz (post-pre) | C51: CI_z low | D51: CI_z high | E51: df | F51: p | G51: status
A52: without ETS/CT | B52: =IF(ISBLANK(INDEX(Results_Long!$K$2:$K$201,MATCH("C4|paris_mid|defined_classified|diff::without ETS/CT",Results_Long!$AK$2:$AK$201,0))),"n.e.",INDEX(Results_Long!$K$2:$K$201,MATCH("C4|paris_mid|defined_classified|diff::without ETS/CT",Results_Long!$AK$2:$AK$201,0))) -> -0.013785907 | C52: =IF(ISBLANK(INDEX(Results_Long!$P$2:$P$201,MATCH("C4|paris_mid|defined_classified|diff::without ETS/CT",Results_Long!$AK$2:$AK$201,0))),"n.e.",INDEX(Results_Long!$P$2:$P$201,MATCH("C4|paris_mid|defined_classified|diff::without ETS/CT",Results_Long!$AK$2:$AK$201,0))) -> -0.083456451 | D52: =IF(ISBLANK(INDEX(Results_Long!$Q$2:$Q$201,MATCH("C4|paris_mid|defined_classified|diff::without ETS/CT",Results_Long!$AK$2:$AK$201,0))),"n.e.",INDEX(Results_Long!$Q$2:$Q$201,MATCH("C4|paris_mid|defined_classified|diff::without ETS/CT",Results_Long!$AK$2:$AK$201,0))) -> 0.055884637 | E52: =IF(ISBLANK(INDEX(Results_Long!$N$2:$N$201,MATCH("C4|paris_mid|defined_classified|diff::without ETS/CT",Results_Long!$AK$2:$AK$201,0))),"n.e.",INDEX(Results_Long!$N$2:$N$201,MATCH("C4|paris_mid|defined_classified|diff::without ETS/CT",Results_Long!$AK$2:$AK$201,0))) -> 5.9953518 | F52: =IF(ISBLANK(INDEX(Results_Long!$O$2:$O$201,MATCH("C4|paris_mid|defined_classified|diff::without ETS/CT",Results_Long!$AK$2:$AK$201,0))),"—",INDEX(Results_Long!$O$2:$O$201,MATCH("C4|paris_mid|defined_classified|diff::without ETS/CT",Results_Long!$AK$2:$AK$201,0))) -> 0.64537731 | G52: =INDEX(Results_Long!$F$2:$F$201,MATCH("C4|paris_mid|defined_classified|diff::without ETS/CT",Results_Long!$AK$2:$AK$201,0)) -> 3LMA-RVE_CR2
...

Sheet 8_Other_Panels
A1: Other panels — industry, economic development, culture, legal origin
A2: Reported in full; main-text prominence per the tiering rule [R1]
A3: All cells formula-linked to Results_Long
A5: C3 — industry
A6: Level (M_A) | B6: r | C6: CI_r low | D6: CI_r high | E6: PI_r low | F6: PI_r high | G6: df
A7: non-sensitive | B7: =IF(ISBLANK(INDEX(Results_Long!$T$2:$T$201,MATCH("C3|levels|classified|lvl::non-sensitive",Results_Long!$AK$2:$AK$201,0))),"n.e.",INDEX(Results_Long!$T$2:$T$201,MATCH("C3|levels|classified|lvl::non-sensitive",Results_Long!$AK$2:$AK$201,0))) -> -0.061609528 | C7: =IF(ISBLANK(INDEX(Results_Long!$U$2:$U$201,MATCH("C3|levels|classified|lvl::non-sensitive",Results_Long!$AK$2:$AK$201,0))),"n.e.",INDEX(Results_Long!$U$2:$U$201,MATCH("C3|levels|classified|lvl::non-sensitive",Results_Long!$AK$2:$AK$201,0))) -> -0.099324122 | D7: =IF(ISBLANK(INDEX(Results_Long!$V$2:$V$201,MATCH("C3|levels|classified|lvl::non-sensitive",Results_Long!$AK$2:$AK$201,0))),"n.e.",INDEX(Results_Long!$V$2:$V$201,MATCH("C3|levels|classified|lvl::non-sensitive",Results_Long!$AK$2:$AK$201,0))) -> -0.023718175 | E7: =IF(ISBLANK(INDEX(Results_Long!$W$2:$W$201,MATCH("C3|levels|classified|lvl::non-sensitive",Results_Long!$AK$2:$AK$201,0))),"n.e.",INDEX(Results_Long!$W$2:$W$201,MATCH("C3|levels|classified|lvl::non-sensitive",Results_Long!$AK$2:$AK$201,0))) -> -0.4234863 | F7: =IF(ISBLANK(INDEX(Results_Long!$X$2:$X$201,MATCH("C3|levels|classified|lvl::non-sensitive",Results_Long!$AK$2:$AK$201,0))),"n.e.",INDEX(Results_Long!$X$2:$X$201,MATCH("C3|levels|classified|lvl::non-sensitive",Results_Long!$AK$2:$AK$201,0))) -> 0.31722383 | G7: =IF(ISBLANK(INDEX(Results_Long!$N$2:$N$201,MATCH("C3|levels|classified|lvl::non-sensitive",Results_Long!$AK$2:$AK$201,0))),"n.e.",INDEX(Results_Long!$N$2:$N$201,MATCH("C3|levels|classified|lvl::non-sensitive",Results_Long!$AK$2:$AK$201,0))) -> 69.595427
A8: sensitive | B8: =IF(ISBLANK(INDEX(Results_Long!$T$2:$T$201,MATCH("C3|levels|classified|lvl::sensitive",Results_Long!$AK$2:$AK$201,0))),"n.e.",INDEX(Results_Long!$T$2:$T$201,MATCH("C3|levels|classified|lvl::sensitive",Results_Long!$AK$2:$AK$201,0))) -> -0.045813193 | C8: =IF(ISBLANK(INDEX(Results_Long!$U$2:$U$201,MATCH("C3|levels|classified|lvl::sensitive",Results_Long!$AK$2:$AK$201,0))),"n.e.",INDEX(Results_Long!$U$2:$U$201,MATCH("C3|levels|classified|lvl::sensitive",Results_Long!$AK$2:$AK$201,0))) -> -0.08067026 | D8: =IF(ISBLANK(INDEX(Results_Long!$V$2:$V$201,MATCH("C3|levels|classified|lvl::sensitive",Results_Long!$AK$2:$AK$201,0))),"n.e.",INDEX(Results_Long!$V$2:$V$201,MATCH("C3|levels|classified|lvl::sensitive",Results_Long!$AK$2:$AK$201,0))) -> -0.010844206 | E8: =IF(ISBLANK(INDEX(Results_Long!$W$2:$W$201,MATCH("C3|levels|classified|lvl::sensitive",Results_Long!$AK$2:$AK$201,0))),"n.e.",INDEX(Results_Long!$W$2:$W$201,MATCH("C3|levels|classified|lvl::sensitive",Results_Long!$AK$2:$AK$201,0))) -> -0.45332966 | F8: =IF(ISBLANK(INDEX(Results_Long!$X$2:$X$201,MATCH("C3|levels|classified|lvl::sensitive",Results_Long!$AK$2:$AK$201,0))),"n.e.",INDEX(Results_Long!$X$2:$X$201,MATCH("C3|levels|classified|lvl::sensitive",Results_Long!$AK$2:$AK$201,0))) -> 0.37754438 | G8: =IF(ISBLANK(INDEX(Results_Long!$N$2:$N$201,MATCH("C3|levels|classified|lvl::sensitive",Results_Long!$AK$2:$AK$201,0))),"n.e.",INDEX(Results_Long!$N$2:$N$201,MATCH("C3|levels|classified|lvl::sensitive",Results_Long!$AK$2:$AK$201,0))) -> 8.8463406
A10: Paris shift (M_B) | B10: dz (post-pre) | C10: CI_z low | D10: CI_z high | E10: df | F10: p | G10: status
A11: non-sensitive | B11: =IF(ISBLANK(INDEX(Results_Long!$K$2:$K$201,MATCH("C3|paris_mid|defined_classified|diff::non-sensitive",Results_Long!$AK$2:$AK$201,0))),"n.e.",INDEX(Results_Long!$K$2:$K$201,MATCH("C3|paris_mid|defined_classified|diff::non-sensitive",Results_Long!$AK$2:$AK$201,0))) -> 0.019059525 | C11: =IF(ISBLANK(INDEX(Results_Long!$P$2:$P$201,MATCH("C3|paris_mid|defined_classified|diff::non-sensitive",Results_Long!$AK$2:$AK$201,0))),"n.e.",INDEX(Results_Long!$P$2:$P$201,MATCH("C3|paris_mid|defined_classified|diff::non-sensitive",Results_Long!$AK$2:$AK$201,0))) -> -0.037560931 | D11: =IF(ISBLANK(INDEX(Results_Long!$Q$2:$Q$201,MATCH("C3|paris_mid|defined_classified|diff::non-sensitive",Results_Long!$AK$2:$AK$201,0))),"n.e.",INDEX(Results_Long!$Q$2:$Q$201,MATCH("C3|paris_mid|defined_classified|diff::non-sensitive",Results_Long!$AK$2:$AK$201,0))) -> 0.075679981 | E11: =IF(ISBLANK(INDEX(Results_Long!$N$2:$N$201,MATCH("C3|paris_mid|defined_classified|diff::non-sensitive",Results_Long!$AK$2:$AK$201,0))),"n.e.",INDEX(Results_Long!$N$2:$N$201,MATCH("C3|paris_mid|defined_classified|diff::non-sensitive",Results_Long!$AK$2:$AK$201,0))) -> 25.771443 | F11: =IF(ISBLANK(INDEX(Results_Long!$O$2:$O$201,MATCH("C3|paris_mid|defined_classified|diff::non-sensitive",Results_Long!$AK$2:$AK$201,0))),"—",INDEX(Results_Long!$O$2:$O$201,MATCH("C3|paris_mid|defined_classified|diff::non-sensitive",Results_Long!$AK$2:$AK$201,0))) -> 0.49498378 | G11: =INDEX(Results_Long!$F$2:$F$201,MATCH("C3|paris_mid|defined_classified|diff::non-sensitive",Results_Long!$AK$2:$AK$201,0)) -> 3LMA-RVE_CR2
A12: sensitive | B12: =IF(ISBLANK(INDEX(Results_Long!$K$2:$K$201,MATCH("C3|paris_mid|defined_classified|diff::sensitive",Results_Long!$AK$2:$AK$201,0))),"n.e.",INDEX(Results_Long!$K$2:$K$201,MATCH("C3|paris_mid|defined_classified|diff::sensitive",Results_Long!$AK$2:$AK$201,0))) -> 0.039265731 | C12: =IF(ISBLANK(INDEX(Results_Long!$P$2:$P$201,MATCH("C3|paris_mid|defined_classified|diff::sensitive",Results_Long!$AK$2:$AK$201,0))),"n.e.",INDEX(Results_Long!$P$2:$P$201,MATCH("C3|paris_mid|defined_classified|diff::sensitive",Results_Long!$AK$2:$AK$201,0))) -> -0.042041651 | D12: =IF(ISBLANK(INDEX(Results_Long!$Q$2:$Q$201,MATCH("C3|paris_mid|defined_classified|diff::sensitive",Results_Long!$AK$2:$AK$201,0))),"n.e.",INDEX(Results_Long!$Q$2:$Q$201,MATCH("C3|paris_mid|defined_classified|diff::sensitive",Results_Long!$AK$2:$AK$201,0))) -> 0.12057311 | E12: =IF(ISBLANK(INDEX(Results_Long!$N$2:$N$201,MATCH("C3|paris_mid|defined_classified|diff::sensitive",Results_Long!$AK$2:$AK$201,0))),"n.e.",INDEX(Results_Long!$N$2:$N$201,MATCH("C3|paris_mid|defined_classified|diff::sensitive",Results_Long!$AK$2:$AK$201,0))) -> 3.8212558 | F12: =IF(ISBLANK(INDEX(Results_Long!$O$2:$O$201,MATCH("C3|paris_mid|defined_classified|diff::sensitive",Results_Long!$AK$2:$AK$201,0))),"—",INDEX(Results_Long!$O$2:$O$201,MATCH("C3|paris_mid|defined_classified|diff::sensitive",Results_Long!$AK$2:$AK$201,0))) -> — | G12: =INDEX(Results_Long!$F$2:$F$201,MATCH("C3|paris_mid|defined_classified|diff::sensitive",Results_Long!$AK$2:$AK$201,0)) -> 3LMA-RVE_CR2
A14: Level contrasts (M_A) | B14: dz | C14: df | D14: p
