Workbook

Sheet 1_README
A1: FOMA CER–COD — T8 results workbook (Paris identification battery, Block B: B2/B4/B5/B8)
A2: Template: docs/results_workbook_template.md (binding) · built by project chat from output/T8_results.csv
A3: run 2026-07-15 21:54 CEST · verifier 27/27 PASS · commit 76074a2 (gate 3d7d0c8)
A5: Item | B5: Value
A6: Version | B6: T8 v5 — R/08_identification.R @ 76074a2; Gate-2 GO 2026-07-15 @ 3d7d0c8
A7: Method | B7: 3-level RVE (rma.mv REML, ~1|cluster_id/study/esid; V rho=0.6 on cluster_id; CR2/Satterthwaite) — identification battery: race, placebos, segmented MR, dose, composition, bounding
A8: Scope | B8: dose/period domain: 2,705 ES / 113 studies / 112 clusters [DEC-042b]
A9: Repo | B9: rwitte-wu-research/FOMA-CER-COD-Paris (main)
A10: Stack | B10: R 4.6.1 · metafor 5.0-1 · clubSandwich 0.7.0 · renv 1.2.3 (lockfile)
A11: Scripts | B11: R/08_identification.R (v5) + R/08_verify_outputs.R (27 checks)
A12: Decision basis | B12: DEC-007/021/024/024a · DEC-031 + 031a/c/d/e · DEC-042a/b · plan Addendum A.2/A.3/A.9/A.10
A14: TAB-INDEX
A15: 1_README | B15: this tab
A16: 2_Methodology | B16: quantity → construction → reference
A17: 3_Interpretation_Guide | B17: how to read; decision rules
A18: 4_Formula_Reference | B18: exact R calls
A19: 5_Data_Provenance | B19: domain, md5, run, verifier, pins
A20: 6_T8_Design | B20: design constants (11 rows)
A21: 7_B2_Dose | B21: dose model + predictions + contrasts
A22: 8_B4_Trend_vs_Break | B22: race, placebos, segmented
A23: 9_B5_Composition | B23: composition control
A24: 10_B8_Bounding | B24: Oster analog + E-values
A25: Results_Long | B25: verbatim run CSV — single formula source
A26: Manuscript_Inputs | B26: ms_input rows, formula-derived strings
A27: Manuscript_Text_Blocks | B27: TB-20…TB-28 (EN, framing-neutral)

Sheet 2_Methodology
A1: Methodology — T8 identification battery
A2: Quantity | Formula / Construction | Reference
A3: run 2026-07-15 21:54 CEST · verifier 27/27 PASS · commit 76074a2 (gate 3d7d0c8)
A5: Quantity | B5: Formula / Construction | C5: Reference
A6: V matrix | B6: impute_covariance_matrix(vi, cluster = cluster_id, r = 0.6) | C6: [DEC-017; D31.1; F56]
A7: Random structure | B7: ~ 1 | cluster_id/study/esid (REML, sparse) | C7: [D31.1; plan A.2]
A8: Inference | B8: CR2 + Satterthwaite on cluster_id (coef_test / conf_int / linear_contrast; Wald HTZ) | C8: [Tipton & Pustejovsky 2015; plan §3]
A9: Placebo recode | B9: share_Y = clip((end−Y+1)/(end−start+1),0,1); pp_Y = 1{share_Y ≥ 0.5}, ties→Post; 2016 identity gate | C9: [DEC-024a; DEC-024]
A10: break_only | B10: cell-means ~ 0 + factor(pp); diff = CR2 contrast (−1,+1) — T2/B1 convention | C10: [DEC-031e]
A11: Dose predictions | B11: z̄(s) at calendar 2015.5 via offset (KNOT − CENTER); contrasts on dose slope | C11: [DEC-024; plan A.9]
A12: Composition set | B12: {country_region, COD_instrument, CER_measure}; refs {1_US, loan, performance}; 99_NCE own level | C12: [DEC-031d; F61]
A13: Oster analog | B13: R² = 1 − Σσ²_m/Σσ²_0; uncontrolled = race, controlled = trend_composition; Rmax = min(1.3·R²_c, 1); β*(δ=1); δ* | C13: [Oster 2019; DEC-031d P1]
A14: E-value | B14: r→d = 2r/√(1−r²); RR ≈ exp(0.91·d); E = RR + √(RR(RR−1)) | C14: [VanderWeele & Ding 2017]
A15: SESOI band | B15: |r| = 0.070 primary (F27v2); |Δr| = 0.05 secondary; read-out Δβ + adjusted CI, not p | C15: [DEC-031 Block E; F61-P3]

Sheet 3_Interpretation_Guide
A1: Interpretation guide
A2: Quantity | Meaning | Decision rule
A3: run 2026-07-15 21:54 CEST · verifier 27/27 PASS · commit 76074a2 (gate 3d7d0c8)
A5: Quantity | B5: Meaning | C5: Decision rule
A6: diff / contrast (z) | B6: difference of Fisher-z means; |Δz| ≈ |Δr| at these magnitudes (3rd-order approx) | C6: no tanh transform of differences; z-only rows
A7: SESOI read-out | B7: Δβ vs anchor + adjusted CI against the SESOI band | C7: inside ±0.070 (primary) → precise null; ±0.05 secondary reported [F61-P3]
A8: df transfer rule | B8: Satterthwaite df on the coefficient | C8: df ≥ 5 full inference; df < 4–5 descriptive [DEC-024]; flags in note
A9: Placebo rank | B9: rank of |2016 break| among 9 cutoffs (1 = largest) | C9: localization requires rank ≈ 1; high rank = no treaty-specific break
A10: pseudo-R² | B10: variance-component reduction vs intercept-only | C10: can be negative under REML — disclosed, not an error
A11: δ* (Oster) | B11: selection strength driving β to 0 | C11: mechanically unstable near a null; read jointly with β* and mask E-values
A12: E-value | B12: min. confounding RR to explain / mask an association | C12: small E on residual = fragile signal; small E on mask = bounding not the pillar

Sheet 4_Formula_Reference
A1: Formula reference — exact R calls
A2: Quantity | R call | Script section
A3: run 2026-07-15 21:54 CEST · verifier 27/27 PASS · commit 76074a2 (gate 3d7d0c8)
A5: Quantity | B5: R call | C5: Reference / script section
A6: Fit spine | B6: rma.mv(zi, V6, mods, random=~1|cluster_id/study/esid, sparse=TRUE, method="REML") | C6: fit3l(), §2
A7: CR2 vcov | B7: vcovCR(m, cluster = cluster_id, type = "CR2") | C7: vcr(), §2
A8: Coefficients | B8: coef_test(m, vcov, test="Satterthwaite"); conf_int(m, vcov, level=.95) | C8: coef_rows(), §2
A9: Predictions/contrasts | B9: linear_contrast(m, vcov, contrasts = rbind(Lp, Lc), level=.95) | C9: pred_contrast_rows(), §4
A10: Wald | B10: Wald_test(m, constrain_zero(idx), vcov, test="HTZ") | C10: wald_row(), §2
A11: break_only diff | B11: linear_contrast(mB, vcov, contrasts = rbind(diff = c(-1, 1))) | C11: §5 [DEC-031e]
A12: share_Y | B12: pmin(pmax((d_sample_end − Y + 1)/L, 0), 1); L = end − start + 1 | C12: share_y(), §1 [DEC-024a]
A13: E-value | B13: d = 2r/sqrt(1−r²); RR = exp(0.91·d); E = RR + sqrt(RR·(RR−1)) | C13: evalue_r(), §7

Sheet 5_Data_Provenance
A1: Data provenance & run record
A2: Item | Value | Source
A3: run 2026-07-15 21:54 CEST · verifier 27/27 PASS · commit 76074a2 (gate 3d7d0c8)
A5: Item | B5: Value | C5: Source
A6: Estimation set | B6: 2,713 ES / 115 studies / 114 clusters | C6: [DEC-042a]
A7: Dose/period domain | B7: 2,705 ES / 113 studies / 112 clusters; delta = 8 ES / 2 studies / 2 clusters (Bhattacharya & Sharma 2019; Ng & Rezaee 2012), listwise on window codings | C7: [DEC-042b; F61-P2]
A8: dat_prep md5 | B8: 6702ef3dc45fe0b693b13f50ebd1576b | C8: output/T8_run_meta.txt
A9: pr$n / pr$seed | B9: 2713 / 20260710 (contract asserted) | C9: run_meta
A10: Spec revision | B10: R/08_identification.R v5 @ 76074a2; Gate-2 GO @ 3d7d0c8 | C10: git
A11: Run / verifier | B11: 2026-07-15 21:54:41 CEST · 27/27 PASS, exit 0 · O15 replication at machine precision (Δ ≈ 1e-16) | C11: CC transcript; independent re-check project chat
A12: CENTER / OFFSET | B12: sample_mid_c centered at 2012.257855823 (grand mean); predictions at calendar 2015.5 via offset 3.242144177 | C12: run_meta; design row
A13: mB parameterization | B13: cell-means per DEC-031e after nlminb false convergence (σ²_study boundary); 17/17 convergence certificates in run_meta | C13: [DEC-031e]
A14: F60 placebo cells | B14: 2008: 2367/100/99 … 2015: 784/38/38 (pinned, verifier O9) | C14: [DEC-024a]
A15: Known warnings | B15: impute_covariance_matrix() deprecation (frozen-in F56 behavior) | C15: CC transcript

Sheet 6_T8_Design
A1: T8 design constants (result-blind, v12-derived)
A2: value column formula-linked to Results_Long
A3: run 2026-07-15 21:54 CEST · verifier 27/27 PASS · commit 76074a2 (gate 3d7d0c8)
A5: Constant | B5: Value | C5: Note (verbatim CSV)
A6: subset_dose_period | B6: =Results_Long!AG2 -> 2705 | C6: =Results_Long!AJ2 -> 2,705 ES / 113 studies / 112 clusters [DEC-042b]; run date in T8_run_meta.txt
A7: period_na | B7: =Results_Long!AG3 -> 8 | C7: =Results_Long!AJ3 -> 8 ES / 2 studies / 2 clusters (Bhattacharya & Sharma 2019; Ng & Rezaee 2012) [DEC-042b]; provenance for workbook Tab 5_Data_Provenance
A8: post_cell_2016 | B8: =Results_Long!AG4 -> 711 | C8: =Results_Long!AJ4 -> 711 ES / 31 studies / 31 clusters (v12 design constant)
A9: corr_sample_mid_share | B9: =Results_Long!AG5 -> 0.8145797 | C9: =Results_Long!AJ5 -> ES-level Pearson on 2,705; supersedes stale 0.70 pin (v8-era) — plan Section 4 disclosure updates [DEC-031 counts-re-derive]
A10: share_distinct | B10: =Results_Long!AG6 -> 41 | C10: =Results_Long!AJ6 -> distinct pp_share_lag0 values; T2 pin P1 confirmed
A11: share_p95_es | B11: =Results_Long!AG7 -> 1 | C11: =Results_Long!AJ7 -> v12 supersedes the stale p95 = 0.6 pin; contrast point 0.6 retained by role [DEC-024; DEC-031 counts-re-derive]
A12: share_eq1 | B12: =Results_Long!AG8 -> 318 | C12: =Results_Long!AJ8 -> 13 studies / 13 clusters at share = 1
A13: share_eq0 | B13: =Results_Long!AG9 -> 611 | C13: =Results_Long!AJ9 -> 27 studies at share = 0
A14: center_sample_mid | B14: =Results_Long!AG10 -> 2012.2579 | C14: =Results_Long!AJ10 -> derived in-script: sample_mid - sample_mid_c (constancy asserted); predictions evaluated at calendar 2015.5 via offset
A15: study_mid_median | B15: =Results_Long!AG11 -> 2013 | C15: =Results_Long!AJ11 -> study-level median of sample_mid (placebo-support disclosure; supersedes stale 2012)
A16: studies_mid_ge2016 | B16: =Results_Long!AG12 -> 25 | C16: =Results_Long!AJ12 -> studies with study-level median sample_mid >= 2016 (supersedes stale 8)
A18: Verdict: Design constants match the pinned table (verifier O7–O14); p95(share) = 1.0 and corr = 0.8146 supersede the stale §4 pins [plan A.9].

Sheet 7_B2_Dose
A1: B2 — Continuous exposure-dose model [DEC-024]
A2: zi ~ sample_mid_c + pp_share_lag0 · predictions at calendar 2015.5 · quadratic check
A3: run 2026-07-15 21:54 CEST · verifier 27/27 PASS · commit 76074a2 (gate 3d7d0c8)
A5: Term | B5: k (ES/St/Cl) | C5: est_z | D5: se_z | E5: df | F5: p | G5: CI_z lb | H5: CI_z ub | I5: est_r | J5: CI_r lb | K5: CI_r ub
A6: intercept | B6: =Results_Long!H13&" / "&Results_Long!I13&" / "&Results_Long!J13 -> 2705 / 113 / 112 | C6: =Results_Long!K13 -> -0.075610163 | D6: =Results_Long!L13 -> 0.027871806 | E6: =Results_Long!N13 -> 36.584625 | F6: =Results_Long!O13 -> 0.010108005 | G6: =Results_Long!P13 -> -0.13210546 | H6: =Results_Long!Q13 -> -0.019114869 | I6: =Results_Long!T13 -> -0.075466407 | J6: =Results_Long!U13 -> -0.13134229 | K6: =Results_Long!V13 -> -0.019112541
A7: sample_mid_c (per yr) | B7: =Results_Long!H14&" / "&Results_Long!I14&" / "&Results_Long!J14 -> 2705 / 113 / 112 | C7: =Results_Long!K14 -> -0.003545879 | D7: =Results_Long!L14 -> 0.0021628055 | E7: =Results_Long!N14 -> 17.658313 | F7: =Results_Long!O14 -> 0.11880584 | G7: =Results_Long!P14 -> -0.0080960752 | H7: =Results_Long!Q14 -> 0.0010043172 | I7: =Results_Long!T14 -> 0 | J7: =Results_Long!U14 -> 0 | K7: =Results_Long!V14 -> 0
A8: pp_share_lag0 (slope) | B8: =Results_Long!H15&" / "&Results_Long!I15&" / "&Results_Long!J15 -> 2705 / 113 / 112 | C8: =Results_Long!K15 -> 0.051814945 | D8: =Results_Long!L15 -> 0.046149053 | E8: =Results_Long!N15 -> 27.648549 | F8: =Results_Long!O15 -> 0.27118917 | G8: =Results_Long!P15 -> -0.04277127 | H8: =Results_Long!Q15 -> 0.14640116 | I8: =Results_Long!T15 -> 0 | J8: =Results_Long!U15 -> 0 | K8: =Results_Long!V15 -> 0
A9: pred z̄(0) | B9: =Results_Long!H16&" / "&Results_Long!I16&" / "&Results_Long!J16 -> 2705 / 113 / 112 | C9: =Results_Long!K16 -> -0.087106414 | D9: =Results_Long!L16 -> 0.034527129 | E9: =Results_Long!N16 -> 36.463339 | F9: =Results_Long!O16 -> 0.016139246 | G9: =Results_Long!P16 -> -0.15709979 | H9: =Results_Long!Q16 -> -0.017113034 | I9: =Results_Long!T16 -> -0.086886773 | J9: =Results_Long!U16 -> -0.15582 | K9: =Results_Long!V16 -> -0.017111364
A10: pred z̄(0.6) | B10: =Results_Long!H17&" / "&Results_Long!I17&" / "&Results_Long!J17 -> 2705 / 113 / 112 | C10: =Results_Long!K17 -> -0.056017447 | D10: =Results_Long!L17 -> 0.011237148 | E10: =Results_Long!N17 -> 41.335498 | F10: =Results_Long!O17 -> 1.1564624e-05 | G10: =Results_Long!P17 -> -0.078705736 | H10: =Results_Long!Q17 -> -0.033329158 | I10: =Results_Long!T17 -> -0.055958927 | J10: =Results_Long!U17 -> -0.078543621 | K10: =Results_Long!V17 -> -0.033316822
A11: pred z̄(1) | B11: =Results_Long!H18&" / "&Results_Long!I18&" / "&Results_Long!J18 -> 2705 / 113 / 112 | C11: =Results_Long!K18 -> -0.035291469 | D11: =Results_Long!L18 -> 0.016358529 | E11: =Results_Long!N18 -> 25.439838 | F11: =Results_Long!O18 -> 0.040609684 | G11: =Results_Long!P18 -> -0.068952979 | H11: =Results_Long!Q18 -> -0.0016299586 | I11: =Results_Long!T18 -> -0.035276824 | J11: =Results_Long!U18 -> -0.068843907 | K11: =Results_Long!V18 -> -0.0016299572
A12: contrast 0→0.6 | B12: =Results_Long!H19&" / "&Results_Long!I19&" / "&Results_Long!J19 -> 2705 / 113 / 112 | C12: =Results_Long!K19 -> 0.031088967 | D12: =Results_Long!L19 -> 0.027689432 | E12: =Results_Long!N19 -> 27.648549 | F12: =Results_Long!O19 -> 0.27118917 | G12: =Results_Long!P19 -> -0.025662762 | H12: =Results_Long!Q19 -> 0.087840696 | I12: =Results_Long!T19 -> 0 | J12: =Results_Long!U19 -> 0 | K12: =Results_Long!V19 -> 0
A13: contrast 0→1 | B13: =Results_Long!H20&" / "&Results_Long!I20&" / "&Results_Long!J20 -> 2705 / 113 / 112 | C13: =Results_Long!K20 -> 0.051814945 | D13: =Results_Long!L20 -> 0.046149053 | E13: =Results_Long!N20 -> 27.648549 | F13: =Results_Long!O20 -> 0.27118917 | G13: =Results_Long!P20 -> -0.04277127 | H13: =Results_Long!Q20 -> 0.14640116 | I13: =Results_Long!T20 -> 0 | J13: =Results_Long!U20 -> 0 | K13: =Results_Long!V20 -> 0
A14: quad: share² | B14: =Results_Long!H24&" / "&Results_Long!I24&" / "&Results_Long!J24 -> 2705 / 113 / 112 | C14: =Results_Long!K24 -> -0.0734801 | D14: =Results_Long!L24 -> 0.074948332 | E14: =Results_Long!N24 -> 50.654819 | F14: =Results_Long!O24 -> 0.33154324 | G14: =Results_Long!P24 -> -0.22397005 | H14: =Results_Long!Q24 -> 0.077009854 | I14: =Results_Long!T24 -> 0 | J14: =Results_Long!U24 -> 0 | K14: =Results_Long!V24 -> 0
A15: joint share = share² = 0 | C15: =Results_Long!M25 -> 1.660682 | D15: F (HTZ) | E15: =Results_Long!N25 -> 30.508684 | F15: =Results_Long!O25 -> 0.2067275
A17: Interpretation
A18: No dose–response gradient: slope p = .271; pinned 0→0.6 contrast +0.031 [−0.026; +0.088]; quadratic p = .332; joint p = .207.
A19: Direction of the point estimates is positive (attenuation of the negative CER–COD association with exposure), but imprecise.
A20: Model-implied levels stay negative across the dose range (z̄(0) = −0.087 → z̄(1) = −0.035 at calendar 2015.5).
A21: Read alongside corr(sample_mid, share) = 0.8146 (design row): dose is interpretable only jointly with the trend [plan §4/A.9].
A22: z̄(1): marginal support (318 ES / 13 clusters at share = 1); joint (mid, share) caveat — share = 1 implies mid ≥ 2016.
A24: Question | B24: Answer
A25: Is the positive slope evidence of post-Paris attenuation? | B25: As a point direction only; the CI includes 0 and both SESOI anchors — the pre-registered read-out (Δβ + CI vs band) does not support a dose effect.
A26: Why evaluate predictions at 2015.5? | B26: Knot of the binary coding [A.3]; implemented via offset from the derived centering constant (2012.258), so evaluation is calendar-anchored, not centering-dependent.
A27: Why is 0→0.6 the headline contrast when p95(share) = 1.0? | B27: Contrast point pinned by role [DEC-024]; the v12 support re-derivation (p95 = 1.0) is disclosed in A.9 — 0→0.6 is now a conservative interior contrast.
A29: Verdict: No dose–response gradient in post-Paris exposure (slope p = .271; joint p = .207); associations remain negative across the dose range.

Sheet 8_B4_Trend_vs_Break
A1: B4 — Trend vs break: race, placebo cutoffs, segmented MR [Moves 1–3]
A2: break_only in T2/B1 cell-means parameterization [DEC-031e]; placebos per DEC-024a
A3: run 2026-07-15 21:54 CEST · verifier 27/27 PASS · commit 76074a2 (gate 3d7d0c8)
A5: Term | B5: k (ES/St/Cl) | C5: est_z | D5: se_z | E5: df | F5: p | G5: CI_z lb | H5: CI_z ub | I5: est_r | J5: CI_r lb | K5: CI_r ub
A6: trend_only: mid_c (per yr) | B6: =Results_Long!H27&" / "&Results_Long!I27&" / "&Results_Long!J27 -> 2705 / 113 / 112 | C6: =Results_Long!K27 -> -0.00075129233 | D6: =Results_Long!L27 -> 0.0009840004 | E6: =Results_Long!N27 -> 26.595944 | F6: =Results_Long!O27 -> 0.45188063 | G6: =Results_Long!P27 -> -0.0027717306 | H6: =Results_Long!Q27 -> 0.0012691459 | I6: =Results_Long!T27 -> 0 | J6: =Results_Long!U27 -> 0 | K6: =Results_Long!V27 -> 0
A7: break_only: pre level | B7: =Results_Long!H28&" / "&Results_Long!I28&" / "&Results_Long!J28 -> 2705 / 113 / 112 | C7: =Results_Long!K28 -> -0.061599157 | D7: =Results_Long!L28 -> 0.018046114 | E7: =Results_Long!N28 -> 68.597113 | F7: =Results_Long!O28 -> 0.0010804696 | G7: =Results_Long!P28 -> -0.097603942 | H7: =Results_Long!Q28 -> -0.025594371 | I7: =Results_Long!T28 -> -0.061521363 | J7: =Results_Long!U28 -> -0.097295177 | K7: =Results_Long!V28 -> -0.025588783
A8: break_only: diff (=T2/B1) | B8: =Results_Long!H29&" / "&Results_Long!I29&" / "&Results_Long!J29 -> 2705 / 113 / 112 | C8: =Results_Long!K29 -> 0.010175907 | D8: =Results_Long!L29 -> 0.018107282 | E8: =Results_Long!N29 -> 14.992066 | F8: =Results_Long!O29 -> 0.58243573 | G8: =Results_Long!P29 -> -0.028420631 | H8: =Results_Long!Q29 -> 0.048772445 | I8: =Results_Long!T29 -> 0 | J8: =Results_Long!U29 -> 0 | K8: =Results_Long!V29 -> 0
A9: race: trend (per yr) | B9: =Results_Long!H31&" / "&Results_Long!I31&" / "&Results_Long!J31 -> 2705 / 113 / 112 | C9: =Results_Long!K31 -> -0.0024440929 | D9: =Results_Long!L31 -> 0.0014718308 | E9: =Results_Long!N31 -> 18.915188 | F9: =Results_Long!O31 -> 0.11328437 | G9: =Results_Long!P31 -> -0.0055256052 | H9: =Results_Long!Q31 -> 0.00063741945 | I9: =Results_Long!T31 -> 0 | J9: =Results_Long!U31 -> 0 | K9: =Results_Long!V31 -> 0
A10: race: break | B10: =Results_Long!H32&" / "&Results_Long!I32&" / "&Results_Long!J32 -> 2705 / 113 / 112 | C10: =Results_Long!K32 -> 0.026448036 | D10: =Results_Long!L32 -> 0.025130655 | E10: =Results_Long!N32 -> 18.841967 | F10: =Results_Long!O32 -> 0.30591673 | G10: =Results_Long!P32 -> -0.026180906 | H10: =Results_Long!Q32 -> 0.079076977 | I10: =Results_Long!T32 -> 0 | J10: =Results_Long!U32 -> 0 | K10: =Results_Long!V32 -> 0
A11: seg: level at knot (pre) | B11: =Results_Long!H50&" / "&Results_Long!I50&" / "&Results_Long!J50 -> 2705 / 113 / 112 | C11: =Results_Long!K50 -> -0.07271775 | D11: =Results_Long!L50 -> 0.024897575 | E11: =Results_Long!N50 -> 58.094169 | F11: =Results_Long!O50 -> 0.0049656598 | G11: =Results_Long!P50 -> -0.12255394 | H11: =Results_Long!Q50 -> -0.022881558 | I11: =Results_Long!T50 -> -0.072589846 | J11: =Results_Long!U50 -> -0.12194404 | K11: =Results_Long!V50 -> -0.022877565
A12: seg: slope pre (per yr) | B12: =Results_Long!H51&" / "&Results_Long!I51&" / "&Results_Long!J51 -> 2705 / 113 / 112 | C12: =Results_Long!K51 -> -0.0023783827 | D12: =Results_Long!L51 -> 0.0016184972 | E12: =Results_Long!N51 -> 16.685286 | F12: =Results_Long!O51 -> 0.16030032 | G12: =Results_Long!P51 -> -0.0057980263 | H12: =Results_Long!Q51 -> 0.0010412609 | I12: =Results_Long!T51 -> 0 | J12: =Results_Long!U51 -> 0 | K12: =Results_Long!V51 -> 0
A13: seg: level shift 2016 | B13: =Results_Long!H52&" / "&Results_Long!I52&" / "&Results_Long!J52 -> 2705 / 113 / 112 | C13: =Results_Long!K52 -> 0.028269368 | D13: =Results_Long!L52 -> 0.023754374 | E13: =Results_Long!N52 -> 10.513684 | F13: =Results_Long!O52 -> 0.26019772 | G13: =Results_Long!P52 -> -0.024310234 | H13: =Results_Long!Q52 -> 0.080848971 | I13: =Results_Long!T52 -> 0 | J13: =Results_Long!U52 -> 0 | K13: =Results_Long!V52 -> 0
A14: seg: slope change 2016 | B14: =Results_Long!H53&" / "&Results_Long!I53&" / "&Results_Long!J53 -> 2705 / 113 / 112 | C14: =Results_Long!K53 -> -0.001040523 | D14: =Results_Long!L53 -> 0.006262604 | E14: =Results_Long!N53 -> 13.537939 | F14: =Results_Long!O53 -> 0.87049579 | G14: =Results_Long!P53 -> -0.01451561 | H14: =Results_Long!Q53 -> 0.012434564 | I14: =Results_Long!T53 -> 0 | J14: =Results_Long!U53 -> 0 | K14: =Results_Long!V53 -> 0
A15: seg: joint level shift = slope change = 0 | C15: =Results_Long!M54 -> 0.67101908 | D15: F (HTZ) | E15: =Results_Long!N54 -> 16.592023 | F15: =Results_Long!O54 -> 0.52452536
A17: Placebo cutoffs (break-only form; post cells pinned [DEC-024a])
A18: Cutoff Y | C18: est_z | D18: se_z | E18: df | F18: p | G18: CI_z lb | H18: CI_z ub
A19: 2008 | C19: =Results_Long!K34 -> -0.024026676 | D19: =Results_Long!L34 -> 0.0176243 | E19: =Results_Long!N34 -> 14.942101 | F19: =Results_Long!O34 -> 0.19298764 | G19: =Results_Long!P34 -> -0.061604665 | H19: =Results_Long!Q34 -> 0.013551313
A20: 2009 | C20: =Results_Long!K36 -> -0.039526755 | D20: =Results_Long!L36 -> 0.018622444 | E20: =Results_Long!N36 -> 6.2816542 | F20: =Results_Long!O36 -> 0.075948862 | G20: =Results_Long!P36 -> -0.084603525 | H20: =Results_Long!Q36 -> 0.0055500144
A21: 2010 | C21: =Results_Long!K38 -> -0.036534391 | D21: =Results_Long!L38 -> 0.019295162 | E21: =Results_Long!N38 -> 6.7804765 | F21: =Results_Long!O38 -> 0.10152293 | G21: =Results_Long!P38 -> -0.082461362 | H21: =Results_Long!Q38 -> 0.0093925811
A22: 2011 | C22: =Results_Long!K40 -> -0.033330837 | D22: =Results_Long!L40 -> 0.018895156 | E22: =Results_Long!N40 -> 9.564408 | F22: =Results_Long!O40 -> 0.10957911 | G22: =Results_Long!P40 -> -0.075693223 | H22: =Results_Long!Q40 -> 0.0090315501
A23: 2012 | C23: =Results_Long!K42 -> -0.00094643456 | D23: =Results_Long!L42 -> 0.017128675 | E23: =Results_Long!N42 -> 11.660405 | F23: =Results_Long!O42 -> 0.95687123 | G23: =Results_Long!P42 -> -0.038387516 | H23: =Results_Long!Q42 -> 0.036494647
A24: 2013 | C24: =Results_Long!K44 -> 0.025954305 | D24: =Results_Long!L44 -> 0.021560613 | E24: =Results_Long!N44 -> 14.282378 | F24: =Results_Long!O44 -> 0.24824608 | G24: =Results_Long!P44 -> -0.020202984 | H24: =Results_Long!Q44 -> 0.072111595
A25: 2014 | C25: =Results_Long!K46 -> 0.023149445 | D25: =Results_Long!L46 -> 0.022786093 | E25: =Results_Long!N46 -> 22.565951 | F25: =Results_Long!O46 -> 0.32042466 | G25: =Results_Long!P46 -> -0.024037399 | H25: =Results_Long!Q46 -> 0.070336289
A26: 2015 | C26: =Results_Long!K48 -> 0.0023798621 | D26: =Results_Long!L48 -> 0.020323441 | E26: =Results_Long!N48 -> 18.166093 | F26: =Results_Long!O48 -> 0.90806625 | G26: =Results_Long!P48 -> -0.040290138 | H26: =Results_Long!Q48 -> 0.045049862
A27: rank of |2016| among 9 cutoffs | B27: =Results_Long!AG49 -> 7
A29: Interpretation
A30: Race double null: trend −0.0024/yr (p = .113); break +0.026 [−0.026; +0.079] (p = .306) — neither component is needed.
A31: Placebo localization: 2016 ranks 7 of 9 by |break|; cuts at 2009–2011 produce |0.033–0.040| vs |0.010| at the treaty year; smallest placebo p = .076.
A32: Segmented MR at 2015.5: no level shift (p = .260), no slope change (p = .871), no pre-trend (p = .160); joint F = 0.67, p = .525.
A33: Precision limit (pre-anticipated): race-adjusted break CI reaches +0.079 (> both SESOI anchors) — SE inflation from corr = 0.81, effect-size read-out per F61-P3; equivalence precision rests on the unadjusted and composition-adjusted forms.
A34: Realized df on the unadjusted diff = 15.0 vs design df 31.9 (disclosure, note field).
A36: Question | B36: Answer
A37: Does a secular trend explain the null Paris moderation? | B37: No trend is supported (−0.0024/yr, p = .113), and the break stays null with the trend allowed — the data need neither.
A38: Is 2016 special among cutoffs? | B38: No: rank 7/9; three placebo years yield 3–4× larger spurious breaks. There is no localization at the treaty.
A39: Why cell-means for break_only? | B39: nlminb false convergence of the dummy form at the σ²_study boundary; the cell-means form is the committed T2/B1 convention on the identical likelihood — O15 reproduces T2 at machine precision [DEC-031e].
A40: Why is the race CI so much wider? | B40: corr(sample_mid, share/break) = 0.81 inflates SEs when trend and break compete; disclosed a priori — the race buys identification, not precision.
A42: Verdict: Neither trend nor 2016 break is supported; the Paris cut ranks 7/9 among placebo cutoffs — no localization at the treaty (joint segmented test p = .525).

Sheet 9_B5_Composition
A1: B5 — Composition control (Move 4 core) [DEC-031d]
A2: covariates = {country_region, COD_instrument, CER_measure}; refs {1_US, loan, performance}; 99_NCE own level
A3: run 2026-07-15 21:54 CEST · verifier 27/27 PASS · commit 76074a2 (gate 3d7d0c8)
A5: Term | B5: k (ES/St/Cl) | C5: est_z | D5: se_z | E5: df | F5: p | G5: CI_z lb | H5: CI_z ub | I5: est_r | J5: CI_r lb | K5: CI_r ub
A6: comp_adj: intercept | B6: =Results_Long!H55&" / "&Results_Long!I55&" / "&Results_Long!J55 -> 2705 / 113 / 112 | C6: =Results_Long!K55 -> -0.020423821 | D6: =Results_Long!L55 -> 0.016388621 | E6: =Results_Long!N55 -> 20.739753 | F6: =Results_Long!O55 -> 0.22657732 | G6: =Results_Long!P55 -> -0.054531884 | H6: =Results_Long!Q55 -> 0.013684241 | I6: =Results_Long!T55 -> -0.020420982 | J6: =Results_Long!U55 -> -0.054477894 | K6: =Results_Long!V55 -> 0.013683387
A7: comp_adj: Paris diff | B7: =Results_Long!H56&" / "&Results_Long!I56&" / "&Results_Long!J56 -> 2705 / 113 / 112 | C7: =Results_Long!K56 -> 0.012457468 | D7: =Results_Long!L56 -> 0.01734915 | E7: =Results_Long!N56 -> 14.224253 | F7: =Results_Long!O56 -> 0.48435711 | G7: =Results_Long!P56 -> -0.024697796 | H7: =Results_Long!Q56 -> 0.049612732 | I7: =Results_Long!T56 -> 0 | J7: =Results_Long!U56 -> 0 | K7: =Results_Long!V56 -> 0
A8: comp_adj: CER_measuredisclosure | B8: =Results_Long!H63&" / "&Results_Long!I63&" / "&Results_Long!J63 -> 2705 / 113 / 112 | C8: =Results_Long!K63 -> -0.012871263 | D8: =Results_Long!L63 -> 0.015048376 | E8: =Results_Long!N63 -> 8.4723829 | F8: =Results_Long!O63 -> 0.41590249 | G8: =Results_Long!P63 -> -0.047238967 | H8: =Results_Long!Q63 -> 0.02149644 | I8: =Results_Long!T63 -> 0 | J8: =Results_Long!U63 -> 0 | K8: =Results_Long!V63 -> 0
A9: comp_adj: COD_instrumentbond (yield) | B9: =Results_Long!H60&" / "&Results_Long!I60&" / "&Results_Long!J60 -> 2705 / 113 / 112 | C9: =Results_Long!K60 -> -0.05592881 | D9: =Results_Long!L60 -> 0.015942618 | E9: =Results_Long!N60 -> 7.5162705 | F9: =Results_Long!O60 -> 0.0088164324 | G9: =Results_Long!P60 -> -0.093108494 | H9: =Results_Long!Q60 -> -0.018749126 | I9: =Results_Long!T60 -> 0 | J9: =Results_Long!U60 -> 0 | K9: =Results_Long!V60 -> 0
A10: comp_adj: COD_instrumentderivativ (CDS spread) | B10: =Results_Long!H61&" / "&Results_Long!I61&" / "&Results_Long!J61 -> 2705 / 113 / 112 | C10: =Results_Long!K61 -> -0.085060825 | D10: =Results_Long!L61 -> 0.074350479 | E10: =Results_Long!N61 -> 6.5335976 | F10: =Results_Long!O61 -> 0.29277936 | G10: =Results_Long!P61 -> -0.26344823 | H10: =Results_Long!Q61 -> 0.093326578 | I10: =Results_Long!T61 -> 0 | J10: =Results_Long!U61 -> 0 | K10: =Results_Long!V61 -> 0
A11: comp_adj: COD_instrumentrating | B11: =Results_Long!H62&" / "&Results_Long!I62&" / "&Results_Long!J62 -> 2705 / 113 / 112 | C11: =Results_Long!K62 -> -0.021533768 | D11: =Results_Long!L62 -> 0.016482783 | E11: =Results_Long!N62 -> 6.3373718 | F11: =Results_Long!O62 -> 0.23681238 | G11: =Results_Long!P62 -> -0.061350899 | H11: =Results_Long!Q62 -> 0.018283364 | I11: =Results_Long!T62 -> 0 | J11: =Results_Long!U62 -> 0 | K11: =Results_Long!V62 -> 0
A12: comp_adj: country_region2_Europe | B12: =Results_Long!H57&" / "&Results_Long!I57&" / "&Results_Long!J57 -> 2705 / 113 / 112 | C12: =Results_Long!K57 -> -0.04151393 | D12: =Results_Long!L57 -> 0.038720079 | E12: =Results_Long!N57 -> 2.7070037 | F12: =Results_Long!O57 -> 0.36981689 | G12: =Results_Long!P57 -> -0.17263838 | H12: =Results_Long!Q57 -> 0.089610522 | I12: =Results_Long!T57 -> 0 | J12: =Results_Long!U57 -> 0 | K12: =Results_Long!V57 -> 0
A13: comp_adj: country_region3_AsiaPac | B13: =Results_Long!H58&" / "&Results_Long!I58&" / "&Results_Long!J58 -> 2705 / 113 / 112 | C13: =Results_Long!K58 -> -0.023841964 | D13: =Results_Long!L58 -> 0.023263852 | E13: =Results_Long!N58 -> 21.277461 | F13: =Results_Long!O58 -> 0.31694497 | G13: =Results_Long!P58 -> -0.072183407 | H13: =Results_Long!Q58 -> 0.024499479 | I13: =Results_Long!T58 -> 0 | J13: =Results_Long!U58 -> 0 | K13: =Results_Long!V58 -> 0
A14: comp_adj: country_region99_NCE | B14: =Results_Long!H59&" / "&Results_Long!I59&" / "&Results_Long!J59 -> 2705 / 113 / 112 | C14: =Results_Long!K59 -> -0.011996542 | D14: =Results_Long!L59 -> 0.018297315 | E14: =Results_Long!N59 -> 8.5857178 | F14: =Results_Long!O59 -> 0.52922713 | G14: =Results_Long!P59 -> -0.053694404 | H14: =Results_Long!Q59 -> 0.029701321 | I14: =Results_Long!T59 -> 0 | J14: =Results_Long!U59 -> 0 | K14: =Results_Long!V59 -> 0
A15: trend_comp: Paris diff | B15: =Results_Long!H68&" / "&Results_Long!I68&" / "&Results_Long!J68 -> 2705 / 113 / 112 | C15: =Results_Long!K68 -> 0.013931503 | D15: =Results_Long!L68 -> 0.018317116 | E15: =Results_Long!N68 -> 19.200189 | F15: =Results_Long!O68 -> 0.45615155 | G15: =Results_Long!P68 -> -0.024379624 | H15: =Results_Long!Q68 -> 0.052242631 | I15: =Results_Long!T68 -> 0 | J15: =Results_Long!U68 -> 0 | K15: =Results_Long!V68 -> 0
A16: trend_comp: trend (per yr) | B16: =Results_Long!H67&" / "&Results_Long!I67&" / "&Results_Long!J67 -> 2705 / 113 / 112 | C16: =Results_Long!K67 -> -0.00022856645 | D16: =Results_Long!L67 -> 0.0018053732 | E16: =Results_Long!N67 -> 23.38542 | F16: =Results_Long!O67 -> 0.90033654 | G16: =Results_Long!P67 -> -0.0039598625 | H16: =Results_Long!Q67 -> 0.0035027296 | I16: =Results_Long!T67 -> 0 | J16: =Results_Long!U67 -> 0 | K16: =Results_Long!V67 -> 0
A17: comp_adj: joint composition = 0 | C17: =Results_Long!M64 -> 1.501443 | D17: F (HTZ) | E17: =Results_Long!N64 -> 7.8060316 | F17: =Results_Long!O64 -> 0.29200344
A18: trend_comp: joint composition = 0 | C18: =Results_Long!M76 -> 1.4467369 | D18: F (HTZ) | E18: =Results_Long!N76 -> 7.1801927 | F18: =Results_Long!O76 -> 0.31668984
A20: Δβ vs break_only anchor (z) | B20: =Results_Long!AG65 -> 0.0022815611
A22: Interpretation
A23: Composition adjustment moves the Paris contrast by +0.0023 z (anchor = break_only on the identical 2,705 domain [F61-P1]).
A24: Adjusted contrasts: +0.012 [−0.025; +0.050] (df 14.2, full inference) and, with trend, +0.014 [−0.024; +0.052] (df 19.2, full inference) — transfer-rule flags in the note field [F61-P2].
A25: SESOI read-out [F61-P3]: both adjusted CIs lie inside the primary band ±0.070; against the secondary ±0.05 the comp_adj CI is inside, the trend_comp upper edge (+0.0522) is marginally outside.
A26: The composition covariates are jointly insignificant in both models (F ≈ 1.5, p ≈ .3): the disclosed drift does not carry the effect sizes.
A27: 99_NCE dummy rows retained for domain completeness, flagged not-interpreted [F61-P2].
A29: Question | B29: Answer
A30: §6 lists five drift dimensions — why control three? | B30: The two continuous drifts run through pre-assigned channels: sample size via the variance-weighting machinery and the T5 selection battery (a precision regressor would be PET logic — a different estimand); window length via sample_mid_c + the attenuation disclosure [DEC-031d].
A31: Why not industry? | B31: Selection rule (not a §6-disclosed drift), 3-cluster post cell (noise, not control), and estimand separation: a B5 main effect would pre-label the exposure margin C3 is designed to test [DEC-031d].
A32: Could the null be "by construction" from drift-correlated controls? | B32: The verdict criterion was pinned a priori as Δβ + adjusted CI vs the SESOI band, not p-survival — SE inflation cannot manufacture the conclusion [F61-P3].
A34: Verdict: Composition explains essentially nothing of the Paris contrast (Δβ = +0.002); the adjusted contrast is a precise null against the primary SESOI.

Sheet 10_B8_Bounding
A1: B8 — Bounding: Oster analog + E-values (Move 7) [DEC-031d P1]
A2: uncontrolled = race, controlled = trend_composition (same domain); SESOI masks per DEC-031 Block E
A3: run 2026-07-15 21:54 CEST · verifier 27/27 PASS · commit 76074a2 (gate 3d7d0c8)
A5: Quantity | B5: Value | C5: Note (verbatim CSV)
A6: r2_uncontrolled | B6: =Results_Long!AG77 -> -0.014745523 | C6: =Results_Long!AJ77 -> Oster-logic ANALOG on variance-component pseudo-R2: R2 = 1 - sum(sigma2_model)/sum(sigma2_intercept-only), same subset/V; uncontrolled = race (time trend held in both models [F61-P1]), controlled = trend_composition; Rmax = min(1.3 x R2_c, 1) [Oster 2019]; pseudo-R2 can be negative (REML)
A7: r2_controlled | B7: =Results_Long!AG78 -> 0.0098149609 | C7: =Results_Long!AJ78 -> Oster-logic ANALOG on variance-component pseudo-R2: R2 = 1 - sum(sigma2_model)/sum(sigma2_intercept-only), same subset/V; uncontrolled = race (time trend held in both models [F61-P1]), controlled = trend_composition; Rmax = min(1.3 x R2_c, 1) [Oster 2019]; pseudo-R2 can be negative (REML)
A8: beta_star_delta1 | B8: =Results_Long!AG79 -> 0.012430931 | C8: =Results_Long!AJ79 -> Oster-logic ANALOG on variance-component pseudo-R2: R2 = 1 - sum(sigma2_model)/sum(sigma2_intercept-only), same subset/V; uncontrolled = race (time trend held in both models [F61-P1]), controlled = trend_composition; Rmax = min(1.3 x R2_c, 1) [Oster 2019]; pseudo-R2 can be negative (REML); delta = 1; z-scale
A9: delta_for_beta_zero | B9: =Results_Long!AG80 -> 9.2841268 | C9: =Results_Long!AJ80 -> Oster-logic ANALOG on variance-component pseudo-R2: R2 = 1 - sum(sigma2_model)/sum(sigma2_intercept-only), same subset/V; uncontrolled = race (time trend held in both models [F61-P1]), controlled = trend_composition; Rmax = min(1.3 x R2_c, 1) [Oster 2019]; pseudo-R2 can be negative (REML); CAVEAT: near-null coefficients make delta* mechanically unstable — read jointly with beta_star and the mask E-values
A10: evalue_point | B10: =Results_Long!AG81 -> 1.187983 | C10: =Results_Long!AJ81 -> on |final-model Paris coefficient|; |delta z| read as |delta r| (third-order approx at these magnitudes); r->d = 2r/sqrt(1-r^2), RR approx exp(0.91 d) [VanderWeele & Ding 2017]
A11: evalue_ci_edge | B11: =Results_Long!AG82 -> 1.4313579 | C11: =Results_Long!AJ82 -> on max |CR2 CI bound| of the final-model Paris coefficient; |delta z| read as |delta r| (third-order approx at these magnitudes); r->d = 2r/sqrt(1-r^2), RR approx exp(0.91 d) [VanderWeele & Ding 2017]
A12: evalue_mask_sesoi_contrast | B12: =Results_Long!AG83 -> 1.4186489 | C12: =Results_Long!AJ83 -> confounding strength needed to mask a true |delta r| = 0.05 contrast [DEC-031 Block E secondary SESOI]; |delta z| read as |delta r| (third-order approx at these magnitudes); r->d = 2r/sqrt(1-r^2), RR approx exp(0.91 d) [VanderWeele & Ding 2017]
A13: evalue_mask_sesoi_pooled | B13: =Results_Long!AG84 -> 1.5296545 | C13: =Results_Long!AJ84 -> mask reference at the pooled-mean SESOI |r| = 0.070 (F27v2) [DEC-031 Block E primary]; |delta z| read as |delta r| (third-order approx at these magnitudes); r->d = 2r/sqrt(1-r^2), RR approx exp(0.91 d) [VanderWeele & Ding 2017]
A15: Interpretation
A16: Under Oster-style proportional selection (δ = 1, Rmax = 1.3·R²_c) the Paris contrast moves to +0.0124 z — deep inside the SESOI band.
A17: δ* = 9.28 is mechanically unstable near a null coefficient (caveat in note) and is read jointly with β* and the mask E-values.
A18: Mask E-values: confounding of RR ≈ 1.42 (1.53) suffices to hide a true contrast at the secondary (primary) SESOI; the CI-edge E-value is 1.43 — the residual signal is fragile in both directions.
A19: R²_u = −0.015 (negative pseudo-R² possible under REML; disclosed) — bounding is supportive, the identification weight lies on race + placebos + composition.
A21: Question | B21: Answer
A22: Is δ* ≈ 9 strong evidence of robustness? | B22: No — with a near-null coefficient δ* is mechanically unstable; the informative quantities are β*(δ=1) = +0.012 and the mask E-values [note caveat].
A23: Why race as the uncontrolled model? | B23: The design variable (time) belongs in both regressions; proportional selection runs over the covariate set, not over the running variable of the identification [F61-P1].
A25: Verdict: Bounding keeps the Paris contrast within the SESOI band under δ = 1 (β* = +0.012); it is supportive, not the pillar of the null defense.

Sheet Results_Long
A1: analysis_id | B1: spec | C1: subset | D1: term | E1: metric | F1: estimator | G1: rho | H1: k_es | I1: k_study | J1: k_cluster | K1: est_z | L1: se_z | M1: t_stat | N1: df | O1: p | P1: ci_lb_z | Q1: ci_ub_z | R1: pi_lb_z | S1: pi_ub_z | T1: est_r | U1: ci_lb_r | V1: ci_ub_r | W1: pi_lb_r | X1: pi_ub_r | Y1: sigma2_cluster | Z1: sigma2_study | AA1: sigma2_esid | AB1: pct_cluster | AC1: pct_study | AD1: pct_esid | AE1: pct_sampling | AF1: typical_v | AG1: value | AH1: ms_input | AI1: ms_label | AJ1: note
A2: T8_design | B2: design | C2: defined | D2: subset_dose_period | E2: count | F2: descriptive | H2: 2705 | I2: 113 | J2: 112 | AG2: 2705 | AH2: =FALSE() -> FALSE | AJ2: 2,705 ES / 113 studies / 112 clusters [DEC-042b]; run date in T8_run_meta.txt
A3: T8_design | B3: design | C3: defined | D3: period_na | E3: count | F3: descriptive | H3: 2705 | I3: 113 | J3: 112 | AG3: 8 | AH3: =FALSE() -> FALSE | AJ3: 8 ES / 2 studies / 2 clusters (Bhattacharya & Sharma 2019; Ng & Rezaee 2012) [DEC-042b]; provenance for workbook Tab 5_Data_Provenance
A4: T8_design | B4: design | C4: defined | D4: post_cell_2016 | E4: count | F4: descriptive | H4: 2705 | I4: 113 | J4: 112 | AG4: 711 | AH4: =FALSE() -> FALSE | AJ4: 711 ES / 31 studies / 31 clusters (v12 design constant)
A5: T8_design | B5: design | C5: defined | D5: corr_sample_mid_share | E5: corr | F5: descriptive | H5: 2705 | I5: 113 | J5: 112 | AG5: 0.8145797 | AH5: =FALSE() -> FALSE | AJ5: ES-level Pearson on 2,705; supersedes stale 0.70 pin (v8-era) — plan Section 4 disclosure updates [DEC-031 counts-re-derive]
A6: T8_design | B6: design | C6: defined | D6: share_distinct | E6: count | F6: descriptive | H6: 2705 | I6: 113 | J6: 112 | AG6: 41 | AH6: =FALSE() -> FALSE | AJ6: distinct pp_share_lag0 values; T2 pin P1 confirmed
A7: T8_design | B7: design | C7: defined | D7: share_p95_es | E7: share | F7: descriptive | H7: 2705 | I7: 113 | J7: 112 | AG7: 1 | AH7: =FALSE() -> FALSE | AJ7: v12 supersedes the stale p95 = 0.6 pin; contrast point 0.6 retained by role [DEC-024; DEC-031 counts-re-derive]
A8: T8_design | B8: design | C8: defined | D8: share_eq1 | E8: count | F8: descriptive | H8: 2705 | I8: 113 | J8: 112 | AG8: 318 | AH8: =FALSE() -> FALSE | AJ8: 13 studies / 13 clusters at share = 1
A9: T8_design | B9: design | C9: defined | D9: share_eq0 | E9: count | F9: descriptive | H9: 2705 | I9: 113 | J9: 112 | AG9: 611 | AH9: =FALSE() -> FALSE | AJ9: 27 studies at share = 0
A10: T8_design | B10: design | C10: defined | D10: center_sample_mid | E10: year | F10: descriptive | H10: 2705 | I10: 113 | J10: 112 | AG10: 2012.2579 | AH10: =FALSE() -> FALSE | AJ10: derived in-script: sample_mid - sample_mid_c (constancy asserted); predictions evaluated at calendar 2015.5 via offset
A11: T8_design | B11: design | C11: defined | D11: study_mid_median | E11: year | F11: descriptive | H11: 2705 | I11: 113 | J11: 112 | AG11: 2013 | AH11: =FALSE() -> FALSE | AJ11: study-level median of sample_mid (placebo-support disclosure; supersedes stale 2012)
A12: T8_design | B12: design | C12: defined | D12: studies_mid_ge2016 | E12: count | F12: descriptive | H12: 2705 | I12: 113 | J12: 112 | AG12: 25 | AH12: =FALSE() -> FALSE | AJ12: studies with study-level median sample_mid >= 2016 (supersedes stale 8)
A13: B2 | B13: dose_linear | C13: defined | D13: intercept | E13: Fisher_z | F13: 3LMA-RVE_CR2 | G13: 0.6 | H13: 2705 | I13: 113 | J13: 112 | K13: -0.075610163 | L13: 0.027871806 | M13: -2.7127831 | N13: 36.584625 | O13: 0.010108005 | P13: -0.13210546 | Q13: -0.019114869 | T13: -0.075466407 | U13: -0.13134229 | V13: -0.019112541 | Y13: 0.020660228 | Z13: 2.0743763e-09 | AA13: 0.011874591 | AH13: =FALSE() -> FALSE | AJ13: rma.mv mods=~ sample_mid_c + pp_share_lag0; random ~1|cluster_id/study/esid; V blocks within cluster_id, rho=0.6; CR2/Satterthwaite on cluster_id [D31.1/A.2]; k = complete cases on window codings [DEC-042b]
A14: B2 | B14: dose_linear | C14: defined | D14: sample_mid_c | E14: Fisher_z | F14: 3LMA-RVE_CR2 | G14: 0.6 | H14: 2705 | I14: 113 | J14: 112 | K14: -0.003545879 | L14: 0.0021628055 | M14: -1.6394813 | N14: 17.658313 | O14: 0.11880584 | P14: -0.0080960752 | Q14: 0.0010043172 | Y14: 0.020660228 | Z14: 2.0743763e-09 | AA14: 0.011874591 | AH14: =FALSE() -> FALSE | AJ14: rma.mv mods=~ sample_mid_c + pp_share_lag0; random ~1|cluster_id/study/esid; V blocks within cluster_id, rho=0.6; CR2/Satterthwaite on cluster_id [D31.1/A.2]; k = complete cases on window codings [DEC-042b]
A15: B2 | B15: dose_linear | C15: defined | D15: pp_share_lag0 | E15: Fisher_z | F15: 3LMA-RVE_CR2 | G15: 0.6 | H15: 2705 | I15: 113 | J15: 112 | K15: 0.051814945 | L15: 0.046149053 | M15: 1.1227737 | N15: 27.648549 | O15: 0.27118917 | P15: -0.04277127 | Q15: 0.14640116 | Y15: 0.020660228 | Z15: 2.0743763e-09 | AA15: 0.011874591 | AH15: =TRUE() -> TRUE | AI15: dose_slope | AJ15: rma.mv mods=~ sample_mid_c + pp_share_lag0; random ~1|cluster_id/study/esid; V blocks within cluster_id, rho=0.6; CR2/Satterthwaite on cluster_id [D31.1/A.2]; k = complete cases on window codings [DEC-042b]; identification core [DEC-024]; interpret only alongside trend (corr disclosure row)
A16: B2 | B16: dose_linear | C16: defined | D16: pred_share_0 | E16: Fisher_z | F16: 3LMA-RVE_CR2 | G16: 0.6 | H16: 2705 | I16: 113 | J16: 112 | K16: -0.087106414 | L16: 0.034527129 | M16: -2.5228398 | N16: 36.463339 | O16: 0.016139246 | P16: -0.15709979 | Q16: -0.017113034 | T16: -0.086886773 | U16: -0.15582 | V16: -0.017111364 | Y16: 0.020660228 | Z16: 2.0743763e-09 | AA16: 0.011874591 | AH16: =FALSE() -> FALSE | AJ16: rma.mv mods=~ sample_mid_c + pp_share_lag0; random ~1|cluster_id/study/esid; V blocks within cluster_id, rho=0.6; CR2/Satterthwaite on cluster_id [D31.1/A.2]; k = complete cases on window codings [DEC-042b]; model-implied cell mean at calendar 2015.5, dose = 0; dose-0 endpoint support: 611 ES / 27 studies at share = 0 (v12)
A17: B2 | B17: dose_linear | C17: defined | D17: pred_share_0.6 | E17: Fisher_z | F17: 3LMA-RVE_CR2 | G17: 0.6 | H17: 2705 | I17: 113 | J17: 112 | K17: -0.056017447 | L17: 0.011237148 | M17: -4.9850233 | N17: 41.335498 | O17: 1.1564624e-05 | P17: -0.078705736 | Q17: -0.033329158 | T17: -0.055958927 | U17: -0.078543621 | V17: -0.033316822 | Y17: 0.020660228 | Z17: 2.0743763e-09 | AA17: 0.011874591 | AH17: =FALSE() -> FALSE | AJ17: rma.mv mods=~ sample_mid_c + pp_share_lag0; random ~1|cluster_id/study/esid; V blocks within cluster_id, rho=0.6; CR2/Satterthwaite on cluster_id [D31.1/A.2]; k = complete cases on window codings [DEC-042b]; model-implied cell mean at calendar 2015.5, dose = 0.6; pinned contrast point [DEC-024]
A18: B2 | B18: dose_linear | C18: defined | D18: pred_share_1 | E18: Fisher_z | F18: 3LMA-RVE_CR2 | G18: 0.6 | H18: 2705 | I18: 113 | J18: 112 | K18: -0.035291469 | L18: 0.016358529 | M18: -2.1573742 | N18: 25.439838 | O18: 0.040609684 | P18: -0.068952979 | Q18: -0.0016299586 | T18: -0.035276824 | U18: -0.068843907 | V18: -0.0016299572 | Y18: 0.020660228 | Z18: 2.0743763e-09 | AA18: 0.011874591 | AH18: =FALSE() -> FALSE | AJ18: rma.mv mods=~ sample_mid_c + pp_share_lag0; random ~1|cluster_id/study/esid; V blocks within cluster_id, rho=0.6; CR2/Satterthwaite on cluster_id [D31.1/A.2]; k = complete cases on window codings [DEC-042b]; model-implied cell mean at calendar 2015.5, dose = 1; marginal support: 318 ES / 13 clusters at share = 1 (v12); joint (mid, share) support caveat: share = 1 implies mid >= 2016
A19: B2 | B19: dose_linear | C19: defined | D19: contrast_0_to_0.6 | E19: Fisher_z | F19: 3LMA-RVE_CR2 | G19: 0.6 | H19: 2705 | I19: 113 | J19: 112 | K19: 0.031088967 | L19: 0.027689432 | M19: 1.1227737 | N19: 27.648549 | O19: 0.27118917 | P19: -0.025662762 | Q19: 0.087840696 | Y19: 0.020660228 | Z19: 2.0743763e-09 | AA19: 0.011874591 | AH19: =TRUE() -> TRUE | AI19: dose_contrast_0_06 | AJ19: rma.mv mods=~ sample_mid_c + pp_share_lag0; random ~1|cluster_id/study/esid; V blocks within cluster_id, rho=0.6; CR2/Satterthwaite on cluster_id [D31.1/A.2]; k = complete cases on window codings [DEC-042b]; = 0.6 x dose slope; pinned headline dose contrast [DEC-024]; difference of Fisher-z means; no tanh transform of differences
A20: B2 | B20: dose_linear | C20: defined | D20: contrast_0_to_1 | E20: Fisher_z | F20: 3LMA-RVE_CR2 | G20: 0.6 | H20: 2705 | I20: 113 | J20: 112 | K20: 0.051814945 | L20: 0.046149053 | M20: 1.1227737 | N20: 27.648549 | O20: 0.27118917 | P20: -0.04277127 | Q20: 0.14640116 | Y20: 0.020660228 | Z20: 2.0743763e-09 | AA20: 0.011874591 | AH20: =FALSE() -> FALSE | AJ20: rma.mv mods=~ sample_mid_c + pp_share_lag0; random ~1|cluster_id/study/esid; V blocks within cluster_id, rho=0.6; CR2/Satterthwaite on cluster_id [D31.1/A.2]; k = complete cases on window codings [DEC-042b]; = dose slope; full-regime contrast; marginal support v12 (see pred_share_1); difference of Fisher-z means; no tanh transform of differences
A21: B2 | B21: dose_quadratic | C21: defined | D21: intercept | E21: Fisher_z | F21: 3LMA-RVE_CR2 | G21: 0.6 | H21: 2705 | I21: 113 | J21: 112 | K21: -0.085300075 | L21: 0.025477475 | M21: -3.3480585 | N21: 16.802723 | O21: 0.0038631335 | P21: -0.13910096 | Q21: -0.031499187 | T21: -0.085093791 | U21: -0.13821069 | V21: -0.031488773 | Y21: 0.020867938 | Z21: 3.0707011e-09 | AA21: 0.011873099 | AH21: =FALSE() -> FALSE | AJ21: rma.mv mods=~ sample_mid_c + pp_share_lag0 + I(pp_share_lag0^2); random ~1|cluster_id/study/esid; V blocks within cluster_id, rho=0.6; CR2/Satterthwaite on cluster_id [D31.1/A.2]; k = complete cases on window codings [DEC-042b]
A22: B2 | B22: dose_quadratic | C22: defined | D22: sample_mid_c | E22: Fisher_z | F22: 3LMA-RVE_CR2 | G22: 0.6 | H22: 2705 | I22: 113 | J22: 112 | K22: -0.0041452252 | L22: 0.0020859499 | M22: -1.9872123 | N22: 18.959531 | O22: 0.061540685 | P22: -0.0085117993 | Q22: 0.00022134886 | Y22: 0.020867938 | Z22: 3.0707011e-09 | AA22: 0.011873099 | AH22: =FALSE() -> FALSE | AJ22: rma.mv mods=~ sample_mid_c + pp_share_lag0 + I(pp_share_lag0^2); random ~1|cluster_id/study/esid; V blocks within cluster_id, rho=0.6; CR2/Satterthwaite on cluster_id [D31.1/A.2]; k = complete cases on window codings [DEC-042b]
A23: B2 | B23: dose_quadratic | C23: defined | D23: pp_share_lag0 | E23: Fisher_z | F23: 3LMA-RVE_CR2 | G23: 0.6 | H23: 2705 | I23: 113 | J23: 112 | K23: 0.12794546 | L23: 0.075137876 | M23: 1.7028091 | N23: 25.443051 | O23: 0.10079174 | P23: -0.026667367 | Q23: 0.28255829 | Y23: 0.020867938 | Z23: 3.0707011e-09 | AA23: 0.011873099 | AH23: =FALSE() -> FALSE | AJ23: rma.mv mods=~ sample_mid_c + pp_share_lag0 + I(pp_share_lag0^2); random ~1|cluster_id/study/esid; V blocks within cluster_id, rho=0.6; CR2/Satterthwaite on cluster_id [D31.1/A.2]; k = complete cases on window codings [DEC-042b]
A24: B2 | B24: dose_quadratic | C24: defined | D24: pp_share_lag0_sq | E24: Fisher_z | F24: 3LMA-RVE_CR2 | G24: 0.6 | H24: 2705 | I24: 113 | J24: 112 | K24: -0.0734801 | L24: 0.074948332 | M24: -0.98041007 | N24: 50.654819 | O24: 0.33154324 | P24: -0.22397005 | Q24: 0.077009854 | Y24: 0.020867938 | Z24: 3.0707011e-09 | AA24: 0.011873099 | AH24: =FALSE() -> FALSE | AJ24: rma.mv mods=~ sample_mid_c + pp_share_lag0 + I(pp_share_lag0^2); random ~1|cluster_id/study/esid; V blocks within cluster_id, rho=0.6; CR2/Satterthwaite on cluster_id [D31.1/A.2]; k = complete cases on window codings [DEC-042b]; quadratic-in-share check [DEC-024]
A25: B2 | B25: dose_quadratic | C25: defined | D25: wald_share_joint | E25: F_test | F25: 3LMA-RVE_CR2 | G25: 0.6 | H25: 2705 | I25: 113 | J25: 112 | M25: 1.660682 | N25: 30.508684 | O25: 0.2067275 | Y25: 0.020867938 | Z25: 3.0707011e-09 | AA25: 0.011873099 | AH25: =FALSE() -> FALSE | AJ25: rma.mv mods=~ sample_mid_c + pp_share_lag0 + I(pp_share_lag0^2); random ~1|cluster_id/study/esid; V blocks within cluster_id, rho=0.6; CR2/Satterthwaite on cluster_id [D31.1/A.2]; k = complete cases on window codings [DEC-042b]; H0: share = share^2 = 0 (joint dose signal); HTZ; num_df = 2
A26: B4 | B26: trend_only | C26: defined | D26: intercept | E26: Fisher_z | F26: 3LMA-RVE_CR2 | G26: 0.6 | H26: 2705 | I26: 113 | J26: 112 | K26: -0.058517912 | L26: 0.014208488 | M26: -4.1185179 | N26: 106.56636 | O26: 7.5508546e-05 | P26: -0.086685893 | Q26: -0.030349931 | T26: -0.058451208 | U26: -0.086469411 | V26: -0.030340615 | Y26: 0.020450151 | Z26: 2.1459155e-09 | AA26: 0.011878988 | AH26: =FALSE() -> FALSE | AJ26: rma.mv mods=~ sample_mid_c; random ~1|cluster_id/study/esid; V blocks within cluster_id, rho=0.6; CR2/Satterthwaite on cluster_id [D31.1/A.2]; k = complete cases on window codings [DEC-042b]
A27: B4 | B27: trend_only | C27: defined | D27: sample_mid_c | E27: Fisher_z | F27: 3LMA-RVE_CR2 | G27: 0.6 | H27: 2705 | I27: 113 | J27: 112 | K27: -0.00075129233 | L27: 0.0009840004 | M27: -0.76350816 | N27: 26.595944 | O27: 0.45188063 | P27: -0.0027717306 | Q27: 0.0012691459 | Y27: 0.020450151 | Z27: 2.1459155e-09 | AA27: 0.011878988 | AH27: =FALSE() -> FALSE | AJ27: rma.mv mods=~ sample_mid_c; random ~1|cluster_id/study/esid; V blocks within cluster_id, rho=0.6; CR2/Satterthwaite on cluster_id [D31.1/A.2]; k = complete cases on window codings [DEC-042b]; secular drift, no break term
A28: B4 | B28: break_only | C28: defined | D28: intercept | E28: Fisher_z | F28: 3LMA-RVE_CR2 | G28: 0.6 | H28: 2705 | I28: 113 | J28: 112 | K28: -0.061599157 | L28: 0.018046114 | M28: -3.4134304 | N28: 68.597113 | O28: 0.0010804696 | P28: -0.097603942 | Q28: -0.025594371 | T28: -0.061521363 | U28: -0.097295177 | V28: -0.025588783 | Y28: 0.020466604 | Z28: 1.8647279e-09 | AA28: 0.011878551 | AH28: =FALSE() -> FALSE | AJ28: rma.mv mods=~ 0 + pp_cell (cell-means [DEC-031e]; estimand identical to ~ pp_mid_lag0); random ~1|cluster_id/study/esid; V blocks within cluster_id, rho=0.6; CR2/Satterthwaite on cluster_id [D31.1/A.2]; k = complete cases on window codings [DEC-042b]; pre-cell mean; parameterization-identical to T2/B1 cell_pre (~0+factor(coding))
A29: B4 | B29: break_only | C29: defined | D29: pp_mid_lag0 | E29: Fisher_z | F29: 3LMA-RVE_CR2 | G29: 0.6 | H29: 2705 | I29: 113 | J29: 112 | K29: 0.010175907 | L29: 0.018107282 | M29: 0.56197868 | N29: 14.992066 | O29: 0.58243573 | P29: -0.028420631 | Q29: 0.048772445 | Y29: 0.020466604 | Z29: 1.8647279e-09 | AA29: 0.011878551 | AH29: =FALSE() -> FALSE | AJ29: rma.mv mods=~ 0 + pp_cell (cell-means [DEC-031e]; estimand identical to ~ pp_mid_lag0); random ~1|cluster_id/study/esid; V blocks within cluster_id, rho=0.6; CR2/Satterthwaite on cluster_id [D31.1/A.2]; k = complete cases on window codings [DEC-042b]; post-minus-pre contrast (-1, +1) = T2/B1 paris_mid diff, verifier identity O15; cell-means parameterization per DEC-031e; realized vs design df disclosure: design df = 31.9 [T0.4]; difference of Fisher-z means; no tanh transform of differences
A30: B4 | B30: race | C30: defined | D30: intercept | E30: Fisher_z | F30: 3LMA-RVE_CR2 | G30: 0.6 | H30: 2705 | I30: 113 | J30: 112 | K30: -0.065131872 | L30: 0.019723365 | M30: -3.3022698 | N30: 55.167517 | O30: 0.0016867222 | P30: -0.10465568 | Q30: -0.025608064 | T30: -0.065039928 | U30: -0.10427526 | V30: -0.025602468 | Y30: 0.020692162 | Z30: 2.4653269e-09 | AA30: 0.011874897 | AH30: =FALSE() -> FALSE | AJ30: rma.mv mods=~ sample_mid_c + pp_mid_lag0; random ~1|cluster_id/study/esid; V blocks within cluster_id, rho=0.6; CR2/Satterthwaite on cluster_id [D31.1/A.2]; k = complete cases on window codings [DEC-042b]
A31: B4 | B31: race | C31: defined | D31: sample_mid_c | E31: Fisher_z | F31: 3LMA-RVE_CR2 | G31: 0.6 | H31: 2705 | I31: 113 | J31: 112 | K31: -0.0024440929 | L31: 0.0014718308 | M31: -1.6605801 | N31: 18.915188 | O31: 0.11328437 | P31: -0.0055256052 | Q31: 0.00063741945 | Y31: 0.020692162 | Z31: 2.4653269e-09 | AA31: 0.011874897 | AH31: =TRUE() -> TRUE | AI31: race_trend | AJ31: rma.mv mods=~ sample_mid_c + pp_mid_lag0; random ~1|cluster_id/study/esid; V blocks within cluster_id, rho=0.6; CR2/Satterthwaite on cluster_id [D31.1/A.2]; k = complete cases on window codings [DEC-042b]
A32: B4 | B32: race | C32: defined | D32: pp_mid_lag0 | E32: Fisher_z | F32: 3LMA-RVE_CR2 | G32: 0.6 | H32: 2705 | I32: 113 | J32: 112 | K32: 0.026448036 | L32: 0.025130655 | M32: 1.0524212 | N32: 18.841967 | O32: 0.30591673 | P32: -0.026180906 | Q32: 0.079076977 | Y32: 0.020692162 | Z32: 2.4653269e-09 | AA32: 0.011874897 | AH32: =TRUE() -> TRUE | AI32: race_break | AJ32: rma.mv mods=~ sample_mid_c + pp_mid_lag0; random ~1|cluster_id/study/esid; V blocks within cluster_id, rho=0.6; CR2/Satterthwaite on cluster_id [D31.1/A.2]; k = complete cases on window codings [DEC-042b]; Move 1: break net of smooth drift [Identifikation tab]; difference of Fisher-z means
A33: B4 | B33: placebo_2008 | C33: defined | D33: intercept | E33: Fisher_z | F33: 3LMA-RVE_CR2 | G33: 0.6 | H33: 2705 | I33: 113 | J33: 112 | K33: -0.03747016 | L33: 0.0076556985 | M33: -4.8944142 | N33: 11.807969 | O33: 0.00038713335 | P33: -0.05418063 | Q33: -0.020759689 | T33: -0.037452633 | U33: -0.054127675 | V33: -0.020756708 | Y33: 0.020430519 | Z33: 2.865334e-09 | AA33: 0.01187772 | AH33: =FALSE() -> FALSE | AJ33: rma.mv mods=~ pp_break_2008; random ~1|cluster_id/study/esid; V blocks within cluster_id, rho=0.6; CR2/Satterthwaite on cluster_id [D31.1/A.2]; k = complete cases on window codings [DEC-042b]
A34: B4 | B34: placebo_2008 | C34: defined | D34: pp_break_2008 | E34: Fisher_z | F34: 3LMA-RVE_CR2 | G34: 0.6 | H34: 2705 | I34: 113 | J34: 112 | K34: -0.024026676 | L34: 0.0176243 | M34: -1.3632698 | N34: 14.942101 | O34: 0.19298764 | P34: -0.061604665 | Q34: 0.013551313 | Y34: 0.020430519 | Z34: 2.865334e-09 | AA34: 0.01187772 | AH34: =FALSE() -> FALSE | AJ34: rma.mv mods=~ pp_break_2008; random ~1|cluster_id/study/esid; V blocks within cluster_id, rho=0.6; CR2/Satterthwaite on cluster_id [D31.1/A.2]; k = complete cases on window codings [DEC-042b]; post cell pinned: 2367 ES / 100 studies / 99 clusters; rule: share_2008 >= 0.5, ties to Post [F60/DEC-024]; difference of Fisher-z means
A35: B4 | B35: placebo_2009 | C35: defined | D35: intercept | E35: Fisher_z | F35: 3LMA-RVE_CR2 | G35: 0.6 | H35: 2705 | I35: 113 | J35: 112 | K35: -0.024108388 | L35: 0.014921315 | M35: -1.6157013 | N35: 7.6339972 | O35: 0.14662911 | P35: -0.058806276 | Q35: 0.010589501 | T35: -0.024103718 | U35: -0.058738582 | V35: 0.010589105 | Y35: 0.020411456 | Z35: 2.344849e-09 | AA35: 0.011872655 | AH35: =FALSE() -> FALSE | AJ35: rma.mv mods=~ pp_break_2009; random ~1|cluster_id/study/esid; V blocks within cluster_id, rho=0.6; CR2/Satterthwaite on cluster_id [D31.1/A.2]; k = complete cases on window codings [DEC-042b]
A36: B4 | B36: placebo_2009 | C36: defined | D36: pp_break_2009 | E36: Fisher_z | F36: 3LMA-RVE_CR2 | G36: 0.6 | H36: 2705 | I36: 113 | J36: 112 | K36: -0.039526755 | L36: 0.018622444 | M36: -2.1225332 | N36: 6.2816542 | O36: 0.075948862 | P36: -0.084603525 | Q36: 0.0055500144 | Y36: 0.020411456 | Z36: 2.344849e-09 | AA36: 0.011872655 | AH36: =FALSE() -> FALSE | AJ36: rma.mv mods=~ pp_break_2009; random ~1|cluster_id/study/esid; V blocks within cluster_id, rho=0.6; CR2/Satterthwaite on cluster_id [D31.1/A.2]; k = complete cases on window codings [DEC-042b]; post cell pinned: 2345 ES / 99 studies / 98 clusters; rule: share_2009 >= 0.5, ties to Post [F60/DEC-024]; difference of Fisher-z means
A37: B4 | B37: placebo_2010 | C37: defined | D37: intercept | E37: Fisher_z | F37: 3LMA-RVE_CR2 | G37: 0.6 | H37: 2705 | I37: 113 | J37: 112 | K37: -0.027059837 | L37: 0.015260496 | M37: -1.7731951 | N37: 8.2886008 | O37: 0.11282122 | P37: -0.062038459 | Q37: 0.0079187853 | T37: -0.027053234 | U37: -0.061958991 | V37: 0.0079186197 | Y37: 0.020438618 | Z37: 3.0694772e-09 | AA37: 0.011873276 | AH37: =FALSE() -> FALSE | AJ37: rma.mv mods=~ pp_break_2010; random ~1|cluster_id/study/esid; V blocks within cluster_id, rho=0.6; CR2/Satterthwaite on cluster_id [D31.1/A.2]; k = complete cases on window codings [DEC-042b]
A38: B4 | B38: placebo_2010 | C38: defined | D38: pp_break_2010 | E38: Fisher_z | F38: 3LMA-RVE_CR2 | G38: 0.6 | H38: 2705 | I38: 113 | J38: 112 | K38: -0.036534391 | L38: 0.019295162 | M38: -1.8934483 | N38: 6.7804765 | O38: 0.10152293 | P38: -0.082461362 | Q38: 0.0093925811 | Y38: 0.020438618 | Z38: 3.0694772e-09 | AA38: 0.011873276 | AH38: =FALSE() -> FALSE | AJ38: rma.mv mods=~ pp_break_2010; random ~1|cluster_id/study/esid; V blocks within cluster_id, rho=0.6; CR2/Satterthwaite on cluster_id [D31.1/A.2]; k = complete cases on window codings [DEC-042b]; post cell pinned: 2326 ES / 98 studies / 97 clusters; rule: share_2010 >= 0.5, ties to Post [F60/DEC-024]; difference of Fisher-z means
A39: B4 | B39: placebo_2011 | C39: defined | D39: intercept | E39: Fisher_z | F39: 3LMA-RVE_CR2 | G39: 0.6 | H39: 2705 | I39: 113 | J39: 112 | K39: -0.031417375 | L39: 0.013228391 | M39: -2.374996 | N39: 11.983811 | O39: 0.035106757 | P39: -0.060243881 | Q39: -0.0025908681 | T39: -0.031407042 | U39: -0.060171105 | V39: -0.0025908623 | Y39: 0.020445602 | Z39: 2.1600468e-09 | AA39: 0.011873027 | AH39: =FALSE() -> FALSE | AJ39: rma.mv mods=~ pp_break_2011; random ~1|cluster_id/study/esid; V blocks within cluster_id, rho=0.6; CR2/Satterthwaite on cluster_id [D31.1/A.2]; k = complete cases on window codings [DEC-042b]
A40: B4 | B40: placebo_2011 | C40: defined | D40: pp_break_2011 | E40: Fisher_z | F40: 3LMA-RVE_CR2 | G40: 0.6 | H40: 2705 | I40: 113 | J40: 112 | K40: -0.033330837 | L40: 0.018895156 | M40: -1.7639884 | N40: 9.564408 | O40: 0.10957911 | P40: -0.075693223 | Q40: 0.0090315501 | Y40: 0.020445602 | Z40: 2.1600468e-09 | AA40: 0.011873027 | AH40: =FALSE() -> FALSE | AJ40: rma.mv mods=~ pp_break_2011; random ~1|cluster_id/study/esid; V blocks within cluster_id, rho=0.6; CR2/Satterthwaite on cluster_id [D31.1/A.2]; k = complete cases on window codings [DEC-042b]; post cell pinned: 2077 ES / 93 studies / 92 clusters; rule: share_2011 >= 0.5, ties to Post [F60/DEC-024]; difference of Fisher-z means
...

Sheet Manuscript_Inputs
A1: Manuscript inputs — ms_input = TRUE rows (10), fully formula-derived from Results_Long
A2: p-format: IF(p<0.0001,"< 0.0001",TEXT(p,"0.000")) · strings paste-ready
A3: run 2026-07-15 21:54 CEST · verifier 27/27 PASS · commit 76074a2 (gate 3d7d0c8)
A5: ms_label | B5: analysis | C5: spec | D5: term | E5: paste-ready string (EN)
A6: dose_slope | B6: B2 | C6: dose_linear | D6: pp_share_lag0 | E6: ="z = "&TEXT(Results_Long!K15,"+0.0000;-0.0000")&" (SE "&TEXT(Results_Long!L15,"0.0000")&"), 95% CI ["&TEXT(Results_Long!P15,"+0.0000;-0.0000")&"; "&TEXT(Results_Long!Q15,"+0.0000;-0.0000")&"], df = "&TEXT(Results_Long!N15,"0.0")&", p = "&IF(Results_Long!O15<0.0001,"< 0.0001",TEXT(Results_Long!O15,"0.000")) -> #VALUE!
A7: dose_contrast_0_06 | B7: B2 | C7: dose_linear | D7: contrast_0_to_0.6 | E7: ="z = "&TEXT(Results_Long!K19,"+0.0000;-0.0000")&" (SE "&TEXT(Results_Long!L19,"0.0000")&"), 95% CI ["&TEXT(Results_Long!P19,"+0.0000;-0.0000")&"; "&TEXT(Results_Long!Q19,"+0.0000;-0.0000")&"], df = "&TEXT(Results_Long!N19,"0.0")&", p = "&IF(Results_Long!O19<0.0001,"< 0.0001",TEXT(Results_Long!O19,"0.000")) -> #VALUE!
A8: race_trend | B8: B4 | C8: race | D8: sample_mid_c | E8: ="z = "&TEXT(Results_Long!K31,"+0.0000;-0.0000")&" (SE "&TEXT(Results_Long!L31,"0.0000")&"), 95% CI ["&TEXT(Results_Long!P31,"+0.0000;-0.0000")&"; "&TEXT(Results_Long!Q31,"+0.0000;-0.0000")&"], df = "&TEXT(Results_Long!N31,"0.0")&", p = "&IF(Results_Long!O31<0.0001,"< 0.0001",TEXT(Results_Long!O31,"0.000")) -> #VALUE!
A9: race_break | B9: B4 | C9: race | D9: pp_mid_lag0 | E9: ="z = "&TEXT(Results_Long!K32,"+0.0000;-0.0000")&" (SE "&TEXT(Results_Long!L32,"0.0000")&"), 95% CI ["&TEXT(Results_Long!P32,"+0.0000;-0.0000")&"; "&TEXT(Results_Long!Q32,"+0.0000;-0.0000")&"], df = "&TEXT(Results_Long!N32,"0.0")&", p = "&IF(Results_Long!O32<0.0001,"< 0.0001",TEXT(Results_Long!O32,"0.000")) -> #VALUE!
