Workbook

Sheet 1_README
A1: FOMA CER–COD–Paris — TF / Block F results workbook (outliers & influence F1–F7; robustness-register completion / G11 close)
A2: Template: docs/results_workbook_template.md (binding) · one workbook per run
A3: Canonical run · start 2026-07-30 21:58:15, outputs 2026-07-31 · script HEAD 06d1eeb · meta re-emission + verifier @ c1e8b6c: R/12_verify_outputs.R 12/12 PASS [DEC-051b]
A5: Item | B5: Value
A6: Data version | B6: CERCOD v12 — estimation set 2,713 ES / 115 studies / 114 clusters (per-spec domains in each tab)
A7: Method (one line) | B7: 3L-RVE spine verbatim (random ~1|cluster_id/study/esid; CS rho=0.6; CR2/Satterthwaite on cluster_id; ladder DEC-031f); identification + handling per DEC-051
A8: Scope | B8: Block F: rstudent/MAD identification, four handling refits (outlier_rstudent, outlier_mad, winsor, trim_1_99), 114-cluster LOO, influence diagnostics; register completion (23 × 18)
A9: Repository | B9: github.com/rwitte-wu-research/FOMA-CER-COD-Paris (public, main)
A10: Computational stack | B10: R 4.6.1 · metafor 5.0-1 · clubSandwich 0.7.0 · seed 20260710
A11: Scripts | B11: R/12_outliers.R @ 06d1eeb (canonical) · R/12_reemit_meta.R + R/12_verify_outputs.R @ c1e8b6c
A12: Decision basis | B12: DEC-051 · DEC-051a · DEC-051b · DEC-013 · analysis_plan A.16; language regime per DEC-047
A14: TAB-INDEX
A15: 1_README | B15: this tab
A16: 2_Methodology | B16: quantity | formula/construction | reference
A17: 3_Interpretation_Guide | B17: how to read each quantity; decision rules
A18: 4_Formula_Reference | B18: exact R calls; workbook formula conventions (incl. documented in-tab-transport deviation for LOO/influence)
A19: 5_Data_Provenance | B19: run record, gates, verifier history, first-attempt episode, identification record
A20: 6_Outlier_Refits | B20: identification + four handling variants, reference row = T1-A1
A21: 7_LOO | B21: cluster leave-one-out: summary (formula-derived) + full 114-row transport of TF_loo.csv
A22: 8_Influence | B22: Cook’s D / hat values, descriptive; full 2,713-row transport of TF_influence.csv
A23: Results_Long | B23: verbatim TF_results.csv (36 cols) + AK key helper — single formula source for tab 6
A24: Manuscript_Inputs | B24: ms_input note (TG style per F-Q9)
A25: Manuscript_Text_Blocks | B25: TB-65 (finalized) · TB-68 (superseded) · TB-69…TB-71

Sheet 2_Methodology
A1: Methodology — Block F outlier & influence specs
A3: Quantity | B3: Formula / Construction | C3: Reference
A4: Spine engine (all refits) | B4: 3L random effects ~1|cluster_id/study/esid; CS V blocks within cluster_id, rho = 0.6; CR2/Satterthwaite on cluster_id; optimizer ladder nlminb→BFGS→Nelder-Mead | C4: [DEC-051 no.1; DEC-031f; A.2]
A5: F1 identification (rstudent) | B5: studentized deleted residuals on the full-set spine fit, ES-wise, reestimate = FALSE (sigma2 fixed at full-set estimates; FE-only deletion — convention disclosed); threshold |t| > 3 (conditional rule resolved); computed parallel snow, ncpus = 8 | C5: [DEC-051 no.2; DEC-051a]
A6: F6 identification (MAD) | B6: flag zi outside median(zi) ± 3·MAD(zi), b = 1.4826, computed once on the full estimation set, ES level | C6: [Leys et al. 2013; DEC-051 no.3]
A7: F2 handling | B7: two drop-and-refit specs: outlier_rstudent (drop 13 flags) and outlier_mad (drop 275 flags); overlap disclosed (13); no union spec (pre-stated catalogue) | C7: [DEC-051 no.4]
A8: F3 winsor / unwinsor | B8: zi winsorized at empirical P1/P99 of the full estimation set (type-7 quantile, computed once; A.13/H3 pin; 56 ES clipped); unwinsor ≡ headline (DEC-013(a) status-quo semantics; cross-reference, no fit) | C8: [DEC-051 no.5]
A9: F7 trim_1_99 | B9: drop rows with zi outside [P1, P99] (same percentiles as winsor; 56 ES) | C9: [DEC-051 no.6]
A10: F4 cluster LOO | B10: 114 cluster-deletion 3L-REML refits, each with CR2/Satterthwaite CI; PSOCK W = 8; not_estimable routing per P-T5-4 under the DEC-031f ladder (observed ne = 0) | C10: [DEC-051 no.7; DEC-051a]
A11: F5 influence diagnostics | B11: cluster Cook’s D from the LOO fits: D_j = (μ̂ − μ̂(−j))² / Var̂(μ̂), model-based full-set Var̂; ES hatvalues from the full-set fit; descriptive only, no thresholds | C11: [DEC-051 no.8]
A12: Register completion (G11) | B12: robustness_register.csv rebuilt 23 × 18: 5 A + 11 G rows carried by value (re-verified 1e-9) + 7 F rows incl. leave_one_out summary, influence diagnostic, loso_post_cell cross-reference (values single-homed in T2/B6) | C12: [DEC-051 no.9; A.8]
A13: Excluded treatments | B13: trim-and-fill excluded (unreliable under heterogeneity); ±k·SD rules and SAMD excluded (mean/SD themselves outlier-distorted; superseded by model-based studentized residuals) | C13: [A.5; DEC-031a.4; Carter et al. 2019; Leys et al. 2013; Viechtbauer]

Sheet 3_Interpretation_Guide
A1: Interpretation guide
A3: Quantity | B3: Meaning | C3: Decision rule
A4: est_z / est_r | B4: pooled Fisher-z estimate and its back-transform tanh(z) | C4: report both scales for levels; r-scale for prose
A5: Δ_z & flags | B5: presentation-layer difference vs the T1-A1 headline; sign / CI-excludes-0 / SESOI flags | C5: descriptive only — no spec-vs-headline tests [DEC-031a.6; N5 single home]
A6: rstudent t | B6: studentized deleted residual under fixed sigma2 (reestimate = FALSE) | C6: |t| > 3 flags; identification, not adjudication [DEC-051 no.2]
A7: MAD flag | B7: Leys robust-dispersion flag, k = 3 on zi | C7: broad by construction on a heavy-tailed zi distribution; second identification, fully reported [DEC-051 no.3]
A8: Cook’s D (cluster) | B8: squared shift of the pooled estimate from deleting cluster j, scaled by Var̂(μ̂) | C8: descriptive appendix; no threshold [DEC-051 no.8]
A9: hat value (ES) | B9: observation leverage in the full-set fit | C9: descriptive; mean ≈ 1/k
A10: SESOI | B10: |r| = 0.070 smallest effect size of interest band | C10: [Doucouliagos 2011 anchor; plan A.8]
A11: df (Satterthwaite) | B11: small-sample-adjusted df per CR2 | C11: df ≥ 4 for reliable coverage [Tipton]

Sheet 4_Formula_Reference
A1: Formula reference — R calls and workbook conventions
A3: Quantity | B3: R call / workbook formula | C3: Reference / script section
A4: Spine fit | B4: rma.mv(yi=zi, V=impute_covariance_matrix(vi, cluster_id, r=0.6), random=~1|cluster_id/study/esid, method="REML", sparse=TRUE) | C4: R/12_outliers.R fit3l
A5: F1 rstudent pass | B5: rstudent(f_full, reestimate = FALSE, parallel = "snow", ncpus = 8) | C5: R/12_outliers.R [DEC-051a]
A6: F6 MAD rule | B6: abs(zi − median(zi)) > 3 * mad(zi, constant = 1.4826) | C6: R/12_outliers.R
A7: Winsor / trim percentiles | B7: quantile(zi, c(0.01, 0.99), type = 7) | C7: R/12_outliers.R; verifier V10
A8: LOO refit + CI | B8: fit3l(dat[cluster_id != j, ]); coef_test(vcov="CR2", test="Satterthwaite") | C8: R/12_outliers.R loo_fit
A9: Cook’s D (cluster) | B9: (mu_full − est_j)^2 / vcov(f_full)[1,1] | C9: R/12_outliers.R [DEC-051 no.8]
A10: ES hat values | B10: hatvalues(f_full) | C10: R/12_outliers.R
A11: T1-A1 anchor (this workbook) | B11: by value from output/T1_results.csv (label key analysis_id == "A1"): est_z = -0.058646736610098; verified 1e-9 at build | C11: [DEC-050c pattern; DEC-051 no.11]
A12: Workbook lookups | B12: INDEX/MATCH on the Results_Long AK key (analysis_id|spec|subset|term); no XLOOKUP/FILTER/SORT | C12: template rules
A13: Documented deviation | B13: tabs 7_LOO and 8_Influence derive their summary cells from in-tab verbatim transports of TF_loo.csv / TF_influence.csv (auxiliary CSVs outside the 36-col run CSV); percentile check via PERCENTILE(zi-range, .01/.99) ≡ R type 7 | C13: analog to the TG TEXT() deviation note

Sheet 5_Data_Provenance
A1: Data provenance & run record
A2: Canonical run accepted under DEC-051 + 051a/b; fresh verifier 12/12 @ c1e8b6c
A3: ERROR #35 (unprobed serial pass) and #36 (jsonlite digits) logged; no committed bytes invalid
A5: Item | B5: Value | C5: Source
A6: Estimation set | B6: 2,713 ES / 115 studies / 114 clusters (dat_prep); per-spec domains in Results_Long | C6: TF_run_meta.json
A7: dat_prep md5 | B7: 6702ef3dc45fe0b693b13f50ebd1576b | C7: TF_run_meta.json; A.16 pin
A8: Seed / rho | B8: 20260710 / 0.6 | C8: FIXZONE / frozen constants
A9: Run stamp | B9: start 2026-07-30 21:58:15 · F1 rstudent pass 249.4 min (parallel snow, ncpus = 8) · LOO PSOCK W = 8, first fit 0.44 min · 121 model fits · outputs 4 / 114 / 2,713 rows | C9: TF_run_meta.json; console tee
A10: First-attempt episode | B10: serial F1 pass aborted > 10 h (implied serial cost ≈ 32 h); terminal-write design held: no outputs existed, tree clean; re-route per DEC-051a | C10: [ERROR #35; DEC-051a]
A11: Gate A (script + verifier) | B11: pre-flight CS-aggregate by value: −0.0616608 (df 113), 1e-9 — PASS | C11: [DEC-048; DEC-051 no.11]
A12: Gate B (verifier) | B12: independent 3L headline refit matched to committed output/T1_results.csv A1 at 1e-6; all three sigma2 located by value — PASS | C12: [DEC-050b/c; DEC-051 no.11]
A13: Verifier history | B13: first pass 11/12 (V10: jsonlite digits=4 truncated winsor_q — serialization only; statistics proven intact by V10 legs b/c) → DEC-051b re-emission → 12/12 PASS | C13: [ERROR #36; DEC-051b]
A14: Identification record | B14: rstudent flags 13 (0 non-finite) · MAD flags 275 · overlap 13 (rstudent ⊆ MAD) · winsor_q = −0.380770461057388 / 0.184714878917096 · clipped/trimmed 56 | C14: TF_run_meta.json; TF_influence.csv
A15: DEC-013 anchors | B15: Drago −0.9977 (zi −3.392): present, top flag |t| = 18.6, dominant influence (Cook’s D 1.64). Devalle +0.9998: superseded by the documented v12 Devalle regime — ruling R1 (v12 buildlog "P7 adoptions … Devalle per R1 ausgeschlossen"; v12 verifier V7 PASS, signs 0.089/0.147/−0.296); the estimation set carries three recomputed Devalle ES, none flagged | C15: v12 buildlog/verifier; DEC-013
A16: Canonical HEAD | B16: 06d1eeb — TF canonical script; c1e8b6c — digits pin + reemit + 12/12; outputs committed with the Block-F result package | C16: git log

Sheet 6_Outlier_Refits
A1: Outlier identification & handling refits (F1–F3, F6, F7) — four variants on the verbatim spine
A2: Reference row = T1-A1 headline, by value (source output/T1_results.csv, verified 1e-9 at build) [DEC-051 no.11]
A3: Δ and flags are presentation-layer; no spec-vs-headline tests [DEC-031a.6; N5 single home]. Identification: rstudent 13 (|t| > 3) ⊆ MAD 275 (k = 3); winsor/trim on P1/P99 = −0.38077 / 0.18471 (type-7).
A5: Spec | B5: k_es | C5: k_study | D5: k_cluster | E5: est_z | F5: CI_z low | G5: CI_z high | H5: est_r | I5: CI_r low | J5: CI_r high | K5: df | L5: p | M5: Δ_z vs headline | N5: sign retained | O5: CI excl. 0 | P5: inside SESOI (|r| ≤ .070)
A6: T1-A1 headline (reference) | B6: 2713 | C6: 115 | D6: 114 | E6: -0.058646737 | F6: -0.086102595 | G6: -0.031190879 | H6: -0.058579592 | I6: -0.085890445 | J6: -0.031180768 | K6: 111.6718 | L6: 4.7619835e-05
A7: F2 outlier_rstudent (drop 13) | B7: =INDEX(Results_Long!$H$2:$H$5,MATCH("F2|outlier_rstudent|estimation|intrcpt",Results_Long!$AK$2:$AK$5,0)) -> 2700 | C7: =INDEX(Results_Long!$I$2:$I$5,MATCH("F2|outlier_rstudent|estimation|intrcpt",Results_Long!$AK$2:$AK$5,0)) -> 115 | D7: =INDEX(Results_Long!$J$2:$J$5,MATCH("F2|outlier_rstudent|estimation|intrcpt",Results_Long!$AK$2:$AK$5,0)) -> 114 | E7: =INDEX(Results_Long!$K$2:$K$5,MATCH("F2|outlier_rstudent|estimation|intrcpt",Results_Long!$AK$2:$AK$5,0)) -> -0.037638204 | F7: =INDEX(Results_Long!$P$2:$P$5,MATCH("F2|outlier_rstudent|estimation|intrcpt",Results_Long!$AK$2:$AK$5,0)) -> -0.046528191 | G7: =INDEX(Results_Long!$Q$2:$Q$5,MATCH("F2|outlier_rstudent|estimation|intrcpt",Results_Long!$AK$2:$AK$5,0)) -> -0.028748216 | H7: =INDEX(Results_Long!$T$2:$T$5,MATCH("F2|outlier_rstudent|estimation|intrcpt",Results_Long!$AK$2:$AK$5,0)) -> -0.037620441 | I7: =INDEX(Results_Long!$U$2:$U$5,MATCH("F2|outlier_rstudent|estimation|intrcpt",Results_Long!$AK$2:$AK$5,0)) -> -0.046494645 | J7: =INDEX(Results_Long!$V$2:$V$5,MATCH("F2|outlier_rstudent|estimation|intrcpt",Results_Long!$AK$2:$AK$5,0)) -> -0.028740299 | K7: =INDEX(Results_Long!$N$2:$N$5,MATCH("F2|outlier_rstudent|estimation|intrcpt",Results_Long!$AK$2:$AK$5,0)) -> 102.47497 | L7: =INDEX(Results_Long!$O$2:$O$5,MATCH("F2|outlier_rstudent|estimation|intrcpt",Results_Long!$AK$2:$AK$5,0)) -> 2.7119642e-13 | M7: =E7-$E$6 -> 0.021008533 | N7: =IF(E7*$E$6>0,"TRUE","FALSE") -> TRUE | O7: =IF(OR(F7>0,G7<0),"TRUE","FALSE") -> TRUE | P7: =IF(ABS(H7)<=0.07,"TRUE","FALSE") -> TRUE
A8: F2 outlier_mad (drop 275) | B8: =INDEX(Results_Long!$H$2:$H$5,MATCH("F2|outlier_mad|estimation|intrcpt",Results_Long!$AK$2:$AK$5,0)) -> 2438 | C8: =INDEX(Results_Long!$I$2:$I$5,MATCH("F2|outlier_mad|estimation|intrcpt",Results_Long!$AK$2:$AK$5,0)) -> 110 | D8: =INDEX(Results_Long!$J$2:$J$5,MATCH("F2|outlier_mad|estimation|intrcpt",Results_Long!$AK$2:$AK$5,0)) -> 109 | E8: =INDEX(Results_Long!$K$2:$K$5,MATCH("F2|outlier_mad|estimation|intrcpt",Results_Long!$AK$2:$AK$5,0)) -> -0.032135296 | F8: =INDEX(Results_Long!$P$2:$P$5,MATCH("F2|outlier_mad|estimation|intrcpt",Results_Long!$AK$2:$AK$5,0)) -> -0.038501337 | G8: =INDEX(Results_Long!$Q$2:$Q$5,MATCH("F2|outlier_mad|estimation|intrcpt",Results_Long!$AK$2:$AK$5,0)) -> -0.025769255 | H8: =INDEX(Results_Long!$T$2:$T$5,MATCH("F2|outlier_mad|estimation|intrcpt",Results_Long!$AK$2:$AK$5,0)) -> -0.032124239 | I8: =INDEX(Results_Long!$U$2:$U$5,MATCH("F2|outlier_mad|estimation|intrcpt",Results_Long!$AK$2:$AK$5,0)) -> -0.038482324 | J8: =INDEX(Results_Long!$V$2:$V$5,MATCH("F2|outlier_mad|estimation|intrcpt",Results_Long!$AK$2:$AK$5,0)) -> -0.025763552 | K8: =INDEX(Results_Long!$N$2:$N$5,MATCH("F2|outlier_mad|estimation|intrcpt",Results_Long!$AK$2:$AK$5,0)) -> 96.596611 | L8: =INDEX(Results_Long!$O$2:$O$5,MATCH("F2|outlier_mad|estimation|intrcpt",Results_Long!$AK$2:$AK$5,0)) -> 1.2703725e-16 | M8: =E8-$E$6 -> 0.026511441 | N8: =IF(E8*$E$6>0,"TRUE","FALSE") -> TRUE | O8: =IF(OR(F8>0,G8<0),"TRUE","FALSE") -> TRUE | P8: =IF(ABS(H8)<=0.07,"TRUE","FALSE") -> TRUE
A9: F3 winsor (clip 56) | B9: =INDEX(Results_Long!$H$2:$H$5,MATCH("F3|winsor|estimation|intrcpt",Results_Long!$AK$2:$AK$5,0)) -> 2713 | C9: =INDEX(Results_Long!$I$2:$I$5,MATCH("F3|winsor|estimation|intrcpt",Results_Long!$AK$2:$AK$5,0)) -> 115 | D9: =INDEX(Results_Long!$J$2:$J$5,MATCH("F3|winsor|estimation|intrcpt",Results_Long!$AK$2:$AK$5,0)) -> 114 | E9: =INDEX(Results_Long!$K$2:$K$5,MATCH("F3|winsor|estimation|intrcpt",Results_Long!$AK$2:$AK$5,0)) -> -0.040527601 | F9: =INDEX(Results_Long!$P$2:$P$5,MATCH("F3|winsor|estimation|intrcpt",Results_Long!$AK$2:$AK$5,0)) -> -0.049769063 | G9: =INDEX(Results_Long!$Q$2:$Q$5,MATCH("F3|winsor|estimation|intrcpt",Results_Long!$AK$2:$AK$5,0)) -> -0.031286138 | H9: =INDEX(Results_Long!$T$2:$T$5,MATCH("F3|winsor|estimation|intrcpt",Results_Long!$AK$2:$AK$5,0)) -> -0.040505427 | I9: =INDEX(Results_Long!$U$2:$U$5,MATCH("F3|winsor|estimation|intrcpt",Results_Long!$AK$2:$AK$5,0)) -> -0.049728012 | J9: =INDEX(Results_Long!$V$2:$V$5,MATCH("F3|winsor|estimation|intrcpt",Results_Long!$AK$2:$AK$5,0)) -> -0.031275934 | K9: =INDEX(Results_Long!$N$2:$N$5,MATCH("F3|winsor|estimation|intrcpt",Results_Long!$AK$2:$AK$5,0)) -> 104.57779 | L9: =INDEX(Results_Long!$O$2:$O$5,MATCH("F3|winsor|estimation|intrcpt",Results_Long!$AK$2:$AK$5,0)) -> 5.2254732e-14 | M9: =E9-$E$6 -> 0.018119136 | N9: =IF(E9*$E$6>0,"TRUE","FALSE") -> TRUE | O9: =IF(OR(F9>0,G9<0),"TRUE","FALSE") -> TRUE | P9: =IF(ABS(H9)<=0.07,"TRUE","FALSE") -> TRUE
A10: F7 trim_1_99 (drop 56) | B10: =INDEX(Results_Long!$H$2:$H$5,MATCH("F7|trim_1_99|estimation|intrcpt",Results_Long!$AK$2:$AK$5,0)) -> 2657 | C10: =INDEX(Results_Long!$I$2:$I$5,MATCH("F7|trim_1_99|estimation|intrcpt",Results_Long!$AK$2:$AK$5,0)) -> 114 | D10: =INDEX(Results_Long!$J$2:$J$5,MATCH("F7|trim_1_99|estimation|intrcpt",Results_Long!$AK$2:$AK$5,0)) -> 113 | E10: =INDEX(Results_Long!$K$2:$K$5,MATCH("F7|trim_1_99|estimation|intrcpt",Results_Long!$AK$2:$AK$5,0)) -> -0.041057843 | F10: =INDEX(Results_Long!$P$2:$P$5,MATCH("F7|trim_1_99|estimation|intrcpt",Results_Long!$AK$2:$AK$5,0)) -> -0.050379546 | G10: =INDEX(Results_Long!$Q$2:$Q$5,MATCH("F7|trim_1_99|estimation|intrcpt",Results_Long!$AK$2:$AK$5,0)) -> -0.031736139 | H10: =INDEX(Results_Long!$T$2:$T$5,MATCH("F7|trim_1_99|estimation|intrcpt",Results_Long!$AK$2:$AK$5,0)) -> -0.041034787 | I10: =INDEX(Results_Long!$U$2:$U$5,MATCH("F7|trim_1_99|estimation|intrcpt",Results_Long!$AK$2:$AK$5,0)) -> -0.050336967 | J10: =INDEX(Results_Long!$V$2:$V$5,MATCH("F7|trim_1_99|estimation|intrcpt",Results_Long!$AK$2:$AK$5,0)) -> -0.031725489 | K10: =INDEX(Results_Long!$N$2:$N$5,MATCH("F7|trim_1_99|estimation|intrcpt",Results_Long!$AK$2:$AK$5,0)) -> 105.12463 | L10: =INDEX(Results_Long!$O$2:$O$5,MATCH("F7|trim_1_99|estimation|intrcpt",Results_Long!$AK$2:$AK$5,0)) -> 4.1657933e-14 | M10: =E10-$E$6 -> 0.017588894 | N10: =IF(E10*$E$6>0,"TRUE","FALSE") -> TRUE | O10: =IF(OR(F10>0,G10<0),"TRUE","FALSE") -> TRUE | P10: =IF(ABS(H10)<=0.07,"TRUE","FALSE") -> TRUE
A12: Interpretation
A13: All four handling variants attenuate toward zero (r −.032…−.041 vs headline −.059): the flagged/clipped tail is predominantly negative (9 of 13 rstudent flags; led by Drago et al (2018), zi = -3.392, |t| = 18.6), so removing or attenuating it pulls the pooled estimate up.
A14: Sign retained and CI excludes 0 in 4/4 variants; every estimate lies inside the SESOI band. The MAD refit is the strongest attenuation because k = 3 MAD flags a broad band (275 ES, 10.1%) on the heavy-tailed zi distribution; the rstudent set (13 ES, 0.5%) is fully contained in it.
A15: DEC-013 anchors: Drago is flagged and dropped here (primary specification untouched, DEC-005); the Devalle +0.9998 value was superseded by the documented v12 Devalle regime (ruling R1; v12 buildlog/verifier V7) — its three recomputed ES are unflagged.
A17: Reviewer Q&A — Finance/Econometrics
A18: Question | B18: Answer
A19: Is reestimate = FALSE a shortcut? | B19: It is the disclosed metafor-native deleted-residual convention: sigma2 fixed at full-set estimates, FE-only deletion. Full re-estimation at k = 2,713 is computationally prohibitive (implied serial cost ≈ 32 h for the FE-only route alone); threshold and route were pinned a priori [DEC-051/051a].
A20: Why two flag sets and no union? | B20: The pre-stated catalogue carries outlier_rstudent and outlier_mad separately [A.5; DEC-031a.4]; a union spec would be post hoc. The overlap is disclosed (13; rstudent ⊆ MAD), so the union refit would equal the MAD refit here.
A22: Reviewer Q&A — Management/BSE
A23: Question | B23: Answer
A24: Does outlier handling overturn the headline reading? | B24: No: 4/4 negative signs, 4/4 CIs excluding zero, 4/4 inside the SESOI band. Handling attenuates magnitude (max Δ_z +0.027, MAD drop), which the register discloses per spec.
A26: Verdict
A27: Mechanical outcome: sign and significance retained in 4/4 handling variants; all estimates inside |r| ≤ .070; outlier handling attenuates magnitude (r −.032…−.041 vs headline −.059). Wording per the resolved gate [DEC-044/DEC-047].

Sheet 7_LOO
A1: Cluster leave-one-out (F4) — 114 deletion refits on the verbatim spine
A2: Summary cells are formula-derived from the in-tab verbatim transport of output/TF_loo.csv (rows 31–144); documented deviation, see 4_Formula_Reference
A3: T1-A1 headline anchor (by value, verified 1e-9 at build): | C3: -0.058646737
A5: Quantity | B5: Value | C5: Detail
A6: LOO refits ok / ne | B6: =COUNTIF($M$31:$M$144,"ok")&" / "&COUNTIF($M$31:$M$144,"not_estimable") -> 114 / 0 | C6: S-F4 gate ≤ 5 [DEC-051 no.7]
A7: est_z minimum | B7: =MIN($D$31:$D$144) -> -0.060109449 | C7: =INDEX($A$31:$A$144,MATCH(MIN($D$31:$D$144),$D$31:$D$144,0)) -> Okimoto & Takaoka (2024)
A8: est_z maximum | B8: =MAX($D$31:$D$144) -> -0.040893852 | C8: =INDEX($A$31:$A$144,MATCH(MAX($D$31:$D$144),$D$31:$D$144,0)) -> Drago et al (2018)
A9: est_z range | B9: =MAX($D$31:$D$144)-MIN($D$31:$D$144) -> 0.019215597 | C9: max single-cluster shift vs headline: =MAX(ABS(MAX($D$31:$D$144)-$C$3),ABS(MIN($D$31:$D$144)-$C$3))
A10: signs retained (< 0) | B10: =COUNTIF($D$31:$D$144,"<0")&" / 114" -> 114 / 114
A11: CIs excluding 0 (upper < 0) | B11: =COUNTIF($G$31:$G$144,"<0")&" / 114" -> 114 / 114
A12: max Cook’s D (cluster) | B12: =MAX($L$31:$L$144) -> 1.6391534 | C12: =INDEX($A$31:$A$144,MATCH(MAX($L$31:$L$144),$L$31:$L$144,0)) -> Drago et al (2018)
A13: 2nd-largest Cook’s D | B13: =LARGE($L$31:$L$144,2) -> 0.023531442 | C13: dominance ratio: =MAX($L$31:$L$144)/LARGE($L$31:$L$144,2)
A15: Interpretation
A16: No single cluster overturns sign or significance: est_z stays within [−.0601; −.0409] (range 0.0192), 114/114 negative with CIs excluding zero.
A17: One dominant influence point: Drago et al (2018) — Cook’s D 1.64 (70× the runner-up Ben Slimane et al (2019) at 0.024); its deletion gives the maximum shift. The minimum sits at Okimoto & Takaoka (2024).
A19: Reviewer Q&A — Finance/Econometrics
A20: Question | B20: Answer
A21: Why a summary row in the register instead of 114 rows? | B21: G11 semantics: one register row per specification; the full 114-row table is committed as output/TF_loo.csv and transported verbatim below (rows 31–144).
A23: Reviewer Q&A — Management/BSE
A24: Question | B24: Answer
A25: Is the result driven by one study? | B25: Dropping the most influential cluster (Drago et al (2018)) attenuates the pooled estimate to −.0409 but does not change sign, significance, or the SESOI reading; the other 113 deletions move it by at most 0.0021.
A27: Verdict
A28: Mechanical outcome: 114/114 LOO refits retain sign and significance; the largest single-cluster shift is +0.0178 z (Drago et al (2018)). Wording per the resolved gate [DEC-044/DEC-047].
A30: cluster_id_dropped | B30: k_es | C30: k_study | D30: est_z | E30: se_z | F30: ci_lb_z | G30: ci_ub_z | H30: df | I30: sigma2_1 | J30: sigma2_2 | K30: sigma2_3 | L30: cooks_d_cluster | M30: status | N30: note
A31: Al-Fakir Al Rabab'a et al (2023) | B31: 2657 | C31: 114 | D31: -0.058659453 | E31: 0.013986771 | F31: -0.086376054 | G31: -0.030942851 | H31: 110.68092 | I31: 0.019931188 | J31: 3.1340707e-09 | K31: 0.012002076 | L31: 8.4096419e-07 | M31: ok
A32: Ali et al (2023) | B32: 2703 | C32: 114 | D32: -0.058026175 | E32: 0.013980725 | F32: -0.085730779 | G32: -0.030321571 | H32: 110.68699 | I32: 0.019932787 | J32: 2.8562719e-09 | K32: 0.011908622 | L32: 0.0020028643 | M32: ok
A33: Ali et al (2026) | B33: 2704 | C33: 114 | D33: -0.058948164 | E33: 0.013998411 | F33: -0.086687803 | G33: -0.031208525 | H33: 110.69085 | I33: 0.019986217 | J33: 2.6063275e-09 | K33: 0.011919487 | L33: 0.00047254985 | M33: ok
A34: Almutairi (2026) | B34: 2697 | C34: 114 | D34: -0.058609617 | E34: 0.014005985 | F34: -0.086364253 | G34: -0.030854981 | H34: 110.69557 | I34: 0.02001322 | J34: 2.6759578e-10 | K34: 0.011897895 | L34: 7.1663057e-06 | M34: ok
A35: Altavilla et al (2024) | B35: 2631 | C35: 114 | D35: -0.058955539 | E35: 0.013906986 | F35: -0.086514195 | G35: -0.031396883 | H35: 110.6233 | I35: 0.019645484 | J35: 2.1666633e-09 | K35: 0.012295164 | L35: 0.00049595512 | M35: ok
A36: Apergis et al (2022) | B36: 2711 | C36: 114 | D36: -0.05847143 | E36: 0.013977269 | F36: -0.086169088 | G36: -0.030773772 | H36: 110.72173 | I36: 0.01996266 | J36: 2.1613961e-09 | K36: 0.011887238 | L36: 0.00015983702 | M36: ok
A37: Atif, Ali (2021) | B37: 2711 | C37: 114 | D37: -0.058758038 | E37: 0.013981239 | F37: -0.086463569 | G37: -0.031052507 | H37: 110.71971 | I37: 0.019973334 | J37: 1.7720511e-09 | K37: 0.011887134 | L37: 6.442915e-05 | M37: ok
A38: Attig et al (2025) | B38: 2697 | C38: 114 | D38: -0.059460828 | E38: 0.013974687 | F38: -0.08715347 | G38: -0.031768186 | H38: 110.68529 | I38: 0.01990705 | J38: 1.6052259e-09 | K38: 0.011920493 | L38: 0.0034468965 | M38: ok
A39: Azmi et al (2021) | B39: 2710 | C39: 114 | D39: -0.059464987 | E39: 0.013946762 | F39: -0.087102203 | G39: -0.031827771 | H39: 110.7178 | I39: 0.019869749 | J39: 2.4008953e-09 | K39: 0.011888675 | L39: 0.0034822036 | M39: ok
A40: Bannier et al (2022) | B40: 2700 | C40: 114 | D40: -0.059173448 | E40: 0.013987646 | F40: -0.086891767 | G40: -0.031455129 | H40: 110.68633 | I40: 0.019946496 | J40: 1.8182169e-09 | K40: 0.011938962 | L40: 0.0014428684 | M40: ok
A41: Bauer, Hann (2010) | B41: 2547 | C41: 114 | D41: -0.05883243 | E41: 0.013808356 | F41: -0.086195854 | G41: -0.031469007 | H41: 110.54356 | I41: 0.01929977 | J41: 2.5004175e-09 | K41: 0.012666794 | L41: 0.00017933953 | M41: ok
A42: Ben Slimane et al (2019) | B42: 2705 | C42: 114 | D42: -0.056519659 | E42: 0.0150096 | F42: -0.086260982 | G42: -0.026778336 | H42: 111.40822 | I42: 0.023901101 | J42: 1.6678857e-09 | K42: 0.006850588 | L42: 0.023531442 | M42: ok
... A144: Zhu, Zhao (2022) | B144: 2685 | C144: 114 | D144: -0.059019092 | E144: 0.013976904 | F144: -0.086716152 | G144: -0.031322031 | H144: 110.67599 | I144: 0.019898912 | J144: 1.9634392e-09 | K144: 0.012017242 | L144: 0.00072110065 | M144: ok

Sheet 8_Influence
A1: Influence diagnostics (F5) — descriptive appendix, no thresholds, no adjudication
A2: Summary cells are formula-derived from the in-tab verbatim transport of output/TF_influence.csv (rows 31–2743); cluster Cook’s D lives in tab 7_LOO
A5: Quantity | B5: Value | C5: Detail
A6: rstudent flags (|t| > 3) | B6: =COUNTIF($G$31:$G$2743,TRUE()) -> 13 | C6: of =COUNT($F$31:$F$2743)
A7: MAD flags (k = 3) | B7: =COUNTIF($J$31:$J$2743,TRUE()) -> 275 | C7: overlap: =COUNTIF($K$31:$K$2743,TRUE)
A8: max |rstudent t| | B8: =MAX(MAX($F$31:$F$2743),-MIN($F$31:$F$2743)) -> 18.610163 | C8: =INDEX($B$31:$B$2743,MATCH(MIN($F$31:$F$2743),$F$31:$F$2743,0)) -> Drago et al (2018)
A9: winsor P1 (check) | B9: =PERCENTILE($D$31:$D$2743,0.01) -> -0.38077046 | C9: vs run_meta winsor_q[1] = −0.380770461057388
A10: winsor P99 (check) | B10: =PERCENTILE($D$31:$D$2743,0.99) -> 0.18471488 | C10: vs run_meta winsor_q[2] = 0.184714878917096
A11: max hat value | B11: =MAX($L$31:$L$2743) -> 0.0060510463 | C11: mean: =AVERAGE($L$31:$L$2743)
A13: Interpretation
A14: Leverage is unremarkable: max hat 0.00605 against a mean of 0.00037 (≈ 1/k). The influence story is concentrated in one observation — Drago et al (2018), zi = -3.392, |t| = 18.6 — whose cluster carries Cook’s D 1.64 (tab 7).
A16: Reviewer Q&A — Finance/Econometrics
A17: Question | B17: Answer
A18: Why no ES-level Cook’s D? | B18: Deletion-based ES-level Cook’s D at k = 2,713 is computationally prohibitive; the cluster level is the inference level (CR2 on cluster_id), and the ES level is covered by rstudent + hat values [DEC-051 no.8].
A20: Reviewer Q&A — Management/BSE
A21: Question | B21: Answer
A22: What should a reader take from this tab? | B22: A transparency appendix: every one of the 2,713 effect sizes is listed with its residual, flags, and leverage; no adjudication is performed here.
A24: Verdict
A25: Mechanical outcome: diagnostics are descriptive; influence concentrates in a single disclosed observation (Drago et al 2018). Wording per the resolved gate [DEC-044/DEC-047].
A30: cluster_id | B30: study | C30: esid | D30: zi | E30: vi | F30: rstudent_t | G30: flag_rstudent | H30: mad_center | I30: mad_scale | J30: flag_mad | K30: flag_both | L30: hatvalue
A31: Al-Fakir Al Rabab'a et al (2023) | B31: Al-Fakir Al Rabab'a et al (2023) | C31: 1 | D31: -0.3095196 | E31: 1.7049426e-05 | F31: -1.4065021 | G31: =FALSE() -> FALSE | H31: -0.028210083 | I31: 0.041824269 | J31: =TRUE() -> TRUE | K31: =FALSE() -> FALSE | L31: 0.00035108632
A32: Al-Fakir Al Rabab'a et al (2023) | B32: Al-Fakir Al Rabab'a et al (2023) | C32: 2 | D32: -0.080171325 | E32: 1.7049426e-05 | F32: -0.1206828 | G32: =FALSE() -> FALSE | H32: -0.028210083 | I32: 0.041824269 | J32: =FALSE() -> FALSE | K32: =FALSE() -> FALSE | L32: 0.00035108632
A33: Al-Fakir Al Rabab'a et al (2023) | B33: Al-Fakir Al Rabab'a et al (2023) | C33: 3 | D33: -0.12058103 | E33: 1.7049426e-05 | F33: -0.34723595 | G33: =FALSE() -> FALSE | H33: -0.028210083 | I33: 0.041824269 | J33: =FALSE() -> FALSE | K33: =FALSE() -> FALSE | L33: 0.00035108632
A34: Al-Fakir Al Rabab'a et al (2023) | B34: Al-Fakir Al Rabab'a et al (2023) | C34: 4 | D34: -0.15114044 | E34: 1.7049426e-05 | F34: -0.51856436 | G34: =FALSE() -> FALSE | H34: -0.028210083 | I34: 0.041824269 | J34: =FALSE() -> FALSE | K34: =FALSE() -> FALSE | L34: 0.00035108632
A35: Al-Fakir Al Rabab'a et al (2023) | B35: Al-Fakir Al Rabab'a et al (2023) | C35: 5 | D35: -0.039957984 | E35: 0.00027300027 | F35: 0.10432352 | G35: =FALSE() -> FALSE | H35: -0.028210083 | I35: 0.041824269 | J35: =FALSE() -> FALSE | K35: =FALSE() -> FALSE | L35: 0.00025277019
A36: Al-Fakir Al Rabab'a et al (2023) | B36: Al-Fakir Al Rabab'a et al (2023) | C36: 6 | D36: -0.039462896 | E36: 0.00027300027 | F36: 0.10708781 | G36: =FALSE() -> FALSE | H36: -0.028210083 | I36: 0.041824269 | J36: =FALSE() -> FALSE | K36: =FALSE() -> FALSE | L36: 0.00025277019
A37: Al-Fakir Al Rabab'a et al (2023) | B37: Al-Fakir Al Rabab'a et al (2023) | C37: 7 | D37: -0.040453063 | E37: 0.00027300027 | F37: 0.10155929 | G37: =FALSE() -> FALSE | H37: -0.028210083 | I37: 0.041824269 | J37: =FALSE() -> FALSE | K37: =FALSE() -> FALSE | L37: 0.00025277019
A38: Al-Fakir Al Rabab'a et al (2023) | B38: Al-Fakir Al Rabab'a et al (2023) | C38: 8 | D38: -0.030384687 | E38: 0.00027300027 | F38: 0.15777525 | G38: =FALSE() -> FALSE | H38: -0.028210083 | I38: 0.041824269 | J38: =FALSE() -> FALSE | K38: =FALSE() -> FALSE | L38: 0.00025277019
A39: Al-Fakir Al Rabab'a et al (2023) | B39: Al-Fakir Al Rabab'a et al (2023) | C39: 9 | D39: -0.05068229 | E39: 0.00027300027 | F39: 0.044445236 | G39: =FALSE() -> FALSE | H39: -0.028210083 | I39: 0.041824269 | J39: =FALSE() -> FALSE | K39: =FALSE() -> FALSE | L39: 0.00025277019
A40: Al-Fakir Al Rabab'a et al (2023) | B40: Al-Fakir Al Rabab'a et al (2023) | C40: 10 | D40: -0.051507011 | E40: 0.00027300027 | F40: 0.039840473 | G40: =FALSE() -> FALSE | H40: -0.028210083 | I40: 0.041824269 | J40: =FALSE() -> FALSE | K40: =FALSE() -> FALSE | L40: 0.00025277019
A41: Al-Fakir Al Rabab'a et al (2023) | B41: Al-Fakir Al Rabab'a et al (2023) | C41: 11 | D41: -0.049362665 | E41: 0.00027300027 | F41: 0.051813256 | G41: =FALSE() -> FALSE | H41: -0.028210083 | I41: 0.041824269 | J41: =FALSE() -> FALSE | K41: =FALSE() -> FALSE | L41: 0.00025277019
A42: Al-Fakir Al Rabab'a et al (2023) | B42: Al-Fakir Al Rabab'a et al (2023) | C42: 12 | D42: -0.041938239 | E42: 0.00027300027 | F42: 0.093266936 | G42: =FALSE() -> FALSE | H42: -0.028210083 | I42: 0.041824269 | J42: =FALSE() -> FALSE | K42: =FALSE() -> FALSE | L42: 0.00025277019
A43: Al-Fakir Al Rabab'a et al (2023) | B43: Al-Fakir Al Rabab'a et al (2023) | C43: 13 | D43: -0.039627927 | E43: 0.00027300027 | F43: 0.10616637 | G43: =FALSE() -> FALSE | H43: -0.028210083 | I43: 0.041824269 | J43: =FALSE() -> FALSE | K43: =FALSE() -> FALSE | L43: 0.00025277019
... A58: Al-Fakir Al Rabab'a et al (2023) | B58: Al-Fakir Al Rabab'a et al (2023) | C58: 28 | D58: 0.023677969 | E58: 0.00044762757 | F58: 0.45836442 | G58: =FALSE() -> FALSE | H58: -0.028210083 | I58: 0.041824269 | J58: =FALSE() -> FALSE | K58: =FALSE() -> FALSE | L58: 0.00021586915
A59: Al-Fakir Al Rabab'a et al (2023) | B59: Al-Fakir Al Rabab'a et al (2023) | C59: 29 | D59: 0.11569193 | E59: 0.0028011204 | F59: 0.93693415 | G59: =FALSE() -> FALSE | H59: -0.028210083 | I59: 0.041824269 | J59: =TRUE() -> TRUE | K59: =FALSE() -> FALSE | L59: -2.5087513e-05
A60: Al-Fakir Al Rabab'a et al (2023) | B60: Al-Fakir Al Rabab'a et al (2023) | C60: 30 | D60: 0.25801559 | E60: 0.0028011204 | F60: 1.7018065 | G60: =FALSE() -> FALSE | H60: -0.028210083 | I60: 0.041824269 | J60: =TRUE() -> TRUE | K60: =FALSE() -> FALSE | L60: -2.5087513e-05
A61: Al-Fakir Al Rabab'a et al (2023) | B61: Al-Fakir Al Rabab'a et al (2023) | C61: 31 | D61: -0.061625401 | E61: 0.0028011204 | F61: -0.016000314 | G61: =FALSE() -> FALSE | H61: -0.028210083 | I61: 0.041824269 | J61: =FALSE() -> FALSE | K61: =FALSE() -> FALSE | L61: -2.5087513e-05
A62: Al-Fakir Al Rabab'a et al (2023) | B62: Al-Fakir Al Rabab'a et al (2023) | C62: 32 | D62: 0.012121768 | E62: 0.0028011204 | F62: 0.38032992 | G62: =FALSE() -> FALSE | H62: -0.028210083 | I62: 0.041824269 | J62: =FALSE() -> FALSE | K62: =FALSE() -> FALSE | L62: -2.5087513e-05
A63: Al-Fakir Al Rabab'a et al (2023) | B63: Al-Fakir Al Rabab'a et al (2023) | C63: 33 | D63: -0.13598893 | E63: 0.0029325513 | F63: -0.41484975 | G63: =FALSE() -> FALSE | H63: -0.028210083 | I63: 0.041824269 | J63: =FALSE() -> FALSE | K63: =FALSE() -> FALSE | L63: -3.3657384e-05
A64: Al-Fakir Al Rabab'a et al (2023) | B64: Al-Fakir Al Rabab'a et al (2023) | C64: 34 | D64: 0.072185252 | E64: 0.0029325513 | F64: 0.7017874 | G64: =FALSE() -> FALSE | H64: -0.028210083 | I64: 0.041824269 | J64: =FALSE() -> FALSE | K64: =FALSE() -> FALSE | L64: -3.3657384e-05
...

Sheet Results_Long
A1: analysis_id | B1: spec | C1: subset | D1: term | E1: metric | F1: estimator | G1: rho | H1: k_es | I1: k_study | J1: k_cluster | K1: est_z | L1: se_z | M1: t_stat | N1: df | O1: p | P1: ci_lb_z | Q1: ci_ub_z | R1: pi_lb_z | S1: pi_ub_z | T1: est_r | U1: ci_lb_r | V1: ci_ub_r | W1: pi_lb_r | X1: pi_ub_r | Y1: sigma2_cluster | Z1: sigma2_study | AA1: sigma2_esid | AB1: pct_cluster | AC1: pct_study | AD1: pct_esid | AE1: pct_sampling | AF1: typical_v | AG1: value | AH1: ms_input | AI1: ms_label | AJ1: note | AK1: KEY
A2: F2 | B2: outlier_rstudent | C2: estimation | D2: intrcpt | E2: NA | F2: TRUE | G2: NA | H2: 2700 | I2: 115 | J2: 114 | K2: -0.037638204 | L2: 0.0044822302 | M2: NA | N2: 102.47497 | O2: 2.7119642e-13 | P2: -0.046528191 | Q2: -0.028748216 | R2: NA | S2: NA | T2: -0.037620441 | U2: -0.046494645 | V2: -0.028740299 | W2: NA | X2: NA | Y2: NA | Z2: NA | AA2: NA | AB2: NA | AC2: NA | AD2: NA | AE2: NA | AF2: NA | AG2: NA | AH2: NA | AI2: NA | AJ2: drop 13 ES with |rstudent(reestimate=FALSE)| > 3 [DEC-051]; overlap with MAD set = 13; N5/H3 mask relation disclosed descriptively | AK2: =A2&"|"&B2&"|"&C2&"|"&D2 -> F2|outlier_rstudent|estimation|intrcpt
A3: F2 | B3: outlier_mad | C3: estimation | D3: intrcpt | E3: NA | F3: TRUE | G3: NA | H3: 2438 | I3: 110 | J3: 109 | K3: -0.032135296 | L3: 0.0032073519 | M3: NA | N3: 96.596611 | O3: 1.2703725e-16 | P3: -0.038501337 | Q3: -0.025769255 | R3: NA | S3: NA | T3: -0.032124239 | U3: -0.038482324 | V3: -0.025763552 | W3: NA | X3: NA | Y3: NA | Z3: NA | AA3: NA | AB3: NA | AC3: NA | AD3: NA | AE3: NA | AF3: NA | AG3: NA | AH3: NA | AI3: NA | AJ3: drop 275 ES outside median +/- 3*MAD (b=1.4826, zi, full estimation set) [Leys 2013; DEC-051]; overlap with rstudent set = 13 | AK3: =A3&"|"&B3&"|"&C3&"|"&D3 -> F2|outlier_mad|estimation|intrcpt
A4: F3 | B4: winsor | C4: estimation | D4: intrcpt | E4: NA | F4: TRUE | G4: NA | H4: 2713 | I4: 115 | J4: 114 | K4: -0.040527601 | L4: 0.004660559 | M4: NA | N4: 104.57779 | O4: 5.2254732e-14 | P4: -0.049769063 | Q4: -0.031286138 | R4: NA | S4: NA | T4: -0.040505427 | U4: -0.049728012 | V4: -0.031275934 | W4: NA | X4: NA | Y4: NA | Z4: NA | AA4: NA | AB4: NA | AC4: NA | AD4: NA | AE4: NA | AF4: NA | AG4: NA | AH4: NA | AI4: NA | AJ4: zi winsorized at empirical P1/P99 of the full estimation set (A.13/H3 pin; type-7 quantile); 56 ES clipped; unwinsor == headline (DEC-013(a) status-quo semantics; cross-reference, no fit) | AK4: =A4&"|"&B4&"|"&C4&"|"&D4 -> F3|winsor|estimation|intrcpt
A5: F7 | B5: trim_1_99 | C5: estimation | D5: intrcpt | E5: NA | F5: TRUE | G5: NA | H5: 2657 | I5: 114 | J5: 113 | K5: -0.041057843 | L5: 0.0047013116 | M5: NA | N5: 105.12463 | O5: 4.1657933e-14 | P5: -0.050379546 | Q5: -0.031736139 | R5: NA | S5: NA | T5: -0.041034787 | U5: -0.050336967 | V5: -0.031725489 | W5: NA | X5: NA | Y5: NA | Z5: NA | AA5: NA | AB5: NA | AC5: NA | AD5: NA | AE5: NA | AF5: NA | AG5: NA | AH5: NA | AI5: NA | AJ5: drop 56 ES with zi outside [P1, P99] (same percentiles as winsor) [DEC-051] | AK5: =A5&"|"&B5&"|"&C5&"|"&D5 -> F7|trim_1_99|estimation|intrcpt

Sheet Manuscript_Inputs
A1: Manuscript inputs — ms_input = TRUE rows only
A2: TG style per F-Q9 [DEC-051 no.12]: no script-level ms_input flags
A5: ms_label | B5: analysis | C5: quantity | D5: paste-ready (EN) | E5: k
A6: No rows flagged ms_input in TF_results.csv — formula-live citables via 6_Outlier_Refits / 7_LOO / 8_Influence; prose via TB-69…TB-71 (+ TB-65 final).

Sheet Manuscript_Text_Blocks
A1: Manuscript text blocks — TB numbering continues across runs (TF: TB-69…TB-71; TB-65 finalized here; TB-68 superseded)
A2: Numbers hardcoded from output/TF_results.csv + TF_loo.csv + TF_influence.csv + robustness_register.csv + output/T1_results.csv at build; regenerate on any re-run. Framing per the resolved gate [DEC-047].
A4: ID | B4: Target section | C4: Status | D4: Text (EN) | E4: Source pointers | F4: Note
A5: TB-65 | B5: Robustness — register overview | C5: READY | D5: The robustness register (output/robustness_register.csv; machine-readable companion to the appendix) is complete: 23 specifications on the T1 spine — 5 Block-A anchor rows, 11 Block-G design variants, and 7 Block-F outlier/influence rows. Every populated specification retains the negative sign inside the |r| = 0.070 band (|r| .031 to .062 vs headline .059); 14 of 16 value rows exclude zero (the UWLS+3 and direct-r-only CIs cover it). | E5: robustness_register.csv (23×18, complete); [DEC-051 no.9; DEC-050 §10] | F5: Finalized here per the TB-35 precedent; the TG-workbook cell remains DRAFT (build-historical).
A6: TB-68 | B6: Robustness — register availability | C6: SUPERSEDED | D6: Superseded by the completed register: see TB-65 (final) and TB-69…TB-71. | E6: [DEC-050 §10] | F6: Supersession recorded per the TB-35 precedent; TG-workbook cell build-historical.
A7: TB-69 | B7: Results — outlier robustness (Block F refits) | C7: READY | D7: Outlier handling leaves the pooled association small, negative, and distinguishable from zero in every variant. Studentized deleted residuals from the three-level model flag 13 of 2,713 effect sizes (|t| > 3); a Leys MAD rule (k = 3, b = 1.4826) flags 275, fully containing the rstudent set. Dropping either flag set, winsorizing at the empirical 1st/99th percentiles, or trimming symmetrically yields r between −.032 and −.041 (headline −.059); all four CIs exclude zero and all estimates lie inside the |r| = 0.070 band. Of the two extreme values documented in the screening decisions, Drago et al. (2018; z = -3.39) is flagged and carried by the drop-and-refit variants, while the Devalle et al. (2017) extreme was superseded by a documented data-revision ruling (v12, R1) before analysis. | E7: TF_results.csv; 6_Outlier_Refits; register rows outlier_rstudent…trim_1_99; [DEC-051; DEC-013]
A8: TB-70 | B8: Results — leave-one-out | C8: READY | D8: Leave-one-out over the 114 clusters retains sign and significance in 114/114 refits (est_z −.060 to −.041; range 0.019). The largest single-cluster shift comes from Drago et al. (2018) — Cook’s distance 1.64, 70 times the runner-up — whose single extreme effect size is also the top studentized-residual flag; excluding it attenuates the pooled estimate to r −.041 without changing its reading. | E8: TF_loo.csv; 7_LOO; register row leave_one_out; [DEC-051 no.7]
A9: TB-71 | B9: Appendix — influence diagnostics | C9: READY | D9: Influence diagnostics are reported descriptively: cluster-level Cook’s distances derived from the leave-one-out refits and observation-level hat values from the full-set fit. Apart from the Drago et al. (2018) cluster (D = 1.64), all cluster distances are ≤ 0.024 and hat values are ≤ 0.0061 (mean 0.00037 ≈ 1/k); no threshold-based adjudication is applied. | E9: TF_influence.csv; 8_Influence; register row influence_diagnostics; [DEC-051 no.8]
