Workbook

Sheet 1_README
A1: FOMA CER–COD–Paris — TG / Block G results workbook (robustness register G1–G10)
A2: Template: docs/results_workbook_template.md (binding) · one workbook per run
A3: Canonical run · 2026-07-29 17:28:47 · HEAD c935b28 · verifier R/11_verify_outputs.R: 12/12 PASS
A5: Item | B5: Value
A6: Data version | B6: CERCOD v12 — estimation set 2,713 ES / 115 studies / 114 clusters (per-spec domains in each tab)
A7: Method (one line) | B7: 3L-RVE spine verbatim (random ~1|cluster_id/study/esid; CS rho=0.6; CR2/Satterthwaite on cluster_id); G6 off-spine cluster-median rma.uni(REML, knha)
A8: Scope | B8: Block G: six spine/aggregation variant specs (G1–G6, 7 rows) + four technical level panels (G7–G10); register G11 partial (A+G rows; F rows pending)
A9: Repository | B9: github.com/rwitte-wu-research/FOMA-CER-COD-Paris (public, main)
A10: Computational stack | B10: R 4.6.1 · metafor · clubSandwich · seed 20260710
A11: Scripts | B11: R/11_robustness.R + R/11_verify_outputs.R @ c935b28
A12: Decision basis | B12: DEC-050 · DEC-050a · DEC-050b · DEC-050c · analysis_plan A.15; language regime per DEC-047
A14: TAB-INDEX
A15: 1_README | B15: this tab
A16: 2_Methodology | B16: quantity | formula/construction | reference
A17: 3_Interpretation_Guide | B17: how to read each quantity; decision rules
A18: 4_Formula_Reference | B18: exact R calls; workbook formula conventions (incl. documented TEXT() deviation)
A19: 5_Data_Provenance | B19: run record, gates, verifier, known notes
A20: 6_Spine_Variants | B20: Spine & aggregation variants (G1–G6), reference row = T1-A1
A21: 7_Panel_qVHB | B21: G7 journal-quality cells incl. 99_NCE (descriptive; D5 cross-ref)
A22: 8_Panel_Field | B22: G8 research-field cells
A23: 9_Panel_ES_Measure | B23: G9 FEATURED axis: partial vs bivariate (van Aert)
A24: 10_Panel_ES_Method | B24: G10 conversion route, main-effect-only
A25: Results_Long | B25: verbatim CSV + key; single formula source
A26: Manuscript_Inputs | B26: ms_input rows, fully formula-derived
A27: Manuscript_Text_Blocks | B27: TB-65…TB-68

Sheet 2_Methodology
A1: Methodology — Block G robustness specs
A3: Quantity | B3: Formula / Construction | C3: Reference
A4: Spine engine (G1–G5, G7–G10) | B4: 3L random effects ~1|cluster_id/study/esid; CS V blocks within cluster_id, rho = 0.6; CR2 with Satterthwaite df on cluster_id; optimizer ladder | C4: [DEC-050 §2; DEC-031f; A.2]
A5: G1 no_starbound | B5: drop es_method == "star-bound" (99 ES / 11 studies, asserted) | C5: [DEC-050 §5]
A6: G2 no_nobs_proxyfill | B6: drop dat_prep flag_proxy_n rows — 296 on the estimation set; 297 on the usable basis incl. 134 FLAG-based; one tagged duplicate exits at the estimation filter | C6: [DEC-050 §5; DEC-050a]
A7: G3 n_firms_variance | B7: adj_i = n_obs_i − 1/vi_i (integer share asserted ≥ .99; observed 1.00); vi_g3 = 1/(n_firms − adj); invalid n_firms dropped+counted (0) | C7: [r02f2; DEC-048-K3; DEC-050 §5]
A8: G4 direct_r_only | B8: es_method == "bivariate"; near-identical to the G9 bivariate cell (Δ = 2 ES / 1 study, disclosed) | C8: [DEC-050 §5–6]
A9: G5 pcc_df_k10 / k20 | B9: PCC rows: vi = 1/(n − k − 3), k ∈ {10, 20}; bivariate rows unchanged; k20 excludes the single n = 18 row | C9: [DEC-050 §5; ERROR #14]
A10: G6 one_per_cluster_median | B10: median z per cluster; vi of the median-carrying row (even size: mean of the two middle rows' vi); rma.uni(REML, knha) | C10: [DEC-050 §2/§5; DEC-031a.4]
A11: G7–G10 panels | B11: cell-means level panels: q_VHB (incl. 99_NCE per D31.4), field, ES_measure (featured), es_method (main-effect-only per Annex C); HTZ omnibus + pairwise CR2/Satterthwaite contrasts | C11: [DEC-050 §5; DEC-031a.1]
A12: Inference regime | B12: descriptive throughout; no Holm; no spec-vs-headline tests (N5 multiverse = single inferential home); no prediction intervals (PI home = A3/T1) | C12: [DEC-050 §3–4; DEC-047; DEC-031a.6; A.8]
A13: Δ vs headline / flags | B13: presentation-layer formulas: Δ_z = est_z − T1-A1; sign retained; CI excludes 0; |est_r| ≤ 0.070 (SESOI band F27v2) | C13: [DEC-050 §3/§10]
A14: Register G11 | B14: output/robustness_register.csv assembled by value from committed CSVs (A + TG rows), 1e-9 source verification, mandatory reported-in column; partial until F session | C14: [DEC-050 §10]

Sheet 3_Interpretation_Guide
A1: Interpretation guide
A3: Quantity | B3: Meaning | C3: Decision rule
A4: est_z / est_r | B4: pooled Fisher-z estimate and its back-transform tanh(z) for level rows | C4: report both scales for levels; r-scale for prose
A5: Contrast / HTZ rows | B5: difference-of-z and omnibus F; z-only by convention — tanh is never applied to differences | C5: template rule; z-only
A6: df (Satterthwaite) | B6: small-sample-adjusted df per CR2 | C6: df < 5 on a contrast → interpret descriptively (display flag; DEC-048 convention carried over)
A7: p (panels) | B7: descriptive under the resolved gate — no moderation-style claims from G panels | C7: [DEC-047]; no Holm by design [DEC-050 §4]
A8: Δ_z vs headline | B8: descriptive location shift against the T1-A1 headline; carries no SE/p by design | C8: [DEC-031a.6]; joint spec inference lives in N5
A9: Flag: sign retained | B9: sign(est_z) equals the headline sign | C9: yes/no; descriptive
A10: Flag: CI excludes 0 | B10: both CI ends on the same side of zero | C10: yes/no; descriptive
A11: Flag: inside SESOI | B11: |est_r| ≤ 0.070 — point location inside the pre-registered band (F27v2). NOT an equivalence test; TOST single home = E1/TH-a | C11: yes/no; descriptive
A12: 99_NCE cell (G7) | B12: not-classified journal cell, retained per D31.4; publication-status inference single-homed in D5 | C12: descriptive; cross-reference only

Sheet 4_Formula_Reference
A1: Formula reference — R calls and workbook conventions
A3: Quantity | B3: R call / workbook formula | C3: Reference / script section
A4: Spine fit | B4: rma.mv(yi=zi, V=Vmat(rho=0.6), random=~1|cluster_id/study/esid, method="REML") + clubSandwich coef_test/conf_int (CR2, Satterthwaite) | C4: R/11_robustness.R fit block
A5: G6 aggregate fit | B5: rma.uni(yi=z_med, vi=vi_med, method="REML", test="knha") | C5: R/11_robustness.R G6 block
A6: Panel HTZ / pairwise | B6: clubSandwich::Wald_test(cell-means constraints, vcov=CR2, test="HTZ") / linear contrasts with Satterthwaite df | C6: R/11_robustness.R panel block
A7: T1-A1 anchor (this workbook) | B7: by value from output/T1_results.csv (label key analysis_id=="A1"): est_z = -0.058646736610098; source-verified at build (1e-9); single anchor cell 6_Spine_Variants!E6 | C7: [DEC-050 §10; DEC-050c pattern]
A8: Δ formula | B8: Δ_z = est_z cell − $E$6 anchor (tab 6_Spine_Variants, column M); signed display format | C8: [DEC-050 §3]
A9: Locale-neutral strings | B9: documented TEXT() deviation from the template: number strings built via ROUND/INT/ABS/REPT/LEN arithmetic and "&" concatenation only — no TEXT() format codes, no CONCAT/XLOOKUP | C9: [ERROR #9 lesson; T7 precedent]
A10: Lookups | B10: INDEX/MATCH on Results_Long!$AK (key = analysis_id|spec|subset|term) | C10: template formula rules

Sheet 5_Data_Provenance
A1: Data provenance & run record
A2: Canonical run accepted under DEC-050 + 050a/b/c; verifier 12/12
A3: Delivery-side ERROR #32–#34 logged; nothing entered committed bytes invalid
A5: Item | B5: Value | C5: Source
A6: Estimation set | B6: 2,713 ES / 115 studies / 114 clusters (dat_prep); per-spec domains in Results_Long | C6: TG_run_meta.json
A7: dat_prep md5 | B7: 6702ef3dc45fe0b693b13f50ebd1576b | C7: TG_run_meta.json; A.15 pin
A8: Seed / rho | B8: 20260710 / 0.6 | C8: FROZEN ZONE
A9: Run stamp | B9: 2026-07-29 17:28:47 · budget < 5 min / ≤ 14 fits / ≤ 60 rows [DEC-050 §9]; 36 rows delivered | C9: TG_run_meta.json
A10: Gate A (script) | B10: pre-flight CS-aggregate by value: −0.0616608 (df 113), 1e-9 point / 1e-6 CI tiers — PASS | C10: [DEC-048; DEC-050 §7]
A11: Gate B (verifier) | B11: independent 3L headline refit matched to committed output/T1_results.csv A1: −0.058647; three variance components located ≤ 1e-6; row located by label key (A1≡A3 identity untouched) — PASS | C11: [DEC-050b; DEC-050c]
A12: Verifier | B12: R/11_verify_outputs.R: 12/12 PASS (schema transplant, budget, key uniqueness, domains, G1/G2/G3 asserts, G4/G9 Δ assert, gates) | C12: @ c935b28
A13: S-G2 episode | B13: designed stop fired at 296 vs pinned 297; fully reconciled result-blind (basis difference: estimation set vs usable set; duplicate is a proxy row) — assert re-pinned to 296 | C13: [DEC-050a]
A14: G3 diagnostics | B14: adjustment-integer share = 1.00; rows dropped for invalid n_firms = 0 | C14: TG_run_meta.json
A15: Canonical HEAD | B15: c935b28 — TG canonical run: results 36 rows, verifier 12/12 + DEC-050a/b/c + ERROR #32-34 + status G-flip | C15: git log

Sheet 6_Spine_Variants
A1: Spine & aggregation variants (G1–G6) — seven alternative estimators of the pooled CER–COD association
A2: Reference row = T1-A1 headline, by value (source output/T1_results.csv @ c935b28, verified 1e-9 at build) [DEC-050 §10]
A3: Δ and flags are presentation-layer [DEC-050 §3]; no spec-vs-headline tests [DEC-031a.6; N5 single home]
A5: Spec | B5: k_es | C5: k_study | D5: k_cluster | E5: est_z | F5: CI_z low | G5: CI_z high | H5: est_r | I5: CI_r low | J5: CI_r high | K5: df | L5: p | M5: Δ_z vs headline | N5: sign retained | O5: CI excl. 0 | P5: inside SESOI (|r| ≤ .070)
A6: T1-A1 headline (reference) | B6: 2713 | C6: 115 | D6: 114 | E6: -0.058646737 | F6: -0.086102595 | G6: -0.031190879 | H6: -0.058579592 | I6: -0.085890445 | J6: -0.031180768 | K6: 111.6718 | L6: 4.7619835e-05 | M6: =E6-$E$6 -> 0 | N6: =IF(SIGN(E6)=SIGN($E$6),"yes","no") -> yes | O6: =IF(F6*G6>0,"yes","no") -> yes | P6: =IF(ABS(H6)<=0.07,"yes","no") -> yes
A7: G1 no_starbound | B7: =IF(ISBLANK(INDEX(Results_Long!$H$2:$H$37,MATCH("G1|no_starbound|estimation|intrcpt",Results_Long!$AK$2:$AK$37,0))),"—",INDEX(Results_Long!$H$2:$H$37,MATCH("G1|no_starbound|estimation|intrcpt",Results_Long!$AK$2:$AK$37,0))) -> 2614 | C7: =IF(ISBLANK(INDEX(Results_Long!$I$2:$I$37,MATCH("G1|no_starbound|estimation|intrcpt",Results_Long!$AK$2:$AK$37,0))),"—",INDEX(Results_Long!$I$2:$I$37,MATCH("G1|no_starbound|estimation|intrcpt",Results_Long!$AK$2:$AK$37,0))) -> 112 | D7: =IF(ISBLANK(INDEX(Results_Long!$J$2:$J$37,MATCH("G1|no_starbound|estimation|intrcpt",Results_Long!$AK$2:$AK$37,0))),"—",INDEX(Results_Long!$J$2:$J$37,MATCH("G1|no_starbound|estimation|intrcpt",Results_Long!$AK$2:$AK$37,0))) -> 111 | E7: =IF(ISBLANK(INDEX(Results_Long!$K$2:$K$37,MATCH("G1|no_starbound|estimation|intrcpt",Results_Long!$AK$2:$AK$37,0))),"—",INDEX(Results_Long!$K$2:$K$37,MATCH("G1|no_starbound|estimation|intrcpt",Results_Long!$AK$2:$AK$37,0))) -> -0.057981615 | F7: =IF(ISBLANK(INDEX(Results_Long!$P$2:$P$37,MATCH("G1|no_starbound|estimation|intrcpt",Results_Long!$AK$2:$AK$37,0))),"—",INDEX(Results_Long!$P$2:$P$37,MATCH("G1|no_starbound|estimation|intrcpt",Results_Long!$AK$2:$AK$37,0))) -> -0.086764913 | G7: =IF(ISBLANK(INDEX(Results_Long!$Q$2:$Q$37,MATCH("G1|no_starbound|estimation|intrcpt",Results_Long!$AK$2:$AK$37,0))),"—",INDEX(Results_Long!$Q$2:$Q$37,MATCH("G1|no_starbound|estimation|intrcpt",Results_Long!$AK$2:$AK$37,0))) -> -0.029198317 | H7: =IF(ISBLANK(INDEX(Results_Long!$T$2:$T$37,MATCH("G1|no_starbound|estimation|intrcpt",Results_Long!$AK$2:$AK$37,0))),"—",INDEX(Results_Long!$T$2:$T$37,MATCH("G1|no_starbound|estimation|intrcpt",Results_Long!$AK$2:$AK$37,0))) -> -0.057916727 | I7: =IF(ISBLANK(INDEX(Results_Long!$U$2:$U$37,MATCH("G1|no_starbound|estimation|intrcpt",Results_Long!$AK$2:$AK$37,0))),"—",INDEX(Results_Long!$U$2:$U$37,MATCH("G1|no_starbound|estimation|intrcpt",Results_Long!$AK$2:$AK$37,0))) -> -0.08654784 | J7: =IF(ISBLANK(INDEX(Results_Long!$V$2:$V$37,MATCH("G1|no_starbound|estimation|intrcpt",Results_Long!$AK$2:$AK$37,0))),"—",INDEX(Results_Long!$V$2:$V$37,MATCH("G1|no_starbound|estimation|intrcpt",Results_Long!$AK$2:$AK$37,0))) -> -0.029190023 | K7: =IF(ISBLANK(INDEX(Results_Long!$N$2:$N$37,MATCH("G1|no_starbound|estimation|intrcpt",Results_Long!$AK$2:$AK$37,0))),"—",INDEX(Results_Long!$N$2:$N$37,MATCH("G1|no_starbound|estimation|intrcpt",Results_Long!$AK$2:$AK$37,0))) -> 108.65345 | L7: =IF(ISBLANK(INDEX(Results_Long!$O$2:$O$37,MATCH("G1|no_starbound|estimation|intrcpt",Results_Long!$AK$2:$AK$37,0))),"—",INDEX(Results_Long!$O$2:$O$37,MATCH("G1|no_starbound|estimation|intrcpt",Results_Long!$AK$2:$AK$37,0))) -> 0.00011906297 | M7: =E7-$E$6 -> 0.00066512148 | N7: =IF(SIGN(E7)=SIGN($E$6),"yes","no") -> yes | O7: =IF(F7*G7>0,"yes","no") -> yes | P7: =IF(ABS(H7)<=0.07,"yes","no") -> yes
A8: G2 no_nobs_proxyfill | B8: =IF(ISBLANK(INDEX(Results_Long!$H$2:$H$37,MATCH("G2|no_nobs_proxyfill|estimation|intrcpt",Results_Long!$AK$2:$AK$37,0))),"—",INDEX(Results_Long!$H$2:$H$37,MATCH("G2|no_nobs_proxyfill|estimation|intrcpt",Results_Long!$AK$2:$AK$37,0))) -> 2417 | C8: =IF(ISBLANK(INDEX(Results_Long!$I$2:$I$37,MATCH("G2|no_nobs_proxyfill|estimation|intrcpt",Results_Long!$AK$2:$AK$37,0))),"—",INDEX(Results_Long!$I$2:$I$37,MATCH("G2|no_nobs_proxyfill|estimation|intrcpt",Results_Long!$AK$2:$AK$37,0))) -> 109 | D8: =IF(ISBLANK(INDEX(Results_Long!$J$2:$J$37,MATCH("G2|no_nobs_proxyfill|estimation|intrcpt",Results_Long!$AK$2:$AK$37,0))),"—",INDEX(Results_Long!$J$2:$J$37,MATCH("G2|no_nobs_proxyfill|estimation|intrcpt",Results_Long!$AK$2:$AK$37,0))) -> 109 | E8: =IF(ISBLANK(INDEX(Results_Long!$K$2:$K$37,MATCH("G2|no_nobs_proxyfill|estimation|intrcpt",Results_Long!$AK$2:$AK$37,0))),"—",INDEX(Results_Long!$K$2:$K$37,MATCH("G2|no_nobs_proxyfill|estimation|intrcpt",Results_Long!$AK$2:$AK$37,0))) -> -0.03816762 | F8: =IF(ISBLANK(INDEX(Results_Long!$P$2:$P$37,MATCH("G2|no_nobs_proxyfill|estimation|intrcpt",Results_Long!$AK$2:$AK$37,0))),"—",INDEX(Results_Long!$P$2:$P$37,MATCH("G2|no_nobs_proxyfill|estimation|intrcpt",Results_Long!$AK$2:$AK$37,0))) -> -0.047570794 | G8: =IF(ISBLANK(INDEX(Results_Long!$Q$2:$Q$37,MATCH("G2|no_nobs_proxyfill|estimation|intrcpt",Results_Long!$AK$2:$AK$37,0))),"—",INDEX(Results_Long!$Q$2:$Q$37,MATCH("G2|no_nobs_proxyfill|estimation|intrcpt",Results_Long!$AK$2:$AK$37,0))) -> -0.028764446 | H8: =IF(ISBLANK(INDEX(Results_Long!$T$2:$T$37,MATCH("G2|no_nobs_proxyfill|estimation|intrcpt",Results_Long!$AK$2:$AK$37,0))),"—",INDEX(Results_Long!$T$2:$T$37,MATCH("G2|no_nobs_proxyfill|estimation|intrcpt",Results_Long!$AK$2:$AK$37,0))) -> -0.038149097 | I8: =IF(ISBLANK(INDEX(Results_Long!$U$2:$U$37,MATCH("G2|no_nobs_proxyfill|estimation|intrcpt",Results_Long!$AK$2:$AK$37,0))),"—",INDEX(Results_Long!$U$2:$U$37,MATCH("G2|no_nobs_proxyfill|estimation|intrcpt",Results_Long!$AK$2:$AK$37,0))) -> -0.047534942 | J8: =IF(ISBLANK(INDEX(Results_Long!$V$2:$V$37,MATCH("G2|no_nobs_proxyfill|estimation|intrcpt",Results_Long!$AK$2:$AK$37,0))),"—",INDEX(Results_Long!$V$2:$V$37,MATCH("G2|no_nobs_proxyfill|estimation|intrcpt",Results_Long!$AK$2:$AK$37,0))) -> -0.028756516 | K8: =IF(ISBLANK(INDEX(Results_Long!$N$2:$N$37,MATCH("G2|no_nobs_proxyfill|estimation|intrcpt",Results_Long!$AK$2:$AK$37,0))),"—",INDEX(Results_Long!$N$2:$N$37,MATCH("G2|no_nobs_proxyfill|estimation|intrcpt",Results_Long!$AK$2:$AK$37,0))) -> 95.869275 | L8: =IF(ISBLANK(INDEX(Results_Long!$O$2:$O$37,MATCH("G2|no_nobs_proxyfill|estimation|intrcpt",Results_Long!$AK$2:$AK$37,0))),"—",INDEX(Results_Long!$O$2:$O$37,MATCH("G2|no_nobs_proxyfill|estimation|intrcpt",Results_Long!$AK$2:$AK$37,0))) -> 2.1661548e-12 | M8: =E8-$E$6 -> 0.020479116 | N8: =IF(SIGN(E8)=SIGN($E$6),"yes","no") -> yes | O8: =IF(F8*G8>0,"yes","no") -> yes | P8: =IF(ABS(H8)<=0.07,"yes","no") -> yes
A9: G3 n_firms_variance | B9: =IF(ISBLANK(INDEX(Results_Long!$H$2:$H$37,MATCH("G3|n_firms_variance|estimation|intrcpt",Results_Long!$AK$2:$AK$37,0))),"—",INDEX(Results_Long!$H$2:$H$37,MATCH("G3|n_firms_variance|estimation|intrcpt",Results_Long!$AK$2:$AK$37,0))) -> 2713 | C9: =IF(ISBLANK(INDEX(Results_Long!$I$2:$I$37,MATCH("G3|n_firms_variance|estimation|intrcpt",Results_Long!$AK$2:$AK$37,0))),"—",INDEX(Results_Long!$I$2:$I$37,MATCH("G3|n_firms_variance|estimation|intrcpt",Results_Long!$AK$2:$AK$37,0))) -> 115 | D9: =IF(ISBLANK(INDEX(Results_Long!$J$2:$J$37,MATCH("G3|n_firms_variance|estimation|intrcpt",Results_Long!$AK$2:$AK$37,0))),"—",INDEX(Results_Long!$J$2:$J$37,MATCH("G3|n_firms_variance|estimation|intrcpt",Results_Long!$AK$2:$AK$37,0))) -> 114 | E9: =IF(ISBLANK(INDEX(Results_Long!$K$2:$K$37,MATCH("G3|n_firms_variance|estimation|intrcpt",Results_Long!$AK$2:$AK$37,0))),"—",INDEX(Results_Long!$K$2:$K$37,MATCH("G3|n_firms_variance|estimation|intrcpt",Results_Long!$AK$2:$AK$37,0))) -> -0.051361904 | F9: =IF(ISBLANK(INDEX(Results_Long!$P$2:$P$37,MATCH("G3|n_firms_variance|estimation|intrcpt",Results_Long!$AK$2:$AK$37,0))),"—",INDEX(Results_Long!$P$2:$P$37,MATCH("G3|n_firms_variance|estimation|intrcpt",Results_Long!$AK$2:$AK$37,0))) -> -0.071101693 | G9: =IF(ISBLANK(INDEX(Results_Long!$Q$2:$Q$37,MATCH("G3|n_firms_variance|estimation|intrcpt",Results_Long!$AK$2:$AK$37,0))),"—",INDEX(Results_Long!$Q$2:$Q$37,MATCH("G3|n_firms_variance|estimation|intrcpt",Results_Long!$AK$2:$AK$37,0))) -> -0.031622116 | H9: =IF(ISBLANK(INDEX(Results_Long!$T$2:$T$37,MATCH("G3|n_firms_variance|estimation|intrcpt",Results_Long!$AK$2:$AK$37,0))),"—",INDEX(Results_Long!$T$2:$T$37,MATCH("G3|n_firms_variance|estimation|intrcpt",Results_Long!$AK$2:$AK$37,0))) -> -0.051316787 | I9: =IF(ISBLANK(INDEX(Results_Long!$U$2:$U$37,MATCH("G3|n_firms_variance|estimation|intrcpt",Results_Long!$AK$2:$AK$37,0))),"—",INDEX(Results_Long!$U$2:$U$37,MATCH("G3|n_firms_variance|estimation|intrcpt",Results_Long!$AK$2:$AK$37,0))) -> -0.070982118 | J9: =IF(ISBLANK(INDEX(Results_Long!$V$2:$V$37,MATCH("G3|n_firms_variance|estimation|intrcpt",Results_Long!$AK$2:$AK$37,0))),"—",INDEX(Results_Long!$V$2:$V$37,MATCH("G3|n_firms_variance|estimation|intrcpt",Results_Long!$AK$2:$AK$37,0))) -> -0.03161158 | K9: =IF(ISBLANK(INDEX(Results_Long!$N$2:$N$37,MATCH("G3|n_firms_variance|estimation|intrcpt",Results_Long!$AK$2:$AK$37,0))),"—",INDEX(Results_Long!$N$2:$N$37,MATCH("G3|n_firms_variance|estimation|intrcpt",Results_Long!$AK$2:$AK$37,0))) -> 109.89661 | L9: =IF(ISBLANK(INDEX(Results_Long!$O$2:$O$37,MATCH("G3|n_firms_variance|estimation|intrcpt",Results_Long!$AK$2:$AK$37,0))),"—",INDEX(Results_Long!$O$2:$O$37,MATCH("G3|n_firms_variance|estimation|intrcpt",Results_Long!$AK$2:$AK$37,0))) -> 1.1219714e-06 | M9: =E9-$E$6 -> 0.0072848324 | N9: =IF(SIGN(E9)=SIGN($E$6),"yes","no") -> yes | O9: =IF(F9*G9>0,"yes","no") -> yes | P9: =IF(ABS(H9)<=0.07,"yes","no") -> yes
A10: G4 direct_r_only | B10: =IF(ISBLANK(INDEX(Results_Long!$H$2:$H$37,MATCH("G4|direct_r_only|estimation|intrcpt",Results_Long!$AK$2:$AK$37,0))),"—",INDEX(Results_Long!$H$2:$H$37,MATCH("G4|direct_r_only|estimation|intrcpt",Results_Long!$AK$2:$AK$37,0))) -> 104 | C10: =IF(ISBLANK(INDEX(Results_Long!$I$2:$I$37,MATCH("G4|direct_r_only|estimation|intrcpt",Results_Long!$AK$2:$AK$37,0))),"—",INDEX(Results_Long!$I$2:$I$37,MATCH("G4|direct_r_only|estimation|intrcpt",Results_Long!$AK$2:$AK$37,0))) -> 52 | D10: =IF(ISBLANK(INDEX(Results_Long!$J$2:$J$37,MATCH("G4|direct_r_only|estimation|intrcpt",Results_Long!$AK$2:$AK$37,0))),"—",INDEX(Results_Long!$J$2:$J$37,MATCH("G4|direct_r_only|estimation|intrcpt",Results_Long!$AK$2:$AK$37,0))) -> 52 | E10: =IF(ISBLANK(INDEX(Results_Long!$K$2:$K$37,MATCH("G4|direct_r_only|estimation|intrcpt",Results_Long!$AK$2:$AK$37,0))),"—",INDEX(Results_Long!$K$2:$K$37,MATCH("G4|direct_r_only|estimation|intrcpt",Results_Long!$AK$2:$AK$37,0))) -> -0.037776735 | F10: =IF(ISBLANK(INDEX(Results_Long!$P$2:$P$37,MATCH("G4|direct_r_only|estimation|intrcpt",Results_Long!$AK$2:$AK$37,0))),"—",INDEX(Results_Long!$P$2:$P$37,MATCH("G4|direct_r_only|estimation|intrcpt",Results_Long!$AK$2:$AK$37,0))) -> -0.086196589 | G10: =IF(ISBLANK(INDEX(Results_Long!$Q$2:$Q$37,MATCH("G4|direct_r_only|estimation|intrcpt",Results_Long!$AK$2:$AK$37,0))),"—",INDEX(Results_Long!$Q$2:$Q$37,MATCH("G4|direct_r_only|estimation|intrcpt",Results_Long!$AK$2:$AK$37,0))) -> 0.010643118 | H10: =IF(ISBLANK(INDEX(Results_Long!$T$2:$T$37,MATCH("G4|direct_r_only|estimation|intrcpt",Results_Long!$AK$2:$AK$37,0))),"—",INDEX(Results_Long!$T$2:$T$37,MATCH("G4|direct_r_only|estimation|intrcpt",Results_Long!$AK$2:$AK$37,0))) -> -0.037758776 | I10: =IF(ISBLANK(INDEX(Results_Long!$U$2:$U$37,MATCH("G4|direct_r_only|estimation|intrcpt",Results_Long!$AK$2:$AK$37,0))),"—",INDEX(Results_Long!$U$2:$U$37,MATCH("G4|direct_r_only|estimation|intrcpt",Results_Long!$AK$2:$AK$37,0))) -> -0.085983746 | J10: =IF(ISBLANK(INDEX(Results_Long!$V$2:$V$37,MATCH("G4|direct_r_only|estimation|intrcpt",Results_Long!$AK$2:$AK$37,0))),"—",INDEX(Results_Long!$V$2:$V$37,MATCH("G4|direct_r_only|estimation|intrcpt",Results_Long!$AK$2:$AK$37,0))) -> 0.010642716 | K10: =IF(ISBLANK(INDEX(Results_Long!$N$2:$N$37,MATCH("G4|direct_r_only|estimation|intrcpt",Results_Long!$AK$2:$AK$37,0))),"—",INDEX(Results_Long!$N$2:$N$37,MATCH("G4|direct_r_only|estimation|intrcpt",Results_Long!$AK$2:$AK$37,0))) -> 49.503425 | L10: =IF(ISBLANK(INDEX(Results_Long!$O$2:$O$37,MATCH("G4|direct_r_only|estimation|intrcpt",Results_Long!$AK$2:$AK$37,0))),"—",INDEX(Results_Long!$O$2:$O$37,MATCH("G4|direct_r_only|estimation|intrcpt",Results_Long!$AK$2:$AK$37,0))) -> 0.1233804 | M10: =E10-$E$6 -> 0.020870001 | N10: =IF(SIGN(E10)=SIGN($E$6),"yes","no") -> yes | O10: =IF(F10*G10>0,"yes","no") -> no | P10: =IF(ABS(H10)<=0.07,"yes","no") -> yes
A11: G5 pcc_df_k10 | B11: =IF(ISBLANK(INDEX(Results_Long!$H$2:$H$37,MATCH("G5|pcc_df_k10|estimation|intrcpt",Results_Long!$AK$2:$AK$37,0))),"—",INDEX(Results_Long!$H$2:$H$37,MATCH("G5|pcc_df_k10|estimation|intrcpt",Results_Long!$AK$2:$AK$37,0))) -> 2713 | C11: =IF(ISBLANK(INDEX(Results_Long!$I$2:$I$37,MATCH("G5|pcc_df_k10|estimation|intrcpt",Results_Long!$AK$2:$AK$37,0))),"—",INDEX(Results_Long!$I$2:$I$37,MATCH("G5|pcc_df_k10|estimation|intrcpt",Results_Long!$AK$2:$AK$37,0))) -> 115 | D11: =IF(ISBLANK(INDEX(Results_Long!$J$2:$J$37,MATCH("G5|pcc_df_k10|estimation|intrcpt",Results_Long!$AK$2:$AK$37,0))),"—",INDEX(Results_Long!$J$2:$J$37,MATCH("G5|pcc_df_k10|estimation|intrcpt",Results_Long!$AK$2:$AK$37,0))) -> 114 | E11: =IF(ISBLANK(INDEX(Results_Long!$K$2:$K$37,MATCH("G5|pcc_df_k10|estimation|intrcpt",Results_Long!$AK$2:$AK$37,0))),"—",INDEX(Results_Long!$K$2:$K$37,MATCH("G5|pcc_df_k10|estimation|intrcpt",Results_Long!$AK$2:$AK$37,0))) -> -0.058528013 | F11: =IF(ISBLANK(INDEX(Results_Long!$P$2:$P$37,MATCH("G5|pcc_df_k10|estimation|intrcpt",Results_Long!$AK$2:$AK$37,0))),"—",INDEX(Results_Long!$P$2:$P$37,MATCH("G5|pcc_df_k10|estimation|intrcpt",Results_Long!$AK$2:$AK$37,0))) -> -0.086054509 | G11: =IF(ISBLANK(INDEX(Results_Long!$Q$2:$Q$37,MATCH("G5|pcc_df_k10|estimation|intrcpt",Results_Long!$AK$2:$AK$37,0))),"—",INDEX(Results_Long!$Q$2:$Q$37,MATCH("G5|pcc_df_k10|estimation|intrcpt",Results_Long!$AK$2:$AK$37,0))) -> -0.031001516 | H11: =IF(ISBLANK(INDEX(Results_Long!$T$2:$T$37,MATCH("G5|pcc_df_k10|estimation|intrcpt",Results_Long!$AK$2:$AK$37,0))),"—",INDEX(Results_Long!$T$2:$T$37,MATCH("G5|pcc_df_k10|estimation|intrcpt",Results_Long!$AK$2:$AK$37,0))) -> -0.058461274 | I11: =IF(ISBLANK(INDEX(Results_Long!$U$2:$U$37,MATCH("G5|pcc_df_k10|estimation|intrcpt",Results_Long!$AK$2:$AK$37,0))),"—",INDEX(Results_Long!$U$2:$U$37,MATCH("G5|pcc_df_k10|estimation|intrcpt",Results_Long!$AK$2:$AK$37,0))) -> -0.085842715 | J11: =IF(ISBLANK(INDEX(Results_Long!$V$2:$V$37,MATCH("G5|pcc_df_k10|estimation|intrcpt",Results_Long!$AK$2:$AK$37,0))),"—",INDEX(Results_Long!$V$2:$V$37,MATCH("G5|pcc_df_k10|estimation|intrcpt",Results_Long!$AK$2:$AK$37,0))) -> -0.030991588 | K11: =IF(ISBLANK(INDEX(Results_Long!$N$2:$N$37,MATCH("G5|pcc_df_k10|estimation|intrcpt",Results_Long!$AK$2:$AK$37,0))),"—",INDEX(Results_Long!$N$2:$N$37,MATCH("G5|pcc_df_k10|estimation|intrcpt",Results_Long!$AK$2:$AK$37,0))) -> 111.63275 | L11: =IF(ISBLANK(INDEX(Results_Long!$O$2:$O$37,MATCH("G5|pcc_df_k10|estimation|intrcpt",Results_Long!$AK$2:$AK$37,0))),"—",INDEX(Results_Long!$O$2:$O$37,MATCH("G5|pcc_df_k10|estimation|intrcpt",Results_Long!$AK$2:$AK$37,0))) -> 5.1297295e-05 | M11: =E11-$E$6 -> 0.00011872392 | N11: =IF(SIGN(E11)=SIGN($E$6),"yes","no") -> yes | O11: =IF(F11*G11>0,"yes","no") -> yes | P11: =IF(ABS(H11)<=0.07,"yes","no") -> yes
A12: G5 pcc_df_k20 | B12: =IF(ISBLANK(INDEX(Results_Long!$H$2:$H$37,MATCH("G5|pcc_df_k20|estimation|intrcpt",Results_Long!$AK$2:$AK$37,0))),"—",INDEX(Results_Long!$H$2:$H$37,MATCH("G5|pcc_df_k20|estimation|intrcpt",Results_Long!$AK$2:$AK$37,0))) -> 2712 | C12: =IF(ISBLANK(INDEX(Results_Long!$I$2:$I$37,MATCH("G5|pcc_df_k20|estimation|intrcpt",Results_Long!$AK$2:$AK$37,0))),"—",INDEX(Results_Long!$I$2:$I$37,MATCH("G5|pcc_df_k20|estimation|intrcpt",Results_Long!$AK$2:$AK$37,0))) -> 115 | D12: =IF(ISBLANK(INDEX(Results_Long!$J$2:$J$37,MATCH("G5|pcc_df_k20|estimation|intrcpt",Results_Long!$AK$2:$AK$37,0))),"—",INDEX(Results_Long!$J$2:$J$37,MATCH("G5|pcc_df_k20|estimation|intrcpt",Results_Long!$AK$2:$AK$37,0))) -> 114 | E12: =IF(ISBLANK(INDEX(Results_Long!$K$2:$K$37,MATCH("G5|pcc_df_k20|estimation|intrcpt",Results_Long!$AK$2:$AK$37,0))),"—",INDEX(Results_Long!$K$2:$K$37,MATCH("G5|pcc_df_k20|estimation|intrcpt",Results_Long!$AK$2:$AK$37,0))) -> -0.058005717 | F12: =IF(ISBLANK(INDEX(Results_Long!$P$2:$P$37,MATCH("G5|pcc_df_k20|estimation|intrcpt",Results_Long!$AK$2:$AK$37,0))),"—",INDEX(Results_Long!$P$2:$P$37,MATCH("G5|pcc_df_k20|estimation|intrcpt",Results_Long!$AK$2:$AK$37,0))) -> -0.085619616 | G12: =IF(ISBLANK(INDEX(Results_Long!$Q$2:$Q$37,MATCH("G5|pcc_df_k20|estimation|intrcpt",Results_Long!$AK$2:$AK$37,0))),"—",INDEX(Results_Long!$Q$2:$Q$37,MATCH("G5|pcc_df_k20|estimation|intrcpt",Results_Long!$AK$2:$AK$37,0))) -> -0.030391819 | H12: =IF(ISBLANK(INDEX(Results_Long!$T$2:$T$37,MATCH("G5|pcc_df_k20|estimation|intrcpt",Results_Long!$AK$2:$AK$37,0))),"—",INDEX(Results_Long!$T$2:$T$37,MATCH("G5|pcc_df_k20|estimation|intrcpt",Results_Long!$AK$2:$AK$37,0))) -> -0.057940748 | I12: =IF(ISBLANK(INDEX(Results_Long!$U$2:$U$37,MATCH("G5|pcc_df_k20|estimation|intrcpt",Results_Long!$AK$2:$AK$37,0))),"—",INDEX(Results_Long!$U$2:$U$37,MATCH("G5|pcc_df_k20|estimation|intrcpt",Results_Long!$AK$2:$AK$37,0))) -> -0.08541101 | J12: =IF(ISBLANK(INDEX(Results_Long!$V$2:$V$37,MATCH("G5|pcc_df_k20|estimation|intrcpt",Results_Long!$AK$2:$AK$37,0))),"—",INDEX(Results_Long!$V$2:$V$37,MATCH("G5|pcc_df_k20|estimation|intrcpt",Results_Long!$AK$2:$AK$37,0))) -> -0.030382465 | K12: =IF(ISBLANK(INDEX(Results_Long!$N$2:$N$37,MATCH("G5|pcc_df_k20|estimation|intrcpt",Results_Long!$AK$2:$AK$37,0))),"—",INDEX(Results_Long!$N$2:$N$37,MATCH("G5|pcc_df_k20|estimation|intrcpt",Results_Long!$AK$2:$AK$37,0))) -> 111.57395 | L12: =IF(ISBLANK(INDEX(Results_Long!$O$2:$O$37,MATCH("G5|pcc_df_k20|estimation|intrcpt",Results_Long!$AK$2:$AK$37,0))),"—",INDEX(Results_Long!$O$2:$O$37,MATCH("G5|pcc_df_k20|estimation|intrcpt",Results_Long!$AK$2:$AK$37,0))) -> 6.2250522e-05 | M12: =E12-$E$6 -> 0.0006410192 | N12: =IF(SIGN(E12)=SIGN($E$6),"yes","no") -> yes | O12: =IF(F12*G12>0,"yes","no") -> yes | P12: =IF(ABS(H12)<=0.07,"yes","no") -> yes
A13: G6 one_per_cluster_median | B13: =IF(ISBLANK(INDEX(Results_Long!$H$2:$H$37,MATCH("G6|one_per_cluster_median|aggregate|intrcpt",Results_Long!$AK$2:$AK$37,0))),"—",INDEX(Results_Long!$H$2:$H$37,MATCH("G6|one_per_cluster_median|aggregate|intrcpt",Results_Long!$AK$2:$AK$37,0))) -> — | C13: =IF(ISBLANK(INDEX(Results_Long!$I$2:$I$37,MATCH("G6|one_per_cluster_median|aggregate|intrcpt",Results_Long!$AK$2:$AK$37,0))),"—",INDEX(Results_Long!$I$2:$I$37,MATCH("G6|one_per_cluster_median|aggregate|intrcpt",Results_Long!$AK$2:$AK$37,0))) -> — | D13: =IF(ISBLANK(INDEX(Results_Long!$J$2:$J$37,MATCH("G6|one_per_cluster_median|aggregate|intrcpt",Results_Long!$AK$2:$AK$37,0))),"—",INDEX(Results_Long!$J$2:$J$37,MATCH("G6|one_per_cluster_median|aggregate|intrcpt",Results_Long!$AK$2:$AK$37,0))) -> — | E13: =IF(ISBLANK(INDEX(Results_Long!$K$2:$K$37,MATCH("G6|one_per_cluster_median|aggregate|intrcpt",Results_Long!$AK$2:$AK$37,0))),"—",INDEX(Results_Long!$K$2:$K$37,MATCH("G6|one_per_cluster_median|aggregate|intrcpt",Results_Long!$AK$2:$AK$37,0))) -> -0.061991376 | F13: =IF(ISBLANK(INDEX(Results_Long!$P$2:$P$37,MATCH("G6|one_per_cluster_median|aggregate|intrcpt",Results_Long!$AK$2:$AK$37,0))),"—",INDEX(Results_Long!$P$2:$P$37,MATCH("G6|one_per_cluster_median|aggregate|intrcpt",Results_Long!$AK$2:$AK$37,0))) -> -0.093843293 | G13: =IF(ISBLANK(INDEX(Results_Long!$Q$2:$Q$37,MATCH("G6|one_per_cluster_median|aggregate|intrcpt",Results_Long!$AK$2:$AK$37,0))),"—",INDEX(Results_Long!$Q$2:$Q$37,MATCH("G6|one_per_cluster_median|aggregate|intrcpt",Results_Long!$AK$2:$AK$37,0))) -> -0.030139459 | H13: =IF(ISBLANK(INDEX(Results_Long!$T$2:$T$37,MATCH("G6|one_per_cluster_median|aggregate|intrcpt",Results_Long!$AK$2:$AK$37,0))),"—",INDEX(Results_Long!$T$2:$T$37,MATCH("G6|one_per_cluster_median|aggregate|intrcpt",Results_Long!$AK$2:$AK$37,0))) -> -0.061912089 | I13: =IF(ISBLANK(INDEX(Results_Long!$U$2:$U$37,MATCH("G6|one_per_cluster_median|aggregate|intrcpt",Results_Long!$AK$2:$AK$37,0))),"—",INDEX(Results_Long!$U$2:$U$37,MATCH("G6|one_per_cluster_median|aggregate|intrcpt",Results_Long!$AK$2:$AK$37,0))) -> -0.093568781 | J13: =IF(ISBLANK(INDEX(Results_Long!$V$2:$V$37,MATCH("G6|one_per_cluster_median|aggregate|intrcpt",Results_Long!$AK$2:$AK$37,0))),"—",INDEX(Results_Long!$V$2:$V$37,MATCH("G6|one_per_cluster_median|aggregate|intrcpt",Results_Long!$AK$2:$AK$37,0))) -> -0.030130337 | K13: =IF(ISBLANK(INDEX(Results_Long!$N$2:$N$37,MATCH("G6|one_per_cluster_median|aggregate|intrcpt",Results_Long!$AK$2:$AK$37,0))),"—",INDEX(Results_Long!$N$2:$N$37,MATCH("G6|one_per_cluster_median|aggregate|intrcpt",Results_Long!$AK$2:$AK$37,0))) -> 113 | L13: =IF(ISBLANK(INDEX(Results_Long!$O$2:$O$37,MATCH("G6|one_per_cluster_median|aggregate|intrcpt",Results_Long!$AK$2:$AK$37,0))),"—",INDEX(Results_Long!$O$2:$O$37,MATCH("G6|one_per_cluster_median|aggregate|intrcpt",Results_Long!$AK$2:$AK$37,0))) -> 0.00019212486 | M13: =E13-$E$6 -> -0.0033446397 | N13: =IF(SIGN(E13)=SIGN($E$6),"yes","no") -> yes | O13: =IF(F13*G13>0,"yes","no") -> yes | P13: =IF(ABS(H13)<=0.07,"yes","no") -> yes
A15: Interpretation
A16: Five variants reproduce the headline within .008 on the r scale (G1, G3, G5-k10, G5-k20, G6); the assumption-free cluster-median aggregate (−.062) brackets the rho-based headline from below.
A17: Two variants attenuate: G2 (−.038, the narrowest CI of the panel) and G4 (−.038 on 52 studies, CI covering zero); both retain the negative sign and sit inside the SESOI band.
A18: G4 is near-identical to the G9 bivariate cell (Δ = 2 ES / 1 study) — cross-referenced, not an independent check [DEC-050 §6].
A20: Reviewer Q&A — Finance/Econometrics
A21: Question | B21: Answer
A22: Why is there no significance test of each variant against the headline? | B22: Nested-subset differences carry no valid SE [DEC-031a.6]; joint specification inference is single-homed in the N5 multiverse permutation. The Δ column is a descriptive location shift.
A23: What explains the G2 shift? | B23: Mechanically, removing the flagged proxy-filled sample-size rows — drop 296 rows; 297 on the usable basis incl. 134 FLAG-based; one tagged duplicate exits at the estimation filter [DEC-050a] — moves the pooled estimate to −.038 and narrows the CI. The proxy convention itself is pre-registered [R-19]; this drop-spec is its pre-registered stress test.
A25: Reviewer Q&A — Management/BSE
A26: Question | B26: Answer
A27: Does any variant overturn the headline reading? | B27: No: 7/7 negative signs, 7/7 inside the SESOI band, 6/7 CIs excluding zero; the single zero-covering CI (G4) belongs to the 52-study direct-correlation subset and is disclosed [TB-66].
A29: Mechanical outcome: all seven variants retain the negative sign inside |r| ≤ .070; range r = −.038 to −.062; two disclosed attenuations (G2, G4); wording per the resolved gate [DEC-047].

Sheet 7_Panel_qVHB
A1: G7 — Journal-quality panel (q_VHB): 1_VHB high · 0_VHB low · 99_NCE
A2: 99_NCE cell retained per D31.4; publication-status inference single-homed in D5 (cross-reference only)
A3: All cells formula-linked to Results_Long; HTZ + pairwise z-only, descriptive [DEC-047]
A5: Level | B5: k_es | C5: k_cluster | D5: est_z | E5: CI_z low | F5: CI_z high | G5: est_r | H5: CI_r low | I5: CI_r high | J5: df | K5: p
A6: 1_VHB high | B6: =IF(ISBLANK(INDEX(Results_Long!$H$2:$H$37,MATCH("G7|panel_q_vhb|1_VHB high|cell_mean",Results_Long!$AK$2:$AK$37,0))),"—",INDEX(Results_Long!$H$2:$H$37,MATCH("G7|panel_q_vhb|1_VHB high|cell_mean",Results_Long!$AK$2:$AK$37,0))) -> 1591 | C6: =IF(ISBLANK(INDEX(Results_Long!$J$2:$J$37,MATCH("G7|panel_q_vhb|1_VHB high|cell_mean",Results_Long!$AK$2:$AK$37,0))),"—",INDEX(Results_Long!$J$2:$J$37,MATCH("G7|panel_q_vhb|1_VHB high|cell_mean",Results_Long!$AK$2:$AK$37,0))) -> 73 | D6: =IF(ISBLANK(INDEX(Results_Long!$K$2:$K$37,MATCH("G7|panel_q_vhb|1_VHB high|cell_mean",Results_Long!$AK$2:$AK$37,0))),"—",INDEX(Results_Long!$K$2:$K$37,MATCH("G7|panel_q_vhb|1_VHB high|cell_mean",Results_Long!$AK$2:$AK$37,0))) -> -0.060016051 | E6: =IF(ISBLANK(INDEX(Results_Long!$P$2:$P$37,MATCH("G7|panel_q_vhb|1_VHB high|cell_mean",Results_Long!$AK$2:$AK$37,0))),"—",INDEX(Results_Long!$P$2:$P$37,MATCH("G7|panel_q_vhb|1_VHB high|cell_mean",Results_Long!$AK$2:$AK$37,0))) -> -0.10072745 | F6: =IF(ISBLANK(INDEX(Results_Long!$Q$2:$Q$37,MATCH("G7|panel_q_vhb|1_VHB high|cell_mean",Results_Long!$AK$2:$AK$37,0))),"—",INDEX(Results_Long!$Q$2:$Q$37,MATCH("G7|panel_q_vhb|1_VHB high|cell_mean",Results_Long!$AK$2:$AK$37,0))) -> -0.019304652 | G6: =IF(ISBLANK(INDEX(Results_Long!$T$2:$T$37,MATCH("G7|panel_q_vhb|1_VHB high|cell_mean",Results_Long!$AK$2:$AK$37,0))),"—",INDEX(Results_Long!$T$2:$T$37,MATCH("G7|panel_q_vhb|1_VHB high|cell_mean",Results_Long!$AK$2:$AK$37,0))) -> -0.059944097 | H6: =IF(ISBLANK(INDEX(Results_Long!$U$2:$U$37,MATCH("G7|panel_q_vhb|1_VHB high|cell_mean",Results_Long!$AK$2:$AK$37,0))),"—",INDEX(Results_Long!$U$2:$U$37,MATCH("G7|panel_q_vhb|1_VHB high|cell_mean",Results_Long!$AK$2:$AK$37,0))) -> -0.10038817 | I6: =IF(ISBLANK(INDEX(Results_Long!$V$2:$V$37,MATCH("G7|panel_q_vhb|1_VHB high|cell_mean",Results_Long!$AK$2:$AK$37,0))),"—",INDEX(Results_Long!$V$2:$V$37,MATCH("G7|panel_q_vhb|1_VHB high|cell_mean",Results_Long!$AK$2:$AK$37,0))) -> -0.019302254 | J6: =IF(ISBLANK(INDEX(Results_Long!$N$2:$N$37,MATCH("G7|panel_q_vhb|1_VHB high|cell_mean",Results_Long!$AK$2:$AK$37,0))),"—",INDEX(Results_Long!$N$2:$N$37,MATCH("G7|panel_q_vhb|1_VHB high|cell_mean",Results_Long!$AK$2:$AK$37,0))) -> 71.558782 | K6: =IF(ISBLANK(INDEX(Results_Long!$O$2:$O$37,MATCH("G7|panel_q_vhb|1_VHB high|cell_mean",Results_Long!$AK$2:$AK$37,0))),"—",INDEX(Results_Long!$O$2:$O$37,MATCH("G7|panel_q_vhb|1_VHB high|cell_mean",Results_Long!$AK$2:$AK$37,0))) -> 0.0044293243
A7: 0_VHB low | B7: =IF(ISBLANK(INDEX(Results_Long!$H$2:$H$37,MATCH("G7|panel_q_vhb|0_VHB low|cell_mean",Results_Long!$AK$2:$AK$37,0))),"—",INDEX(Results_Long!$H$2:$H$37,MATCH("G7|panel_q_vhb|0_VHB low|cell_mean",Results_Long!$AK$2:$AK$37,0))) -> 442 | C7: =IF(ISBLANK(INDEX(Results_Long!$J$2:$J$37,MATCH("G7|panel_q_vhb|0_VHB low|cell_mean",Results_Long!$AK$2:$AK$37,0))),"—",INDEX(Results_Long!$J$2:$J$37,MATCH("G7|panel_q_vhb|0_VHB low|cell_mean",Results_Long!$AK$2:$AK$37,0))) -> 27 | D7: =IF(ISBLANK(INDEX(Results_Long!$K$2:$K$37,MATCH("G7|panel_q_vhb|0_VHB low|cell_mean",Results_Long!$AK$2:$AK$37,0))),"—",INDEX(Results_Long!$K$2:$K$37,MATCH("G7|panel_q_vhb|0_VHB low|cell_mean",Results_Long!$AK$2:$AK$37,0))) -> -0.056196632 | E7: =IF(ISBLANK(INDEX(Results_Long!$P$2:$P$37,MATCH("G7|panel_q_vhb|0_VHB low|cell_mean",Results_Long!$AK$2:$AK$37,0))),"—",INDEX(Results_Long!$P$2:$P$37,MATCH("G7|panel_q_vhb|0_VHB low|cell_mean",Results_Long!$AK$2:$AK$37,0))) -> -0.087321169 | F7: =IF(ISBLANK(INDEX(Results_Long!$Q$2:$Q$37,MATCH("G7|panel_q_vhb|0_VHB low|cell_mean",Results_Long!$AK$2:$AK$37,0))),"—",INDEX(Results_Long!$Q$2:$Q$37,MATCH("G7|panel_q_vhb|0_VHB low|cell_mean",Results_Long!$AK$2:$AK$37,0))) -> -0.025072096 | G7: =IF(ISBLANK(INDEX(Results_Long!$T$2:$T$37,MATCH("G7|panel_q_vhb|0_VHB low|cell_mean",Results_Long!$AK$2:$AK$37,0))),"—",INDEX(Results_Long!$T$2:$T$37,MATCH("G7|panel_q_vhb|0_VHB low|cell_mean",Results_Long!$AK$2:$AK$37,0))) -> -0.056137549 | H7: =IF(ISBLANK(INDEX(Results_Long!$U$2:$U$37,MATCH("G7|panel_q_vhb|0_VHB low|cell_mean",Results_Long!$AK$2:$AK$37,0))),"—",INDEX(Results_Long!$U$2:$U$37,MATCH("G7|panel_q_vhb|0_VHB low|cell_mean",Results_Long!$AK$2:$AK$37,0))) -> -0.087099903 | I7: =IF(ISBLANK(INDEX(Results_Long!$V$2:$V$37,MATCH("G7|panel_q_vhb|0_VHB low|cell_mean",Results_Long!$AK$2:$AK$37,0))),"—",INDEX(Results_Long!$V$2:$V$37,MATCH("G7|panel_q_vhb|0_VHB low|cell_mean",Results_Long!$AK$2:$AK$37,0))) -> -0.025066844 | J7: =IF(ISBLANK(INDEX(Results_Long!$N$2:$N$37,MATCH("G7|panel_q_vhb|0_VHB low|cell_mean",Results_Long!$AK$2:$AK$37,0))),"—",INDEX(Results_Long!$N$2:$N$37,MATCH("G7|panel_q_vhb|0_VHB low|cell_mean",Results_Long!$AK$2:$AK$37,0))) -> 25.312748 | K7: =IF(ISBLANK(INDEX(Results_Long!$O$2:$O$37,MATCH("G7|panel_q_vhb|0_VHB low|cell_mean",Results_Long!$AK$2:$AK$37,0))),"—",INDEX(Results_Long!$O$2:$O$37,MATCH("G7|panel_q_vhb|0_VHB low|cell_mean",Results_Long!$AK$2:$AK$37,0))) -> 0.0010074756
A8: 99_NCE | B8: =IF(ISBLANK(INDEX(Results_Long!$H$2:$H$37,MATCH("G7|panel_q_vhb|99_NCE|cell_mean",Results_Long!$AK$2:$AK$37,0))),"—",INDEX(Results_Long!$H$2:$H$37,MATCH("G7|panel_q_vhb|99_NCE|cell_mean",Results_Long!$AK$2:$AK$37,0))) -> 680 | C8: =IF(ISBLANK(INDEX(Results_Long!$J$2:$J$37,MATCH("G7|panel_q_vhb|99_NCE|cell_mean",Results_Long!$AK$2:$AK$37,0))),"—",INDEX(Results_Long!$J$2:$J$37,MATCH("G7|panel_q_vhb|99_NCE|cell_mean",Results_Long!$AK$2:$AK$37,0))) -> 14 | D8: =IF(ISBLANK(INDEX(Results_Long!$K$2:$K$37,MATCH("G7|panel_q_vhb|99_NCE|cell_mean",Results_Long!$AK$2:$AK$37,0))),"—",INDEX(Results_Long!$K$2:$K$37,MATCH("G7|panel_q_vhb|99_NCE|cell_mean",Results_Long!$AK$2:$AK$37,0))) -> -0.056558164 | E8: =IF(ISBLANK(INDEX(Results_Long!$P$2:$P$37,MATCH("G7|panel_q_vhb|99_NCE|cell_mean",Results_Long!$AK$2:$AK$37,0))),"—",INDEX(Results_Long!$P$2:$P$37,MATCH("G7|panel_q_vhb|99_NCE|cell_mean",Results_Long!$AK$2:$AK$37,0))) -> -0.10386193 | F8: =IF(ISBLANK(INDEX(Results_Long!$Q$2:$Q$37,MATCH("G7|panel_q_vhb|99_NCE|cell_mean",Results_Long!$AK$2:$AK$37,0))),"—",INDEX(Results_Long!$Q$2:$Q$37,MATCH("G7|panel_q_vhb|99_NCE|cell_mean",Results_Long!$AK$2:$AK$37,0))) -> -0.0092544007 | G8: =IF(ISBLANK(INDEX(Results_Long!$T$2:$T$37,MATCH("G7|panel_q_vhb|99_NCE|cell_mean",Results_Long!$AK$2:$AK$37,0))),"—",INDEX(Results_Long!$T$2:$T$37,MATCH("G7|panel_q_vhb|99_NCE|cell_mean",Results_Long!$AK$2:$AK$37,0))) -> -0.056497934 | H8: =IF(ISBLANK(INDEX(Results_Long!$U$2:$U$37,MATCH("G7|panel_q_vhb|99_NCE|cell_mean",Results_Long!$AK$2:$AK$37,0))),"—",INDEX(Results_Long!$U$2:$U$37,MATCH("G7|panel_q_vhb|99_NCE|cell_mean",Results_Long!$AK$2:$AK$37,0))) -> -0.10349007 | I8: =IF(ISBLANK(INDEX(Results_Long!$V$2:$V$37,MATCH("G7|panel_q_vhb|99_NCE|cell_mean",Results_Long!$AK$2:$AK$37,0))),"—",INDEX(Results_Long!$V$2:$V$37,MATCH("G7|panel_q_vhb|99_NCE|cell_mean",Results_Long!$AK$2:$AK$37,0))) -> -0.0092541365 | J8: =IF(ISBLANK(INDEX(Results_Long!$N$2:$N$37,MATCH("G7|panel_q_vhb|99_NCE|cell_mean",Results_Long!$AK$2:$AK$37,0))),"—",INDEX(Results_Long!$N$2:$N$37,MATCH("G7|panel_q_vhb|99_NCE|cell_mean",Results_Long!$AK$2:$AK$37,0))) -> 12.98801 | K8: =IF(ISBLANK(INDEX(Results_Long!$O$2:$O$37,MATCH("G7|panel_q_vhb|99_NCE|cell_mean",Results_Long!$AK$2:$AK$37,0))),"—",INDEX(Results_Long!$O$2:$O$37,MATCH("G7|panel_q_vhb|99_NCE|cell_mean",Results_Long!$AK$2:$AK$37,0))) -> 0.022729385
A10: Test (z-only) | B10: df | C10: p | D10: note (carries F and df_num verbatim)
A11: HTZ omnibus | B11: =IF(ISBLANK(INDEX(Results_Long!$N$2:$N$37,MATCH("G7|panel_q_vhb|panel|HTZ_omnibus",Results_Long!$AK$2:$AK$37,0))),"—",INDEX(Results_Long!$N$2:$N$37,MATCH("G7|panel_q_vhb|panel|HTZ_omnibus",Results_Long!$AK$2:$AK$37,0))) -> 34.747536 | C11: =IF(ISBLANK(INDEX(Results_Long!$O$2:$O$37,MATCH("G7|panel_q_vhb|panel|HTZ_omnibus",Results_Long!$AK$2:$AK$37,0))),"—",INDEX(Results_Long!$O$2:$O$37,MATCH("G7|panel_q_vhb|panel|HTZ_omnibus",Results_Long!$AK$2:$AK$37,0))) -> 0.98833018 | D11: =IF(ISBLANK(INDEX(Results_Long!$AJ$2:$AJ$37,MATCH("G7|panel_q_vhb|panel|HTZ_omnibus",Results_Long!$AK$2:$AK$37,0))),"—",INDEX(Results_Long!$AJ$2:$AJ$37,MATCH("G7|panel_q_vhb|panel|HTZ_omnibus",Results_Long!$AK$2:$AK$37,0))) -> F=0.0117, df_num=2.0; descriptive [DEC-047]
A13: Contrast (z-only) | B13: Δz | C13: CI_z low | D13: CI_z high | E13: df | F13: p | G13: flag
A14: 1_VHB high vs 0_VHB low | B14: =IF(ISBLANK(INDEX(Results_Long!$K$2:$K$37,MATCH("G7|panel_q_vhb|1_VHB high vs 0_VHB low|pairwise_contrast",Results_Long!$AK$2:$AK$37,0))),"—",INDEX(Results_Long!$K$2:$K$37,MATCH("G7|panel_q_vhb|1_VHB high vs 0_VHB low|pairwise_contrast",Results_Long!$AK$2:$AK$37,0))) -> -0.0038194187 | C14: =IF(ISBLANK(INDEX(Results_Long!$P$2:$P$37,MATCH("G7|panel_q_vhb|1_VHB high vs 0_VHB low|pairwise_contrast",Results_Long!$AK$2:$AK$37,0))),"—",INDEX(Results_Long!$P$2:$P$37,MATCH("G7|panel_q_vhb|1_VHB high vs 0_VHB low|pairwise_contrast",Results_Long!$AK$2:$AK$37,0))) -> — | D14: =IF(ISBLANK(INDEX(Results_Long!$Q$2:$Q$37,MATCH("G7|panel_q_vhb|1_VHB high vs 0_VHB low|pairwise_contrast",Results_Long!$AK$2:$AK$37,0))),"—",INDEX(Results_Long!$Q$2:$Q$37,MATCH("G7|panel_q_vhb|1_VHB high vs 0_VHB low|pairwise_contrast",Results_Long!$AK$2:$AK$37,0))) -> — | E14: =IF(ISBLANK(INDEX(Results_Long!$N$2:$N$37,MATCH("G7|panel_q_vhb|1_VHB high vs 0_VHB low|pairwise_contrast",Results_Long!$AK$2:$AK$37,0))),"—",INDEX(Results_Long!$N$2:$N$37,MATCH("G7|panel_q_vhb|1_VHB high vs 0_VHB low|pairwise_contrast",Results_Long!$AK$2:$AK$37,0))) -> 43.600743 | F14: =IF(ISBLANK(INDEX(Results_Long!$O$2:$O$37,MATCH("G7|panel_q_vhb|1_VHB high vs 0_VHB low|pairwise_contrast",Results_Long!$AK$2:$AK$37,0))),"—",INDEX(Results_Long!$O$2:$O$37,MATCH("G7|panel_q_vhb|1_VHB high vs 0_VHB low|pairwise_contrast",Results_Long!$AK$2:$AK$37,0))) -> 0.88121112 | G14: =IF(INDEX(Results_Long!$N$2:$N$37,MATCH("G7|panel_q_vhb|1_VHB high vs 0_VHB low|pairwise_contrast",Results_Long!$AK$2:$AK$37,0))<5,"df < 5 — descriptive","")
A15: 1_VHB high vs 99_NCE | B15: =IF(ISBLANK(INDEX(Results_Long!$K$2:$K$37,MATCH("G7|panel_q_vhb|1_VHB high vs 99_NCE|pairwise_contrast",Results_Long!$AK$2:$AK$37,0))),"—",INDEX(Results_Long!$K$2:$K$37,MATCH("G7|panel_q_vhb|1_VHB high vs 99_NCE|pairwise_contrast",Results_Long!$AK$2:$AK$37,0))) -> -0.0034578871 | C15: =IF(ISBLANK(INDEX(Results_Long!$P$2:$P$37,MATCH("G7|panel_q_vhb|1_VHB high vs 99_NCE|pairwise_contrast",Results_Long!$AK$2:$AK$37,0))),"—",INDEX(Results_Long!$P$2:$P$37,MATCH("G7|panel_q_vhb|1_VHB high vs 99_NCE|pairwise_contrast",Results_Long!$AK$2:$AK$37,0))) -> — | D15: =IF(ISBLANK(INDEX(Results_Long!$Q$2:$Q$37,MATCH("G7|panel_q_vhb|1_VHB high vs 99_NCE|pairwise_contrast",Results_Long!$AK$2:$AK$37,0))),"—",INDEX(Results_Long!$Q$2:$Q$37,MATCH("G7|panel_q_vhb|1_VHB high vs 99_NCE|pairwise_contrast",Results_Long!$AK$2:$AK$37,0))) -> — | E15: =IF(ISBLANK(INDEX(Results_Long!$N$2:$N$37,MATCH("G7|panel_q_vhb|1_VHB high vs 99_NCE|pairwise_contrast",Results_Long!$AK$2:$AK$37,0))),"—",INDEX(Results_Long!$N$2:$N$37,MATCH("G7|panel_q_vhb|1_VHB high vs 99_NCE|pairwise_contrast",Results_Long!$AK$2:$AK$37,0))) -> 18.613556 | F15: =IF(ISBLANK(INDEX(Results_Long!$O$2:$O$37,MATCH("G7|panel_q_vhb|1_VHB high vs 99_NCE|pairwise_contrast",Results_Long!$AK$2:$AK$37,0))),"—",INDEX(Results_Long!$O$2:$O$37,MATCH("G7|panel_q_vhb|1_VHB high vs 99_NCE|pairwise_contrast",Results_Long!$AK$2:$AK$37,0))) -> 0.90928732 | G15: =IF(INDEX(Results_Long!$N$2:$N$37,MATCH("G7|panel_q_vhb|1_VHB high vs 99_NCE|pairwise_contrast",Results_Long!$AK$2:$AK$37,0))<5,"df < 5 — descriptive","")
A16: 0_VHB low vs 99_NCE | B16: =IF(ISBLANK(INDEX(Results_Long!$K$2:$K$37,MATCH("G7|panel_q_vhb|0_VHB low vs 99_NCE|pairwise_contrast",Results_Long!$AK$2:$AK$37,0))),"—",INDEX(Results_Long!$K$2:$K$37,MATCH("G7|panel_q_vhb|0_VHB low vs 99_NCE|pairwise_contrast",Results_Long!$AK$2:$AK$37,0))) -> 0.00036153168 | C16: =IF(ISBLANK(INDEX(Results_Long!$P$2:$P$37,MATCH("G7|panel_q_vhb|0_VHB low vs 99_NCE|pairwise_contrast",Results_Long!$AK$2:$AK$37,0))),"—",INDEX(Results_Long!$P$2:$P$37,MATCH("G7|panel_q_vhb|0_VHB low vs 99_NCE|pairwise_contrast",Results_Long!$AK$2:$AK$37,0))) -> — | D16: =IF(ISBLANK(INDEX(Results_Long!$Q$2:$Q$37,MATCH("G7|panel_q_vhb|0_VHB low vs 99_NCE|pairwise_contrast",Results_Long!$AK$2:$AK$37,0))),"—",INDEX(Results_Long!$Q$2:$Q$37,MATCH("G7|panel_q_vhb|0_VHB low vs 99_NCE|pairwise_contrast",Results_Long!$AK$2:$AK$37,0))) -> — | E16: =IF(ISBLANK(INDEX(Results_Long!$N$2:$N$37,MATCH("G7|panel_q_vhb|0_VHB low vs 99_NCE|pairwise_contrast",Results_Long!$AK$2:$AK$37,0))),"—",INDEX(Results_Long!$N$2:$N$37,MATCH("G7|panel_q_vhb|0_VHB low vs 99_NCE|pairwise_contrast",Results_Long!$AK$2:$AK$37,0))) -> 27.959093 | F16: =IF(ISBLANK(INDEX(Results_Long!$O$2:$O$37,MATCH("G7|panel_q_vhb|0_VHB low vs 99_NCE|pairwise_contrast",Results_Long!$AK$2:$AK$37,0))),"—",INDEX(Results_Long!$O$2:$O$37,MATCH("G7|panel_q_vhb|0_VHB low vs 99_NCE|pairwise_contrast",Results_Long!$AK$2:$AK$37,0))) -> 0.98925598 | G16: =IF(INDEX(Results_Long!$N$2:$N$37,MATCH("G7|panel_q_vhb|0_VHB low vs 99_NCE|pairwise_contrast",Results_Long!$AK$2:$AK$37,0))<5,"df < 5 — descriptive","")
A18: Interpretation
A19: The three cells sit within .004 of each other on the r scale (−.056 to −.060); HTZ p = .988.
A20: The not-classified cell (680 ES / 14 clusters) is indistinguishable from the classified cells here; any selection-based reading belongs to the D5 selection-model block.
A22: Reviewer Q&A — Finance/Econometrics
A23: Question | B23: Answer
A24: Why keep the not-classified (99_NCE) cell in a quality panel? | B24: It was pre-registered per D31.4; dropping it after seeing results would be a result-contingent design change. Publication-status inference is single-homed in D5; this cell is descriptive.
A25: Why no multiplicity control over the three pairwise contrasts? | B25: Level-only technical panel with no moderation claim; descriptive regime per DEC-047/DEC-050 §4 — a Holm line would suggest an inferential family that is not claimed.
A27: Reviewer Q&A — Management/BSE
A28: Question | B28: Answer
A29: Does journal quality change the headline association? | B29: No indication: all three cells within .004 on the r scale, HTZ p = .988, all pairwise |Δz| ≤ .004. The high-vs-low feature is the text-carrying contrast [TB-67].
A31: Mechanical outcome: cell means r = −.056 to −.060; HTZ F = 0.01 (df = 34.7, p = .988); all pairwise |Δz| ≤ .004 — no quality gradient indicated; wording per the resolved gate [DEC-047].

Sheet 8_Panel_Field
A1: G8 — Research-field panel (field): 1_fin/acc/econ · 2_sust · 3_mgmt
A2: Field of the publishing journal; level panel only
A3: All cells formula-linked to Results_Long; HTZ + pairwise z-only, descriptive [DEC-047]
A5: Level | B5: k_es | C5: k_cluster | D5: est_z | E5: CI_z low | F5: CI_z high | G5: est_r | H5: CI_r low | I5: CI_r high | J5: df | K5: p
A6: 1_fin/acc/econ | B6: =IF(ISBLANK(INDEX(Results_Long!$H$2:$H$37,MATCH("G8|panel_field|1_fin/acc/econ|cell_mean",Results_Long!$AK$2:$AK$37,0))),"—",INDEX(Results_Long!$H$2:$H$37,MATCH("G8|panel_field|1_fin/acc/econ|cell_mean",Results_Long!$AK$2:$AK$37,0))) -> 1852 | C6: =IF(ISBLANK(INDEX(Results_Long!$J$2:$J$37,MATCH("G8|panel_field|1_fin/acc/econ|cell_mean",Results_Long!$AK$2:$AK$37,0))),"—",INDEX(Results_Long!$J$2:$J$37,MATCH("G8|panel_field|1_fin/acc/econ|cell_mean",Results_Long!$AK$2:$AK$37,0))) -> 67 | D6: =IF(ISBLANK(INDEX(Results_Long!$K$2:$K$37,MATCH("G8|panel_field|1_fin/acc/econ|cell_mean",Results_Long!$AK$2:$AK$37,0))),"—",INDEX(Results_Long!$K$2:$K$37,MATCH("G8|panel_field|1_fin/acc/econ|cell_mean",Results_Long!$AK$2:$AK$37,0))) -> -0.045589697 | E6: =IF(ISBLANK(INDEX(Results_Long!$P$2:$P$37,MATCH("G8|panel_field|1_fin/acc/econ|cell_mean",Results_Long!$AK$2:$AK$37,0))),"—",INDEX(Results_Long!$P$2:$P$37,MATCH("G8|panel_field|1_fin/acc/econ|cell_mean",Results_Long!$AK$2:$AK$37,0))) -> -0.060936196 | F6: =IF(ISBLANK(INDEX(Results_Long!$Q$2:$Q$37,MATCH("G8|panel_field|1_fin/acc/econ|cell_mean",Results_Long!$AK$2:$AK$37,0))),"—",INDEX(Results_Long!$Q$2:$Q$37,MATCH("G8|panel_field|1_fin/acc/econ|cell_mean",Results_Long!$AK$2:$AK$37,0))) -> -0.030243199 | G6: =IF(ISBLANK(INDEX(Results_Long!$T$2:$T$37,MATCH("G8|panel_field|1_fin/acc/econ|cell_mean",Results_Long!$AK$2:$AK$37,0))),"—",INDEX(Results_Long!$T$2:$T$37,MATCH("G8|panel_field|1_fin/acc/econ|cell_mean",Results_Long!$AK$2:$AK$37,0))) -> -0.045558139 | H6: =IF(ISBLANK(INDEX(Results_Long!$U$2:$U$37,MATCH("G8|panel_field|1_fin/acc/econ|cell_mean",Results_Long!$AK$2:$AK$37,0))),"—",INDEX(Results_Long!$U$2:$U$37,MATCH("G8|panel_field|1_fin/acc/econ|cell_mean",Results_Long!$AK$2:$AK$37,0))) -> -0.060860885 | I6: =IF(ISBLANK(INDEX(Results_Long!$V$2:$V$37,MATCH("G8|panel_field|1_fin/acc/econ|cell_mean",Results_Long!$AK$2:$AK$37,0))),"—",INDEX(Results_Long!$V$2:$V$37,MATCH("G8|panel_field|1_fin/acc/econ|cell_mean",Results_Long!$AK$2:$AK$37,0))) -> -0.030233981 | J6: =IF(ISBLANK(INDEX(Results_Long!$N$2:$N$37,MATCH("G8|panel_field|1_fin/acc/econ|cell_mean",Results_Long!$AK$2:$AK$37,0))),"—",INDEX(Results_Long!$N$2:$N$37,MATCH("G8|panel_field|1_fin/acc/econ|cell_mean",Results_Long!$AK$2:$AK$37,0))) -> 64.892271 | K6: =IF(ISBLANK(INDEX(Results_Long!$O$2:$O$37,MATCH("G8|panel_field|1_fin/acc/econ|cell_mean",Results_Long!$AK$2:$AK$37,0))),"—",INDEX(Results_Long!$O$2:$O$37,MATCH("G8|panel_field|1_fin/acc/econ|cell_mean",Results_Long!$AK$2:$AK$37,0))) -> 1.267795e-07
A7: 2_sust | B7: =IF(ISBLANK(INDEX(Results_Long!$H$2:$H$37,MATCH("G8|panel_field|2_sust|cell_mean",Results_Long!$AK$2:$AK$37,0))),"—",INDEX(Results_Long!$H$2:$H$37,MATCH("G8|panel_field|2_sust|cell_mean",Results_Long!$AK$2:$AK$37,0))) -> 571 | C7: =IF(ISBLANK(INDEX(Results_Long!$J$2:$J$37,MATCH("G8|panel_field|2_sust|cell_mean",Results_Long!$AK$2:$AK$37,0))),"—",INDEX(Results_Long!$J$2:$J$37,MATCH("G8|panel_field|2_sust|cell_mean",Results_Long!$AK$2:$AK$37,0))) -> 32 | D7: =IF(ISBLANK(INDEX(Results_Long!$K$2:$K$37,MATCH("G8|panel_field|2_sust|cell_mean",Results_Long!$AK$2:$AK$37,0))),"—",INDEX(Results_Long!$K$2:$K$37,MATCH("G8|panel_field|2_sust|cell_mean",Results_Long!$AK$2:$AK$37,0))) -> -0.089903325 | E7: =IF(ISBLANK(INDEX(Results_Long!$P$2:$P$37,MATCH("G8|panel_field|2_sust|cell_mean",Results_Long!$AK$2:$AK$37,0))),"—",INDEX(Results_Long!$P$2:$P$37,MATCH("G8|panel_field|2_sust|cell_mean",Results_Long!$AK$2:$AK$37,0))) -> -0.18579022 | F7: =IF(ISBLANK(INDEX(Results_Long!$Q$2:$Q$37,MATCH("G8|panel_field|2_sust|cell_mean",Results_Long!$AK$2:$AK$37,0))),"—",INDEX(Results_Long!$Q$2:$Q$37,MATCH("G8|panel_field|2_sust|cell_mean",Results_Long!$AK$2:$AK$37,0))) -> 0.005983575 | G7: =IF(ISBLANK(INDEX(Results_Long!$T$2:$T$37,MATCH("G8|panel_field|2_sust|cell_mean",Results_Long!$AK$2:$AK$37,0))),"—",INDEX(Results_Long!$T$2:$T$37,MATCH("G8|panel_field|2_sust|cell_mean",Results_Long!$AK$2:$AK$37,0))) -> -0.089661888 | H7: =IF(ISBLANK(INDEX(Results_Long!$U$2:$U$37,MATCH("G8|panel_field|2_sust|cell_mean",Results_Long!$AK$2:$AK$37,0))),"—",INDEX(Results_Long!$U$2:$U$37,MATCH("G8|panel_field|2_sust|cell_mean",Results_Long!$AK$2:$AK$37,0))) -> -0.18368163 | I7: =IF(ISBLANK(INDEX(Results_Long!$V$2:$V$37,MATCH("G8|panel_field|2_sust|cell_mean",Results_Long!$AK$2:$AK$37,0))),"—",INDEX(Results_Long!$V$2:$V$37,MATCH("G8|panel_field|2_sust|cell_mean",Results_Long!$AK$2:$AK$37,0))) -> 0.0059835036 | J7: =IF(ISBLANK(INDEX(Results_Long!$N$2:$N$37,MATCH("G8|panel_field|2_sust|cell_mean",Results_Long!$AK$2:$AK$37,0))),"—",INDEX(Results_Long!$N$2:$N$37,MATCH("G8|panel_field|2_sust|cell_mean",Results_Long!$AK$2:$AK$37,0))) -> 30.605634 | K7: =IF(ISBLANK(INDEX(Results_Long!$O$2:$O$37,MATCH("G8|panel_field|2_sust|cell_mean",Results_Long!$AK$2:$AK$37,0))),"—",INDEX(Results_Long!$O$2:$O$37,MATCH("G8|panel_field|2_sust|cell_mean",Results_Long!$AK$2:$AK$37,0))) -> 0.065112211
A8: 3_mgmt | B8: =IF(ISBLANK(INDEX(Results_Long!$H$2:$H$37,MATCH("G8|panel_field|3_mgmt|cell_mean",Results_Long!$AK$2:$AK$37,0))),"—",INDEX(Results_Long!$H$2:$H$37,MATCH("G8|panel_field|3_mgmt|cell_mean",Results_Long!$AK$2:$AK$37,0))) -> 290 | C8: =IF(ISBLANK(INDEX(Results_Long!$J$2:$J$37,MATCH("G8|panel_field|3_mgmt|cell_mean",Results_Long!$AK$2:$AK$37,0))),"—",INDEX(Results_Long!$J$2:$J$37,MATCH("G8|panel_field|3_mgmt|cell_mean",Results_Long!$AK$2:$AK$37,0))) -> 16 | D8: =IF(ISBLANK(INDEX(Results_Long!$K$2:$K$37,MATCH("G8|panel_field|3_mgmt|cell_mean",Results_Long!$AK$2:$AK$37,0))),"—",INDEX(Results_Long!$K$2:$K$37,MATCH("G8|panel_field|3_mgmt|cell_mean",Results_Long!$AK$2:$AK$37,0))) -> -0.052160972 | E8: =IF(ISBLANK(INDEX(Results_Long!$P$2:$P$37,MATCH("G8|panel_field|3_mgmt|cell_mean",Results_Long!$AK$2:$AK$37,0))),"—",INDEX(Results_Long!$P$2:$P$37,MATCH("G8|panel_field|3_mgmt|cell_mean",Results_Long!$AK$2:$AK$37,0))) -> -0.080654054 | F8: =IF(ISBLANK(INDEX(Results_Long!$Q$2:$Q$37,MATCH("G8|panel_field|3_mgmt|cell_mean",Results_Long!$AK$2:$AK$37,0))),"—",INDEX(Results_Long!$Q$2:$Q$37,MATCH("G8|panel_field|3_mgmt|cell_mean",Results_Long!$AK$2:$AK$37,0))) -> -0.02366789 | G8: =IF(ISBLANK(INDEX(Results_Long!$T$2:$T$37,MATCH("G8|panel_field|3_mgmt|cell_mean",Results_Long!$AK$2:$AK$37,0))),"—",INDEX(Results_Long!$T$2:$T$37,MATCH("G8|panel_field|3_mgmt|cell_mean",Results_Long!$AK$2:$AK$37,0))) -> -0.052113718 | H8: =IF(ISBLANK(INDEX(Results_Long!$U$2:$U$37,MATCH("G8|panel_field|3_mgmt|cell_mean",Results_Long!$AK$2:$AK$37,0))),"—",INDEX(Results_Long!$U$2:$U$37,MATCH("G8|panel_field|3_mgmt|cell_mean",Results_Long!$AK$2:$AK$37,0))) -> -0.080479621 | I8: =IF(ISBLANK(INDEX(Results_Long!$V$2:$V$37,MATCH("G8|panel_field|3_mgmt|cell_mean",Results_Long!$AK$2:$AK$37,0))),"—",INDEX(Results_Long!$V$2:$V$37,MATCH("G8|panel_field|3_mgmt|cell_mean",Results_Long!$AK$2:$AK$37,0))) -> -0.023663472 | J8: =IF(ISBLANK(INDEX(Results_Long!$N$2:$N$37,MATCH("G8|panel_field|3_mgmt|cell_mean",Results_Long!$AK$2:$AK$37,0))),"—",INDEX(Results_Long!$N$2:$N$37,MATCH("G8|panel_field|3_mgmt|cell_mean",Results_Long!$AK$2:$AK$37,0))) -> 13.469308 | K8: =IF(ISBLANK(INDEX(Results_Long!$O$2:$O$37,MATCH("G8|panel_field|3_mgmt|cell_mean",Results_Long!$AK$2:$AK$37,0))),"—",INDEX(Results_Long!$O$2:$O$37,MATCH("G8|panel_field|3_mgmt|cell_mean",Results_Long!$AK$2:$AK$37,0))) -> 0.0015845348
A10: Test (z-only) | B10: df | C10: p | D10: note (carries F and df_num verbatim)
A11: HTZ omnibus | B11: =IF(ISBLANK(INDEX(Results_Long!$N$2:$N$37,MATCH("G8|panel_field|panel|HTZ_omnibus",Results_Long!$AK$2:$AK$37,0))),"—",INDEX(Results_Long!$N$2:$N$37,MATCH("G8|panel_field|panel|HTZ_omnibus",Results_Long!$AK$2:$AK$37,0))) -> 33.539549 | C11: =IF(ISBLANK(INDEX(Results_Long!$O$2:$O$37,MATCH("G8|panel_field|panel|HTZ_omnibus",Results_Long!$AK$2:$AK$37,0))),"—",INDEX(Results_Long!$O$2:$O$37,MATCH("G8|panel_field|panel|HTZ_omnibus",Results_Long!$AK$2:$AK$37,0))) -> 0.61724392 | D11: =IF(ISBLANK(INDEX(Results_Long!$AJ$2:$AJ$37,MATCH("G8|panel_field|panel|HTZ_omnibus",Results_Long!$AK$2:$AK$37,0))),"—",INDEX(Results_Long!$AJ$2:$AJ$37,MATCH("G8|panel_field|panel|HTZ_omnibus",Results_Long!$AK$2:$AK$37,0))) -> F=0.4895, df_num=2.0; descriptive [DEC-047]
A13: Contrast (z-only) | B13: Δz | C13: CI_z low | D13: CI_z high | E13: df | F13: p | G13: flag
A14: 1_fin/acc/econ vs 2_sust | B14: =IF(ISBLANK(INDEX(Results_Long!$K$2:$K$37,MATCH("G8|panel_field|1_fin/acc/econ vs 2_sust|pairwise_contrast",Results_Long!$AK$2:$AK$37,0))),"—",INDEX(Results_Long!$K$2:$K$37,MATCH("G8|panel_field|1_fin/acc/econ vs 2_sust|pairwise_contrast",Results_Long!$AK$2:$AK$37,0))) -> 0.044313628 | C14: =IF(ISBLANK(INDEX(Results_Long!$P$2:$P$37,MATCH("G8|panel_field|1_fin/acc/econ vs 2_sust|pairwise_contrast",Results_Long!$AK$2:$AK$37,0))),"—",INDEX(Results_Long!$P$2:$P$37,MATCH("G8|panel_field|1_fin/acc/econ vs 2_sust|pairwise_contrast",Results_Long!$AK$2:$AK$37,0))) -> — | D14: =IF(ISBLANK(INDEX(Results_Long!$Q$2:$Q$37,MATCH("G8|panel_field|1_fin/acc/econ vs 2_sust|pairwise_contrast",Results_Long!$AK$2:$AK$37,0))),"—",INDEX(Results_Long!$Q$2:$Q$37,MATCH("G8|panel_field|1_fin/acc/econ vs 2_sust|pairwise_contrast",Results_Long!$AK$2:$AK$37,0))) -> — | E14: =IF(ISBLANK(INDEX(Results_Long!$N$2:$N$37,MATCH("G8|panel_field|1_fin/acc/econ vs 2_sust|pairwise_contrast",Results_Long!$AK$2:$AK$37,0))),"—",INDEX(Results_Long!$N$2:$N$37,MATCH("G8|panel_field|1_fin/acc/econ vs 2_sust|pairwise_contrast",Results_Long!$AK$2:$AK$37,0))) -> 58.817842 | F14: =IF(ISBLANK(INDEX(Results_Long!$O$2:$O$37,MATCH("G8|panel_field|1_fin/acc/econ vs 2_sust|pairwise_contrast",Results_Long!$AK$2:$AK$37,0))),"—",INDEX(Results_Long!$O$2:$O$37,MATCH("G8|panel_field|1_fin/acc/econ vs 2_sust|pairwise_contrast",Results_Long!$AK$2:$AK$37,0))) -> 0.3558225 | G14: =IF(INDEX(Results_Long!$N$2:$N$37,MATCH("G8|panel_field|1_fin/acc/econ vs 2_sust|pairwise_contrast",Results_Long!$AK$2:$AK$37,0))<5,"df < 5 — descriptive","")
A15: 1_fin/acc/econ vs 3_mgmt | B15: =IF(ISBLANK(INDEX(Results_Long!$K$2:$K$37,MATCH("G8|panel_field|1_fin/acc/econ vs 3_mgmt|pairwise_contrast",Results_Long!$AK$2:$AK$37,0))),"—",INDEX(Results_Long!$K$2:$K$37,MATCH("G8|panel_field|1_fin/acc/econ vs 3_mgmt|pairwise_contrast",Results_Long!$AK$2:$AK$37,0))) -> 0.0065712747 | C15: =IF(ISBLANK(INDEX(Results_Long!$P$2:$P$37,MATCH("G8|panel_field|1_fin/acc/econ vs 3_mgmt|pairwise_contrast",Results_Long!$AK$2:$AK$37,0))),"—",INDEX(Results_Long!$P$2:$P$37,MATCH("G8|panel_field|1_fin/acc/econ vs 3_mgmt|pairwise_contrast",Results_Long!$AK$2:$AK$37,0))) -> — | D15: =IF(ISBLANK(INDEX(Results_Long!$Q$2:$Q$37,MATCH("G8|panel_field|1_fin/acc/econ vs 3_mgmt|pairwise_contrast",Results_Long!$AK$2:$AK$37,0))),"—",INDEX(Results_Long!$Q$2:$Q$37,MATCH("G8|panel_field|1_fin/acc/econ vs 3_mgmt|pairwise_contrast",Results_Long!$AK$2:$AK$37,0))) -> — | E15: =IF(ISBLANK(INDEX(Results_Long!$N$2:$N$37,MATCH("G8|panel_field|1_fin/acc/econ vs 3_mgmt|pairwise_contrast",Results_Long!$AK$2:$AK$37,0))),"—",INDEX(Results_Long!$N$2:$N$37,MATCH("G8|panel_field|1_fin/acc/econ vs 3_mgmt|pairwise_contrast",Results_Long!$AK$2:$AK$37,0))) -> 16.009699 | F15: =IF(ISBLANK(INDEX(Results_Long!$O$2:$O$37,MATCH("G8|panel_field|1_fin/acc/econ vs 3_mgmt|pairwise_contrast",Results_Long!$AK$2:$AK$37,0))),"—",INDEX(Results_Long!$O$2:$O$37,MATCH("G8|panel_field|1_fin/acc/econ vs 3_mgmt|pairwise_contrast",Results_Long!$AK$2:$AK$37,0))) -> 0.66308045 | G15: =IF(INDEX(Results_Long!$N$2:$N$37,MATCH("G8|panel_field|1_fin/acc/econ vs 3_mgmt|pairwise_contrast",Results_Long!$AK$2:$AK$37,0))<5,"df < 5 — descriptive","")
