Workbook

Sheet 1_README
A1: TH-a (Block E/H fast frequentist battery) · README
A2: Template: docs/results_workbook_template.md (binding; 13-tab SOMA)
A3: Run 2026-07-24 22:46 (canonical) · verifier R/06_verify_outputs.R 17/17 PASS · chat artefact check 2026-07-26 18/18 PASS · output/TH_a_results.csv 177x36
A5: Item | B5: Value
A6: Workbook version | B6: v1.0 (built post-run by project chat; verifier never reads this file)
A7: Method one-liner | B7: Fast frequentist E/H battery on the 3L-RVE spine: TOST equivalence (E1/E2), gate configuration (E3), sup-break grid (H4), Zarea transplant (H6), cumulative MA (H7), rolling windows (H8), external comparison (H9), conditional p-curve (H10), within-study display (H11).
A8: Scope | B8: Block E (E1-E3) + Block H fast analyses (H4 grid, H6-H11); estimation set 2,713 ES / 115 studies / 114 clusters; period domain 2,705 / 113 / 112.
A9: Repo / commit basis | B9: rwitte-wu-research/FOMA-CER-COD-Paris; chain 5a99de6 -> e44fce7 (#12) -> fce9d3a (#13) -> dafd95e (#14); family commit lands on dafd95e (main = origin)
A10: Computational stack | B10: R 4.6.1 (ucrt) · metafor 5.0-1 · clubSandwich 0.7.0 · Matrix 1.7-5 · Windows 11 x64 (26200) · reference BLAS single-threaded + per-worker thread guards
A11: Scripts | B11: R/06_e_h_fast.R + R/06_verify_outputs.R (paired verifier, 17/17 PASS)
A12: Decision basis | B12: DEC-045 (E/H execution spec incl. supersessions S1-S9) · DEC-031f (optimizer ladder) · DEC-044 (framing A; language gate UNRESOLVED - see 3_Interpretation_Guide)
A13: Framing gate | B13: Framing gate [DEC-044]: all TOST flags and permutation p-values in this workbook are MECHANICAL values; no evidence-of-absence or verdict language is used anywhere; adjudication happens as the documented gate-resolution step after TH-b (H2a/H2b RoBMA).
A14: TAB-INDEX | B14: 1_README | 2_Methodology | 3_Interpretation_Guide | 4_Formula_Reference | 5_Data_Provenance | 6_E_TOST_Battery | 7_H4_Break_Grid | 8_H6_H7_Transpl_Cumul | 9_H8_H9_Rolling_External | 10_H10_H11_pcurve_within | Results_Long | Manuscript_Inputs | Manuscript_Text_Blocks

Sheet 2_Methodology
A1: TH-a (Block E/H fast frequentist battery) · Methodology
A2: Quantity | Formula / Construction | Reference (project notation)
A3: Run 2026-07-24 22:46 (canonical) · verifier R/06_verify_outputs.R 17/17 PASS · chat artefact check 2026-07-26 18/18 PASS · output/TH_a_results.csv 177x36
A5: Quantity | B5: Formula / Construction | C5: Reference
A6: Cell-means Paris model | B6: rma.mv with mods = ~ 0 + pp_cell on the period domain (2,705 ES / 113 studies / 112 clusters); diff = post - pre linear contrast; estimand identical to the T2/B1 moderator parameterization | C6: [DEC-024] [DEC-045 E-pins] [plan A.13]
A7: TOST equivalence machinery | B7: Two one-sided tests, each alpha = .05, equivalent to: 90% CI inside the band; TOST p = max(arm p); flag value = 1{90% CI inside band}; bands: E1 primary |r| = 0.070 (z = atanh = 0.070115), secondary 0.050; E2 secondary-SESOI band ±0.050 on the contrast | C7: Lakens (2017); Lakens et al. (2018) [PK]; [F27v2] [DEC-044 ladder]
A8: Inference spine | B8: 3-level REML (random = ~1 | cluster_id/study/esid), CR2 cluster-robust SEs, Satterthwaite df; inference unit = cluster_id; rho = 0.6 CS working correlation in V | C8: Hedges et al. (2010); Pustejovsky & Tipton (2022); Tipton & Pustejovsky (2015) [PK]; [DEC-031]
A9: Optimizer ladder | B9: nlminb -> BFGS -> Nelder-Mead with metafor convergence certification on EVERY spine fit (148 certificates this run; 148/0 rung-1/fallback) | C9: [DEC-031f R2/R3] [DEC-045 every-spine-fit pin]
A10: H4 sup-break grid | B10: Cell-means break model per candidate year 2008-2019; admissible = Satterthwaite df >= 5 on the break coefficient, computed ONCE on the observed design and held fixed for the TH-c permutation; observed statistic = sup |t| | C10: [DEC-024 transfer rule] [H-Q6/H-Q20] [DEC-045]
A11: H6 Zarea transplantation | B11: Zarea's Paris operationalization (study-midpoint rule WITH tie exclusion) applied within our 3L-RVE framework - the CODING is transplanted into the D31.1 spine, never the naive ES-level RE machinery | C11: [DEC-045/N8] (pinned wording)
A12: H7 cumulative MA | B12: Study-wise chronological refits; order = study median sample_mid, ties alphabetical; 113 steps; CI band from the first step with >= 10 clusters (step 10) | C12: [DEC-045/H-Q17] [Annex H N10]
A13: H8 rolling windows | B13: Width 6 y, step 1 y, anchor 1998 (min sample_mid 1998.5); tiers: >= 10 clusters full CR2 inference, 5-9 clusters descriptive point only, < 5 not estimated | C13: [DEC-045 S6]
A14: H9 external comparison | B14: Descriptive channel comparison against the COE companion STUDY-LEVEL estimate (Table 3, 75 units); explicitly NO test (SE provenance incompatible) | C14: [DEC-045/H-Q10/N12]
A15: H10 conditional p-curve | B15: N13 rule: conditional on >= 5 significant post-cell studies; selection = first-reported ES per post study (dat_prep row order); p reconstructed as 2*pnorm(-|zi|/sqrt(vi)); right-skew binomial + Stouffer, flatness vs. 33% power | C15: Simonsohn et al. (2014) [PK]; [Annex H/DEC-045 N13]
A16: H11 within-study display | B16: Studies with own pre- AND post-Paris ES, descriptive only, explicitly NO p-values; straddle inventory from pp_window_class == 'mixed' | C16: [DEC-045/N15/H-Q11]

Sheet 3_Interpretation_Guide
A1: TH-a (Block E/H fast frequentist battery) · Interpretation Guide
A2: How to read each reported quantity; thresholds with citations
A3: Framing gate [DEC-044]: all TOST flags and permutation p-values in this workbook are MECHANICAL values; no evidence-of-absence or verdict language is used anywhere; adjudication happens as the documented gate-resolution step after TH-b (H2a/H2b RoBMA).
A5: Quantity | B5: Meaning | C5: Decision rule
A6: TOST flag ('value') | B6: 1 = 90% CI inside the band, 0 = not; purely mechanical | C6: No equivalence language attached; gate-resolution step decides wording [DEC-044]
A7: TOST p | B7: max of the two one-sided arm p-values | C7: Compare to alpha = .05 mechanically; adjudication deferred
A8: diff rows | B8: Difference-of-z contrasts are z-only by convention; est_r = NA | C8: [template rule]
A9: Satterthwaite df | B9: Small-sample honest df per coefficient | C9: df >= 4 required for trustworthy CR2 t-inference (Tipton & Pustejovsky 2015 [PK]); H4 admissibility uses df >= 5 [H-Q6]
A10: H4 sup |t| | B10: Largest absolute break statistic over the admissible candidate set | C10: Significance is NOT read from the pointwise p column; the reference distribution is the TH-c cluster time-translation permutation (single-home: TH_c workbook Tab '9_H4_Perm_Sup')
A11: H7 steps 1-9 | B11: Cumulative estimates below the 10-cluster floor | C11: Point-only display; step_001 not_estimable by rule (single cluster; vcovCR guard, ERROR_LOG #12)
A12: H8 descriptive tier | B12: 5-9 cluster windows | C12: Point estimate only, no CI/p by design [DEC-045 S6]
A13: H9 rows | B13: Own pooled (debt) vs. COE companion study-level | C13: Descriptive size comparison only; no formal test [N12]
A14: H10 tests | B14: Right-skew = evidential value; flatness = test against 33% power | C14: Read per Simonsohn et al. (2014); conditional battery, N13
A15: Framing gate | B15: Framing gate [DEC-044]: all TOST flags and permutation p-values in this workbook are MECHANICAL values; no evidence-of-absence or verdict language is used anywhere; adjudication happens as the documented gate-resolution step after TH-b (H2a/H2b RoBMA). | C15: [DEC-044]

Sheet 4_Formula_Reference
A1: TH-a (Block E/H fast frequentist battery) · Formula Reference
A2: Exact calls as implemented (from run notes / run_meta)
A3: Run 2026-07-24 22:46 (canonical) · verifier R/06_verify_outputs.R 17/17 PASS · chat artefact check 2026-07-26 18/18 PASS · output/TH_a_results.csv 177x36
A5: Quantity | B5: R call | C5: Reference / script section
A6: Spine fit | B6: rma.mv(zi, V, mods = ~ 0 + pp_cell, random = ~ 1 | cluster_id/study/esid, method = 'REML', test = 't', sparse = TRUE) with optimizer ladder | C6: R/06 spine block
A7: CR2 inference | B7: clubSandwich::coef_test(fit, vcov = 'CR2', test = 'Satterthwaite'); CIs via conf_int(..., vcov = 'CR2') | C7: R/06
A8: Contrast (diff) | B8: clubSandwich::Wald_test / linear contrast c(-1, +1) on cell means, CR2, Satterthwaite df | C8: R/06 E2/H4/H6
A9: TOST arms | B9: pt((b - band)/se, df) upper arm; pt((b + band)/se, df, lower.tail = FALSE) lower arm; TOST p = max | C9: R/06 E-block [DEC-045 E-pins]
A10: 90% CI (TOST rows) | B10: b ± qt(.95, df) * se | C10: R/06
A11: Back-transform | B11: est_r = tanh(est_z); CI_r = tanh(CI_z) (never on diff rows) | C11: R/06 output writer
A12: H10 p reconstruction | B12: p_i = 2 * pnorm(-abs(zi)/sqrt(vi)); binomial: pbinom on p < .025 half-share; Stouffer on pp-values; flatness vs. 33%-power NCP (sign-corrected, ERROR_LOG #11) | C12: R/06 H10 [N13]
A13: H7/H8 refits | B13: Same spine per cumulative step / rolling window subset; window filter on sample_mid in [a, a+6) | C13: R/06 H7/H8

Sheet 5_Data_Provenance
A1: TH-a (Block E/H fast frequentist battery) · Data Provenance
A2: Estimation set, anchors, counters, environment, disclosures
A3: Run 2026-07-24 22:46 (canonical) · verifier R/06_verify_outputs.R 17/17 PASS · chat artefact check 2026-07-26 18/18 PASS · output/TH_a_results.csv 177x36
A5: Item | B5: Value | C5: Source
A6: Estimation set / domain | B6: 2,713 ES / 115 studies / 114 clusters (E1 pooled, full estimation set); period domain 2,705 / 113 / 112 for all Paris-cell analyses | C6: TH_a_results.csv; [DEC-045]
A7: dat_prep md5 | B7: 6702ef3dc45fe0b693b13f50ebd1576b (identical in TH_a_run_meta and TH_c_run_meta - cross-run anchor) | C7: run_meta both runs
A8: Run stamp / verifier | B8: 2026-07-24 22:46:16 · R/06_verify_outputs.R 17/17 PASS · chat-side artefact check 2026-07-26 18/18 PASS (anchors, arithmetic, inventories, cross-run) | C8: session log §1
A9: Runtime | B9: Not recorded in run_meta; projected 45-70 min per plan A.13 (fast frequentist batch) | C9: plan A.13
A10: Ladder balance | B10: 148 spine fits, ALL converged at rung 1 (nlminb, metafor-certified); zero fallbacks, zero failures [§6(ii)] | C10: TH_a_run_meta certificates
A11: H7 step_001 | B11: not_estimable by rule: single cluster, vcovCR guard fires (ERROR_LOG #12 lesson); all downstream steps estimable | C11: TH_a_results.csv H7
A12: H6 tie inventory | B12: 79 ES / 5 studies / 5 clusters tied at sample_mid = 2015.5 (Ho & Wong 2023; Kordschia 2020; Owolabi et al 2024; Ririmasse et al 2026; Xiang & Gong 2026); post cell 31 -> 26 studies under tie exclusion | C12: TH_design h6_tie_inventory
A13: H4 admissible set | B13: 12 years (2008-2019), Satterthwaite df >= 5 rule, computed once and held fixed for the TH-c permutation | C13: TH_design h4_admissible_years [H-Q20]
A14: H11 inventory | B14: 73 straddling studies; 72 pool across the break; single within-split study = Li et al (2022) | C14: TH_design h11_* rows
A15: Repo basis | B15: 5a99de6 -> e44fce7 (#12) -> fce9d3a (#13) -> dafd95e (#14); family commit lands on dafd95e (main = origin) | C15: session log §1
A16: Environment | B16: R 4.6.1 ucrt · Windows 11 x64 (26200) · locale German_Austria.utf8 / LC_NUMERIC = C · TZ Europe/Vienna · metafor 5.0-1, clubSandwich 0.7.0, Matrix 1.7-5, readr 2.2.0, here 1.0.2 | C16: TH_a_run_meta sessionInfo
A17: Companion caveat | B17: COE between-study variance (~0.00045) is a best-case lower bound vs. COD (~0.029): factor ~65 in variance, ~8 in MDE units - disclose whenever comparing across companions | C17: [project pin; see TH_c H1 S4 mapping]

Sheet 6_E_TOST_Battery
A1: TH-a (Block E/H fast frequentist battery) · Block E - equivalence battery (E1 pooled TOST · E2 Paris-contrast TOST · E3 gate configuration)
A2: Mechanical flags only; CI columns on tost rows carry the 90% CI (TOST convention); mean rows carry 95% CIs.
A3: Run 2026-07-24 22:46 (canonical) · verifier R/06_verify_outputs.R 17/17 PASS · chat artefact check 2026-07-26 18/18 PASS · output/TH_a_results.csv 177x36
A5: Panel row | B5: analysis_id | C5: spec | D5: subset | E5: term | F5: RL row | G5: k_es | H5: k_st | I5: k_cl | J5: est_z | K5: ci_lb_z | L5: ci_ub_z | M5: est_r | N5: ci_lb_r | O5: ci_ub_r | P5: se_z | Q5: t | R5: df | S5: p | T5: value | U5: note (verbatim)
A6: E1 pooled mean (full estimation set) | B6: E1 | C6: tost_pooled | D6: defined | E6: pooled_mean | F6: =SUMPRODUCT((Results_Long!$A$2:$A$178=$B6)*(Results_Long!$B$2:$B$178=$C6)*(Results_Long!$C$2:$C$178=$D6)*(Results_Long!$D$2:$D$178=$E6)*ROW(Results_Long!$A$2:$A$178)) -> 2 | G6: =IF(INDEX(Results_Long!$H:$H,$F6)="","NA",INDEX(Results_Long!$H:$H,$F6)) -> 2713 | H6: =IF(INDEX(Results_Long!$I:$I,$F6)="","NA",INDEX(Results_Long!$I:$I,$F6)) -> 115 | I6: =IF(INDEX(Results_Long!$J:$J,$F6)="","NA",INDEX(Results_Long!$J:$J,$F6)) -> 114 | J6: =IF(INDEX(Results_Long!$K:$K,$F6)="","NA",INDEX(Results_Long!$K:$K,$F6)) -> -0.058646737 | K6: =IF(INDEX(Results_Long!$P:$P,$F6)="","NA",INDEX(Results_Long!$P:$P,$F6)) -> -0.086102595 | L6: =IF(INDEX(Results_Long!$Q:$Q,$F6)="","NA",INDEX(Results_Long!$Q:$Q,$F6)) -> -0.031190879 | M6: =IF(INDEX(Results_Long!$T:$T,$F6)="","NA",INDEX(Results_Long!$T:$T,$F6)) -> -0.058579592 | N6: =IF(INDEX(Results_Long!$U:$U,$F6)="","NA",INDEX(Results_Long!$U:$U,$F6)) -> -0.085890445 | O6: =IF(INDEX(Results_Long!$V:$V,$F6)="","NA",INDEX(Results_Long!$V:$V,$F6)) -> -0.031180768 | P6: =IF(INDEX(Results_Long!$L:$L,$F6)="","NA",INDEX(Results_Long!$L:$L,$F6)) -> 0.01385655 | Q6: =IF(INDEX(Results_Long!$M:$M,$F6)="","NA",INDEX(Results_Long!$M:$M,$F6)) -> -4.2324199 | R6: =IF(INDEX(Results_Long!$N:$N,$F6)="","NA",INDEX(Results_Long!$N:$N,$F6)) -> 111.6718 | S6: =IF(INDEX(Results_Long!$O:$O,$F6)="","NA",INDEX(Results_Long!$O:$O,$F6)) -> 4.7619835e-05 | T6: =IF(INDEX(Results_Long!$AG:$AG,$F6)="","NA",INDEX(Results_Long!$AG:$AG,$F6)) -> NA | U6: =IF(INDEX(Results_Long!$AJ:$AJ,$F6)="","NA",INDEX(Results_Long!$AJ:$AJ,$F6)) -> rma.mv mods=~ 1; random ~1|cluster_id/study/esid; V blocks within cluster_id, rho=0.6; CR2/Satterthwaite on cluster_id [D31.1/A.2]; domain estimation set 2713/115/114 [DEC-042a]; TH-a refit of T1/A1; verifier identity vs committed output/T1_results.csv at 1e-6 [F65]; 95% CI on this row (TOST rows carry 90%)
A7: E1 TOST band |r| = 0.070 (PRIMARY) | B7: E1 | C7: tost_pooled | D7: defined | E7: tost_band_0.070 | F7: =SUMPRODUCT((Results_Long!$A$2:$A$178=$B7)*(Results_Long!$B$2:$B$178=$C7)*(Results_Long!$C$2:$C$178=$D7)*(Results_Long!$D$2:$D$178=$E7)*ROW(Results_Long!$A$2:$A$178)) -> 3 | G7: =IF(INDEX(Results_Long!$H:$H,$F7)="","NA",INDEX(Results_Long!$H:$H,$F7)) -> 2713 | H7: =IF(INDEX(Results_Long!$I:$I,$F7)="","NA",INDEX(Results_Long!$I:$I,$F7)) -> 115 | I7: =IF(INDEX(Results_Long!$J:$J,$F7)="","NA",INDEX(Results_Long!$J:$J,$F7)) -> 114 | J7: =IF(INDEX(Results_Long!$K:$K,$F7)="","NA",INDEX(Results_Long!$K:$K,$F7)) -> -0.058646737 | K7: =IF(INDEX(Results_Long!$P:$P,$F7)="","NA",INDEX(Results_Long!$P:$P,$F7)) -> -0.081629394 | L7: =IF(INDEX(Results_Long!$Q:$Q,$F7)="","NA",INDEX(Results_Long!$Q:$Q,$F7)) -> -0.035664079 | M7: =IF(INDEX(Results_Long!$T:$T,$F7)="","NA",INDEX(Results_Long!$T:$T,$F7)) -> NA | N7: =IF(INDEX(Results_Long!$U:$U,$F7)="","NA",INDEX(Results_Long!$U:$U,$F7)) -> NA | O7: =IF(INDEX(Results_Long!$V:$V,$F7)="","NA",INDEX(Results_Long!$V:$V,$F7)) -> NA | P7: =IF(INDEX(Results_Long!$L:$L,$F7)="","NA",INDEX(Results_Long!$L:$L,$F7)) -> 0.01385655 | Q7: =IF(INDEX(Results_Long!$M:$M,$F7)="","NA",INDEX(Results_Long!$M:$M,$F7)) -> NA | R7: =IF(INDEX(Results_Long!$N:$N,$F7)="","NA",INDEX(Results_Long!$N:$N,$F7)) -> 111.6718 | S7: =IF(INDEX(Results_Long!$O:$O,$F7)="","NA",INDEX(Results_Long!$O:$O,$F7)) -> 0.20482591 | T7: =IF(INDEX(Results_Long!$AG:$AG,$F7)="","NA",INDEX(Results_Long!$AG:$AG,$F7)) -> 0 | U7: =IF(INDEX(Results_Long!$AJ:$AJ,$F7)="","NA",INDEX(Results_Long!$AJ:$AJ,$F7)) -> TOST, two one-sided tests each alpha=.05 <=> 90% CI inside band [DEC-045 E-pins]; PRIMARY level band |r| = 0.070 (F27v2) -> z band atanh = 0.070114671; arm p (lower/upper) = 0.204826 / 7.26341e-16; TOST p = max(arms); CI columns carry the 90% CI (TOST convention); value = 1{90%-CI inside band} (mechanical flag, no verdict language); ex-ante expectation [DEC-044/DEC-045]: this arm is expected to FAIL (T1 CI edge -0.086); E2 adjudicates Tier 1; E1 calibrates the Tier-2 wording only
A8: E1 TOST band |r| = 0.050 (secondary) | B8: E1 | C8: tost_pooled | D8: defined | E8: tost_band_0.050 | F8: =SUMPRODUCT((Results_Long!$A$2:$A$178=$B8)*(Results_Long!$B$2:$B$178=$C8)*(Results_Long!$C$2:$C$178=$D8)*(Results_Long!$D$2:$D$178=$E8)*ROW(Results_Long!$A$2:$A$178)) -> 4 | G8: =IF(INDEX(Results_Long!$H:$H,$F8)="","NA",INDEX(Results_Long!$H:$H,$F8)) -> 2713 | H8: =IF(INDEX(Results_Long!$I:$I,$F8)="","NA",INDEX(Results_Long!$I:$I,$F8)) -> 115 | I8: =IF(INDEX(Results_Long!$J:$J,$F8)="","NA",INDEX(Results_Long!$J:$J,$F8)) -> 114 | J8: =IF(INDEX(Results_Long!$K:$K,$F8)="","NA",INDEX(Results_Long!$K:$K,$F8)) -> -0.058646737 | K8: =IF(INDEX(Results_Long!$P:$P,$F8)="","NA",INDEX(Results_Long!$P:$P,$F8)) -> -0.081629394 | L8: =IF(INDEX(Results_Long!$Q:$Q,$F8)="","NA",INDEX(Results_Long!$Q:$Q,$F8)) -> -0.035664079 | M8: =IF(INDEX(Results_Long!$T:$T,$F8)="","NA",INDEX(Results_Long!$T:$T,$F8)) -> NA | N8: =IF(INDEX(Results_Long!$U:$U,$F8)="","NA",INDEX(Results_Long!$U:$U,$F8)) -> NA | O8: =IF(INDEX(Results_Long!$V:$V,$F8)="","NA",INDEX(Results_Long!$V:$V,$F8)) -> NA | P8: =IF(INDEX(Results_Long!$L:$L,$F8)="","NA",INDEX(Results_Long!$L:$L,$F8)) -> 0.01385655 | Q8: =IF(INDEX(Results_Long!$M:$M,$F8)="","NA",INDEX(Results_Long!$M:$M,$F8)) -> NA | R8: =IF(INDEX(Results_Long!$N:$N,$F8)="","NA",INDEX(Results_Long!$N:$N,$F8)) -> 111.6718 | S8: =IF(INDEX(Results_Long!$O:$O,$F8)="","NA",INDEX(Results_Long!$O:$O,$F8)) -> 0.73206958 | T8: =IF(INDEX(Results_Long!$AG:$AG,$F8)="","NA",INDEX(Results_Long!$AG:$AG,$F8)) -> 0 | U8: =IF(INDEX(Results_Long!$AJ:$AJ,$F8)="","NA",INDEX(Results_Long!$AJ:$AJ,$F8)) -> TOST, two one-sided tests each alpha=.05 <=> 90% CI inside band [DEC-045 E-pins]; SECONDARY level band |r| = 0.05 -> z band atanh = 0.050041729; arm p (lower/upper) = 0.73207 / 1.41843e-12; TOST p = max(arms); CI columns carry the 90% CI (TOST convention); value = 1{90%-CI inside band} (mechanical flag, no verdict language)
A9: E2 cell pre (headline coding) | B9: E2 | C9: tost_paris | D9: defined | E9: cell_pre | F9: =SUMPRODUCT((Results_Long!$A$2:$A$178=$B9)*(Results_Long!$B$2:$B$178=$C9)*(Results_Long!$C$2:$C$178=$D9)*(Results_Long!$D$2:$D$178=$E9)*ROW(Results_Long!$A$2:$A$178)) -> 5 | G9: =IF(INDEX(Results_Long!$H:$H,$F9)="","NA",INDEX(Results_Long!$H:$H,$F9)) -> 1994 | H9: =IF(INDEX(Results_Long!$I:$I,$F9)="","NA",INDEX(Results_Long!$I:$I,$F9)) -> 83 | I9: =IF(INDEX(Results_Long!$J:$J,$F9)="","NA",INDEX(Results_Long!$J:$J,$F9)) -> 82 | J9: =IF(INDEX(Results_Long!$K:$K,$F9)="","NA",INDEX(Results_Long!$K:$K,$F9)) -> -0.061599157 | K9: =IF(INDEX(Results_Long!$P:$P,$F9)="","NA",INDEX(Results_Long!$P:$P,$F9)) -> -0.097603942 | L9: =IF(INDEX(Results_Long!$Q:$Q,$F9)="","NA",INDEX(Results_Long!$Q:$Q,$F9)) -> -0.025594371 | M9: =IF(INDEX(Results_Long!$T:$T,$F9)="","NA",INDEX(Results_Long!$T:$T,$F9)) -> -0.061521363 | N9: =IF(INDEX(Results_Long!$U:$U,$F9)="","NA",INDEX(Results_Long!$U:$U,$F9)) -> -0.097295177 | O9: =IF(INDEX(Results_Long!$V:$V,$F9)="","NA",INDEX(Results_Long!$V:$V,$F9)) -> -0.025588783 | P9: =IF(INDEX(Results_Long!$L:$L,$F9)="","NA",INDEX(Results_Long!$L:$L,$F9)) -> 0.018046114 | Q9: =IF(INDEX(Results_Long!$M:$M,$F9)="","NA",INDEX(Results_Long!$M:$M,$F9)) -> -3.4134304 | R9: =IF(INDEX(Results_Long!$N:$N,$F9)="","NA",INDEX(Results_Long!$N:$N,$F9)) -> 68.597113 | S9: =IF(INDEX(Results_Long!$O:$O,$F9)="","NA",INDEX(Results_Long!$O:$O,$F9)) -> 0.0010804696 | T9: =IF(INDEX(Results_Long!$AG:$AG,$F9)="","NA",INDEX(Results_Long!$AG:$AG,$F9)) -> NA | U9: =IF(INDEX(Results_Long!$AJ:$AJ,$F9)="","NA",INDEX(Results_Long!$AJ:$AJ,$F9)) -> rma.mv mods=~ 0 + pp_cell (cell-means; estimand identical to ~ pp_mid_lag0); random ~1|cluster_id/study/esid; V blocks within cluster_id, rho=0.6; CR2/Satterthwaite on cluster_id [D31.1/A.2]; domain period domain 2705/113/112 [DEC-042b]; cell mean at coding = 0 (pre)
A10: E2 cell post | B10: E2 | C10: tost_paris | D10: defined | E10: cell_post | F10: =SUMPRODUCT((Results_Long!$A$2:$A$178=$B10)*(Results_Long!$B$2:$B$178=$C10)*(Results_Long!$C$2:$C$178=$D10)*(Results_Long!$D$2:$D$178=$E10)*ROW(Results_Long!$A$2:$A$178)) -> 6 | G10: =IF(INDEX(Results_Long!$H:$H,$F10)="","NA",INDEX(Results_Long!$H:$H,$F10)) -> 711 | H10: =IF(INDEX(Results_Long!$I:$I,$F10)="","NA",INDEX(Results_Long!$I:$I,$F10)) -> 31 | I10: =IF(INDEX(Results_Long!$J:$J,$F10)="","NA",INDEX(Results_Long!$J:$J,$F10)) -> 31 | J10: =IF(INDEX(Results_Long!$K:$K,$F10)="","NA",INDEX(Results_Long!$K:$K,$F10)) -> -0.05142325 | K10: =IF(INDEX(Results_Long!$P:$P,$F10)="","NA",INDEX(Results_Long!$P:$P,$F10)) -> -0.072986923 | L10: =IF(INDEX(Results_Long!$Q:$Q,$F10)="","NA",INDEX(Results_Long!$Q:$Q,$F10)) -> -0.029859576 | M10: =IF(INDEX(Results_Long!$T:$T,$F10)="","NA",INDEX(Results_Long!$T:$T,$F10)) -> -0.051377971 | N10: =IF(INDEX(Results_Long!$U:$U,$F10)="","NA",INDEX(Results_Long!$U:$U,$F10)) -> -0.072857596 | O10: =IF(INDEX(Results_Long!$V:$V,$F10)="","NA",INDEX(Results_Long!$V:$V,$F10)) -> -0.029850705 | P10: =IF(INDEX(Results_Long!$L:$L,$F10)="","NA",INDEX(Results_Long!$L:$L,$F10)) -> 0.010329352 | Q10: =IF(INDEX(Results_Long!$M:$M,$F10)="","NA",INDEX(Results_Long!$M:$M,$F10)) -> -4.9783615 | R10: =IF(INDEX(Results_Long!$N:$N,$F10)="","NA",INDEX(Results_Long!$N:$N,$F10)) -> 19.756715 | S10: =IF(INDEX(Results_Long!$O:$O,$F10)="","NA",INDEX(Results_Long!$O:$O,$F10)) -> 7.4752952e-05 | T10: =IF(INDEX(Results_Long!$AG:$AG,$F10)="","NA",INDEX(Results_Long!$AG:$AG,$F10)) -> NA | U10: =IF(INDEX(Results_Long!$AJ:$AJ,$F10)="","NA",INDEX(Results_Long!$AJ:$AJ,$F10)) -> rma.mv mods=~ 0 + pp_cell (cell-means; estimand identical to ~ pp_mid_lag0); random ~1|cluster_id/study/esid; V blocks within cluster_id, rho=0.6; CR2/Satterthwaite on cluster_id [D31.1/A.2]; domain period domain 2705/113/112 [DEC-042b]; cell mean at coding = 1 (post)
A11: E2 diff = post - pre (z-only) | B11: E2 | C11: tost_paris | D11: defined | E11: diff | F11: =SUMPRODUCT((Results_Long!$A$2:$A$178=$B11)*(Results_Long!$B$2:$B$178=$C11)*(Results_Long!$C$2:$C$178=$D11)*(Results_Long!$D$2:$D$178=$E11)*ROW(Results_Long!$A$2:$A$178)) -> 7 | G11: =IF(INDEX(Results_Long!$H:$H,$F11)="","NA",INDEX(Results_Long!$H:$H,$F11)) -> 2705 | H11: =IF(INDEX(Results_Long!$I:$I,$F11)="","NA",INDEX(Results_Long!$I:$I,$F11)) -> 113 | I11: =IF(INDEX(Results_Long!$J:$J,$F11)="","NA",INDEX(Results_Long!$J:$J,$F11)) -> 112 | J11: =IF(INDEX(Results_Long!$K:$K,$F11)="","NA",INDEX(Results_Long!$K:$K,$F11)) -> 0.010175907 | K11: =IF(INDEX(Results_Long!$P:$P,$F11)="","NA",INDEX(Results_Long!$P:$P,$F11)) -> -0.028420631 | L11: =IF(INDEX(Results_Long!$Q:$Q,$F11)="","NA",INDEX(Results_Long!$Q:$Q,$F11)) -> 0.048772445 | M11: =IF(INDEX(Results_Long!$T:$T,$F11)="","NA",INDEX(Results_Long!$T:$T,$F11)) -> NA | N11: =IF(INDEX(Results_Long!$U:$U,$F11)="","NA",INDEX(Results_Long!$U:$U,$F11)) -> NA | O11: =IF(INDEX(Results_Long!$V:$V,$F11)="","NA",INDEX(Results_Long!$V:$V,$F11)) -> NA | P11: =IF(INDEX(Results_Long!$L:$L,$F11)="","NA",INDEX(Results_Long!$L:$L,$F11)) -> 0.018107282 | Q11: =IF(INDEX(Results_Long!$M:$M,$F11)="","NA",INDEX(Results_Long!$M:$M,$F11)) -> 0.56197868 | R11: =IF(INDEX(Results_Long!$N:$N,$F11)="","NA",INDEX(Results_Long!$N:$N,$F11)) -> 14.992066 | S11: =IF(INDEX(Results_Long!$O:$O,$F11)="","NA",INDEX(Results_Long!$O:$O,$F11)) -> 0.58243573 | T11: =IF(INDEX(Results_Long!$AG:$AG,$F11)="","NA",INDEX(Results_Long!$AG:$AG,$F11)) -> NA | U11: =IF(INDEX(Results_Long!$AJ:$AJ,$F11)="","NA",INDEX(Results_Long!$AJ:$AJ,$F11)) -> rma.mv mods=~ 0 + pp_cell (cell-means; estimand identical to ~ pp_mid_lag0); random ~1|cluster_id/study/esid; V blocks within cluster_id, rho=0.6; CR2/Satterthwaite on cluster_id [D31.1/A.2]; domain period domain 2705/113/112 [DEC-042b]; post-minus-pre contrast (-1, +1); cell-means parameterization [DEC-031e/A.11]; difference of Fisher-z means; no tanh transform of differences; TH-a refit of T2/B1 paris_mid; verifier identity vs committed output/T2_results.csv at 1e-6 [F65]
A12: E2 TOST band ±0.050 on diff | B12: E2 | C12: tost_paris | D12: defined | E12: tost_band_0.050 | F12: =SUMPRODUCT((Results_Long!$A$2:$A$178=$B12)*(Results_Long!$B$2:$B$178=$C12)*(Results_Long!$C$2:$C$178=$D12)*(Results_Long!$D$2:$D$178=$E12)*ROW(Results_Long!$A$2:$A$178)) -> 8 | G12: =IF(INDEX(Results_Long!$H:$H,$F12)="","NA",INDEX(Results_Long!$H:$H,$F12)) -> 2705 | H12: =IF(INDEX(Results_Long!$I:$I,$F12)="","NA",INDEX(Results_Long!$I:$I,$F12)) -> 113 | I12: =IF(INDEX(Results_Long!$J:$J,$F12)="","NA",INDEX(Results_Long!$J:$J,$F12)) -> 112 | J12: =IF(INDEX(Results_Long!$K:$K,$F12)="","NA",INDEX(Results_Long!$K:$K,$F12)) -> 0.010175907 | K12: =IF(INDEX(Results_Long!$P:$P,$F12)="","NA",INDEX(Results_Long!$P:$P,$F12)) -> -0.021568174 | L12: =IF(INDEX(Results_Long!$Q:$Q,$F12)="","NA",INDEX(Results_Long!$Q:$Q,$F12)) -> 0.041919988 | M12: =IF(INDEX(Results_Long!$T:$T,$F12)="","NA",INDEX(Results_Long!$T:$T,$F12)) -> NA | N12: =IF(INDEX(Results_Long!$U:$U,$F12)="","NA",INDEX(Results_Long!$U:$U,$F12)) -> NA | O12: =IF(INDEX(Results_Long!$V:$V,$F12)="","NA",INDEX(Results_Long!$V:$V,$F12)) -> NA | P12: =IF(INDEX(Results_Long!$L:$L,$F12)="","NA",INDEX(Results_Long!$L:$L,$F12)) -> 0.018107282 | Q12: =IF(INDEX(Results_Long!$M:$M,$F12)="","NA",INDEX(Results_Long!$M:$M,$F12)) -> NA | R12: =IF(INDEX(Results_Long!$N:$N,$F12)="","NA",INDEX(Results_Long!$N:$N,$F12)) -> 14.992066 | S12: =IF(INDEX(Results_Long!$O:$O,$F12)="","NA",INDEX(Results_Long!$O:$O,$F12)) -> 0.02197985 | T12: =IF(INDEX(Results_Long!$AG:$AG,$F12)="","NA",INDEX(Results_Long!$AG:$AG,$F12)) -> 1 | U12: =IF(INDEX(Results_Long!$AJ:$AJ,$F12)="","NA",INDEX(Results_Long!$AJ:$AJ,$F12)) -> TOST, two one-sided tests each alpha=.05 <=> 90% CI inside band [DEC-045 E-pins]; contrast band |dr| = 0.05 (secondary SESOI = the contrast band [DEC-031 Block E]); applied on the z-difference directly; |dz| read as |dr| (third-order approx, T8/B8 convention); arm p (lower/upper) = 0.00231753 / 0.0219798; TOST p = max(arms); CI columns carry the 90% CI (TOST convention); value = 1{90%-CI inside band} (mechanical flag, no verdict language); E2 adjudicates Tier 1 (the Paris null) [DEC-045 E-pins]; dose transfer NOT triggered (design df 31.9 [DEC-024/A.3])
A13: E3 gate config: E2 requirement | B13: E3 | C13: gate | D13: defined | E13: config_e2_requirement | F13: =SUMPRODUCT((Results_Long!$A$2:$A$178=$B13)*(Results_Long!$B$2:$B$178=$C13)*(Results_Long!$C$2:$C$178=$D13)*(Results_Long!$D$2:$D$178=$E13)*ROW(Results_Long!$A$2:$A$178)) -> 9 | G13: =IF(INDEX(Results_Long!$H:$H,$F13)="","NA",INDEX(Results_Long!$H:$H,$F13)) -> NA | H13: =IF(INDEX(Results_Long!$I:$I,$F13)="","NA",INDEX(Results_Long!$I:$I,$F13)) -> NA | I13: =IF(INDEX(Results_Long!$J:$J,$F13)="","NA",INDEX(Results_Long!$J:$J,$F13)) -> NA | J13: =IF(INDEX(Results_Long!$K:$K,$F13)="","NA",INDEX(Results_Long!$K:$K,$F13)) -> NA | K13: =IF(INDEX(Results_Long!$P:$P,$F13)="","NA",INDEX(Results_Long!$P:$P,$F13)) -> NA | L13: =IF(INDEX(Results_Long!$Q:$Q,$F13)="","NA",INDEX(Results_Long!$Q:$Q,$F13)) -> NA | M13: =IF(INDEX(Results_Long!$T:$T,$F13)="","NA",INDEX(Results_Long!$T:$T,$F13)) -> NA | N13: =IF(INDEX(Results_Long!$U:$U,$F13)="","NA",INDEX(Results_Long!$U:$U,$F13)) -> NA | O13: =IF(INDEX(Results_Long!$V:$V,$F13)="","NA",INDEX(Results_Long!$V:$V,$F13)) -> NA | P13: =IF(INDEX(Results_Long!$L:$L,$F13)="","NA",INDEX(Results_Long!$L:$L,$F13)) -> NA | Q13: =IF(INDEX(Results_Long!$M:$M,$F13)="","NA",INDEX(Results_Long!$M:$M,$F13)) -> NA | R13: =IF(INDEX(Results_Long!$N:$N,$F13)="","NA",INDEX(Results_Long!$N:$N,$F13)) -> NA | S13: =IF(INDEX(Results_Long!$O:$O,$F13)="","NA",INDEX(Results_Long!$O:$O,$F13)) -> NA | T13: =IF(INDEX(Results_Long!$AG:$AG,$F13)="","NA",INDEX(Results_Long!$AG:$AG,$F13)) -> NA | U13: =IF(INDEX(Results_Long!$AJ:$AJ,$F13)="","NA",INDEX(Results_Long!$AJ:$AJ,$F13)) -> Tier-1 evidence-of-absence wording REQUIRES an E2 PASS; E2 FAIL -> no Tier-1 EoA regardless of BF [DEC-045 ladder / H-Q21]
A14: E3 gate config: BF01 ladder | B14: E3 | C14: gate | D14: defined | E14: config_bf_ladder | F14: =SUMPRODUCT((Results_Long!$A$2:$A$178=$B14)*(Results_Long!$B$2:$B$178=$C14)*(Results_Long!$C$2:$C$178=$D14)*(Results_Long!$D$2:$D$178=$E14)*ROW(Results_Long!$A$2:$A$178)) -> 10 | G14: =IF(INDEX(Results_Long!$H:$H,$F14)="","NA",INDEX(Results_Long!$H:$H,$F14)) -> NA | H14: =IF(INDEX(Results_Long!$I:$I,$F14)="","NA",INDEX(Results_Long!$I:$I,$F14)) -> NA | I14: =IF(INDEX(Results_Long!$J:$J,$F14)="","NA",INDEX(Results_Long!$J:$J,$F14)) -> NA | J14: =IF(INDEX(Results_Long!$K:$K,$F14)="","NA",INDEX(Results_Long!$K:$K,$F14)) -> NA | K14: =IF(INDEX(Results_Long!$P:$P,$F14)="","NA",INDEX(Results_Long!$P:$P,$F14)) -> NA | L14: =IF(INDEX(Results_Long!$Q:$Q,$F14)="","NA",INDEX(Results_Long!$Q:$Q,$F14)) -> NA | M14: =IF(INDEX(Results_Long!$T:$T,$F14)="","NA",INDEX(Results_Long!$T:$T,$F14)) -> NA | N14: =IF(INDEX(Results_Long!$U:$U,$F14)="","NA",INDEX(Results_Long!$U:$U,$F14)) -> NA | O14: =IF(INDEX(Results_Long!$V:$V,$F14)="","NA",INDEX(Results_Long!$V:$V,$F14)) -> NA | P14: =IF(INDEX(Results_Long!$L:$L,$F14)="","NA",INDEX(Results_Long!$L:$L,$F14)) -> NA | Q14: =IF(INDEX(Results_Long!$M:$M,$F14)="","NA",INDEX(Results_Long!$M:$M,$F14)) -> NA | R14: =IF(INDEX(Results_Long!$N:$N,$F14)="","NA",INDEX(Results_Long!$N:$N,$F14)) -> NA | S14: =IF(INDEX(Results_Long!$O:$O,$F14)="","NA",INDEX(Results_Long!$O:$O,$F14)) -> NA | T14: =IF(INDEX(Results_Long!$AG:$AG,$F14)="","NA",INDEX(Results_Long!$AG:$AG,$F14)) -> NA | U14: =IF(INDEX(Results_Long!$AJ:$AJ,$F14)="","NA",INDEX(Results_Long!$AJ:$AJ,$F14)) -> with H2b: BF01 >= 3 full EoA; 1 < BF01 < 3 equivalence-based, BF disclosed as directionally supportive, not strong; BF01 <= 1 conflict disclosure, conservative wording; without RoBMA.reg: pre-registered configuration E2 + level BF (H2a) [DEC-045; Jeffreys/Lee-Wagenmakers bands pinned]
A15: E3 gate status | B15: E3 | C15: gate | D15: defined | E15: status | F15: =SUMPRODUCT((Results_Long!$A$2:$A$178=$B15)*(Results_Long!$B$2:$B$178=$C15)*(Results_Long!$C$2:$C$178=$D15)*(Results_Long!$D$2:$D$178=$E15)*ROW(Results_Long!$A$2:$A$178)) -> 11 | G15: =IF(INDEX(Results_Long!$H:$H,$F15)="","NA",INDEX(Results_Long!$H:$H,$F15)) -> NA | H15: =IF(INDEX(Results_Long!$I:$I,$F15)="","NA",INDEX(Results_Long!$I:$I,$F15)) -> NA | I15: =IF(INDEX(Results_Long!$J:$J,$F15)="","NA",INDEX(Results_Long!$J:$J,$F15)) -> NA | J15: =IF(INDEX(Results_Long!$K:$K,$F15)="","NA",INDEX(Results_Long!$K:$K,$F15)) -> NA | K15: =IF(INDEX(Results_Long!$P:$P,$F15)="","NA",INDEX(Results_Long!$P:$P,$F15)) -> NA | L15: =IF(INDEX(Results_Long!$Q:$Q,$F15)="","NA",INDEX(Results_Long!$Q:$Q,$F15)) -> NA | M15: =IF(INDEX(Results_Long!$T:$T,$F15)="","NA",INDEX(Results_Long!$T:$T,$F15)) -> NA | N15: =IF(INDEX(Results_Long!$U:$U,$F15)="","NA",INDEX(Results_Long!$U:$U,$F15)) -> NA | O15: =IF(INDEX(Results_Long!$V:$V,$F15)="","NA",INDEX(Results_Long!$V:$V,$F15)) -> NA | P15: =IF(INDEX(Results_Long!$L:$L,$F15)="","NA",INDEX(Results_Long!$L:$L,$F15)) -> NA | Q15: =IF(INDEX(Results_Long!$M:$M,$F15)="","NA",INDEX(Results_Long!$M:$M,$F15)) -> NA | R15: =IF(INDEX(Results_Long!$N:$N,$F15)="","NA",INDEX(Results_Long!$N:$N,$F15)) -> NA | S15: =IF(INDEX(Results_Long!$O:$O,$F15)="","NA",INDEX(Results_Long!$O:$O,$F15)) -> NA | T15: =IF(INDEX(Results_Long!$AG:$AG,$F15)="","NA",INDEX(Results_Long!$AG:$AG,$F15)) -> NA | U15: =IF(INDEX(Results_Long!$AJ:$AJ,$F15)="","NA",INDEX(Results_Long!$AJ:$AJ,$F15)) -> resolution deferred: documented post-run step after TH-b (N3), never an automatic rewrite [DEC-044/DEC-045]; ex-ante expectation carried on the E1 primary-band row
A17: Interpretation
A18: Mechanical reading only: 'value' = 1{90% CI inside band}; TOST p = max of the two one-sided arms.
A19: Ex-ante expectation pinned result-blind [DEC-044/DEC-045]: the E1 primary-band arm was EXPECTED to fail (T1 CI edge -0.086); E2 adjudicates Tier 1, E1 calibrates the Tier-2 wording only (see row notes, verbatim).
A20: E1/E2 flags feed the documented gate-resolution step together with the TH-b Bayes factors (H2b); no equivalence language is attached in this workbook.
A22: Question | B22: Answer
A23: Why a 90% CI on the TOST rows? | B23: Two one-sided tests at alpha = .05 each are jointly equivalent to the 90% two-sided CI lying inside the band (Lakens 2017; Lakens et al. 2018); the mean rows keep conventional 95% CIs.
A24: Why bands 0.070 and 0.050? | B24: |r| = 0.070 is the pre-registered primary SESOI (F27v2); ±0.05 is the secondary band of the DEC-044 claim ladder; both were pinned before any Block-E estimate existed [DEC-045 E-pins].
A25: Does an E2 pass already license 'evidence of absence'? | B25: No. The language gate combines E2 with the H2b BF01 ladder and resolves only as a documented post-TH-b step [DEC-044]; this workbook reports mechanical flags.
A27: Verdict: Mechanical outcome: E1 equivalence flags = 0 at both bands; E2 secondary-band flag = 1 (see 'value' column); adjudication deferred to the documented gate-resolution step [DEC-044].

Sheet 7_H4_Break_Grid
A1: TH-a (Block E/H fast frequentist battery) · H4 - sup-break grid over admissible candidate years (2008-2019)
A2: Break coefficient per candidate year, cell-means parameterization; observed statistic = sup |t|; reference distribution single-homed in the TH-c workbook (Tab '9_H4_Perm_Sup').
A3: Run 2026-07-24 22:46 (canonical) · verifier R/06_verify_outputs.R 17/17 PASS · chat artefact check 2026-07-26 18/18 PASS · output/TH_a_results.csv 177x36
A5: Panel row | B5: analysis_id | C5: spec | D5: subset | E5: term | F5: RL row | G5: k_es | H5: k_st | I5: k_cl | J5: est_z | K5: ci_lb_z | L5: ci_ub_z | M5: est_r | N5: ci_lb_r | O5: ci_ub_r | P5: se_z | Q5: t | R5: df | S5: p | T5: value | U5: note (verbatim) | V5: year | W5: |t| (helper)
A6: break 2008 | B6: H4 | C6: break_2008 | D6: defined | E6: break | F6: =SUMPRODUCT((Results_Long!$A$2:$A$178=$B6)*(Results_Long!$B$2:$B$178=$C6)*(Results_Long!$C$2:$C$178=$D6)*(Results_Long!$D$2:$D$178=$E6)*ROW(Results_Long!$A$2:$A$178)) -> 12 | G6: =IF(INDEX(Results_Long!$H:$H,$F6)="","NA",INDEX(Results_Long!$H:$H,$F6)) -> 2705 | H6: =IF(INDEX(Results_Long!$I:$I,$F6)="","NA",INDEX(Results_Long!$I:$I,$F6)) -> 113 | I6: =IF(INDEX(Results_Long!$J:$J,$F6)="","NA",INDEX(Results_Long!$J:$J,$F6)) -> 112 | J6: =IF(INDEX(Results_Long!$K:$K,$F6)="","NA",INDEX(Results_Long!$K:$K,$F6)) -> -0.024026676 | K6: =IF(INDEX(Results_Long!$P:$P,$F6)="","NA",INDEX(Results_Long!$P:$P,$F6)) -> -0.061604665 | L6: =IF(INDEX(Results_Long!$Q:$Q,$F6)="","NA",INDEX(Results_Long!$Q:$Q,$F6)) -> 0.013551313 | M6: =IF(INDEX(Results_Long!$T:$T,$F6)="","NA",INDEX(Results_Long!$T:$T,$F6)) -> NA | N6: =IF(INDEX(Results_Long!$U:$U,$F6)="","NA",INDEX(Results_Long!$U:$U,$F6)) -> NA | O6: =IF(INDEX(Results_Long!$V:$V,$F6)="","NA",INDEX(Results_Long!$V:$V,$F6)) -> NA | P6: =IF(INDEX(Results_Long!$L:$L,$F6)="","NA",INDEX(Results_Long!$L:$L,$F6)) -> 0.0176243 | Q6: =IF(INDEX(Results_Long!$M:$M,$F6)="","NA",INDEX(Results_Long!$M:$M,$F6)) -> -1.3632698 | R6: =IF(INDEX(Results_Long!$N:$N,$F6)="","NA",INDEX(Results_Long!$N:$N,$F6)) -> 14.942101 | S6: =IF(INDEX(Results_Long!$O:$O,$F6)="","NA",INDEX(Results_Long!$O:$O,$F6)) -> 0.19298764 | T6: =IF(INDEX(Results_Long!$AG:$AG,$F6)="","NA",INDEX(Results_Long!$AG:$AG,$F6)) -> NA | U6: =IF(INDEX(Results_Long!$AJ:$AJ,$F6)="","NA",INDEX(Results_Long!$AJ:$AJ,$F6)) -> rma.mv mods=~ 0 + pp_cell (break 2008, cell-means); random ~1|cluster_id/study/esid; V blocks within cluster_id, rho=0.6; CR2/Satterthwaite on cluster_id [D31.1/A.2]; domain period domain 2705/113/112; post cell: 2367 ES / 100 studies / 99 clusters; rule: share_2008 >= 0.5, ties to Post [F60/DEC-024]; candidate year of the sup-break grid [DEC-045/H-Q6]; difference of Fisher-z means | V6: 2008 | W6: =IF($Q6="NA","NA",ABS($Q6)) -> 1.3632698
A7: break 2009 | B7: H4 | C7: break_2009 | D7: defined | E7: break | F7: =SUMPRODUCT((Results_Long!$A$2:$A$178=$B7)*(Results_Long!$B$2:$B$178=$C7)*(Results_Long!$C$2:$C$178=$D7)*(Results_Long!$D$2:$D$178=$E7)*ROW(Results_Long!$A$2:$A$178)) -> 13 | G7: =IF(INDEX(Results_Long!$H:$H,$F7)="","NA",INDEX(Results_Long!$H:$H,$F7)) -> 2705 | H7: =IF(INDEX(Results_Long!$I:$I,$F7)="","NA",INDEX(Results_Long!$I:$I,$F7)) -> 113 | I7: =IF(INDEX(Results_Long!$J:$J,$F7)="","NA",INDEX(Results_Long!$J:$J,$F7)) -> 112 | J7: =IF(INDEX(Results_Long!$K:$K,$F7)="","NA",INDEX(Results_Long!$K:$K,$F7)) -> -0.039526755 | K7: =IF(INDEX(Results_Long!$P:$P,$F7)="","NA",INDEX(Results_Long!$P:$P,$F7)) -> -0.084603525 | L7: =IF(INDEX(Results_Long!$Q:$Q,$F7)="","NA",INDEX(Results_Long!$Q:$Q,$F7)) -> 0.0055500143 | M7: =IF(INDEX(Results_Long!$T:$T,$F7)="","NA",INDEX(Results_Long!$T:$T,$F7)) -> NA | N7: =IF(INDEX(Results_Long!$U:$U,$F7)="","NA",INDEX(Results_Long!$U:$U,$F7)) -> NA | O7: =IF(INDEX(Results_Long!$V:$V,$F7)="","NA",INDEX(Results_Long!$V:$V,$F7)) -> NA | P7: =IF(INDEX(Results_Long!$L:$L,$F7)="","NA",INDEX(Results_Long!$L:$L,$F7)) -> 0.018622444 | Q7: =IF(INDEX(Results_Long!$M:$M,$F7)="","NA",INDEX(Results_Long!$M:$M,$F7)) -> -2.1225332 | R7: =IF(INDEX(Results_Long!$N:$N,$F7)="","NA",INDEX(Results_Long!$N:$N,$F7)) -> 6.2816543 | S7: =IF(INDEX(Results_Long!$O:$O,$F7)="","NA",INDEX(Results_Long!$O:$O,$F7)) -> 0.075948862 | T7: =IF(INDEX(Results_Long!$AG:$AG,$F7)="","NA",INDEX(Results_Long!$AG:$AG,$F7)) -> NA | U7: =IF(INDEX(Results_Long!$AJ:$AJ,$F7)="","NA",INDEX(Results_Long!$AJ:$AJ,$F7)) -> rma.mv mods=~ 0 + pp_cell (break 2009, cell-means); random ~1|cluster_id/study/esid; V blocks within cluster_id, rho=0.6; CR2/Satterthwaite on cluster_id [D31.1/A.2]; domain period domain 2705/113/112; post cell: 2345 ES / 99 studies / 98 clusters; rule: share_2009 >= 0.5, ties to Post [F60/DEC-024]; candidate year of the sup-break grid [DEC-045/H-Q6]; difference of Fisher-z means | V7: 2009 | W7: =IF($Q7="NA","NA",ABS($Q7)) -> 2.1225332
A8: break 2010 | B8: H4 | C8: break_2010 | D8: defined | E8: break | F8: =SUMPRODUCT((Results_Long!$A$2:$A$178=$B8)*(Results_Long!$B$2:$B$178=$C8)*(Results_Long!$C$2:$C$178=$D8)*(Results_Long!$D$2:$D$178=$E8)*ROW(Results_Long!$A$2:$A$178)) -> 14 | G8: =IF(INDEX(Results_Long!$H:$H,$F8)="","NA",INDEX(Results_Long!$H:$H,$F8)) -> 2705 | H8: =IF(INDEX(Results_Long!$I:$I,$F8)="","NA",INDEX(Results_Long!$I:$I,$F8)) -> 113 | I8: =IF(INDEX(Results_Long!$J:$J,$F8)="","NA",INDEX(Results_Long!$J:$J,$F8)) -> 112 | J8: =IF(INDEX(Results_Long!$K:$K,$F8)="","NA",INDEX(Results_Long!$K:$K,$F8)) -> -0.036534391 | K8: =IF(INDEX(Results_Long!$P:$P,$F8)="","NA",INDEX(Results_Long!$P:$P,$F8)) -> -0.082461362 | L8: =IF(INDEX(Results_Long!$Q:$Q,$F8)="","NA",INDEX(Results_Long!$Q:$Q,$F8)) -> 0.0093925811 | M8: =IF(INDEX(Results_Long!$T:$T,$F8)="","NA",INDEX(Results_Long!$T:$T,$F8)) -> NA | N8: =IF(INDEX(Results_Long!$U:$U,$F8)="","NA",INDEX(Results_Long!$U:$U,$F8)) -> NA | O8: =IF(INDEX(Results_Long!$V:$V,$F8)="","NA",INDEX(Results_Long!$V:$V,$F8)) -> NA | P8: =IF(INDEX(Results_Long!$L:$L,$F8)="","NA",INDEX(Results_Long!$L:$L,$F8)) -> 0.019295162 | Q8: =IF(INDEX(Results_Long!$M:$M,$F8)="","NA",INDEX(Results_Long!$M:$M,$F8)) -> -1.8934483 | R8: =IF(INDEX(Results_Long!$N:$N,$F8)="","NA",INDEX(Results_Long!$N:$N,$F8)) -> 6.7804765 | S8: =IF(INDEX(Results_Long!$O:$O,$F8)="","NA",INDEX(Results_Long!$O:$O,$F8)) -> 0.10152293 | T8: =IF(INDEX(Results_Long!$AG:$AG,$F8)="","NA",INDEX(Results_Long!$AG:$AG,$F8)) -> NA | U8: =IF(INDEX(Results_Long!$AJ:$AJ,$F8)="","NA",INDEX(Results_Long!$AJ:$AJ,$F8)) -> rma.mv mods=~ 0 + pp_cell (break 2010, cell-means); random ~1|cluster_id/study/esid; V blocks within cluster_id, rho=0.6; CR2/Satterthwaite on cluster_id [D31.1/A.2]; domain period domain 2705/113/112; post cell: 2326 ES / 98 studies / 97 clusters; rule: share_2010 >= 0.5, ties to Post [F60/DEC-024]; candidate year of the sup-break grid [DEC-045/H-Q6]; difference of Fisher-z means | V8: 2010 | W8: =IF($Q8="NA","NA",ABS($Q8)) -> 1.8934483
A9: break 2011 | B9: H4 | C9: break_2011 | D9: defined | E9: break | F9: =SUMPRODUCT((Results_Long!$A$2:$A$178=$B9)*(Results_Long!$B$2:$B$178=$C9)*(Results_Long!$C$2:$C$178=$D9)*(Results_Long!$D$2:$D$178=$E9)*ROW(Results_Long!$A$2:$A$178)) -> 15 | G9: =IF(INDEX(Results_Long!$H:$H,$F9)="","NA",INDEX(Results_Long!$H:$H,$F9)) -> 2705 | H9: =IF(INDEX(Results_Long!$I:$I,$F9)="","NA",INDEX(Results_Long!$I:$I,$F9)) -> 113 | I9: =IF(INDEX(Results_Long!$J:$J,$F9)="","NA",INDEX(Results_Long!$J:$J,$F9)) -> 112 | J9: =IF(INDEX(Results_Long!$K:$K,$F9)="","NA",INDEX(Results_Long!$K:$K,$F9)) -> -0.033330835 | K9: =IF(INDEX(Results_Long!$P:$P,$F9)="","NA",INDEX(Results_Long!$P:$P,$F9)) -> -0.075693221 | L9: =IF(INDEX(Results_Long!$Q:$Q,$F9)="","NA",INDEX(Results_Long!$Q:$Q,$F9)) -> 0.0090315501 | M9: =IF(INDEX(Results_Long!$T:$T,$F9)="","NA",INDEX(Results_Long!$T:$T,$F9)) -> NA | N9: =IF(INDEX(Results_Long!$U:$U,$F9)="","NA",INDEX(Results_Long!$U:$U,$F9)) -> NA | O9: =IF(INDEX(Results_Long!$V:$V,$F9)="","NA",INDEX(Results_Long!$V:$V,$F9)) -> NA | P9: =IF(INDEX(Results_Long!$L:$L,$F9)="","NA",INDEX(Results_Long!$L:$L,$F9)) -> 0.018895156 | Q9: =IF(INDEX(Results_Long!$M:$M,$F9)="","NA",INDEX(Results_Long!$M:$M,$F9)) -> -1.7639884 | R9: =IF(INDEX(Results_Long!$N:$N,$F9)="","NA",INDEX(Results_Long!$N:$N,$F9)) -> 9.5644089 | S9: =IF(INDEX(Results_Long!$O:$O,$F9)="","NA",INDEX(Results_Long!$O:$O,$F9)) -> 0.10957911 | T9: =IF(INDEX(Results_Long!$AG:$AG,$F9)="","NA",INDEX(Results_Long!$AG:$AG,$F9)) -> NA | U9: =IF(INDEX(Results_Long!$AJ:$AJ,$F9)="","NA",INDEX(Results_Long!$AJ:$AJ,$F9)) -> rma.mv mods=~ 0 + pp_cell (break 2011, cell-means); random ~1|cluster_id/study/esid; V blocks within cluster_id, rho=0.6; CR2/Satterthwaite on cluster_id [D31.1/A.2]; domain period domain 2705/113/112; post cell: 2077 ES / 93 studies / 92 clusters; rule: share_2011 >= 0.5, ties to Post [F60/DEC-024]; candidate year of the sup-break grid [DEC-045/H-Q6]; difference of Fisher-z means | V9: 2011 | W9: =IF($Q9="NA","NA",ABS($Q9)) -> 1.7639884
A10: break 2012 | B10: H4 | C10: break_2012 | D10: defined | E10: break | F10: =SUMPRODUCT((Results_Long!$A$2:$A$178=$B10)*(Results_Long!$B$2:$B$178=$C10)*(Results_Long!$C$2:$C$178=$D10)*(Results_Long!$D$2:$D$178=$E10)*ROW(Results_Long!$A$2:$A$178)) -> 16 | G10: =IF(INDEX(Results_Long!$H:$H,$F10)="","NA",INDEX(Results_Long!$H:$H,$F10)) -> 2705 | H10: =IF(INDEX(Results_Long!$I:$I,$F10)="","NA",INDEX(Results_Long!$I:$I,$F10)) -> 113 | I10: =IF(INDEX(Results_Long!$J:$J,$F10)="","NA",INDEX(Results_Long!$J:$J,$F10)) -> 112 | J10: =IF(INDEX(Results_Long!$K:$K,$F10)="","NA",INDEX(Results_Long!$K:$K,$F10)) -> -0.00094643433 | K10: =IF(INDEX(Results_Long!$P:$P,$F10)="","NA",INDEX(Results_Long!$P:$P,$F10)) -> -0.038387516 | L10: =IF(INDEX(Results_Long!$Q:$Q,$F10)="","NA",INDEX(Results_Long!$Q:$Q,$F10)) -> 0.036494647 | M10: =IF(INDEX(Results_Long!$T:$T,$F10)="","NA",INDEX(Results_Long!$T:$T,$F10)) -> NA | N10: =IF(INDEX(Results_Long!$U:$U,$F10)="","NA",INDEX(Results_Long!$U:$U,$F10)) -> NA | O10: =IF(INDEX(Results_Long!$V:$V,$F10)="","NA",INDEX(Results_Long!$V:$V,$F10)) -> NA | P10: =IF(INDEX(Results_Long!$L:$L,$F10)="","NA",INDEX(Results_Long!$L:$L,$F10)) -> 0.017128675 | Q10: =IF(INDEX(Results_Long!$M:$M,$F10)="","NA",INDEX(Results_Long!$M:$M,$F10)) -> -0.055254382 | R10: =IF(INDEX(Results_Long!$N:$N,$F10)="","NA",INDEX(Results_Long!$N:$N,$F10)) -> 11.660405 | S10: =IF(INDEX(Results_Long!$O:$O,$F10)="","NA",INDEX(Results_Long!$O:$O,$F10)) -> 0.95687124 | T10: =IF(INDEX(Results_Long!$AG:$AG,$F10)="","NA",INDEX(Results_Long!$AG:$AG,$F10)) -> NA | U10: =IF(INDEX(Results_Long!$AJ:$AJ,$F10)="","NA",INDEX(Results_Long!$AJ:$AJ,$F10)) -> rma.mv mods=~ 0 + pp_cell (break 2012, cell-means); random ~1|cluster_id/study/esid; V blocks within cluster_id, rho=0.6; CR2/Satterthwaite on cluster_id [D31.1/A.2]; domain period domain 2705/113/112; post cell: 1769 ES / 82 studies / 81 clusters; rule: share_2012 >= 0.5, ties to Post [F60/DEC-024]; candidate year of the sup-break grid [DEC-045/H-Q6]; difference of Fisher-z means | V10: 2012 | W10: =IF($Q10="NA","NA",ABS($Q10)) -> 0.055254382
A11: break 2013 | B11: H4 | C11: break_2013 | D11: defined | E11: break | F11: =SUMPRODUCT((Results_Long!$A$2:$A$178=$B11)*(Results_Long!$B$2:$B$178=$C11)*(Results_Long!$C$2:$C$178=$D11)*(Results_Long!$D$2:$D$178=$E11)*ROW(Results_Long!$A$2:$A$178)) -> 17 | G11: =IF(INDEX(Results_Long!$H:$H,$F11)="","NA",INDEX(Results_Long!$H:$H,$F11)) -> 2705 | H11: =IF(INDEX(Results_Long!$I:$I,$F11)="","NA",INDEX(Results_Long!$I:$I,$F11)) -> 113 | I11: =IF(INDEX(Results_Long!$J:$J,$F11)="","NA",INDEX(Results_Long!$J:$J,$F11)) -> 112 | J11: =IF(INDEX(Results_Long!$K:$K,$F11)="","NA",INDEX(Results_Long!$K:$K,$F11)) -> 0.025954305 | K11: =IF(INDEX(Results_Long!$P:$P,$F11)="","NA",INDEX(Results_Long!$P:$P,$F11)) -> -0.020202989 | L11: =IF(INDEX(Results_Long!$Q:$Q,$F11)="","NA",INDEX(Results_Long!$Q:$Q,$F11)) -> 0.072111598 | M11: =IF(INDEX(Results_Long!$T:$T,$F11)="","NA",INDEX(Results_Long!$T:$T,$F11)) -> NA | N11: =IF(INDEX(Results_Long!$U:$U,$F11)="","NA",INDEX(Results_Long!$U:$U,$F11)) -> NA | O11: =IF(INDEX(Results_Long!$V:$V,$F11)="","NA",INDEX(Results_Long!$V:$V,$F11)) -> NA | P11: =IF(INDEX(Results_Long!$L:$L,$F11)="","NA",INDEX(Results_Long!$L:$L,$F11)) -> 0.021560617 | Q11: =IF(INDEX(Results_Long!$M:$M,$F11)="","NA",INDEX(Results_Long!$M:$M,$F11)) -> 1.203783 | R11: =IF(INDEX(Results_Long!$N:$N,$F11)="","NA",INDEX(Results_Long!$N:$N,$F11)) -> 14.28239 | S11: =IF(INDEX(Results_Long!$O:$O,$F11)="","NA",INDEX(Results_Long!$O:$O,$F11)) -> 0.24824616 | T11: =IF(INDEX(Results_Long!$AG:$AG,$F11)="","NA",INDEX(Results_Long!$AG:$AG,$F11)) -> NA | U11: =IF(INDEX(Results_Long!$AJ:$AJ,$F11)="","NA",INDEX(Results_Long!$AJ:$AJ,$F11)) -> rma.mv mods=~ 0 + pp_cell (break 2013, cell-means); random ~1|cluster_id/study/esid; V blocks within cluster_id, rho=0.6; CR2/Satterthwaite on cluster_id [D31.1/A.2]; domain period domain 2705/113/112; post cell: 1486 ES / 69 studies / 69 clusters; rule: share_2013 >= 0.5, ties to Post [F60/DEC-024]; candidate year of the sup-break grid [DEC-045/H-Q6]; difference of Fisher-z means | V11: 2013 | W11: =IF($Q11="NA","NA",ABS($Q11)) -> 1.203783
A12: break 2014 | B12: H4 | C12: break_2014 | D12: defined | E12: break | F12: =SUMPRODUCT((Results_Long!$A$2:$A$178=$B12)*(Results_Long!$B$2:$B$178=$C12)*(Results_Long!$C$2:$C$178=$D12)*(Results_Long!$D$2:$D$178=$E12)*ROW(Results_Long!$A$2:$A$178)) -> 18 | G12: =IF(INDEX(Results_Long!$H:$H,$F12)="","NA",INDEX(Results_Long!$H:$H,$F12)) -> 2705 | H12: =IF(INDEX(Results_Long!$I:$I,$F12)="","NA",INDEX(Results_Long!$I:$I,$F12)) -> 113 | I12: =IF(INDEX(Results_Long!$J:$J,$F12)="","NA",INDEX(Results_Long!$J:$J,$F12)) -> 112 | J12: =IF(INDEX(Results_Long!$K:$K,$F12)="","NA",INDEX(Results_Long!$K:$K,$F12)) -> 0.023149446 | K12: =IF(INDEX(Results_Long!$P:$P,$F12)="","NA",INDEX(Results_Long!$P:$P,$F12)) -> -0.024037398 | L12: =IF(INDEX(Results_Long!$Q:$Q,$F12)="","NA",INDEX(Results_Long!$Q:$Q,$F12)) -> 0.070336289 | M12: =IF(INDEX(Results_Long!$T:$T,$F12)="","NA",INDEX(Results_Long!$T:$T,$F12)) -> NA | N12: =IF(INDEX(Results_Long!$U:$U,$F12)="","NA",INDEX(Results_Long!$U:$U,$F12)) -> NA | O12: =IF(INDEX(Results_Long!$V:$V,$F12)="","NA",INDEX(Results_Long!$V:$V,$F12)) -> NA | P12: =IF(INDEX(Results_Long!$L:$L,$F12)="","NA",INDEX(Results_Long!$L:$L,$F12)) -> 0.022786093 | Q12: =IF(INDEX(Results_Long!$M:$M,$F12)="","NA",INDEX(Results_Long!$M:$M,$F12)) -> 1.0159463 | R12: =IF(INDEX(Results_Long!$N:$N,$F12)="","NA",INDEX(Results_Long!$N:$N,$F12)) -> 22.565949 | S12: =IF(INDEX(Results_Long!$O:$O,$F12)="","NA",INDEX(Results_Long!$O:$O,$F12)) -> 0.32042466 | T12: =IF(INDEX(Results_Long!$AG:$AG,$F12)="","NA",INDEX(Results_Long!$AG:$AG,$F12)) -> NA | U12: =IF(INDEX(Results_Long!$AJ:$AJ,$F12)="","NA",INDEX(Results_Long!$AJ:$AJ,$F12)) -> rma.mv mods=~ 0 + pp_cell (break 2014, cell-means); random ~1|cluster_id/study/esid; V blocks within cluster_id, rho=0.6; CR2/Satterthwaite on cluster_id [D31.1/A.2]; domain period domain 2705/113/112; post cell: 1269 ES / 55 studies / 55 clusters; rule: share_2014 >= 0.5, ties to Post [F60/DEC-024]; candidate year of the sup-break grid [DEC-045/H-Q6]; difference of Fisher-z means | V12: 2014 | W12: =IF($Q12="NA","NA",ABS($Q12)) -> 1.0159463
A13: break 2015 | B13: H4 | C13: break_2015 | D13: defined | E13: break | F13: =SUMPRODUCT((Results_Long!$A$2:$A$178=$B13)*(Results_Long!$B$2:$B$178=$C13)*(Results_Long!$C$2:$C$178=$D13)*(Results_Long!$D$2:$D$178=$E13)*ROW(Results_Long!$A$2:$A$178)) -> 19 | G13: =IF(INDEX(Results_Long!$H:$H,$F13)="","NA",INDEX(Results_Long!$H:$H,$F13)) -> 2705 | H13: =IF(INDEX(Results_Long!$I:$I,$F13)="","NA",INDEX(Results_Long!$I:$I,$F13)) -> 113 | I13: =IF(INDEX(Results_Long!$J:$J,$F13)="","NA",INDEX(Results_Long!$J:$J,$F13)) -> 112 | J13: =IF(INDEX(Results_Long!$K:$K,$F13)="","NA",INDEX(Results_Long!$K:$K,$F13)) -> 0.0023798646 | K13: =IF(INDEX(Results_Long!$P:$P,$F13)="","NA",INDEX(Results_Long!$P:$P,$F13)) -> -0.040290136 | L13: =IF(INDEX(Results_Long!$Q:$Q,$F13)="","NA",INDEX(Results_Long!$Q:$Q,$F13)) -> 0.045049866 | M13: =IF(INDEX(Results_Long!$T:$T,$F13)="","NA",INDEX(Results_Long!$T:$T,$F13)) -> NA | N13: =IF(INDEX(Results_Long!$U:$U,$F13)="","NA",INDEX(Results_Long!$U:$U,$F13)) -> NA | O13: =IF(INDEX(Results_Long!$V:$V,$F13)="","NA",INDEX(Results_Long!$V:$V,$F13)) -> NA | P13: =IF(INDEX(Results_Long!$L:$L,$F13)="","NA",INDEX(Results_Long!$L:$L,$F13)) -> 0.020323441 | Q13: =IF(INDEX(Results_Long!$M:$M,$F13)="","NA",INDEX(Results_Long!$M:$M,$F13)) -> 0.11709949 | R13: =IF(INDEX(Results_Long!$N:$N,$F13)="","NA",INDEX(Results_Long!$N:$N,$F13)) -> 18.166087 | S13: =IF(INDEX(Results_Long!$O:$O,$F13)="","NA",INDEX(Results_Long!$O:$O,$F13)) -> 0.90806615 | T13: =IF(INDEX(Results_Long!$AG:$AG,$F13)="","NA",INDEX(Results_Long!$AG:$AG,$F13)) -> NA | U13: =IF(INDEX(Results_Long!$AJ:$AJ,$F13)="","NA",INDEX(Results_Long!$AJ:$AJ,$F13)) -> rma.mv mods=~ 0 + pp_cell (break 2015, cell-means); random ~1|cluster_id/study/esid; V blocks within cluster_id, rho=0.6; CR2/Satterthwaite on cluster_id [D31.1/A.2]; domain period domain 2705/113/112; post cell: 784 ES / 38 studies / 38 clusters; rule: share_2015 >= 0.5, ties to Post [F60/DEC-024]; candidate year of the sup-break grid [DEC-045/H-Q6]; difference of Fisher-z means | V13: 2015 | W13: =IF($Q13="NA","NA",ABS($Q13)) -> 0.11709949
A14: break 2016 | B14: H4 | C14: break_2016 | D14: defined | E14: break | F14: =SUMPRODUCT((Results_Long!$A$2:$A$178=$B14)*(Results_Long!$B$2:$B$178=$C14)*(Results_Long!$C$2:$C$178=$D14)*(Results_Long!$D$2:$D$178=$E14)*ROW(Results_Long!$A$2:$A$178)) -> 20 | G14: =IF(INDEX(Results_Long!$H:$H,$F14)="","NA",INDEX(Results_Long!$H:$H,$F14)) -> 2705 | H14: =IF(INDEX(Results_Long!$I:$I,$F14)="","NA",INDEX(Results_Long!$I:$I,$F14)) -> 113 | I14: =IF(INDEX(Results_Long!$J:$J,$F14)="","NA",INDEX(Results_Long!$J:$J,$F14)) -> 112 | J14: =IF(INDEX(Results_Long!$K:$K,$F14)="","NA",INDEX(Results_Long!$K:$K,$F14)) -> 0.010175907 | K14: =IF(INDEX(Results_Long!$P:$P,$F14)="","NA",INDEX(Results_Long!$P:$P,$F14)) -> -0.028420631 | L14: =IF(INDEX(Results_Long!$Q:$Q,$F14)="","NA",INDEX(Results_Long!$Q:$Q,$F14)) -> 0.048772445 | M14: =IF(INDEX(Results_Long!$T:$T,$F14)="","NA",INDEX(Results_Long!$T:$T,$F14)) -> NA | N14: =IF(INDEX(Results_Long!$U:$U,$F14)="","NA",INDEX(Results_Long!$U:$U,$F14)) -> NA | O14: =IF(INDEX(Results_Long!$V:$V,$F14)="","NA",INDEX(Results_Long!$V:$V,$F14)) -> NA | P14: =IF(INDEX(Results_Long!$L:$L,$F14)="","NA",INDEX(Results_Long!$L:$L,$F14)) -> 0.018107282 | Q14: =IF(INDEX(Results_Long!$M:$M,$F14)="","NA",INDEX(Results_Long!$M:$M,$F14)) -> 0.56197868 | R14: =IF(INDEX(Results_Long!$N:$N,$F14)="","NA",INDEX(Results_Long!$N:$N,$F14)) -> 14.992066 | S14: =IF(INDEX(Results_Long!$O:$O,$F14)="","NA",INDEX(Results_Long!$O:$O,$F14)) -> 0.58243573 | T14: =IF(INDEX(Results_Long!$AG:$AG,$F14)="","NA",INDEX(Results_Long!$AG:$AG,$F14)) -> NA | U14: =IF(INDEX(Results_Long!$AJ:$AJ,$F14)="","NA",INDEX(Results_Long!$AJ:$AJ,$F14)) -> rma.mv mods=~ 0 + pp_cell (break 2016, cell-means); random ~1|cluster_id/study/esid; V blocks within cluster_id, rho=0.6; CR2/Satterthwaite on cluster_id [D31.1/A.2]; domain period domain 2705/113/112; post cell: 711 ES / 31 studies / 31 clusters; rule: share_2016 >= 0.5, ties to Post [F60/DEC-024]; candidate year of the sup-break grid [DEC-045/H-Q6]; difference of Fisher-z means | V14: 2016 | W14: =IF($Q14="NA","NA",ABS($Q14)) -> 0.56197868
A15: break 2017 | B15: H4 | C15: break_2017 | D15: defined | E15: break | F15: =SUMPRODUCT((Results_Long!$A$2:$A$178=$B15)*(Results_Long!$B$2:$B$178=$C15)*(Results_Long!$C$2:$C$178=$D15)*(Results_Long!$D$2:$D$178=$E15)*ROW(Results_Long!$A$2:$A$178)) -> 21 | G15: =IF(INDEX(Results_Long!$H:$H,$F15)="","NA",INDEX(Results_Long!$H:$H,$F15)) -> 2705 | H15: =IF(INDEX(Results_Long!$I:$I,$F15)="","NA",INDEX(Results_Long!$I:$I,$F15)) -> 113 | I15: =IF(INDEX(Results_Long!$J:$J,$F15)="","NA",INDEX(Results_Long!$J:$J,$F15)) -> 112 | J15: =IF(INDEX(Results_Long!$K:$K,$F15)="","NA",INDEX(Results_Long!$K:$K,$F15)) -> 0.0080340694 | K15: =IF(INDEX(Results_Long!$P:$P,$F15)="","NA",INDEX(Results_Long!$P:$P,$F15)) -> -0.031649894 | L15: =IF(INDEX(Results_Long!$Q:$Q,$F15)="","NA",INDEX(Results_Long!$Q:$Q,$F15)) -> 0.047718033 | M15: =IF(INDEX(Results_Long!$T:$T,$F15)="","NA",INDEX(Results_Long!$T:$T,$F15)) -> NA | N15: =IF(INDEX(Results_Long!$U:$U,$F15)="","NA",INDEX(Results_Long!$U:$U,$F15)) -> NA | O15: =IF(INDEX(Results_Long!$V:$V,$F15)="","NA",INDEX(Results_Long!$V:$V,$F15)) -> NA | P15: =IF(INDEX(Results_Long!$L:$L,$F15)="","NA",INDEX(Results_Long!$L:$L,$F15)) -> 0.018000133 | Q15: =IF(INDEX(Results_Long!$M:$M,$F15)="","NA",INDEX(Results_Long!$M:$M,$F15)) -> 0.4463339 | R15: =IF(INDEX(Results_Long!$N:$N,$F15)="","NA",INDEX(Results_Long!$N:$N,$F15)) -> 10.852183 | S15: =IF(INDEX(Results_Long!$O:$O,$F15)="","NA",INDEX(Results_Long!$O:$O,$F15)) -> 0.6641308 | T15: =IF(INDEX(Results_Long!$AG:$AG,$F15)="","NA",INDEX(Results_Long!$AG:$AG,$F15)) -> NA | U15: =IF(INDEX(Results_Long!$AJ:$AJ,$F15)="","NA",INDEX(Results_Long!$AJ:$AJ,$F15)) -> rma.mv mods=~ 0 + pp_cell (break 2017, cell-means); random ~1|cluster_id/study/esid; V blocks within cluster_id, rho=0.6; CR2/Satterthwaite on cluster_id [D31.1/A.2]; domain period domain 2705/113/112; post cell: 623 ES / 23 studies / 23 clusters; rule: share_2017 >= 0.5, ties to Post [F60/DEC-024]; candidate year of the sup-break grid [DEC-045/H-Q6]; difference of Fisher-z means | V15: 2017 | W15: =IF($Q15="NA","NA",ABS($Q15)) -> 0.4463339
A16: break 2018 | B16: H4 | C16: break_2018 | D16: defined | E16: break | F16: =SUMPRODUCT((Results_Long!$A$2:$A$178=$B16)*(Results_Long!$B$2:$B$178=$C16)*(Results_Long!$C$2:$C$178=$D16)*(Results_Long!$D$2:$D$178=$E16)*ROW(Results_Long!$A$2:$A$178)) -> 22 | G16: =IF(INDEX(Results_Long!$H:$H,$F16)="","NA",INDEX(Results_Long!$H:$H,$F16)) -> 2705 | H16: =IF(INDEX(Results_Long!$I:$I,$F16)="","NA",INDEX(Results_Long!$I:$I,$F16)) -> 113 | I16: =IF(INDEX(Results_Long!$J:$J,$F16)="","NA",INDEX(Results_Long!$J:$J,$F16)) -> 112 | J16: =IF(INDEX(Results_Long!$K:$K,$F16)="","NA",INDEX(Results_Long!$K:$K,$F16)) -> 0.0031230426 | K16: =IF(INDEX(Results_Long!$P:$P,$F16)="","NA",INDEX(Results_Long!$P:$P,$F16)) -> -0.04345977 | L16: =IF(INDEX(Results_Long!$Q:$Q,$F16)="","NA",INDEX(Results_Long!$Q:$Q,$F16)) -> 0.049705855 | M16: =IF(INDEX(Results_Long!$T:$T,$F16)="","NA",INDEX(Results_Long!$T:$T,$F16)) -> NA | N16: =IF(INDEX(Results_Long!$U:$U,$F16)="","NA",INDEX(Results_Long!$U:$U,$F16)) -> NA | O16: =IF(INDEX(Results_Long!$V:$V,$F16)="","NA",INDEX(Results_Long!$V:$V,$F16)) -> NA | P16: =IF(INDEX(Results_Long!$L:$L,$F16)="","NA",INDEX(Results_Long!$L:$L,$F16)) -> 0.022238266 | Q16: =IF(INDEX(Results_Long!$M:$M,$F16)="","NA",INDEX(Results_Long!$M:$M,$F16)) -> 0.14043553 | R16: =IF(INDEX(Results_Long!$N:$N,$F16)="","NA",INDEX(Results_Long!$N:$N,$F16)) -> 18.776144 | S16: =IF(INDEX(Results_Long!$O:$O,$F16)="","NA",INDEX(Results_Long!$O:$O,$F16)) -> 0.88981151 | T16: =IF(INDEX(Results_Long!$AG:$AG,$F16)="","NA",INDEX(Results_Long!$AG:$AG,$F16)) -> NA | U16: =IF(INDEX(Results_Long!$AJ:$AJ,$F16)="","NA",INDEX(Results_Long!$AJ:$AJ,$F16)) -> rma.mv mods=~ 0 + pp_cell (break 2018, cell-means); random ~1|cluster_id/study/esid; V blocks within cluster_id, rho=0.6; CR2/Satterthwaite on cluster_id [D31.1/A.2]; domain period domain 2705/113/112; post cell: 506 ES / 15 studies / 15 clusters; rule: share_2018 >= 0.5, ties to Post [F60/DEC-024]; candidate year of the sup-break grid [DEC-045/H-Q6]; difference of Fisher-z means | V16: 2018 | W16: =IF($Q16="NA","NA",ABS($Q16)) -> 0.14043553
A17: break 2019 | B17: H4 | C17: break_2019 | D17: defined | E17: break | F17: =SUMPRODUCT((Results_Long!$A$2:$A$178=$B17)*(Results_Long!$B$2:$B$178=$C17)*(Results_Long!$C$2:$C$178=$D17)*(Results_Long!$D$2:$D$178=$E17)*ROW(Results_Long!$A$2:$A$178)) -> 23 | G17: =IF(INDEX(Results_Long!$H:$H,$F17)="","NA",INDEX(Results_Long!$H:$H,$F17)) -> 2705 | H17: =IF(INDEX(Results_Long!$I:$I,$F17)="","NA",INDEX(Results_Long!$I:$I,$F17)) -> 113 | I17: =IF(INDEX(Results_Long!$J:$J,$F17)="","NA",INDEX(Results_Long!$J:$J,$F17)) -> 112 | J17: =IF(INDEX(Results_Long!$K:$K,$F17)="","NA",INDEX(Results_Long!$K:$K,$F17)) -> 0.0042056666 | K17: =IF(INDEX(Results_Long!$P:$P,$F17)="","NA",INDEX(Results_Long!$P:$P,$F17)) -> -0.044236954 | L17: =IF(INDEX(Results_Long!$Q:$Q,$F17)="","NA",INDEX(Results_Long!$Q:$Q,$F17)) -> 0.052648287 | M17: =IF(INDEX(Results_Long!$T:$T,$F17)="","NA",INDEX(Results_Long!$T:$T,$F17)) -> NA | N17: =IF(INDEX(Results_Long!$U:$U,$F17)="","NA",INDEX(Results_Long!$U:$U,$F17)) -> NA | O17: =IF(INDEX(Results_Long!$V:$V,$F17)="","NA",INDEX(Results_Long!$V:$V,$F17)) -> NA | P17: =IF(INDEX(Results_Long!$L:$L,$F17)="","NA",INDEX(Results_Long!$L:$L,$F17)) -> 0.022784454 | Q17: =IF(INDEX(Results_Long!$M:$M,$F17)="","NA",INDEX(Results_Long!$M:$M,$F17)) -> 0.18458491 | R17: =IF(INDEX(Results_Long!$N:$N,$F17)="","NA",INDEX(Results_Long!$N:$N,$F17)) -> 15.443904 | S17: =IF(INDEX(Results_Long!$O:$O,$F17)="","NA",INDEX(Results_Long!$O:$O,$F17)) -> 0.85595667 | T17: =IF(INDEX(Results_Long!$AG:$AG,$F17)="","NA",INDEX(Results_Long!$AG:$AG,$F17)) -> NA | U17: =IF(INDEX(Results_Long!$AJ:$AJ,$F17)="","NA",INDEX(Results_Long!$AJ:$AJ,$F17)) -> rma.mv mods=~ 0 + pp_cell (break 2019, cell-means); random ~1|cluster_id/study/esid; V blocks within cluster_id, rho=0.6; CR2/Satterthwaite on cluster_id [D31.1/A.2]; domain period domain 2705/113/112; post cell: 323 ES / 13 studies / 13 clusters; rule: share_2019 >= 0.5, ties to Post [F60/DEC-024]; candidate year of the sup-break grid [DEC-045/H-Q6]; difference of Fisher-z means | V17: 2019 | W17: =IF($Q17="NA","NA",ABS($Q17)) -> 0.18458491
