Workbook

Sheet 1_README
A1: TH-c (simulation & permutation family) · README
A2: Template: docs/results_workbook_template.md (binding; 13-tab SOMA)
A3: Run finished 2026-07-26 17:39 (canonical) · runtime 44.3 h · verifier R/09_verify_outputs.R 19/19 PASS · chat artefact check 2026-07-26 18/18 PASS · output/TH_c_results.csv 1347x36 · counters fits/fallback/fail: 11,500/92/0 (pass) · 540/3/0 (curve) · 200/2/0 (calibration) · eff_B 500/500/500 · not_estimable cells: 0
A5: Item | B5: Value
A6: Workbook version | B6: v1.0 (built post-run by project chat; verifier never reads this file)
A7: Method one-liner | B7: Simulation & permutation family: design-based MDE/power battery with full-REML calibration (H1), 1,260-cell specification curve with joint time-translation permutation (H3), permutation references for the sup-break (H4) and race (H5) statistics.
A8: Scope | B8: H1 (6 scenarios x 9-point delta grid + calibration), H3 (1,260 cells + core family + whole-curve stats), H4 perm, H5 perm; period domain 2,705 ES / 113 studies / 112 clusters.
A9: Repo / commit basis | B9: rwitte-wu-research/FOMA-CER-COD-Paris; chain 5a99de6 -> e44fce7 (#12) -> fce9d3a (#13) -> dafd95e (#14); family commit lands on dafd95e (main = origin)
A10: Computational stack | B10: R 4.6.1 (ucrt) · metafor 5.0-1 · clubSandwich 0.7.0 · Matrix 1.7-5 · Windows 11 x64 (26200) · reference BLAS single-threaded + per-worker thread guards
A11: Scripts | B11: R/09_sim_perm.R + R/09_verify_outputs.R (paired verifier, 19/19 PASS)
A12: Decision basis | B12: DEC-045 (E/H execution spec incl. supersessions S1-S9) · DEC-031f (optimizer ladder) · DEC-044 (framing A; language gate UNRESOLVED - see 3_Interpretation_Guide)
A13: Framing gate | B13: Framing gate [DEC-044]: all TOST flags and permutation p-values in this workbook are MECHANICAL values; no evidence-of-absence or verdict language is used anywhere; adjudication happens as the documented gate-resolution step after TH-b (H2a/H2b RoBMA).
A14: TAB-INDEX | B14: 1_README | 2_Methodology | 3_Interpretation_Guide | 4_Formula_Reference | 5_Data_Provenance | 6_H1_MDE_Power | 7_H3_Spec_Curve | 8_H3_Core_Family | 9_H4_Perm_Sup | 10_H5_Perm_Race | Results_Long | Manuscript_Inputs | Manuscript_Text_Blocks

Sheet 2_Methodology
A1: TH-c (simulation & permutation family) · Methodology
A2: Quantity | Formula / Construction | Reference (project notation)
A3: Run finished 2026-07-26 17:39 (canonical) · runtime 44.3 h · verifier R/09_verify_outputs.R 19/19 PASS · chat artefact check 2026-07-26 18/18 PASS · output/TH_c_results.csv 1347x36 · counters fits/fallback/fail: 11,500/92/0 (pass) · 540/3/0 (curve) · 200/2/0 (calibration) · eff_B 500/500/500 · not_estimable cells: 0
A5: Quantity | B5: Formula / Construction | C5: Reference
A6: H1 power precompute | B6: Design-based, y-free: SE and Satterthwaite df of the pp_mid contrast precomputed from X = [1, pp_mid], V and the FIXED variance components; delta enters as a noncentral shift of one B = 5,000 stream; power(delta) on the 9-point grid delta = 0.00..0.08 | C6: [DEC-045/H-Q14/R1] [plan A.13]
A7: H1 MDE definition | B7: MDE = smallest delta with power >= .80 (resp. .90), linear interpolation on the grid; NA = above the grid ceiling 0.08 (disclosed) | C7: [DEC-045/H-Q14]
A8: H1 variance scenarios | B8: own x0.5/x1.0/x2.0 = T1/A2 components (0.0197455 / 1.02e-09 / 0.0118832) scaled; coe x0.5/x1.0/x2.0 = one-level lower bound tau2_COE = (0.083/3.92)^2, allocated by T1/A2 proportions [S4]; fixed VC are DESIGN INPUTS here (semantically licensed for MDE, prohibited in H3/H5 inference) | C8: [H-Q4] [DEC-045 S4] [project pin]
A9: H1 calibration | B9: 200 full REML (optimizer ladder) + CR2/Satterthwaite refits at delta = 0.08 (primary scenario; MDE above ceiling -> calibrated at the 0.08 fallback, disclosed); optimism = 0.80 - rejection rate (positive = precompute stream optimistic) | C9: [H-Q14] [DEC-045]
A10: H3 factor space | B10: 1,260 cells = 10 Paris codings x 3 outlier treatments (none/rstudent/winsor) x 2 ES sets (full/no_starbound) x 3 df bases (dfE/k10/k20) x 7 estimator-rho variants (3LMA-RVE CR2 rho .4/.6/.8; one-per-cluster rho .4/.6/.8; UWLS3); 10-coding family frozen verbatim from committed T2 output [D1 amendment] | C10: [DEC-045 S2/S3] [Steegen et al. 2016; Simonsohn et al. 2020 [PK]]
A11: H3 core family & whole-curve stats | B11: Core = 10 codings x 3LMA-RVE x rho .6 x dfE x outlier none x full set; statistic 1 = share of core cells with p < .05, statistic 2 = median |t| over core cells | C11: [DEC-045 S3] [H-Q15]
A12: Joint permutation (H3/H4/H5) | B12: ONE cluster time-translation per replicate applied jointly; codings re-derived per replicate; 23 fits per replicate in ONE pass (H5 race + H4 12 breaks + 10 core cells); p = (1 + #{|stat_perm| >= |stat_obs|}) / (B_eff + 1); B = 500 [S5]; identical permutation list across H3/H4/H5 | C12: [H-Q15/H-Q16/H-Q20/R3] [DEC-045 S5]
A13: H4/H5 observed anchors | B13: H4: sup |t| over the 12-year admissible set fixed at the observed design (read from TH_a_results.csv, membership-verified); H5: |t_race| of the pp_mid coefficient in the T8 race model (F65 anchor gates passed at 1e-9/1e-6) | C13: [H-Q20] [F65] [DEC-045]
A14: Outlier treatments | B14: rstudent mask: |standardized marginal residual| > 3 from the full-set intercept spine (mu = -0.058647, sum sigma2 = 0.031629), computed ONCE, fixed across cells and replicates (13 ES); winsor: zi at empirical P1/P99 of the full set [-0.380770; 0.184715], computed once | C14: [DEC-045 amendment] [Aguinis & Joo 2013; Leys et al. 2013 [PK]]
A15: df bases | B15: dfE = F21 base vi = 1/(n-3); k10/k20 via identity vi_k = 1/(1/vi - k) on PCC rows (= 1/(n-13), 1/(n-23)); bivariate rows carry base vi; k20 basis excludes 1 tiny-n row (disclosed) | C15: [DEC-028] [F21] [DEC-045 amendment]
A16: Determinism | B16: Permutation list generated FIRST under seed 20260710 (112 x 500, output/TH_c_perms.rds, md5-pinned); workers receive indices (scheduling-invariant); reference BLAS single-threaded + per-worker OMP/OPENBLAS/MKL guards; execution order pinned: PERMS -> masks -> H1 stream -> H1 calibration -> permutation pass -> H3 curve | C16: [DEC-045] [TH_design rows]

Sheet 3_Interpretation_Guide
A1: TH-c (simulation & permutation family) · Interpretation Guide
A2: How to read each reported quantity; thresholds with citations
A3: Framing gate [DEC-044]: all TOST flags and permutation p-values in this workbook are MECHANICAL values; no evidence-of-absence or verdict language is used anywhere; adjudication happens as the documented gate-resolution step after TH-b (H2a/H2b RoBMA).
A5: Quantity | B5: Meaning | C5: Decision rule
A6: p_perm | B6: (1 + exceedances) / (B_eff + 1); minimum attainable value 1/(B_eff+1) ~ 0.002 | C6: Compare to alpha mechanically; p_perm(share) = 1.000 means NO replicate produced a smaller/equal-extreme share statistic than observed - tabulated without verdict language
A7: MDE80 / MDE90 = NA | B7: Smallest detectable contrast lies above the pre-registered grid ceiling 0.08 [§6(i)] | C7: Disclose the ceiling and the power at 0.08 (table rows); never extrapolate beyond the grid
A8: optimism (calibration) | B8: 0.80 - full-REML rejection rate at the calibration point | C8: Positive = analytic precompute stream optimistic relative to full REML at the 0.80 target
A9: eff_B | B9: Effective replicates with finite statistic; failed replicates dropped from the denominator | C9: Fail share <= 0.01 enforced; here 500/500/500 (zero drops)
A10: UWLS3 rows (df ~ 2,703) | B10: Unrestricted WLS with k+3 convention; ES-level df by construction | C10: Different estimand family; included as the estimator-structure axis of the multiverse [S2], not as a spine alternative
A11: one_per_cluster rows (df = 111) | B11: Cluster-aggregated two-level check | C11: Assumption-lean second opinion; rho enters via the aggregation working correlation
A12: core vs. full curve | B12: Core = pre-registered 10-cell family; full curve = all 1,260 cells | C12: Inference on the core (joint permutation); the full curve is descriptive breadth
A13: Framing gate | B13: Framing gate [DEC-044]: all TOST flags and permutation p-values in this workbook are MECHANICAL values; no evidence-of-absence or verdict language is used anywhere; adjudication happens as the documented gate-resolution step after TH-b (H2a/H2b RoBMA). | C13: [DEC-044]

Sheet 4_Formula_Reference
A1: TH-c (simulation & permutation family) · Formula Reference
A2: Exact calls as implemented (from run notes / run_meta)
A3: Run finished 2026-07-26 17:39 (canonical) · runtime 44.3 h · verifier R/09_verify_outputs.R 19/19 PASS · chat artefact check 2026-07-26 18/18 PASS · output/TH_c_results.csv 1347x36 · counters fits/fallback/fail: 11,500/92/0 (pass) · 540/3/0 (curve) · 200/2/0 (calibration) · eff_B 500/500/500 · not_estimable cells: 0
A5: Quantity | B5: R call | C5: Reference / script section
A6: Power precompute | B6: se_d <- sqrt(crossprod(c, vcovCR2_yfree) c); df_Satt y-free; power <- pt(qt(.975, df), df, ncp = delta/se_d, lower.tail = FALSE) + pt(-qt(.975, df), df, ncp = delta/se_d) | C6: R/09 H1 block [H-Q14/R1]
A7: MDE interpolation | B7: approx(power_grid, delta_grid, xout = 0.80)$y (resp. 0.90); NA if max(power_grid) < target | C7: R/09 H1
A8: Calibration refit | B8: rma.mv(zi + delta*pp_mid, V, mods = ~ pp_mid, random = ~1|cluster_id/study/esid, REML, optimizer ladder) x 200; reject = |t_CR2| > t_crit(df_Satt) | C8: R/09 H1 calibration
A9: Permutation pass | B9: for b in 1:500: translate cluster windows by perm[[b]]; re-derive all 10 codings; refit H5 race + 12 H4 breaks + 10 core cells (23 fits); collect |t| statistics | C9: R/09 perm pass [R3]
A10: Perm p | B10: p = (1 + sum(abs(stat_perm) >= abs(stat_obs))) / (eff_B + 1) | C10: R/09 [S5]
A11: Curve stats in-workbook | B11: COUNTIFS / _xlfn.MINIFS / _xlfn.MAXIFS over Results_Long H3 diff rows (single formula source) | C11: Tab 7_H3_Spec_Curve
A12: rstudent mask | B12: abs(zi - mu_spine) / sqrt(vi + sum_sigma2) > 3 on the full-set intercept spine; fixed once | C12: R/09 masks [DEC-045 amendment]
A13: Winsorization | B13: zi <- pmin(pmax(zi, q01), q99), bounds computed once on the full estimation set | C13: R/09 masks

Sheet 5_Data_Provenance
A1: TH-c (simulation & permutation family) · Data Provenance
A2: Estimation set, anchors, counters, environment, disclosures
A3: Run finished 2026-07-26 17:39 (canonical) · runtime 44.3 h · verifier R/09_verify_outputs.R 19/19 PASS · chat artefact check 2026-07-26 18/18 PASS · output/TH_c_results.csv 1347x36 · counters fits/fallback/fail: 11,500/92/0 (pass) · 540/3/0 (curve) · 200/2/0 (calibration) · eff_B 500/500/500 · not_estimable cells: 0
A5: Item | B5: Value | C5: Source
A6: Estimation set / domain | B6: Period domain 2,705 ES / 113 studies / 112 clusters (H3/H4/H5, H1 design); full-set spine anchors for masks | C6: TH_c_results.csv
A7: dat_prep md5 | B7: 6702ef3dc45fe0b693b13f50ebd1576b (identical to TH_a_run_meta - cross-run anchor) | C7: run_meta both runs
A8: Permutation list | B8: output/TH_c_perms.rds: 112 x 500 cluster permutations, generated FIRST under seed 20260710; md5 = 077d689b2dee2931467650585089888a; deliberately NOT in git (.gitignore output/*.rds); md5 triple-anchored (run_meta, design row, O13) | C8: TH_design perm_list; session log §1
A9: Run stamp / runtime | B9: Finished 2026-07-26 17:39:47; runtime 44.3 h vs. 13-15 h projected [§6(v)] - decomposition: single-fit benchmark 41.92 s (idle P-core) vs. ~96 CPU-s/fit under 11-worker load (measured probe); 92 ladder fallbacks; straggler scheduling; architecture externally validated via the O5 core anchors; lessons for R/07 pinned | C9: session log §1; [DEC-045]
A10: Counters | B10: fits/fallback/fail = 11,500/92/0 (permutation pass) · 540/3/0 (curve) · 200/2/0 (calibration); eff_B = 500/500/500; not_estimable cells = 0 [§6(ii) analogue] | C10: run_meta; verifier 19/19
A11: k20 exclusion [§6(iii)] | B11: Design row (verbatim): 'k20 basis excludes 1 row(s) with nonpositive/NA vi_k20 (tiny-n edge, n <= 23) from all k20 cells -- disclosed [DEC-045 amendment; author ruling 2026-07-24]'; the excluded row is Chodnicka-Jaworska (2022), n = 18, vi_k20 = NA; 2,607 PCC rows pass the identity assert at 1e-9 | C11: TH_design vi_k_identity; author ruling 2026-07-24
A12: Outlier constants [§6(iv)] | B12: rstudent mask = 13 ES at threshold 3 (full-set intercept spine, mu = -0.058647, sum sigma2 = 0.031629); winsor bounds [-0.380770; 0.184715] (empirical P1/P99, computed once) | C12: TH_design rstudent_mask / winsor_bounds
A13: H1 NA disclosure [§6(i)] | B13: MDE80 AND MDE90 = NA in own_x1.0 and own_x2.0 (grid ceiling 0.08); calibration rule-conformly executed at the 0.08 fallback and disclosed in the calibration note; power at 0.08 tabulated (0.7304 / 0.4476) | C13: TH_c_results.csv H1
A14: Observed anchors | B14: center_sample_mid = 2012.257855823 (in-script, constancy asserted); F65 gates PASSED: T8 B4/race/pp_mid_lag0 matched embedded constants at 1e-9, observed refit identity at 1e-6, |t_race_obs| = 1.052421; H4 admissible echo membership-verified against TH_a_results.csv | C14: TH_design rows
A15: Execution order / determinism | B15: PERMS -> masks -> H1 stream -> H1 calibration -> permutation pass (ONE pass, 23 fits/replicate) -> H3 curve; Windows CRAN reference BLAS single-threaded; OMP/OPENBLAS/MKL guards per worker | C15: TH_design execution_order / blas_note
A16: Repo basis | B16: 5a99de6 -> e44fce7 (#12) -> fce9d3a (#13) -> dafd95e (#14); family commit lands on dafd95e (main = origin); TH-c relaunch executed on dafd95e (post ERROR_LOG #13/#14 fixes) | C16: session log §1
A17: Environment | B17: R 4.6.1 ucrt · Windows 11 x64 (26200) · German_Austria.utf8 / LC_NUMERIC = C · TZ Europe/Vienna · metafor 5.0-1, clubSandwich 0.7.0, Matrix 1.7-5 (sessionInfo identical to TH-a) | C17: TH_c_run_meta sessionInfo

Sheet 6_H1_MDE_Power
A1: TH-c (simulation & permutation family) · H1 - design-based MDE / power battery (6 scenarios) + full-REML calibration
A2: Fixed variance components are DESIGN INPUTS here [H-Q4]; y-free precompute, noncentral-t power; MDE by grid interpolation, NA = above the 0.08 ceiling.
A3: Run finished 2026-07-26 17:39 (canonical) · runtime 44.3 h · verifier R/09_verify_outputs.R 19/19 PASS · chat artefact check 2026-07-26 18/18 PASS · output/TH_c_results.csv 1347x36 · counters fits/fallback/fail: 11,500/92/0 (pass) · 540/3/0 (curve) · 200/2/0 (calibration) · eff_B 500/500/500 · not_estimable cells: 0
A5: Panel row | B5: analysis_id | C5: spec | D5: subset | E5: term | F5: RL row | G5: k_es | H5: k_cl | I5: value | J5: note (verbatim)
A6: calibration: rejection rate (200 REML @ delta 0.08) | B6: H1 | C6: calibration | D6: defined | E6: rejection_rate | F6: =SUMPRODUCT((Results_Long!$A$2:$A$1348=$B6)*(Results_Long!$B$2:$B$1348=$C6)*(Results_Long!$C$2:$C$1348=$D6)*(Results_Long!$D$2:$D$1348=$E6)*ROW(Results_Long!$A$2:$A$1348)) -> 68 | G6: =IF(INDEX(Results_Long!$H:$H,$F6)="","NA",INDEX(Results_Long!$H:$H,$F6)) -> 2705 | H6: =IF(INDEX(Results_Long!$J:$J,$F6)="","NA",INDEX(Results_Long!$J:$J,$F6)) -> 112 | I6: =IF(INDEX(Results_Long!$AG:$AG,$F6)="","NA",INDEX(Results_Long!$AG:$AG,$F6)) -> 0.765 | J6: =IF(INDEX(Results_Long!$AJ:$AJ,$F6)="","NA",INDEX(Results_Long!$AJ:$AJ,$F6)) -> calibration subset [H-Q14]: 200 full REML (ladder) + CR2/Satt refits at delta = 0.080000 (primary scenario; MDE above grid ceiling -> calibrated at 0.08 (disclosed)); optimism = 0.80 - rejection rate (positive = stream optimistic); n effective = 200/200
A7: calibration: optimism (0.80 - rejection) | B7: H1 | C7: calibration | D7: defined | E7: optimism_diff | F7: =SUMPRODUCT((Results_Long!$A$2:$A$1348=$B7)*(Results_Long!$B$2:$B$1348=$C7)*(Results_Long!$C$2:$C$1348=$D7)*(Results_Long!$D$2:$D$1348=$E7)*ROW(Results_Long!$A$2:$A$1348)) -> 69 | G7: =IF(INDEX(Results_Long!$H:$H,$F7)="","NA",INDEX(Results_Long!$H:$H,$F7)) -> NA | H7: =IF(INDEX(Results_Long!$J:$J,$F7)="","NA",INDEX(Results_Long!$J:$J,$F7)) -> NA | I7: =IF(INDEX(Results_Long!$AG:$AG,$F7)="","NA",INDEX(Results_Long!$AG:$AG,$F7)) -> 0.035 | J7: =IF(INDEX(Results_Long!$AJ:$AJ,$F7)="","NA",INDEX(Results_Long!$AJ:$AJ,$F7)) -> calibration subset [H-Q14]: 200 full REML (ladder) + CR2/Satt refits at delta = 0.080000 (primary scenario; MDE above grid ceiling -> calibrated at 0.08 (disclosed)); optimism = 0.80 - rejection rate (positive = stream optimistic); reported as a design row [DEC-045]
A9: Panel row | B9: analysis_id | C9: spec | D9: subset | E9: term | F9: RL row | G9: df_Satt | H9: value
A10: own_x0.5 · power_delta_0.00 | B10: H1 | C10: own_x0.5 | D10: defined | E10: power_delta_0.00 | F10: =SUMPRODUCT((Results_Long!$A$2:$A$1348=$B10)*(Results_Long!$B$2:$B$1348=$C10)*(Results_Long!$C$2:$C$1348=$D10)*(Results_Long!$D$2:$D$1348=$E10)*ROW(Results_Long!$A$2:$A$1348)) -> 2 | G10: =IF(INDEX(Results_Long!$N:$N,$F10)="","NA",INDEX(Results_Long!$N:$N,$F10)) -> 11.576259 | H10: =IF(INDEX(Results_Long!$AG:$AG,$F10)="","NA",INDEX(Results_Long!$AG:$AG,$F10)) -> 0.032
A11: own_x0.5 · power_delta_0.01 | B11: H1 | C11: own_x0.5 | D11: defined | E11: power_delta_0.01 | F11: =SUMPRODUCT((Results_Long!$A$2:$A$1348=$B11)*(Results_Long!$B$2:$B$1348=$C11)*(Results_Long!$C$2:$C$1348=$D11)*(Results_Long!$D$2:$D$1348=$E11)*ROW(Results_Long!$A$2:$A$1348)) -> 3 | G11: =IF(INDEX(Results_Long!$N:$N,$F11)="","NA",INDEX(Results_Long!$N:$N,$F11)) -> 11.576259 | H11: =IF(INDEX(Results_Long!$AG:$AG,$F11)="","NA",INDEX(Results_Long!$AG:$AG,$F11)) -> 0.052
A12: own_x0.5 · power_delta_0.02 | B12: H1 | C12: own_x0.5 | D12: defined | E12: power_delta_0.02 | F12: =SUMPRODUCT((Results_Long!$A$2:$A$1348=$B12)*(Results_Long!$B$2:$B$1348=$C12)*(Results_Long!$C$2:$C$1348=$D12)*(Results_Long!$D$2:$D$1348=$E12)*ROW(Results_Long!$A$2:$A$1348)) -> 4 | G12: =IF(INDEX(Results_Long!$N:$N,$F12)="","NA",INDEX(Results_Long!$N:$N,$F12)) -> 11.576259 | H12: =IF(INDEX(Results_Long!$AG:$AG,$F12)="","NA",INDEX(Results_Long!$AG:$AG,$F12)) -> 0.1142
A13: own_x0.5 · power_delta_0.03 | B13: H1 | C13: own_x0.5 | D13: defined | E13: power_delta_0.03 | F13: =SUMPRODUCT((Results_Long!$A$2:$A$1348=$B13)*(Results_Long!$B$2:$B$1348=$C13)*(Results_Long!$C$2:$C$1348=$D13)*(Results_Long!$D$2:$D$1348=$E13)*ROW(Results_Long!$A$2:$A$1348)) -> 5 | G13: =IF(INDEX(Results_Long!$N:$N,$F13)="","NA",INDEX(Results_Long!$N:$N,$F13)) -> 11.576259 | H13: =IF(INDEX(Results_Long!$AG:$AG,$F13)="","NA",INDEX(Results_Long!$AG:$AG,$F13)) -> 0.238
A14: own_x0.5 · power_delta_0.04 | B14: H1 | C14: own_x0.5 | D14: defined | E14: power_delta_0.04 | F14: =SUMPRODUCT((Results_Long!$A$2:$A$1348=$B14)*(Results_Long!$B$2:$B$1348=$C14)*(Results_Long!$C$2:$C$1348=$D14)*(Results_Long!$D$2:$D$1348=$E14)*ROW(Results_Long!$A$2:$A$1348)) -> 6 | G14: =IF(INDEX(Results_Long!$N:$N,$F14)="","NA",INDEX(Results_Long!$N:$N,$F14)) -> 11.576259 | H14: =IF(INDEX(Results_Long!$AG:$AG,$F14)="","NA",INDEX(Results_Long!$AG:$AG,$F14)) -> 0.4132
A15: own_x0.5 · power_delta_0.05 | B15: H1 | C15: own_x0.5 | D15: defined | E15: power_delta_0.05 | F15: =SUMPRODUCT((Results_Long!$A$2:$A$1348=$B15)*(Results_Long!$B$2:$B$1348=$C15)*(Results_Long!$C$2:$C$1348=$D15)*(Results_Long!$D$2:$D$1348=$E15)*ROW(Results_Long!$A$2:$A$1348)) -> 7 | G15: =IF(INDEX(Results_Long!$N:$N,$F15)="","NA",INDEX(Results_Long!$N:$N,$F15)) -> 11.576259 | H15: =IF(INDEX(Results_Long!$AG:$AG,$F15)="","NA",INDEX(Results_Long!$AG:$AG,$F15)) -> 0.6004
A16: own_x0.5 · power_delta_0.06 | B16: H1 | C16: own_x0.5 | D16: defined | E16: power_delta_0.06 | F16: =SUMPRODUCT((Results_Long!$A$2:$A$1348=$B16)*(Results_Long!$B$2:$B$1348=$C16)*(Results_Long!$C$2:$C$1348=$D16)*(Results_Long!$D$2:$D$1348=$E16)*ROW(Results_Long!$A$2:$A$1348)) -> 8 | G16: =IF(INDEX(Results_Long!$N:$N,$F16)="","NA",INDEX(Results_Long!$N:$N,$F16)) -> 11.576259 | H16: =IF(INDEX(Results_Long!$AG:$AG,$F16)="","NA",INDEX(Results_Long!$AG:$AG,$F16)) -> 0.7684
A17: own_x0.5 · power_delta_0.07 | B17: H1 | C17: own_x0.5 | D17: defined | E17: power_delta_0.07 | F17: =SUMPRODUCT((Results_Long!$A$2:$A$1348=$B17)*(Results_Long!$B$2:$B$1348=$C17)*(Results_Long!$C$2:$C$1348=$D17)*(Results_Long!$D$2:$D$1348=$E17)*ROW(Results_Long!$A$2:$A$1348)) -> 9 | G17: =IF(INDEX(Results_Long!$N:$N,$F17)="","NA",INDEX(Results_Long!$N:$N,$F17)) -> 11.576259 | H17: =IF(INDEX(Results_Long!$AG:$AG,$F17)="","NA",INDEX(Results_Long!$AG:$AG,$F17)) -> 0.8868
A18: own_x0.5 · power_delta_0.08 | B18: H1 | C18: own_x0.5 | D18: defined | E18: power_delta_0.08 | F18: =SUMPRODUCT((Results_Long!$A$2:$A$1348=$B18)*(Results_Long!$B$2:$B$1348=$C18)*(Results_Long!$C$2:$C$1348=$D18)*(Results_Long!$D$2:$D$1348=$E18)*ROW(Results_Long!$A$2:$A$1348)) -> 10 | G18: =IF(INDEX(Results_Long!$N:$N,$F18)="","NA",INDEX(Results_Long!$N:$N,$F18)) -> 11.576259 | H18: =IF(INDEX(Results_Long!$AG:$AG,$F18)="","NA",INDEX(Results_Long!$AG:$AG,$F18)) -> 0.9526
A19: own_x0.5 · mde_power80 | B19: H1 | C19: own_x0.5 | D19: defined | E19: mde_power80 | F19: =SUMPRODUCT((Results_Long!$A$2:$A$1348=$B19)*(Results_Long!$B$2:$B$1348=$C19)*(Results_Long!$C$2:$C$1348=$D19)*(Results_Long!$D$2:$D$1348=$E19)*ROW(Results_Long!$A$2:$A$1348)) -> 11 | G19: =IF(INDEX(Results_Long!$N:$N,$F19)="","NA",INDEX(Results_Long!$N:$N,$F19)) -> 11.576259 | H19: =IF(INDEX(Results_Long!$AG:$AG,$F19)="","NA",INDEX(Results_Long!$AG:$AG,$F19)) -> 0.062668919
A20: own_x0.5 · mde_power90 | B20: H1 | C20: own_x0.5 | D20: defined | E20: mde_power90 | F20: =SUMPRODUCT((Results_Long!$A$2:$A$1348=$B20)*(Results_Long!$B$2:$B$1348=$C20)*(Results_Long!$C$2:$C$1348=$D20)*(Results_Long!$D$2:$D$1348=$E20)*ROW(Results_Long!$A$2:$A$1348)) -> 12 | G20: =IF(INDEX(Results_Long!$N:$N,$F20)="","NA",INDEX(Results_Long!$N:$N,$F20)) -> 11.576259 | H20: =IF(INDEX(Results_Long!$AG:$AG,$F20)="","NA",INDEX(Results_Long!$AG:$AG,$F20)) -> 0.072006079
A21: own_x1.0 · power_delta_0.00 | B21: H1 | C21: own_x1.0 | D21: defined | E21: power_delta_0.00 | F21: =SUMPRODUCT((Results_Long!$A$2:$A$1348=$B21)*(Results_Long!$B$2:$B$1348=$C21)*(Results_Long!$C$2:$C$1348=$D21)*(Results_Long!$D$2:$D$1348=$E21)*ROW(Results_Long!$A$2:$A$1348)) -> 13 | G21: =IF(INDEX(Results_Long!$N:$N,$F21)="","NA",INDEX(Results_Long!$N:$N,$F21)) -> 11.819361 | H21: =IF(INDEX(Results_Long!$AG:$AG,$F21)="","NA",INDEX(Results_Long!$AG:$AG,$F21)) -> 0.0344
... A75: coe_x2.0 · mde_power90 | B75: H1 | C75: coe_x2.0 | D75: defined | E75: mde_power90 | F75: =SUMPRODUCT((Results_Long!$A$2:$A$1348=$B75)*(Results_Long!$B$2:$B$1348=$C75)*(Results_Long!$C$2:$C$1348=$D75)*(Results_Long!$D$2:$D$1348=$E75)*ROW(Results_Long!$A$2:$A$1348)) -> 67 | G75: =IF(INDEX(Results_Long!$N:$N,$F75)="","NA",INDEX(Results_Long!$N:$N,$F75)) -> 10.458402 | H75: =IF(INDEX(Results_Long!$AG:$AG,$F75)="","NA",INDEX(Results_Long!$AG:$AG,$F75)) -> 0.019752817
A77: Interpretation
A78: §6(i) disclosure: MDE80 AND MDE90 are NA in own_x1.0 and own_x2.0 - the smallest detectable contrast lies above the pre-registered delta-grid ceiling of 0.08; the power at the ceiling is tabulated in the power_delta_0.08 rows. The calibration therefore ran rule-conformly at the 0.08 fallback (disclosed in its row note).
A79: Scenario provenance: own streams scale the observed T1/A2 variance components; coe streams map the equity-companion between-study variance as a one-level LOWER BOUND [S4] - the companion caveat (variance factor ~65, MDE factor ~8) applies to any cross-channel reading.
A80: df_Satt is precomputed y-free per stream (df column); the value column carries power (power rows) or the MDE in z units (mde rows).
A82: Question | B82: Answer
A83: Why fixed variance components - is that not prohibited? | B83: Fixed VC are prohibited where the ACTUAL test-statistic distribution must be replicated (H3 permutation, H5); in the MDE context they are semantically correct design inputs [H-Q4] - the question answered is 'what was detectable under the observed design'.
A84: Why is the calibration run at 0.08 and not at the MDE? | B84: The primary-scenario MDE is above the grid ceiling; extrapolating beyond the pinned grid is not licensed, so the calibration anchors at the ceiling fallback and discloses it [H-Q14].
A85: Why does the coe mapping matter? | B85: It bounds the best case: if the debt literature were as homogeneous as the equity companion's study level, contrasts of ~0.01-0.02 z would have been detectable - the observed heterogeneity is the binding constraint, not k.
A87: Verdict: Mechanical outcome: 6-scenario power grid, MDE rows (with rule-conform NA above the ceiling) and 200-replicate calibration tabulated; adjudication deferred to the documented gate-resolution step [DEC-044].

Sheet 7_H3_Spec_Curve
A1: TH-c (simulation & permutation family) · H3 - specification curve: whole-curve statistics + joint permutation
A2: Core = pre-registered 10-cell family [S3]; full curve = 1,260 cells; joint permutation re-derives codings per replicate [H-Q15/R3].
A3: Run finished 2026-07-26 17:39 (canonical) · runtime 44.3 h · verifier R/09_verify_outputs.R 19/19 PASS · chat artefact check 2026-07-26 18/18 PASS · output/TH_c_results.csv 1347x36 · counters fits/fallback/fail: 11,500/92/0 (pass) · 540/3/0 (curve) · 200/2/0 (calibration) · eff_B 500/500/500 · not_estimable cells: 0
A5: Panel row | B5: analysis_id | C5: spec | D5: subset | E5: term | F5: RL row | G5: k_es | H5: k_cl | I5: value | J5: note (verbatim)
A6: observed share p < .05 (core, of 10) | B6: H3 | C6: core_curve | D6: defined | E6: observed_share_sig | F6: =SUMPRODUCT((Results_Long!$A$2:$A$1348=$B6)*(Results_Long!$B$2:$B$1348=$C6)*(Results_Long!$C$2:$C$1348=$D6)*(Results_Long!$D$2:$D$1348=$E6)*ROW(Results_Long!$A$2:$A$1348)) -> 74 | G6: =IF(INDEX(Results_Long!$H:$H,$F6)="","NA",INDEX(Results_Long!$H:$H,$F6)) -> 2705 | H6: =IF(INDEX(Results_Long!$J:$J,$F6)="","NA",INDEX(Results_Long!$J:$J,$F6)) -> 112 | I6: =IF(INDEX(Results_Long!$AG:$AG,$F6)="","NA",INDEX(Results_Long!$AG:$AG,$F6)) -> 0 | J6: =IF(INDEX(Results_Long!$AJ:$AJ,$F6)="","NA",INDEX(Results_Long!$AJ:$AJ,$F6)) -> Simonsohn whole-curve statistic 1: share of the 10 core cells with p < .05 (observed); core = B3 coding family x 3LMA-RVE x rho .6 x dfE x outlier none x full set [S3]; per-cell |t|: paris_mid=0.5620, tie_break_median=0.5525, end_any_exposure=0.9270, share_recut_2017=0.4463, share_recut_2018=0.1404, share_recut_2019=0.1846, end_lag1=0.3087, end_lag2=1.5221, end_lag3=0.9796, clean_window=0.7455
A7: observed median |t| (core) | B7: H3 | C7: core_curve | D7: defined | E7: observed_median_t | F7: =SUMPRODUCT((Results_Long!$A$2:$A$1348=$B7)*(Results_Long!$B$2:$B$1348=$C7)*(Results_Long!$C$2:$C$1348=$D7)*(Results_Long!$D$2:$D$1348=$E7)*ROW(Results_Long!$A$2:$A$1348)) -> 75 | G7: =IF(INDEX(Results_Long!$H:$H,$F7)="","NA",INDEX(Results_Long!$H:$H,$F7)) -> 2705 | H7: =IF(INDEX(Results_Long!$J:$J,$F7)="","NA",INDEX(Results_Long!$J:$J,$F7)) -> 112 | I7: =IF(INDEX(Results_Long!$AG:$AG,$F7)="","NA",INDEX(Results_Long!$AG:$AG,$F7)) -> 0.55723246 | J7: =IF(INDEX(Results_Long!$AJ:$AJ,$F7)="","NA",INDEX(Results_Long!$AJ:$AJ,$F7)) -> Simonsohn whole-curve statistic 2: median |t| over the 10 core cells (observed)
A8: p_perm - share statistic | B8: H3 | C8: core_curve | D8: defined | E8: p_perm_share_sig | F8: =SUMPRODUCT((Results_Long!$A$2:$A$1348=$B8)*(Results_Long!$B$2:$B$1348=$C8)*(Results_Long!$C$2:$C$1348=$D8)*(Results_Long!$D$2:$D$1348=$E8)*ROW(Results_Long!$A$2:$A$1348)) -> 76 | G8: =IF(INDEX(Results_Long!$H:$H,$F8)="","NA",INDEX(Results_Long!$H:$H,$F8)) -> NA | H8: =IF(INDEX(Results_Long!$J:$J,$F8)="","NA",INDEX(Results_Long!$J:$J,$F8)) -> NA | I8: =IF(INDEX(Results_Long!$AG:$AG,$F8)="","NA",INDEX(Results_Long!$AG:$AG,$F8)) -> 1 | J8: =IF(INDEX(Results_Long!$AJ:$AJ,$F8)="","NA",INDEX(Results_Long!$AJ:$AJ,$F8)) -> joint permutation [H-Q15/R3]: ONE cluster time-translation per replicate applied to all 10 core cells (codings re-derived); p = (1 + 500)/(500 + 1)
A9: p_perm - median-|t| statistic | B9: H3 | C9: core_curve | D9: defined | E9: p_perm_median_t | F9: =SUMPRODUCT((Results_Long!$A$2:$A$1348=$B9)*(Results_Long!$B$2:$B$1348=$C9)*(Results_Long!$C$2:$C$1348=$D9)*(Results_Long!$D$2:$D$1348=$E9)*ROW(Results_Long!$A$2:$A$1348)) -> 77 | G9: =IF(INDEX(Results_Long!$H:$H,$F9)="","NA",INDEX(Results_Long!$H:$H,$F9)) -> NA | H9: =IF(INDEX(Results_Long!$J:$J,$F9)="","NA",INDEX(Results_Long!$J:$J,$F9)) -> NA | I9: =IF(INDEX(Results_Long!$AG:$AG,$F9)="","NA",INDEX(Results_Long!$AG:$AG,$F9)) -> 0.85429142 | J9: =IF(INDEX(Results_Long!$AJ:$AJ,$F9)="","NA",INDEX(Results_Long!$AJ:$AJ,$F9)) -> joint permutation, statistic 2; p = (1 + 427)/(500 + 1)
A10: effective replicates | B10: H3 | C10: core_curve | D10: defined | E10: eff_B | F10: =SUMPRODUCT((Results_Long!$A$2:$A$1348=$B10)*(Results_Long!$B$2:$B$1348=$C10)*(Results_Long!$C$2:$C$1348=$D10)*(Results_Long!$D$2:$D$1348=$E10)*ROW(Results_Long!$A$2:$A$1348)) -> 78 | G10: =IF(INDEX(Results_Long!$H:$H,$F10)="","NA",INDEX(Results_Long!$H:$H,$F10)) -> NA | H10: =IF(INDEX(Results_Long!$J:$J,$F10)="","NA",INDEX(Results_Long!$J:$J,$F10)) -> NA | I10: =IF(INDEX(Results_Long!$AG:$AG,$F10)="","NA",INDEX(Results_Long!$AG:$AG,$F10)) -> 500 | J10: =IF(INDEX(Results_Long!$AJ:$AJ,$F10)="","NA",INDEX(Results_Long!$AJ:$AJ,$F10)) -> effective replicates of 500; mean estimable core cells per replicate = 10.00
A12: Full-curve descriptives (formula-derived from Results_Long; single formula source)
A13: Quantity | B13: Restriction | C13: Value (formula)
A14: n multiverse cells (diff rows) | B14: analysis H3, term diff | C14: =COUNTIFS(Results_Long!$A:$A,"H3",Results_Long!$D:$D,"diff") -> 1260
A15: n cells with p < .05 | B15: same | C15: =COUNTIFS(Results_Long!$A:$A,"H3",Results_Long!$D:$D,"diff",Results_Long!$O:$O,"<0.05") -> 1
A16: share p < .05 (full curve) | B16: same | C16: =$C$15/$C$14 -> 0.00079365079
A17: n sig | 3LMA-RVE_CR2 | B17: estimator restriction | C17: =COUNTIFS(Results_Long!$A:$A,"H3",Results_Long!$D:$D,"diff",Results_Long!$F:$F,"3LMA-RVE_CR2",Results_Long!$O:$O,"<0.05") -> 1
A18: n sig | one_per_cluster | B18: estimator restriction | C18: =COUNTIFS(Results_Long!$A:$A,"H3",Results_Long!$D:$D,"diff",Results_Long!$F:$F,"one_per_cluster",Results_Long!$O:$O,"<0.05") -> 0
A19: n sig | UWLS3 | B19: estimator restriction | C19: =COUNTIFS(Results_Long!$A:$A,"H3",Results_Long!$D:$D,"diff",Results_Long!$F:$F,"UWLS3",Results_Long!$O:$O,"<0.05") -> 0
A20: min diff_z over full curve | B20: all 1,260 cells | C20: =_xlfn.MINIFS(Results_Long!$K:$K,Results_Long!$A:$A,"H3",Results_Long!$D:$D,"diff") -> -0.077030271
A21: max diff_z over full curve | B21: all 1,260 cells | C21: =_xlfn.MAXIFS(Results_Long!$K:$K,Results_Long!$A:$A,"H3",Results_Long!$D:$D,"diff") -> 0.04050162
A22: min p over full curve | B22: all 1,260 cells | C22: =_xlfn.MINIFS(Results_Long!$O:$O,Results_Long!$A:$A,"H3",Results_Long!$D:$D,"diff") -> 0.048903456
A24: Interpretation
A25: The per-cell core |t| listing is carried verbatim in the observed_share_sig row note.
A26: Inference lives on the core family via the joint permutation; the full-curve descriptives display robustness breadth without multiplicity claims.
A27: The full curve contains exactly one cell below .05 (locatable via the estimator-restricted counts and the min-p row) - a descriptive observation against ~63 cells expected under a global null at alpha = .05 (5% of 1,260).
A28: p_perm(share) at its boundary value means no replicate reached a share as small as/equal to the observed one under the null translation - a mechanical statement.
A30: Question | B30: Answer
A31: Why permute time-translations instead of cluster labels? | B31: The estimand is a TIME moderation; translating cluster windows preserves the within-cluster dependence structure while breaking the calendar alignment - the label-permutation variant would destroy the wrong structure [H-Q15/H-Q20 supersession of Annex-H N7].
A32: Why re-derive the codings per replicate? | B32: All 10 codings are deterministic functions of the (translated) windows; holding them fixed would leak observed-design information into the null [R3].
A34: Verdict: Mechanical outcome: whole-curve statistics and joint-permutation p-values tabulated; full-curve descriptives formula-derived above; adjudication deferred to the documented gate-resolution step [DEC-044].

Sheet 8_H3_Core_Family
A1: TH-c (simulation & permutation family) · H3 - core cell family (10 codings; 3LMA-RVE CR2, rho .6, dfE, outlier none, full set)
A2: Family frozen verbatim from committed T2 output [D1 amendment]; diff rows z-only.
A3: Run finished 2026-07-26 17:39 (canonical) · runtime 44.3 h · verifier R/09_verify_outputs.R 19/19 PASS · chat artefact check 2026-07-26 18/18 PASS · output/TH_c_results.csv 1347x36 · counters fits/fallback/fail: 11,500/92/0 (pass) · 540/3/0 (curve) · 200/2/0 (calibration) · eff_B 500/500/500 · not_estimable cells: 0
A5: Panel row | B5: analysis_id | C5: spec | D5: subset | E5: term | F5: RL row | G5: k_es | H5: k_st | I5: k_cl | J5: est_z | K5: ci_lb_z | L5: ci_ub_z | M5: est_r | N5: ci_lb_r | O5: ci_ub_r | P5: se_z | Q5: t | R5: df | S5: p | T5: value
A6: core: paris_mid | B6: H3 | C6: paris_mid|none|full|dfE | D6: 3LMA-RVE_CR2|r0.6 | E6: diff | F6: =SUMPRODUCT((Results_Long!$A$2:$A$1348=$B6)*(Results_Long!$B$2:$B$1348=$C6)*(Results_Long!$C$2:$C$1348=$D6)*(Results_Long!$D$2:$D$1348=$E6)*ROW(Results_Long!$A$2:$A$1348)) -> 439 | G6: =IF(INDEX(Results_Long!$H:$H,$F6)="","NA",INDEX(Results_Long!$H:$H,$F6)) -> 2705 | H6: =IF(INDEX(Results_Long!$I:$I,$F6)="","NA",INDEX(Results_Long!$I:$I,$F6)) -> 113 | I6: =IF(INDEX(Results_Long!$J:$J,$F6)="","NA",INDEX(Results_Long!$J:$J,$F6)) -> 112 | J6: =IF(INDEX(Results_Long!$K:$K,$F6)="","NA",INDEX(Results_Long!$K:$K,$F6)) -> 0.010175907 | K6: =IF(INDEX(Results_Long!$P:$P,$F6)="","NA",INDEX(Results_Long!$P:$P,$F6)) -> NA | L6: =IF(INDEX(Results_Long!$Q:$Q,$F6)="","NA",INDEX(Results_Long!$Q:$Q,$F6)) -> NA | M6: =IF(INDEX(Results_Long!$T:$T,$F6)="","NA",INDEX(Results_Long!$T:$T,$F6)) -> NA | N6: =IF(INDEX(Results_Long!$U:$U,$F6)="","NA",INDEX(Results_Long!$U:$U,$F6)) -> NA | O6: =IF(INDEX(Results_Long!$V:$V,$F6)="","NA",INDEX(Results_Long!$V:$V,$F6)) -> NA | P6: =IF(INDEX(Results_Long!$L:$L,$F6)="","NA",INDEX(Results_Long!$L:$L,$F6)) -> 0.018107282 | Q6: =IF(INDEX(Results_Long!$M:$M,$F6)="","NA",INDEX(Results_Long!$M:$M,$F6)) -> 0.56197868 | R6: =IF(INDEX(Results_Long!$N:$N,$F6)="","NA",INDEX(Results_Long!$N:$N,$F6)) -> 14.992066 | S6: =IF(INDEX(Results_Long!$O:$O,$F6)="","NA",INDEX(Results_Long!$O:$O,$F6)) -> 0.58243573 | T6: =IF(INDEX(Results_Long!$AG:$AG,$F6)="","NA",INDEX(Results_Long!$AG:$AG,$F6)) -> NA
A7: core: tie_break_median | B7: H3 | C7: tie_break_median|none|full|dfE | D7: 3LMA-RVE_CR2|r0.6 | E7: diff | F7: =SUMPRODUCT((Results_Long!$A$2:$A$1348=$B7)*(Results_Long!$B$2:$B$1348=$C7)*(Results_Long!$C$2:$C$1348=$D7)*(Results_Long!$D$2:$D$1348=$E7)*ROW(Results_Long!$A$2:$A$1348)) -> 440 | G7: =IF(INDEX(Results_Long!$H:$H,$F7)="","NA",INDEX(Results_Long!$H:$H,$F7)) -> 2705 | H7: =IF(INDEX(Results_Long!$I:$I,$F7)="","NA",INDEX(Results_Long!$I:$I,$F7)) -> 113 | I7: =IF(INDEX(Results_Long!$J:$J,$F7)="","NA",INDEX(Results_Long!$J:$J,$F7)) -> 112 | J7: =IF(INDEX(Results_Long!$K:$K,$F7)="","NA",INDEX(Results_Long!$K:$K,$F7)) -> 0.0098055409 | K7: =IF(INDEX(Results_Long!$P:$P,$F7)="","NA",INDEX(Results_Long!$P:$P,$F7)) -> NA | L7: =IF(INDEX(Results_Long!$Q:$Q,$F7)="","NA",INDEX(Results_Long!$Q:$Q,$F7)) -> NA | M7: =IF(INDEX(Results_Long!$T:$T,$F7)="","NA",INDEX(Results_Long!$T:$T,$F7)) -> NA | N7: =IF(INDEX(Results_Long!$U:$U,$F7)="","NA",INDEX(Results_Long!$U:$U,$F7)) -> NA | O7: =IF(INDEX(Results_Long!$V:$V,$F7)="","NA",INDEX(Results_Long!$V:$V,$F7)) -> NA | P7: =IF(INDEX(Results_Long!$L:$L,$F7)="","NA",INDEX(Results_Long!$L:$L,$F7)) -> 0.017748027 | Q7: =IF(INDEX(Results_Long!$M:$M,$F7)="","NA",INDEX(Results_Long!$M:$M,$F7)) -> 0.55248624 | R7: =IF(INDEX(Results_Long!$N:$N,$F7)="","NA",INDEX(Results_Long!$N:$N,$F7)) -> 12.26371 | S7: =IF(INDEX(Results_Long!$O:$O,$F7)="","NA",INDEX(Results_Long!$O:$O,$F7)) -> 0.59054305 | T7: =IF(INDEX(Results_Long!$AG:$AG,$F7)="","NA",INDEX(Results_Long!$AG:$AG,$F7)) -> NA
A8: core: end_any_exposure | B8: H3 | C8: end_any_exposure|none|full|dfE | D8: 3LMA-RVE_CR2|r0.6 | E8: diff | F8: =SUMPRODUCT((Results_Long!$A$2:$A$1348=$B8)*(Results_Long!$B$2:$B$1348=$C8)*(Results_Long!$C$2:$C$1348=$D8)*(Results_Long!$D$2:$D$1348=$E8)*ROW(Results_Long!$A$2:$A$1348)) -> 441 | G8: =IF(INDEX(Results_Long!$H:$H,$F8)="","NA",INDEX(Results_Long!$H:$H,$F8)) -> 2705 | H8: =IF(INDEX(Results_Long!$I:$I,$F8)="","NA",INDEX(Results_Long!$I:$I,$F8)) -> 113 | I8: =IF(INDEX(Results_Long!$J:$J,$F8)="","NA",INDEX(Results_Long!$J:$J,$F8)) -> 112 | J8: =IF(INDEX(Results_Long!$K:$K,$F8)="","NA",INDEX(Results_Long!$K:$K,$F8)) -> -0.019403455 | K8: =IF(INDEX(Results_Long!$P:$P,$F8)="","NA",INDEX(Results_Long!$P:$P,$F8)) -> NA | L8: =IF(INDEX(Results_Long!$Q:$Q,$F8)="","NA",INDEX(Results_Long!$Q:$Q,$F8)) -> NA | M8: =IF(INDEX(Results_Long!$T:$T,$F8)="","NA",INDEX(Results_Long!$T:$T,$F8)) -> NA | N8: =IF(INDEX(Results_Long!$U:$U,$F8)="","NA",INDEX(Results_Long!$U:$U,$F8)) -> NA | O8: =IF(INDEX(Results_Long!$V:$V,$F8)="","NA",INDEX(Results_Long!$V:$V,$F8)) -> NA | P8: =IF(INDEX(Results_Long!$L:$L,$F8)="","NA",INDEX(Results_Long!$L:$L,$F8)) -> 0.020931751 | Q8: =IF(INDEX(Results_Long!$M:$M,$F8)="","NA",INDEX(Results_Long!$M:$M,$F8)) -> -0.92698674 | R8: =IF(INDEX(Results_Long!$N:$N,$F8)="","NA",INDEX(Results_Long!$N:$N,$F8)) -> 41.60291 | S8: =IF(INDEX(Results_Long!$O:$O,$F8)="","NA",INDEX(Results_Long!$O:$O,$F8)) -> 0.35928021 | T8: =IF(INDEX(Results_Long!$AG:$AG,$F8)="","NA",INDEX(Results_Long!$AG:$AG,$F8)) -> NA
A9: core: share_recut_2017 | B9: H3 | C9: share_recut_2017|none|full|dfE | D9: 3LMA-RVE_CR2|r0.6 | E9: diff | F9: =SUMPRODUCT((Results_Long!$A$2:$A$1348=$B9)*(Results_Long!$B$2:$B$1348=$C9)*(Results_Long!$C$2:$C$1348=$D9)*(Results_Long!$D$2:$D$1348=$E9)*ROW(Results_Long!$A$2:$A$1348)) -> 442 | G9: =IF(INDEX(Results_Long!$H:$H,$F9)="","NA",INDEX(Results_Long!$H:$H,$F9)) -> 2705 | H9: =IF(INDEX(Results_Long!$I:$I,$F9)="","NA",INDEX(Results_Long!$I:$I,$F9)) -> 113 | I9: =IF(INDEX(Results_Long!$J:$J,$F9)="","NA",INDEX(Results_Long!$J:$J,$F9)) -> 112 | J9: =IF(INDEX(Results_Long!$K:$K,$F9)="","NA",INDEX(Results_Long!$K:$K,$F9)) -> 0.0080340694 | K9: =IF(INDEX(Results_Long!$P:$P,$F9)="","NA",INDEX(Results_Long!$P:$P,$F9)) -> NA | L9: =IF(INDEX(Results_Long!$Q:$Q,$F9)="","NA",INDEX(Results_Long!$Q:$Q,$F9)) -> NA | M9: =IF(INDEX(Results_Long!$T:$T,$F9)="","NA",INDEX(Results_Long!$T:$T,$F9)) -> NA | N9: =IF(INDEX(Results_Long!$U:$U,$F9)="","NA",INDEX(Results_Long!$U:$U,$F9)) -> NA | O9: =IF(INDEX(Results_Long!$V:$V,$F9)="","NA",INDEX(Results_Long!$V:$V,$F9)) -> NA | P9: =IF(INDEX(Results_Long!$L:$L,$F9)="","NA",INDEX(Results_Long!$L:$L,$F9)) -> 0.018000133 | Q9: =IF(INDEX(Results_Long!$M:$M,$F9)="","NA",INDEX(Results_Long!$M:$M,$F9)) -> 0.4463339 | R9: =IF(INDEX(Results_Long!$N:$N,$F9)="","NA",INDEX(Results_Long!$N:$N,$F9)) -> 10.852183 | S9: =IF(INDEX(Results_Long!$O:$O,$F9)="","NA",INDEX(Results_Long!$O:$O,$F9)) -> 0.6641308 | T9: =IF(INDEX(Results_Long!$AG:$AG,$F9)="","NA",INDEX(Results_Long!$AG:$AG,$F9)) -> NA
A10: core: share_recut_2018 | B10: H3 | C10: share_recut_2018|none|full|dfE | D10: 3LMA-RVE_CR2|r0.6 | E10: diff | F10: =SUMPRODUCT((Results_Long!$A$2:$A$1348=$B10)*(Results_Long!$B$2:$B$1348=$C10)*(Results_Long!$C$2:$C$1348=$D10)*(Results_Long!$D$2:$D$1348=$E10)*ROW(Results_Long!$A$2:$A$1348)) -> 443 | G10: =IF(INDEX(Results_Long!$H:$H,$F10)="","NA",INDEX(Results_Long!$H:$H,$F10)) -> 2705 | H10: =IF(INDEX(Results_Long!$I:$I,$F10)="","NA",INDEX(Results_Long!$I:$I,$F10)) -> 113 | I10: =IF(INDEX(Results_Long!$J:$J,$F10)="","NA",INDEX(Results_Long!$J:$J,$F10)) -> 112 | J10: =IF(INDEX(Results_Long!$K:$K,$F10)="","NA",INDEX(Results_Long!$K:$K,$F10)) -> 0.0031230426 | K10: =IF(INDEX(Results_Long!$P:$P,$F10)="","NA",INDEX(Results_Long!$P:$P,$F10)) -> NA | L10: =IF(INDEX(Results_Long!$Q:$Q,$F10)="","NA",INDEX(Results_Long!$Q:$Q,$F10)) -> NA | M10: =IF(INDEX(Results_Long!$T:$T,$F10)="","NA",INDEX(Results_Long!$T:$T,$F10)) -> NA | N10: =IF(INDEX(Results_Long!$U:$U,$F10)="","NA",INDEX(Results_Long!$U:$U,$F10)) -> NA | O10: =IF(INDEX(Results_Long!$V:$V,$F10)="","NA",INDEX(Results_Long!$V:$V,$F10)) -> NA | P10: =IF(INDEX(Results_Long!$L:$L,$F10)="","NA",INDEX(Results_Long!$L:$L,$F10)) -> 0.022238266 | Q10: =IF(INDEX(Results_Long!$M:$M,$F10)="","NA",INDEX(Results_Long!$M:$M,$F10)) -> 0.14043553 | R10: =IF(INDEX(Results_Long!$N:$N,$F10)="","NA",INDEX(Results_Long!$N:$N,$F10)) -> 18.776144 | S10: =IF(INDEX(Results_Long!$O:$O,$F10)="","NA",INDEX(Results_Long!$O:$O,$F10)) -> 0.88981151 | T10: =IF(INDEX(Results_Long!$AG:$AG,$F10)="","NA",INDEX(Results_Long!$AG:$AG,$F10)) -> NA
A11: core: share_recut_2019 | B11: H3 | C11: share_recut_2019|none|full|dfE | D11: 3LMA-RVE_CR2|r0.6 | E11: diff | F11: =SUMPRODUCT((Results_Long!$A$2:$A$1348=$B11)*(Results_Long!$B$2:$B$1348=$C11)*(Results_Long!$C$2:$C$1348=$D11)*(Results_Long!$D$2:$D$1348=$E11)*ROW(Results_Long!$A$2:$A$1348)) -> 444 | G11: =IF(INDEX(Results_Long!$H:$H,$F11)="","NA",INDEX(Results_Long!$H:$H,$F11)) -> 2705 | H11: =IF(INDEX(Results_Long!$I:$I,$F11)="","NA",INDEX(Results_Long!$I:$I,$F11)) -> 113 | I11: =IF(INDEX(Results_Long!$J:$J,$F11)="","NA",INDEX(Results_Long!$J:$J,$F11)) -> 112 | J11: =IF(INDEX(Results_Long!$K:$K,$F11)="","NA",INDEX(Results_Long!$K:$K,$F11)) -> 0.0042056666 | K11: =IF(INDEX(Results_Long!$P:$P,$F11)="","NA",INDEX(Results_Long!$P:$P,$F11)) -> NA | L11: =IF(INDEX(Results_Long!$Q:$Q,$F11)="","NA",INDEX(Results_Long!$Q:$Q,$F11)) -> NA | M11: =IF(INDEX(Results_Long!$T:$T,$F11)="","NA",INDEX(Results_Long!$T:$T,$F11)) -> NA | N11: =IF(INDEX(Results_Long!$U:$U,$F11)="","NA",INDEX(Results_Long!$U:$U,$F11)) -> NA | O11: =IF(INDEX(Results_Long!$V:$V,$F11)="","NA",INDEX(Results_Long!$V:$V,$F11)) -> NA | P11: =IF(INDEX(Results_Long!$L:$L,$F11)="","NA",INDEX(Results_Long!$L:$L,$F11)) -> 0.022784454 | Q11: =IF(INDEX(Results_Long!$M:$M,$F11)="","NA",INDEX(Results_Long!$M:$M,$F11)) -> 0.18458491 | R11: =IF(INDEX(Results_Long!$N:$N,$F11)="","NA",INDEX(Results_Long!$N:$N,$F11)) -> 15.443904 | S11: =IF(INDEX(Results_Long!$O:$O,$F11)="","NA",INDEX(Results_Long!$O:$O,$F11)) -> 0.85595667 | T11: =IF(INDEX(Results_Long!$AG:$AG,$F11)="","NA",INDEX(Results_Long!$AG:$AG,$F11)) -> NA
A12: core: end_lag1 | B12: H3 | C12: end_lag1|none|full|dfE | D12: 3LMA-RVE_CR2|r0.6 | E12: diff | F12: =SUMPRODUCT((Results_Long!$A$2:$A$1348=$B12)*(Results_Long!$B$2:$B$1348=$C12)*(Results_Long!$C$2:$C$1348=$D12)*(Results_Long!$D$2:$D$1348=$E12)*ROW(Results_Long!$A$2:$A$1348)) -> 445 | G12: =IF(INDEX(Results_Long!$H:$H,$F12)="","NA",INDEX(Results_Long!$H:$H,$F12)) -> 2705 | H12: =IF(INDEX(Results_Long!$I:$I,$F12)="","NA",INDEX(Results_Long!$I:$I,$F12)) -> 113 | I12: =IF(INDEX(Results_Long!$J:$J,$F12)="","NA",INDEX(Results_Long!$J:$J,$F12)) -> 112 | J12: =IF(INDEX(Results_Long!$K:$K,$F12)="","NA",INDEX(Results_Long!$K:$K,$F12)) -> -0.0063644567 | K12: =IF(INDEX(Results_Long!$P:$P,$F12)="","NA",INDEX(Results_Long!$P:$P,$F12)) -> NA | L12: =IF(INDEX(Results_Long!$Q:$Q,$F12)="","NA",INDEX(Results_Long!$Q:$Q,$F12)) -> NA | M12: =IF(INDEX(Results_Long!$T:$T,$F12)="","NA",INDEX(Results_Long!$T:$T,$F12)) -> NA | N12: =IF(INDEX(Results_Long!$U:$U,$F12)="","NA",INDEX(Results_Long!$U:$U,$F12)) -> NA | O12: =IF(INDEX(Results_Long!$V:$V,$F12)="","NA",INDEX(Results_Long!$V:$V,$F12)) -> NA | P12: =IF(INDEX(Results_Long!$L:$L,$F12)="","NA",INDEX(Results_Long!$L:$L,$F12)) -> 0.020619187 | Q12: =IF(INDEX(Results_Long!$M:$M,$F12)="","NA",INDEX(Results_Long!$M:$M,$F12)) -> -0.30866672 | R12: =IF(INDEX(Results_Long!$N:$N,$F12)="","NA",INDEX(Results_Long!$N:$N,$F12)) -> 17.755888 | S12: =IF(INDEX(Results_Long!$O:$O,$F12)="","NA",INDEX(Results_Long!$O:$O,$F12)) -> 0.76116727 | T12: =IF(INDEX(Results_Long!$AG:$AG,$F12)="","NA",INDEX(Results_Long!$AG:$AG,$F12)) -> NA
A13: core: end_lag2 | B13: H3 | C13: end_lag2|none|full|dfE | D13: 3LMA-RVE_CR2|r0.6 | E13: diff | F13: =SUMPRODUCT((Results_Long!$A$2:$A$1348=$B13)*(Results_Long!$B$2:$B$1348=$C13)*(Results_Long!$C$2:$C$1348=$D13)*(Results_Long!$D$2:$D$1348=$E13)*ROW(Results_Long!$A$2:$A$1348)) -> 446 | G13: =IF(INDEX(Results_Long!$H:$H,$F13)="","NA",INDEX(Results_Long!$H:$H,$F13)) -> 2705 | H13: =IF(INDEX(Results_Long!$I:$I,$F13)="","NA",INDEX(Results_Long!$I:$I,$F13)) -> 113 | I13: =IF(INDEX(Results_Long!$J:$J,$F13)="","NA",INDEX(Results_Long!$J:$J,$F13)) -> 112 | J13: =IF(INDEX(Results_Long!$K:$K,$F13)="","NA",INDEX(Results_Long!$K:$K,$F13)) -> 0.039789555 | K13: =IF(INDEX(Results_Long!$P:$P,$F13)="","NA",INDEX(Results_Long!$P:$P,$F13)) -> NA | L13: =IF(INDEX(Results_Long!$Q:$Q,$F13)="","NA",INDEX(Results_Long!$Q:$Q,$F13)) -> NA | M13: =IF(INDEX(Results_Long!$T:$T,$F13)="","NA",INDEX(Results_Long!$T:$T,$F13)) -> NA | N13: =IF(INDEX(Results_Long!$U:$U,$F13)="","NA",INDEX(Results_Long!$U:$U,$F13)) -> NA | O13: =IF(INDEX(Results_Long!$V:$V,$F13)="","NA",INDEX(Results_Long!$V:$V,$F13)) -> NA | P13: =IF(INDEX(Results_Long!$L:$L,$F13)="","NA",INDEX(Results_Long!$L:$L,$F13)) -> 0.026140798 | Q13: =IF(INDEX(Results_Long!$M:$M,$F13)="","NA",INDEX(Results_Long!$M:$M,$F13)) -> 1.5221248 | R13: =IF(INDEX(Results_Long!$N:$N,$F13)="","NA",INDEX(Results_Long!$N:$N,$F13)) -> 22.01083 | S13: =IF(INDEX(Results_Long!$O:$O,$F13)="","NA",INDEX(Results_Long!$O:$O,$F13)) -> 0.14221586 | T13: =IF(INDEX(Results_Long!$AG:$AG,$F13)="","NA",INDEX(Results_Long!$AG:$AG,$F13)) -> NA
A14: core: end_lag3 | B14: H3 | C14: end_lag3|none|full|dfE | D14: 3LMA-RVE_CR2|r0.6 | E14: diff | F14: =SUMPRODUCT((Results_Long!$A$2:$A$1348=$B14)*(Results_Long!$B$2:$B$1348=$C14)*(Results_Long!$C$2:$C$1348=$D14)*(Results_Long!$D$2:$D$1348=$E14)*ROW(Results_Long!$A$2:$A$1348)) -> 447 | G14: =IF(INDEX(Results_Long!$H:$H,$F14)="","NA",INDEX(Results_Long!$H:$H,$F14)) -> 2705 | H14: =IF(INDEX(Results_Long!$I:$I,$F14)="","NA",INDEX(Results_Long!$I:$I,$F14)) -> 113 | I14: =IF(INDEX(Results_Long!$J:$J,$F14)="","NA",INDEX(Results_Long!$J:$J,$F14)) -> 112 | J14: =IF(INDEX(Results_Long!$K:$K,$F14)="","NA",INDEX(Results_Long!$K:$K,$F14)) -> 0.021318892 | K14: =IF(INDEX(Results_Long!$P:$P,$F14)="","NA",INDEX(Results_Long!$P:$P,$F14)) -> NA | L14: =IF(INDEX(Results_Long!$Q:$Q,$F14)="","NA",INDEX(Results_Long!$Q:$Q,$F14)) -> NA | M14: =IF(INDEX(Results_Long!$T:$T,$F14)="","NA",INDEX(Results_Long!$T:$T,$F14)) -> NA | N14: =IF(INDEX(Results_Long!$U:$U,$F14)="","NA",INDEX(Results_Long!$U:$U,$F14)) -> NA | O14: =IF(INDEX(Results_Long!$V:$V,$F14)="","NA",INDEX(Results_Long!$V:$V,$F14)) -> NA | P14: =IF(INDEX(Results_Long!$L:$L,$F14)="","NA",INDEX(Results_Long!$L:$L,$F14)) -> 0.021762882 | Q14: =IF(INDEX(Results_Long!$M:$M,$F14)="","NA",INDEX(Results_Long!$M:$M,$F14)) -> 0.97959873 | R14: =IF(INDEX(Results_Long!$N:$N,$F14)="","NA",INDEX(Results_Long!$N:$N,$F14)) -> 22.304972 | S14: =IF(INDEX(Results_Long!$O:$O,$F14)="","NA",INDEX(Results_Long!$O:$O,$F14)) -> 0.33779064 | T14: =IF(INDEX(Results_Long!$AG:$AG,$F14)="","NA",INDEX(Results_Long!$AG:$AG,$F14)) -> NA
A15: core: clean_window | B15: H3 | C15: clean_window|none|full|dfE | D15: 3LMA-RVE_CR2|r0.6 | E15: diff | F15: =SUMPRODUCT((Results_Long!$A$2:$A$1348=$B15)*(Results_Long!$B$2:$B$1348=$C15)*(Results_Long!$C$2:$C$1348=$D15)*(Results_Long!$D$2:$D$1348=$E15)*ROW(Results_Long!$A$2:$A$1348)) -> 448 | G15: =IF(INDEX(Results_Long!$H:$H,$F15)="","NA",INDEX(Results_Long!$H:$H,$F15)) -> 929 | H15: =IF(INDEX(Results_Long!$I:$I,$F15)="","NA",INDEX(Results_Long!$I:$I,$F15)) -> 40 | I15: =IF(INDEX(Results_Long!$J:$J,$F15)="","NA",INDEX(Results_Long!$J:$J,$F15)) -> 40 | J15: =IF(INDEX(Results_Long!$K:$K,$F15)="","NA",INDEX(Results_Long!$K:$K,$F15)) -> -0.012921 | K15: =IF(INDEX(Results_Long!$P:$P,$F15)="","NA",INDEX(Results_Long!$P:$P,$F15)) -> NA | L15: =IF(INDEX(Results_Long!$Q:$Q,$F15)="","NA",INDEX(Results_Long!$Q:$Q,$F15)) -> NA | M15: =IF(INDEX(Results_Long!$T:$T,$F15)="","NA",INDEX(Results_Long!$T:$T,$F15)) -> NA | N15: =IF(INDEX(Results_Long!$U:$U,$F15)="","NA",INDEX(Results_Long!$U:$U,$F15)) -> NA | O15: =IF(INDEX(Results_Long!$V:$V,$F15)="","NA",INDEX(Results_Long!$V:$V,$F15)) -> NA | P15: =IF(INDEX(Results_Long!$L:$L,$F15)="","NA",INDEX(Results_Long!$L:$L,$F15)) -> 0.017331989 | Q15: =IF(INDEX(Results_Long!$M:$M,$F15)="","NA",INDEX(Results_Long!$M:$M,$F15)) -> -0.74550013 | R15: =IF(INDEX(Results_Long!$N:$N,$F15)="","NA",INDEX(Results_Long!$N:$N,$F15)) -> 23.474483 | S15: =IF(INDEX(Results_Long!$O:$O,$F15)="","NA",INDEX(Results_Long!$O:$O,$F15)) -> 0.46336937 | T15: =IF(INDEX(Results_Long!$AG:$AG,$F15)="","NA",INDEX(Results_Long!$AG:$AG,$F15)) -> NA
A17: Panel row | B17: analysis_id | C17: spec | D17: subset | E17: term | F17: RL row | G17: df_Satt | H17: value | I17: note (verbatim)
A18: core cell keys (design) | B18: TH_design | C18: design | D18: defined | E18: core_cells | F18: =SUMPRODUCT((Results_Long!$A$2:$A$1348=$B18)*(Results_Long!$B$2:$B$1348=$C18)*(Results_Long!$C$2:$C$1348=$D18)*(Results_Long!$D$2:$D$1348=$E18)*ROW(Results_Long!$A$2:$A$1348)) -> 1348 | G18: =IF(INDEX(Results_Long!$N:$N,$F18)="","NA",INDEX(Results_Long!$N:$N,$F18)) -> NA | H18: =IF(INDEX(Results_Long!$AG:$AG,$F18)="","NA",INDEX(Results_Long!$AG:$AG,$F18)) -> 10 | I18: =IF(INDEX(Results_Long!$AJ:$AJ,$F18)="","NA",INDEX(Results_Long!$AJ:$AJ,$F18)) -> core cell keys: paris_mid|none|full|dfE; tie_break_median|none|full|dfE; end_any_exposure|none|full|dfE; share_recut_2017|none|full|dfE; share_recut_2018|none|full|dfE; share_recut_2019|none|full|dfE; end_lag1|none|full|dfE; end_lag2|none|full|dfE; end_lag3|none|full|dfE; clean_window|none|full|dfE
A20: Interpretation
A21: clean_window is the pre-registered subset coding (929 ES / 40 clusters) - its smaller base is a design feature, not attrition.
A22: The end_lag2 cell carries the largest absolute contrast of the family; its p-value is tabulated in the panel (no verdict language attached).
A23: These 10 cells are exactly the ms_input core rows; the joint permutation over the family lives on Tab '7_H3_Spec_Curve'.
A25: Question | B25: Answer
A26: Why 10 codings rather than the 6 of Annex H? | B26: Author ruling H-Q3 superseded Annex H: the factor space follows the committed T2/B3 coding family (10 codings, extracted verbatim from output/T2_results.csv before any H estimate existed) [DEC-045 D1 amendment].
A27: Why is dfE/none/full the core cell? | B27: It mirrors the pre-registered headline spine (D31.1); outlier treatments, ES-set and df-base variations are robustness axes, not co-equal estimands [S3].
A29: Verdict: Mechanical outcome: 10 core contrasts tabulated with CR2/Satterthwaite columns; adjudication deferred to the documented gate-resolution step [DEC-044].

Sheet 9_H4_Perm_Sup
A1: TH-c (simulation & permutation family) · H4 - permutation reference for the sup-break statistic
A2: Identical permutation list as H5 [H-Q16]; admissible year set fixed at the observed design [H-Q20]; observed sup single-homed in the TH-a workbook Tab 7.
A3: Run finished 2026-07-26 17:39 (canonical) · runtime 44.3 h · verifier R/09_verify_outputs.R 19/19 PASS · chat artefact check 2026-07-26 18/18 PASS · output/TH_c_results.csv 1347x36 · counters fits/fallback/fail: 11,500/92/0 (pass) · 540/3/0 (curve) · 200/2/0 (calibration) · eff_B 500/500/500 · not_estimable cells: 0
A5: Panel row | B5: analysis_id | C5: spec | D5: subset | E5: term | F5: RL row | G5: k_es | H5: k_cl | I5: value | J5: note (verbatim)
A6: p_perm (sup |t|) | B6: H4 | C6: perm_sup | D6: defined | E6: p_perm | F6: =SUMPRODUCT((Results_Long!$A$2:$A$1348=$B6)*(Results_Long!$B$2:$B$1348=$C6)*(Results_Long!$C$2:$C$1348=$D6)*(Results_Long!$D$2:$D$1348=$E6)*ROW(Results_Long!$A$2:$A$1348)) -> 72 | G6: =IF(INDEX(Results_Long!$H:$H,$F6)="","NA",INDEX(Results_Long!$H:$H,$F6)) -> 2705 | H6: =IF(INDEX(Results_Long!$J:$J,$F6)="","NA",INDEX(Results_Long!$J:$J,$F6)) -> 112 | I6: =IF(INDEX(Results_Long!$AG:$AG,$F6)="","NA",INDEX(Results_Long!$AG:$AG,$F6)) -> 0.34131737 | J6: =IF(INDEX(Results_Long!$AJ:$AJ,$F6)="","NA",INDEX(Results_Long!$AJ:$AJ,$F6)) -> time-translation permutation, identical list as H5 [H-Q16/H-Q20]: p = (1 + 170) / (500 + 1); observed sup |t| = 2.122533 (from TH_a_results.csv observed_sup); admissible years fixed at the observed design: 2008, 2009, 2010, 2011, 2012, 2013, 2014, 2015, 2016, 2017, 2018, 2019; exceed count = 170 of 500 effective
A7: effective replicates | B7: H4 | C7: perm_sup | D7: defined | E7: eff_B | F7: =SUMPRODUCT((Results_Long!$A$2:$A$1348=$B7)*(Results_Long!$B$2:$B$1348=$C7)*(Results_Long!$C$2:$C$1348=$D7)*(Results_Long!$D$2:$D$1348=$E7)*ROW(Results_Long!$A$2:$A$1348)) -> 73 | G7: =IF(INDEX(Results_Long!$H:$H,$F7)="","NA",INDEX(Results_Long!$H:$H,$F7)) -> NA | H7: =IF(INDEX(Results_Long!$J:$J,$F7)="","NA",INDEX(Results_Long!$J:$J,$F7)) -> NA | I7: =IF(INDEX(Results_Long!$AG:$AG,$F7)="","NA",INDEX(Results_Long!$AG:$AG,$F7)) -> 500 | J7: =IF(INDEX(Results_Long!$AJ:$AJ,$F7)="","NA",INDEX(Results_Long!$AJ:$AJ,$F7)) -> effective replicates (finite sup statistic) of 500
A9: Panel row | B9: analysis_id | C9: spec | D9: subset | E9: term | F9: RL row | G9: df_Satt | H9: value | I9: note (verbatim)
A10: admissible-set echo (design) | B10: TH_design | C10: design | D10: defined | E10: h4_admissible_echo | F10: =SUMPRODUCT((Results_Long!$A$2:$A$1348=$B10)*(Results_Long!$B$2:$B$1348=$C10)*(Results_Long!$C$2:$C$1348=$D10)*(Results_Long!$D$2:$D$1348=$E10)*ROW(Results_Long!$A$2:$A$1348)) -> 1344 | G10: =IF(INDEX(Results_Long!$N:$N,$F10)="","NA",INDEX(Results_Long!$N:$N,$F10)) -> NA | H10: =IF(INDEX(Results_Long!$AG:$AG,$F10)="","NA",INDEX(Results_Long!$AG:$AG,$F10)) -> 12 | I10: =IF(INDEX(Results_Long!$AJ:$AJ,$F10)="","NA",INDEX(Results_Long!$AJ:$AJ,$F10)) -> read from TH_a_results.csv design row and membership-verified: 2008, 2009, 2010, 2011, 2012, 2013, 2014, 2015, 2016, 2017, 2018, 2019; recomputation identity via the observed permutation-pass machinery
A12: Interpretation
A13: The observed statistic (sup |t| = value in TH_a_results.csv, tabulated in the TH-a workbook Tab '7_H4_Break_Grid') is carried verbatim in the p_perm row note here; this tab reports the reference distribution only (single-home rule).
A14: Each replicate recomputes the full 12-year grid on translated windows and takes its supremum - the multiplicity of the year search is thus inside the null distribution.
A16: Question | B16: Answer
A17: Why B = 500 rather than the Annex-H 2,000? | B17: DEC-045 S5 (benchmark-derived): B = 500 with eff_B enforcement (fail share <= 1%) bounds the minimum attainable p at ~0.002 - sufficient for the pre-registered alpha ladder at a quarter of the runtime.
A19: Verdict: Mechanical outcome: sup-statistic permutation p and effective replicates tabulated; observed sup single-homed in TH-a; adjudication deferred to the documented gate-resolution step [DEC-044].

Sheet 10_H5_Perm_Race
A1: TH-c (simulation & permutation family) · H5 - permutation inference for the trend-vs-break race statistic
A2: Time-translation permutation [H-Q20]; observed |t_race| anchored via F65 gates; point estimate and p_CR2 single-homed in T8 [4a].
A3: Run finished 2026-07-26 17:39 (canonical) · runtime 44.3 h · verifier R/09_verify_outputs.R 19/19 PASS · chat artefact check 2026-07-26 18/18 PASS · output/TH_c_results.csv 1347x36 · counters fits/fallback/fail: 11,500/92/0 (pass) · 540/3/0 (curve) · 200/2/0 (calibration) · eff_B 500/500/500 · not_estimable cells: 0
A5: Panel row | B5: analysis_id | C5: spec | D5: subset | E5: term | F5: RL row | G5: k_es | H5: k_cl | I5: value | J5: note (verbatim)
A6: p_perm (race |t|) | B6: H5 | C6: perm_race | D6: defined | E6: p_perm | F6: =SUMPRODUCT((Results_Long!$A$2:$A$1348=$B6)*(Results_Long!$B$2:$B$1348=$C6)*(Results_Long!$C$2:$C$1348=$D6)*(Results_Long!$D$2:$D$1348=$E6)*ROW(Results_Long!$A$2:$A$1348)) -> 70 | G6: =IF(INDEX(Results_Long!$H:$H,$F6)="","NA",INDEX(Results_Long!$H:$H,$F6)) -> 2705 | H6: =IF(INDEX(Results_Long!$J:$J,$F6)="","NA",INDEX(Results_Long!$J:$J,$F6)) -> 112 | I6: =IF(INDEX(Results_Long!$AG:$AG,$F6)="","NA",INDEX(Results_Long!$AG:$AG,$F6)) -> 0.4011976 | J6: =IF(INDEX(Results_Long!$AJ:$AJ,$F6)="","NA",INDEX(Results_Long!$AJ:$AJ,$F6)) -> time-translation permutation [H-Q20]: p = (1 + 200) / (500 + 1); observed |t_race| = 1.052421 (pp_mid coefficient of the T8 race model; point estimate/p_CR2 live in T8 — single-home [4a]); B = 500, exceed count = 200 of 500 effective
A7: effective replicates | B7: H5 | C7: perm_race | D7: defined | E7: eff_B | F7: =SUMPRODUCT((Results_Long!$A$2:$A$1348=$B7)*(Results_Long!$B$2:$B$1348=$C7)*(Results_Long!$C$2:$C$1348=$D7)*(Results_Long!$D$2:$D$1348=$E7)*ROW(Results_Long!$A$2:$A$1348)) -> 71 | G7: =IF(INDEX(Results_Long!$H:$H,$F7)="","NA",INDEX(Results_Long!$H:$H,$F7)) -> NA | H7: =IF(INDEX(Results_Long!$J:$J,$F7)="","NA",INDEX(Results_Long!$J:$J,$F7)) -> NA | I7: =IF(INDEX(Results_Long!$AG:$AG,$F7)="","NA",INDEX(Results_Long!$AG:$AG,$F7)) -> 500 | J7: =IF(INDEX(Results_Long!$AJ:$AJ,$F7)="","NA",INDEX(Results_Long!$AJ:$AJ,$F7)) -> effective replicates (finite race statistic) of 500; failed replicates dropped from the denominator, share <= 0.01 enforced
A9: Panel row | B9: analysis_id | C9: spec | D9: subset | E9: term | F9: RL row | G9: df_Satt | H9: value | I9: note (verbatim)
A10: T8 race anchor (design) | B10: TH_design | C10: design | D10: defined | E10: t8_race_anchor | F10: =SUMPRODUCT((Results_Long!$A$2:$A$1348=$B10)*(Results_Long!$B$2:$B$1348=$C10)*(Results_Long!$C$2:$C$1348=$D10)*(Results_Long!$D$2:$D$1348=$E10)*ROW(Results_Long!$A$2:$A$1348)) -> 1343 | G10: =IF(INDEX(Results_Long!$N:$N,$F10)="","NA",INDEX(Results_Long!$N:$N,$F10)) -> NA | H10: =IF(INDEX(Results_Long!$AG:$AG,$F10)="","NA",INDEX(Results_Long!$AG:$AG,$F10)) -> NA | I10: =IF(INDEX(Results_Long!$AJ:$AJ,$F10)="","NA",INDEX(Results_Long!$AJ:$AJ,$F10)) -> F65 gates PASSED: committed T8 B4/race/pp_mid_lag0 matched embedded constants at 1e-9; observed refit identity at 1e-6; |t_race_obs| = 1.052421
A12: Interpretation
A13: The race point estimate and its CR2 p-value have ONE reporting home (T8 workbook) [single-home rule 4a]; this tab adds only the permutation reference; the observed |t_race| is carried verbatim in the row notes.
A14: Fixed variance components are prohibited here: each replicate refits the full REML race model so the null distribution replicates the actual test statistic [project pin].
A16: Question | B16: Answer
A17: Why does H5 permute rather than bootstrap? | B17: The estimand is exchangeability of calendar alignment under the null of no time structure; the cluster time-translation design targets exactly that, keeping within-cluster dependence intact [H-Q20].
A19: Verdict: Mechanical outcome: race-statistic permutation p and effective replicates tabulated; point estimate single-homed in T8; adjudication deferred to the documented gate-resolution step [DEC-044].

Sheet Results_Long
A1: analysis_id | B1: spec | C1: subset | D1: term | E1: metric | F1: estimator | G1: rho | H1: k_es | I1: k_study | J1: k_cluster | K1: est_z | L1: se_z | M1: t_stat | N1: df | O1: p | P1: ci_lb_z | Q1: ci_ub_z | R1: pi_lb_z | S1: pi_ub_z | T1: est_r | U1: ci_lb_r | V1: ci_ub_r | W1: pi_lb_r | X1: pi_ub_r | Y1: sigma2_cluster | Z1: sigma2_study | AA1: sigma2_esid | AB1: pct_cluster | AC1: pct_study | AD1: pct_esid | AE1: pct_sampling | AF1: typical_v | AG1: value | AH1: ms_input | AI1: ms_label | AJ1: note
A2: H1 | B2: own_x0.5 | C2: defined | D2: power_delta_0.00 | E2: count | F2: 3LMA-RVE_CR2 | G2: 0.6 | H2: 2705 | J2: 112 | N2: 11.576259 | AG2: 0.032 | AH2: FALSE | AJ2: H1 scenario own_x0.5: fixed VC (cluster/study/esid) = 0.00987277/5.10461e-10/0.00594159 (= T1/A2 components x 0.5); design X = [1, pp_mid] on 2,705/112; CR2/Satterthwaite two-sided alpha=.05, df precomputed y-free; delta enters as noncentral shift of one B=5000 stream [DEC-045/H-Q14/R1]
