Workbook

Sheet data
A1: study | B1: outcome | C1: ES (corr_coeff) | D1: sample_size no_firms_rounded | E1: sample_size no_firm-years_rounded | F1: sample_size no_firms_source | G1: sample_size no_firm-years_source | H1: ES_measure | I1: ES_source | J1: sample_start | K1: sample_end | L1: sample_mid | M1: sample_median | N1: sample_post share_2016 | O1: sample_post share_2017 | P1: sample_post share_2018 | Q1: sample_post share_2019 | R1: pp_share_lag0 | S1: pp_mid_lag0 | T1: pp_median_lag0 | U1: pp_end_lag0 | V1: pp_start_lag0 | W1: pp_window_class | X1: pp_share_lag1 | Y1: pp_share_lag2 | Z1: pp_share_lag3 | AA1: pp_end_lag1 | AB1: pp_end_lag2 | AC1: pp_end_lag3 | AD1: pp_median split | AE1: pp_tertial split | AF1: COD_instrument | AG1: CER_measure | AH1: industry | AI1: regulation_sample_start | AJ1: regulation_sample_end | AK1: country_region | AL1: country_econ | AM1: country_culture | AN1: country_legal | AO1: q_status | AP1: q_VHB | AQ1: field | AR1: country | AS1: source | AT1: x_direction | AU1: outcome_direction | AV1: b | AW1: SE | AX1: t | AY1: p | AZ1: r_bivariate | BA1: n_obs | BB1: x_lag | BC1: estimation_method | BD1: se_clustering | BE1: subsample_dimension | BF1: subsample_value | BG1: subsample_start | BH1: subsample_end | BI1: table_no | BJ1: panel_model | BK1: page | BL1: cell_quote | BM1: construct_label_verbatim | BN1: outcome_label_verbatim | BO1: corpus_segment | BP1: cluster_id | BQ1: es_method | BR1: construct_variant | BS1: unit | BT1: duplicate | BU1: staging_file | BV1: v10_ID | BW1: d_sample_start | BX1: d_sample_end | BY1: d_country | BZ1: d_midyear | CA1: d_post_share | CB1: d_pp_mid | CC1: d_pp_any | CD1: d_fisher_z | CE1: d_es_usable | CF1: row_skey
A2: Al-Fakir Al Rabab'a et al (2023) | B2: 1307 | C2: -0.3 | D2: 3666 | E2: =IF(ISNUMBER($BA2),$BA2,IF(AND(ISNUMBER($D2),ISNUMBER($BW2),ISNUMBER($BX2)),$D2*($BX2-$BW2+1),"")) -> 58656 | H2: bivariate | I2: Correlation coefficient available | J2: =IF($BW2<>"",$BW2,"") -> 2003 | K2: =IF($BX2<>"",$BX2,"") -> 2018 | L2: =IF(AND(ISNUMBER($BW2),ISNUMBER($BX2)),($BW2+$BX2)/2,"") -> 2010.5 | M2: =IF($L2<>"",$L2,"") -> 2010.5 | N2: =IF(AND(ISNUMBER($BW2),ISNUMBER($BX2)),MIN(1,MAX(0,($BX2-2016+1)/($BX2-$BW2+1))),"") -> 0.1875 | O2: =IF(AND(ISNUMBER($BW2),ISNUMBER($BX2)),MIN(1,MAX(0,($BX2-2017+1)/($BX2-$BW2+1))),"") -> 0.125 | P2: =IF(AND(ISNUMBER($BW2),ISNUMBER($BX2)),MIN(1,MAX(0,($BX2-2018+1)/($BX2-$BW2+1))),"") -> 0.0625 | Q2: =IF(AND(ISNUMBER($BW2),ISNUMBER($BX2)),MIN(1,MAX(0,($BX2-2019+1)/($BX2-$BW2+1))),"") -> 0 | R2: =IF(AND(ISNUMBER($BW2),ISNUMBER($BX2)),MIN(1,MAX(0,($BX2-2016+1)/($BX2-$BW2+1))),"") -> 0.1875 | S2: =IF($L2<>"",IF($L2>=2015.5,1,0),"") -> 0 | T2: =IF($L2<>"",IF($L2>=2016,1,0),"") -> 0 | U2: =IF(ISNUMBER($BX2),IF($BX2>=2016,1,0),"") -> 1 | V2: =IF(ISNUMBER($BW2),IF($BW2>=2016,1,0),"") -> 0 | W2: =IF(AND(ISNUMBER($BW2),ISNUMBER($BX2)),IF($BW2>=2016,"post-only",IF($BX2<2016,"pre-only","mixed")),"") -> mixed | X2: =IF(AND(ISNUMBER($BW2),ISNUMBER($BX2)),MIN(1,MAX(0,($BX2-2017+1)/($BX2-$BW2+1))),"") -> 0.125 | Y2: =IF(AND(ISNUMBER($BW2),ISNUMBER($BX2)),MIN(1,MAX(0,($BX2-2018+1)/($BX2-$BW2+1))),"") -> 0.0625 | Z2: =IF(AND(ISNUMBER($BW2),ISNUMBER($BX2)),MIN(1,MAX(0,($BX2-2019+1)/($BX2-$BW2+1))),"") -> 0 | AA2: =IF(ISNUMBER($BX2),IF($BX2>=2017,1,0),"") -> 1 | AB2: =IF(ISNUMBER($BX2),IF($BX2>=2018,1,0),"") -> 1 | AC2: =IF(ISNUMBER($BX2),IF($BX2>=2019,1,0),"") -> 0 | AD2: =IF($L2<>"",IF($L2>2013,1,0),"") -> 0 | AE2: =IF($L2<>"",1+IF($L2>2011,1,0)+IF($L2>2014,1,0),"") -> 1 | AF2: loan (interest rate) | AG2: performance | AH2: non-sensitive | AI2: 99_NCE | AJ2: 99_NCE | AK2: =IF(AND($CF2<>"",IFERROR(INDEX(subsample_country_map!$B:$B,MATCH($CF2,subsample_country_map!$A:$A,0)),"")<>""),INDEX(subsample_country_map!$B:$B,MATCH($CF2,subsample_country_map!$A:$A,0)),INDEX(lookup!$AA:$AA,MATCH($A2,lookup!$A:$A,0))) -> 3_AsiaPac | AL2: =IF(AND($CF2<>"",IFERROR(INDEX(subsample_country_map!$C:$C,MATCH($CF2,subsample_country_map!$A:$A,0)),"")<>""),INDEX(subsample_country_map!$C:$C,MATCH($CF2,subsample_country_map!$A:$A,0)),INDEX(lookup!$AB:$AB,MATCH($A2,lookup!$A:$A,0))) -> 99_NCE | AM2: =IF(AND($CF2<>"",IFERROR(INDEX(subsample_country_map!$D:$D,MATCH($CF2,subsample_country_map!$A:$A,0)),"")<>""),INDEX(subsample_country_map!$D:$D,MATCH($CF2,subsample_country_map!$A:$A,0)),INDEX(lookup!$AC:$AC,MATCH($A2,lookup!$A:$A,0))) -> 99_NCE | AN2: =IF(AND($CF2<>"",IFERROR(INDEX(subsample_country_map!$E:$E,MATCH($CF2,subsample_country_map!$A:$A,0)),"")<>""),INDEX(subsample_country_map!$E:$E,MATCH($CF2,subsample_country_map!$A:$A,0)),INDEX(lookup!$AD:$AD,MATCH($A2,lookup!$A:$A,0))) -> 99_NCE | AO2: =INDEX(lookup!$Y:$Y,MATCH($A2,lookup!$A:$A,0)) -> 0_published | AP2: =INDEX(lookup!$Z:$Z,MATCH($A2,lookup!$A:$A,0)) -> 1_VHB high | AQ2: =INDEX(lookup!$W:$W,MATCH($A2,lookup!$A:$A,0)) -> 1_fin/acc/econ | AS2: staging | AT2: author-inverted-to-good | AU2: cost | AZ2: -0.30 | BA2: FLAG | BB2: 0 | BC2: n/a (structural) | BD2: n/a (structural) | BE2: none | BI2: Table 4 | BJ2: Correlation matrix col (1) | BK2: 8 | BL2: (2) CCP1 -0.30 [bold] | BM2: CCP1 | BN2: COD | BO2: update | BP2: Al-Fakir Al Rabab'a et al (2023) | BQ2: bivariate | BT2: 0 | BU2: staging_Al-Fakir_Al_Rababa_et_al_2023.csv | BW2: 2003 | BX2: 2018 | BY2: multi: 14 Asia-Pacific countries (Australia, China, Hong Kong, India, Indonesia, Japan, Malaysia, New Zealand, Philippines, Singapore, South Korea, Sri Lanka, Taiwan, Thailand) | BZ2: 2010.5 | CA2: 0.1875 | CB2: 0 | CC2: 1 | CD2: -0.3095196 | CE2: 1
A3: Al-Fakir Al Rabab'a et al (2023) | B3: 1308 | C3: -0.08 | D3: 3666 | E3: =IF(ISNUMBER($BA3),$BA3,IF(AND(ISNUMBER($D3),ISNUMBER($BW3),ISNUMBER($BX3)),$D3*($BX3-$BW3+1),"")) -> 58656 | H3: bivariate | I3: Correlation coefficient available | J3: =IF($BW3<>"",$BW3,"") -> 2003 | K3: =IF($BX3<>"",$BX3,"") -> 2018 | L3: =IF(AND(ISNUMBER($BW3),ISNUMBER($BX3)),($BW3+$BX3)/2,"") -> 2010.5 | M3: =IF($L3<>"",$L3,"") -> 2010.5 | N3: =IF(AND(ISNUMBER($BW3),ISNUMBER($BX3)),MIN(1,MAX(0,($BX3-2016+1)/($BX3-$BW3+1))),"") -> 0.1875 | O3: =IF(AND(ISNUMBER($BW3),ISNUMBER($BX3)),MIN(1,MAX(0,($BX3-2017+1)/($BX3-$BW3+1))),"") -> 0.125 | P3: =IF(AND(ISNUMBER($BW3),ISNUMBER($BX3)),MIN(1,MAX(0,($BX3-2018+1)/($BX3-$BW3+1))),"") -> 0.0625 | Q3: =IF(AND(ISNUMBER($BW3),ISNUMBER($BX3)),MIN(1,MAX(0,($BX3-2019+1)/($BX3-$BW3+1))),"") -> 0 | R3: =IF(AND(ISNUMBER($BW3),ISNUMBER($BX3)),MIN(1,MAX(0,($BX3-2016+1)/($BX3-$BW3+1))),"") -> 0.1875 | S3: =IF($L3<>"",IF($L3>=2015.5,1,0),"") -> 0 | T3: =IF($L3<>"",IF($L3>=2016,1,0),"") -> 0 | U3: =IF(ISNUMBER($BX3),IF($BX3>=2016,1,0),"") -> 1 | V3: =IF(ISNUMBER($BW3),IF($BW3>=2016,1,0),"") -> 0 | W3: =IF(AND(ISNUMBER($BW3),ISNUMBER($BX3)),IF($BW3>=2016,"post-only",IF($BX3<2016,"pre-only","mixed")),"") -> mixed | X3: =IF(AND(ISNUMBER($BW3),ISNUMBER($BX3)),MIN(1,MAX(0,($BX3-2017+1)/($BX3-$BW3+1))),"") -> 0.125 | Y3: =IF(AND(ISNUMBER($BW3),ISNUMBER($BX3)),MIN(1,MAX(0,($BX3-2018+1)/($BX3-$BW3+1))),"") -> 0.0625 | Z3: =IF(AND(ISNUMBER($BW3),ISNUMBER($BX3)),MIN(1,MAX(0,($BX3-2019+1)/($BX3-$BW3+1))),"") -> 0 | AA3: =IF(ISNUMBER($BX3),IF($BX3>=2017,1,0),"") -> 1 | AB3: =IF(ISNUMBER($BX3),IF($BX3>=2018,1,0),"") -> 1 | AC3: =IF(ISNUMBER($BX3),IF($BX3>=2019,1,0),"") -> 0 | AD3: =IF($L3<>"",IF($L3>2013,1,0),"") -> 0 | AE3: =IF($L3<>"",1+IF($L3>2011,1,0)+IF($L3>2014,1,0),"") -> 1 | AF3: loan (interest rate) | AG3: performance | AH3: non-sensitive | AI3: 99_NCE | AJ3: 99_NCE | AK3: =IF(AND($CF3<>"",IFERROR(INDEX(subsample_country_map!$B:$B,MATCH($CF3,subsample_country_map!$A:$A,0)),"")<>""),INDEX(subsample_country_map!$B:$B,MATCH($CF3,subsample_country_map!$A:$A,0)),INDEX(lookup!$AA:$AA,MATCH($A3,lookup!$A:$A,0))) -> 3_AsiaPac | AL3: =IF(AND($CF3<>"",IFERROR(INDEX(subsample_country_map!$C:$C,MATCH($CF3,subsample_country_map!$A:$A,0)),"")<>""),INDEX(subsample_country_map!$C:$C,MATCH($CF3,subsample_country_map!$A:$A,0)),INDEX(lookup!$AB:$AB,MATCH($A3,lookup!$A:$A,0))) -> 99_NCE | AM3: =IF(AND($CF3<>"",IFERROR(INDEX(subsample_country_map!$D:$D,MATCH($CF3,subsample_country_map!$A:$A,0)),"")<>""),INDEX(subsample_country_map!$D:$D,MATCH($CF3,subsample_country_map!$A:$A,0)),INDEX(lookup!$AC:$AC,MATCH($A3,lookup!$A:$A,0))) -> 99_NCE | AN3: =IF(AND($CF3<>"",IFERROR(INDEX(subsample_country_map!$E:$E,MATCH($CF3,subsample_country_map!$A:$A,0)),"")<>""),INDEX(subsample_country_map!$E:$E,MATCH($CF3,subsample_country_map!$A:$A,0)),INDEX(lookup!$AD:$AD,MATCH($A3,lookup!$A:$A,0))) -> 99_NCE | AO3: =INDEX(lookup!$Y:$Y,MATCH($A3,lookup!$A:$A,0)) -> 0_published | AP3: =INDEX(lookup!$Z:$Z,MATCH($A3,lookup!$A:$A,0)) -> 1_VHB high | AQ3: =INDEX(lookup!$W:$W,MATCH($A3,lookup!$A:$A,0)) -> 1_fin/acc/econ | AS3: staging | AT3: author-inverted-to-good | AU3: cost | AZ3: -0.08 | BA3: FLAG | BB3: 0 | BC3: n/a (structural) | BD3: n/a (structural) | BE3: none | BI3: Table 4 | BJ3: Correlation matrix col (1) | BK3: 8 | BL3: (3) CCP2 -0.08 [bold] | BM3: CCP2 | BN3: COD | BO3: update | BP3: Al-Fakir Al Rabab'a et al (2023) | BQ3: bivariate | BT3: 0 | BU3: staging_Al-Fakir_Al_Rababa_et_al_2023.csv | BW3: 2003 | BX3: 2018 | BY3: multi: 14 Asia-Pacific countries (Australia, China, Hong Kong, India, Indonesia, Japan, Malaysia, New Zealand, Philippines, Singapore, South Korea, Sri Lanka, Taiwan, Thailand) | BZ3: 2010.5 | CA3: 0.1875 | CB3: 0 | CC3: 1 | CD3: -0.080171325 | CE3: 1
A4: Al-Fakir Al Rabab'a et al (2023) | B4: 1309 | C4: -0.12 | D4: 3666 | E4: =IF(ISNUMBER($BA4),$BA4,IF(AND(ISNUMBER($D4),ISNUMBER($BW4),ISNUMBER($BX4)),$D4*($BX4-$BW4+1),"")) -> 58656 | H4: bivariate | I4: Correlation coefficient available | J4: =IF($BW4<>"",$BW4,"") -> 2003 | K4: =IF($BX4<>"",$BX4,"") -> 2018 | L4: =IF(AND(ISNUMBER($BW4),ISNUMBER($BX4)),($BW4+$BX4)/2,"") -> 2010.5 | M4: =IF($L4<>"",$L4,"") -> 2010.5 | N4: =IF(AND(ISNUMBER($BW4),ISNUMBER($BX4)),MIN(1,MAX(0,($BX4-2016+1)/($BX4-$BW4+1))),"") -> 0.1875 | O4: =IF(AND(ISNUMBER($BW4),ISNUMBER($BX4)),MIN(1,MAX(0,($BX4-2017+1)/($BX4-$BW4+1))),"") -> 0.125 | P4: =IF(AND(ISNUMBER($BW4),ISNUMBER($BX4)),MIN(1,MAX(0,($BX4-2018+1)/($BX4-$BW4+1))),"") -> 0.0625 | Q4: =IF(AND(ISNUMBER($BW4),ISNUMBER($BX4)),MIN(1,MAX(0,($BX4-2019+1)/($BX4-$BW4+1))),"") -> 0 | R4: =IF(AND(ISNUMBER($BW4),ISNUMBER($BX4)),MIN(1,MAX(0,($BX4-2016+1)/($BX4-$BW4+1))),"") -> 0.1875 | S4: =IF($L4<>"",IF($L4>=2015.5,1,0),"") -> 0 | T4: =IF($L4<>"",IF($L4>=2016,1,0),"") -> 0 | U4: =IF(ISNUMBER($BX4),IF($BX4>=2016,1,0),"") -> 1 | V4: =IF(ISNUMBER($BW4),IF($BW4>=2016,1,0),"") -> 0 | W4: =IF(AND(ISNUMBER($BW4),ISNUMBER($BX4)),IF($BW4>=2016,"post-only",IF($BX4<2016,"pre-only","mixed")),"") -> mixed | X4: =IF(AND(ISNUMBER($BW4),ISNUMBER($BX4)),MIN(1,MAX(0,($BX4-2017+1)/($BX4-$BW4+1))),"") -> 0.125 | Y4: =IF(AND(ISNUMBER($BW4),ISNUMBER($BX4)),MIN(1,MAX(0,($BX4-2018+1)/($BX4-$BW4+1))),"") -> 0.0625 | Z4: =IF(AND(ISNUMBER($BW4),ISNUMBER($BX4)),MIN(1,MAX(0,($BX4-2019+1)/($BX4-$BW4+1))),"") -> 0 | AA4: =IF(ISNUMBER($BX4),IF($BX4>=2017,1,0),"") -> 1 | AB4: =IF(ISNUMBER($BX4),IF($BX4>=2018,1,0),"") -> 1 | AC4: =IF(ISNUMBER($BX4),IF($BX4>=2019,1,0),"") -> 0 | AD4: =IF($L4<>"",IF($L4>2013,1,0),"") -> 0 | AE4: =IF($L4<>"",1+IF($L4>2011,1,0)+IF($L4>2014,1,0),"") -> 1 | AF4: loan (interest rate) | AG4: performance | AH4: non-sensitive | AI4: 99_NCE | AJ4: 99_NCE | AK4: =IF(AND($CF4<>"",IFERROR(INDEX(subsample_country_map!$B:$B,MATCH($CF4,subsample_country_map!$A:$A,0)),"")<>""),INDEX(subsample_country_map!$B:$B,MATCH($CF4,subsample_country_map!$A:$A,0)),INDEX(lookup!$AA:$AA,MATCH($A4,lookup!$A:$A,0))) -> 3_AsiaPac | AL4: =IF(AND($CF4<>"",IFERROR(INDEX(subsample_country_map!$C:$C,MATCH($CF4,subsample_country_map!$A:$A,0)),"")<>""),INDEX(subsample_country_map!$C:$C,MATCH($CF4,subsample_country_map!$A:$A,0)),INDEX(lookup!$AB:$AB,MATCH($A4,lookup!$A:$A,0))) -> 99_NCE | AM4: =IF(AND($CF4<>"",IFERROR(INDEX(subsample_country_map!$D:$D,MATCH($CF4,subsample_country_map!$A:$A,0)),"")<>""),INDEX(subsample_country_map!$D:$D,MATCH($CF4,subsample_country_map!$A:$A,0)),INDEX(lookup!$AC:$AC,MATCH($A4,lookup!$A:$A,0))) -> 99_NCE | AN4: =IF(AND($CF4<>"",IFERROR(INDEX(subsample_country_map!$E:$E,MATCH($CF4,subsample_country_map!$A:$A,0)),"")<>""),INDEX(subsample_country_map!$E:$E,MATCH($CF4,subsample_country_map!$A:$A,0)),INDEX(lookup!$AD:$AD,MATCH($A4,lookup!$A:$A,0))) -> 99_NCE | AO4: =INDEX(lookup!$Y:$Y,MATCH($A4,lookup!$A:$A,0)) -> 0_published | AP4: =INDEX(lookup!$Z:$Z,MATCH($A4,lookup!$A:$A,0)) -> 1_VHB high | AQ4: =INDEX(lookup!$W:$W,MATCH($A4,lookup!$A:$A,0)) -> 1_fin/acc/econ | AS4: staging | AT4: good-CER | AU4: cost | AZ4: -0.12 | BA4: FLAG | BB4: 0 | BC4: n/a (structural) | BD4: n/a (structural) | BE4: none | BI4: Table 4 | BJ4: Correlation matrix col (1) | BK4: 8 | BL4: (4) CCP3 -0.12 [bold] | BM4: CCP3 | BN4: COD | BO4: update | BP4: Al-Fakir Al Rabab'a et al (2023) | BQ4: bivariate | BT4: 0 | BU4: staging_Al-Fakir_Al_Rababa_et_al_2023.csv | BW4: 2003 | BX4: 2018 | BY4: multi: 14 Asia-Pacific countries (Australia, China, Hong Kong, India, Indonesia, Japan, Malaysia, New Zealand, Philippines, Singapore, South Korea, Sri Lanka, Taiwan, Thailand) | BZ4: 2010.5 | CA4: 0.1875 | CB4: 0 | CC4: 1 | CD4: -0.12058103 | CE4: 1
A5: Al-Fakir Al Rabab'a et al (2023) | B5: 1310 | C5: -0.15 | D5: 3666 | E5: =IF(ISNUMBER($BA5),$BA5,IF(AND(ISNUMBER($D5),ISNUMBER($BW5),ISNUMBER($BX5)),$D5*($BX5-$BW5+1),"")) -> 58656 | H5: bivariate | I5: Correlation coefficient available | J5: =IF($BW5<>"",$BW5,"") -> 2003 | K5: =IF($BX5<>"",$BX5,"") -> 2018 | L5: =IF(AND(ISNUMBER($BW5),ISNUMBER($BX5)),($BW5+$BX5)/2,"") -> 2010.5 | M5: =IF($L5<>"",$L5,"") -> 2010.5 | N5: =IF(AND(ISNUMBER($BW5),ISNUMBER($BX5)),MIN(1,MAX(0,($BX5-2016+1)/($BX5-$BW5+1))),"") -> 0.1875 | O5: =IF(AND(ISNUMBER($BW5),ISNUMBER($BX5)),MIN(1,MAX(0,($BX5-2017+1)/($BX5-$BW5+1))),"") -> 0.125 | P5: =IF(AND(ISNUMBER($BW5),ISNUMBER($BX5)),MIN(1,MAX(0,($BX5-2018+1)/($BX5-$BW5+1))),"") -> 0.0625 | Q5: =IF(AND(ISNUMBER($BW5),ISNUMBER($BX5)),MIN(1,MAX(0,($BX5-2019+1)/($BX5-$BW5+1))),"") -> 0 | R5: =IF(AND(ISNUMBER($BW5),ISNUMBER($BX5)),MIN(1,MAX(0,($BX5-2016+1)/($BX5-$BW5+1))),"") -> 0.1875 | S5: =IF($L5<>"",IF($L5>=2015.5,1,0),"") -> 0 | T5: =IF($L5<>"",IF($L5>=2016,1,0),"") -> 0 | U5: =IF(ISNUMBER($BX5),IF($BX5>=2016,1,0),"") -> 1 | V5: =IF(ISNUMBER($BW5),IF($BW5>=2016,1,0),"") -> 0 | W5: =IF(AND(ISNUMBER($BW5),ISNUMBER($BX5)),IF($BW5>=2016,"post-only",IF($BX5<2016,"pre-only","mixed")),"") -> mixed | X5: =IF(AND(ISNUMBER($BW5),ISNUMBER($BX5)),MIN(1,MAX(0,($BX5-2017+1)/($BX5-$BW5+1))),"") -> 0.125 | Y5: =IF(AND(ISNUMBER($BW5),ISNUMBER($BX5)),MIN(1,MAX(0,($BX5-2018+1)/($BX5-$BW5+1))),"") -> 0.0625 | Z5: =IF(AND(ISNUMBER($BW5),ISNUMBER($BX5)),MIN(1,MAX(0,($BX5-2019+1)/($BX5-$BW5+1))),"") -> 0 | AA5: =IF(ISNUMBER($BX5),IF($BX5>=2017,1,0),"") -> 1 | AB5: =IF(ISNUMBER($BX5),IF($BX5>=2018,1,0),"") -> 1 | AC5: =IF(ISNUMBER($BX5),IF($BX5>=2019,1,0),"") -> 0 | AD5: =IF($L5<>"",IF($L5>2013,1,0),"") -> 0 | AE5: =IF($L5<>"",1+IF($L5>2011,1,0)+IF($L5>2014,1,0),"") -> 1 | AF5: loan (interest rate) | AG5: performance | AH5: non-sensitive | AI5: 99_NCE | AJ5: 99_NCE | AK5: =IF(AND($CF5<>"",IFERROR(INDEX(subsample_country_map!$B:$B,MATCH($CF5,subsample_country_map!$A:$A,0)),"")<>""),INDEX(subsample_country_map!$B:$B,MATCH($CF5,subsample_country_map!$A:$A,0)),INDEX(lookup!$AA:$AA,MATCH($A5,lookup!$A:$A,0))) -> 3_AsiaPac | AL5: =IF(AND($CF5<>"",IFERROR(INDEX(subsample_country_map!$C:$C,MATCH($CF5,subsample_country_map!$A:$A,0)),"")<>""),INDEX(subsample_country_map!$C:$C,MATCH($CF5,subsample_country_map!$A:$A,0)),INDEX(lookup!$AB:$AB,MATCH($A5,lookup!$A:$A,0))) -> 99_NCE | AM5: =IF(AND($CF5<>"",IFERROR(INDEX(subsample_country_map!$D:$D,MATCH($CF5,subsample_country_map!$A:$A,0)),"")<>""),INDEX(subsample_country_map!$D:$D,MATCH($CF5,subsample_country_map!$A:$A,0)),INDEX(lookup!$AC:$AC,MATCH($A5,lookup!$A:$A,0))) -> 99_NCE | AN5: =IF(AND($CF5<>"",IFERROR(INDEX(subsample_country_map!$E:$E,MATCH($CF5,subsample_country_map!$A:$A,0)),"")<>""),INDEX(subsample_country_map!$E:$E,MATCH($CF5,subsample_country_map!$A:$A,0)),INDEX(lookup!$AD:$AD,MATCH($A5,lookup!$A:$A,0))) -> 99_NCE | AO5: =INDEX(lookup!$Y:$Y,MATCH($A5,lookup!$A:$A,0)) -> 0_published | AP5: =INDEX(lookup!$Z:$Z,MATCH($A5,lookup!$A:$A,0)) -> 1_VHB high | AQ5: =INDEX(lookup!$W:$W,MATCH($A5,lookup!$A:$A,0)) -> 1_fin/acc/econ | AS5: staging | AT5: good-CER | AU5: cost | AZ5: -0.15 | BA5: FLAG | BB5: 0 | BC5: n/a (structural) | BD5: n/a (structural) | BE5: none | BI5: Table 4 | BJ5: Correlation matrix col (1) | BK5: 8 | BL5: (5) CCP4 -0.15 [bold] | BM5: CCP4 | BN5: COD | BO5: update | BP5: Al-Fakir Al Rabab'a et al (2023) | BQ5: bivariate | BT5: 0 | BU5: staging_Al-Fakir_Al_Rababa_et_al_2023.csv | BW5: 2003 | BX5: 2018 | BY5: multi: 14 Asia-Pacific countries (Australia, China, Hong Kong, India, Indonesia, Japan, Malaysia, New Zealand, Philippines, Singapore, South Korea, Sri Lanka, Taiwan, Thailand) | BZ5: 2010.5 | CA5: 0.1875 | CB5: 0 | CC5: 1 | CD5: -0.15114044 | CE5: 1
A6: Al-Fakir Al Rabab'a et al (2023) | B6: 1311 | C6: -0.039936732 | D6: 3666 | E6: =IF(ISNUMBER($BA6),$BA6,IF(AND(ISNUMBER($D6),ISNUMBER($BW6),ISNUMBER($BX6)),$D6*($BX6-$BW6+1),"")) -> 3666 | H6: partial | I6: T-Statistic available | J6: =IF($BW6<>"",$BW6,"") -> 2003 | K6: =IF($BX6<>"",$BX6,"") -> 2018 | L6: =IF(AND(ISNUMBER($BW6),ISNUMBER($BX6)),($BW6+$BX6)/2,"") -> 2010.5 | M6: =IF($L6<>"",$L6,"") -> 2010.5 | N6: =IF(AND(ISNUMBER($BW6),ISNUMBER($BX6)),MIN(1,MAX(0,($BX6-2016+1)/($BX6-$BW6+1))),"") -> 0.1875 | O6: =IF(AND(ISNUMBER($BW6),ISNUMBER($BX6)),MIN(1,MAX(0,($BX6-2017+1)/($BX6-$BW6+1))),"") -> 0.125 | P6: =IF(AND(ISNUMBER($BW6),ISNUMBER($BX6)),MIN(1,MAX(0,($BX6-2018+1)/($BX6-$BW6+1))),"") -> 0.0625 | Q6: =IF(AND(ISNUMBER($BW6),ISNUMBER($BX6)),MIN(1,MAX(0,($BX6-2019+1)/($BX6-$BW6+1))),"") -> 0 | R6: =IF(AND(ISNUMBER($BW6),ISNUMBER($BX6)),MIN(1,MAX(0,($BX6-2016+1)/($BX6-$BW6+1))),"") -> 0.1875 | S6: =IF($L6<>"",IF($L6>=2015.5,1,0),"") -> 0 | T6: =IF($L6<>"",IF($L6>=2016,1,0),"") -> 0 | U6: =IF(ISNUMBER($BX6),IF($BX6>=2016,1,0),"") -> 1 | V6: =IF(ISNUMBER($BW6),IF($BW6>=2016,1,0),"") -> 0 | W6: =IF(AND(ISNUMBER($BW6),ISNUMBER($BX6)),IF($BW6>=2016,"post-only",IF($BX6<2016,"pre-only","mixed")),"") -> mixed | X6: =IF(AND(ISNUMBER($BW6),ISNUMBER($BX6)),MIN(1,MAX(0,($BX6-2017+1)/($BX6-$BW6+1))),"") -> 0.125 | Y6: =IF(AND(ISNUMBER($BW6),ISNUMBER($BX6)),MIN(1,MAX(0,($BX6-2018+1)/($BX6-$BW6+1))),"") -> 0.0625 | Z6: =IF(AND(ISNUMBER($BW6),ISNUMBER($BX6)),MIN(1,MAX(0,($BX6-2019+1)/($BX6-$BW6+1))),"") -> 0 | AA6: =IF(ISNUMBER($BX6),IF($BX6>=2017,1,0),"") -> 1 | AB6: =IF(ISNUMBER($BX6),IF($BX6>=2018,1,0),"") -> 1 | AC6: =IF(ISNUMBER($BX6),IF($BX6>=2019,1,0),"") -> 0 | AD6: =IF($L6<>"",IF($L6>2013,1,0),"") -> 0 | AE6: =IF($L6<>"",1+IF($L6>2011,1,0)+IF($L6>2014,1,0),"") -> 1 | AF6: loan (interest rate) | AG6: performance | AH6: non-sensitive | AI6: 99_NCE | AJ6: 99_NCE | AK6: =IF(AND($CF6<>"",IFERROR(INDEX(subsample_country_map!$B:$B,MATCH($CF6,subsample_country_map!$A:$A,0)),"")<>""),INDEX(subsample_country_map!$B:$B,MATCH($CF6,subsample_country_map!$A:$A,0)),INDEX(lookup!$AA:$AA,MATCH($A6,lookup!$A:$A,0))) -> 3_AsiaPac | AL6: =IF(AND($CF6<>"",IFERROR(INDEX(subsample_country_map!$C:$C,MATCH($CF6,subsample_country_map!$A:$A,0)),"")<>""),INDEX(subsample_country_map!$C:$C,MATCH($CF6,subsample_country_map!$A:$A,0)),INDEX(lookup!$AB:$AB,MATCH($A6,lookup!$A:$A,0))) -> 99_NCE | AM6: =IF(AND($CF6<>"",IFERROR(INDEX(subsample_country_map!$D:$D,MATCH($CF6,subsample_country_map!$A:$A,0)),"")<>""),INDEX(subsample_country_map!$D:$D,MATCH($CF6,subsample_country_map!$A:$A,0)),INDEX(lookup!$AC:$AC,MATCH($A6,lookup!$A:$A,0))) -> 99_NCE | AN6: =IF(AND($CF6<>"",IFERROR(INDEX(subsample_country_map!$E:$E,MATCH($CF6,subsample_country_map!$A:$A,0)),"")<>""),INDEX(subsample_country_map!$E:$E,MATCH($CF6,subsample_country_map!$A:$A,0)),INDEX(lookup!$AD:$AD,MATCH($A6,lookup!$A:$A,0))) -> 99_NCE | AO6: =INDEX(lookup!$Y:$Y,MATCH($A6,lookup!$A:$A,0)) -> 0_published | AP6: =INDEX(lookup!$Z:$Z,MATCH($A6,lookup!$A:$A,0)) -> 1_VHB high | AQ6: =INDEX(lookup!$W:$W,MATCH($A6,lookup!$A:$A,0)) -> 1_fin/acc/econ | AS6: staging | AT6: author-inverted-to-good | AU6: cost | AV6: -0.240 | AX6: -2.42 | BA6: 3666 | BB6: 0 | BC6: OLS | BD6: firm | BE6: none | BI6: Table 5 | BJ6: Panel A col 1 | BK6: 8 | BL6: CCP1 -0.240** (-2.42) | BM6: CCP1 | BN6: COD | BO6: update | BP6: Al-Fakir Al Rabab'a et al (2023) | BQ6: computed | BT6: 0 | BU6: staging_Al-Fakir_Al_Rababa_et_al_2023.csv | BW6: 2003 | BX6: 2018 | BY6: multi: 14 Asia-Pacific countries (Australia, China, Hong Kong, India, Indonesia, Japan, Malaysia, New Zealand, Philippines, Singapore, South Korea, Sri Lanka, Taiwan, Thailand) | BZ6: 2010.5 | CA6: 0.1875 | CB6: 0 | CC6: 1 | CD6: -0.039957984 | CE6: 1
A7: Al-Fakir Al Rabab'a et al (2023) | B7: 1312 | C7: -0.039442423 | D7: 3666 | E7: =IF(ISNUMBER($BA7),$BA7,IF(AND(ISNUMBER($D7),ISNUMBER($BW7),ISNUMBER($BX7)),$D7*($BX7-$BW7+1),"")) -> 3666 | H7: partial | I7: T-Statistic available | J7: =IF($BW7<>"",$BW7,"") -> 2003 | K7: =IF($BX7<>"",$BX7,"") -> 2018 | L7: =IF(AND(ISNUMBER($BW7),ISNUMBER($BX7)),($BW7+$BX7)/2,"") -> 2010.5 | M7: =IF($L7<>"",$L7,"") -> 2010.5 | N7: =IF(AND(ISNUMBER($BW7),ISNUMBER($BX7)),MIN(1,MAX(0,($BX7-2016+1)/($BX7-$BW7+1))),"") -> 0.1875 | O7: =IF(AND(ISNUMBER($BW7),ISNUMBER($BX7)),MIN(1,MAX(0,($BX7-2017+1)/($BX7-$BW7+1))),"") -> 0.125 | P7: =IF(AND(ISNUMBER($BW7),ISNUMBER($BX7)),MIN(1,MAX(0,($BX7-2018+1)/($BX7-$BW7+1))),"") -> 0.0625 | Q7: =IF(AND(ISNUMBER($BW7),ISNUMBER($BX7)),MIN(1,MAX(0,($BX7-2019+1)/($BX7-$BW7+1))),"") -> 0 | R7: =IF(AND(ISNUMBER($BW7),ISNUMBER($BX7)),MIN(1,MAX(0,($BX7-2016+1)/($BX7-$BW7+1))),"") -> 0.1875 | S7: =IF($L7<>"",IF($L7>=2015.5,1,0),"") -> 0 | T7: =IF($L7<>"",IF($L7>=2016,1,0),"") -> 0 | U7: =IF(ISNUMBER($BX7),IF($BX7>=2016,1,0),"") -> 1 | V7: =IF(ISNUMBER($BW7),IF($BW7>=2016,1,0),"") -> 0 | W7: =IF(AND(ISNUMBER($BW7),ISNUMBER($BX7)),IF($BW7>=2016,"post-only",IF($BX7<2016,"pre-only","mixed")),"") -> mixed | X7: =IF(AND(ISNUMBER($BW7),ISNUMBER($BX7)),MIN(1,MAX(0,($BX7-2017+1)/($BX7-$BW7+1))),"") -> 0.125 | Y7: =IF(AND(ISNUMBER($BW7),ISNUMBER($BX7)),MIN(1,MAX(0,($BX7-2018+1)/($BX7-$BW7+1))),"") -> 0.0625 | Z7: =IF(AND(ISNUMBER($BW7),ISNUMBER($BX7)),MIN(1,MAX(0,($BX7-2019+1)/($BX7-$BW7+1))),"") -> 0 | AA7: =IF(ISNUMBER($BX7),IF($BX7>=2017,1,0),"") -> 1 | AB7: =IF(ISNUMBER($BX7),IF($BX7>=2018,1,0),"") -> 1 | AC7: =IF(ISNUMBER($BX7),IF($BX7>=2019,1,0),"") -> 0 | AD7: =IF($L7<>"",IF($L7>2013,1,0),"") -> 0 | AE7: =IF($L7<>"",1+IF($L7>2011,1,0)+IF($L7>2014,1,0),"") -> 1 | AF7: loan (interest rate) | AG7: performance | AH7: non-sensitive | AI7: 99_NCE | AJ7: 99_NCE | AK7: =IF(AND($CF7<>"",IFERROR(INDEX(subsample_country_map!$B:$B,MATCH($CF7,subsample_country_map!$A:$A,0)),"")<>""),INDEX(subsample_country_map!$B:$B,MATCH($CF7,subsample_country_map!$A:$A,0)),INDEX(lookup!$AA:$AA,MATCH($A7,lookup!$A:$A,0))) -> 3_AsiaPac | AL7: =IF(AND($CF7<>"",IFERROR(INDEX(subsample_country_map!$C:$C,MATCH($CF7,subsample_country_map!$A:$A,0)),"")<>""),INDEX(subsample_country_map!$C:$C,MATCH($CF7,subsample_country_map!$A:$A,0)),INDEX(lookup!$AB:$AB,MATCH($A7,lookup!$A:$A,0))) -> 99_NCE | AM7: =IF(AND($CF7<>"",IFERROR(INDEX(subsample_country_map!$D:$D,MATCH($CF7,subsample_country_map!$A:$A,0)),"")<>""),INDEX(subsample_country_map!$D:$D,MATCH($CF7,subsample_country_map!$A:$A,0)),INDEX(lookup!$AC:$AC,MATCH($A7,lookup!$A:$A,0))) -> 99_NCE | AN7: =IF(AND($CF7<>"",IFERROR(INDEX(subsample_country_map!$E:$E,MATCH($CF7,subsample_country_map!$A:$A,0)),"")<>""),INDEX(subsample_country_map!$E:$E,MATCH($CF7,subsample_country_map!$A:$A,0)),INDEX(lookup!$AD:$AD,MATCH($A7,lookup!$A:$A,0))) -> 99_NCE | AO7: =INDEX(lookup!$Y:$Y,MATCH($A7,lookup!$A:$A,0)) -> 0_published | AP7: =INDEX(lookup!$Z:$Z,MATCH($A7,lookup!$A:$A,0)) -> 1_VHB high | AQ7: =INDEX(lookup!$W:$W,MATCH($A7,lookup!$A:$A,0)) -> 1_fin/acc/econ | AS7: staging | AT7: author-inverted-to-good | AU7: cost | AV7: -0.238 | AX7: -2.39 | BA7: 3666 | BB7: 0 | BC7: OLS | BD7: firm | BE7: none | BI7: Table 5 | BJ7: Panel A col 2 | BK7: 8 | BL7: CCP2 -0.238** (-2.39) | BM7: CCP2 | BN7: COD | BO7: update | BP7: Al-Fakir Al Rabab'a et al (2023) | BQ7: computed | BT7: 0 | BU7: staging_Al-Fakir_Al_Rababa_et_al_2023.csv | BW7: 2003 | BX7: 2018 | BY7: multi: 14 Asia-Pacific countries (Australia, China, Hong Kong, India, Indonesia, Japan, Malaysia, New Zealand, Philippines, Singapore, South Korea, Sri Lanka, Taiwan, Thailand) | BZ7: 2010.5 | CA7: 0.1875 | CB7: 0 | CC7: 1 | CD7: -0.039462896 | CE7: 1
A8: Al-Fakir Al Rabab'a et al (2023) | B8: 1313 | C8: -0.040431011 | D8: 3666 | E8: =IF(ISNUMBER($BA8),$BA8,IF(AND(ISNUMBER($D8),ISNUMBER($BW8),ISNUMBER($BX8)),$D8*($BX8-$BW8+1),"")) -> 3666 | H8: partial | I8: T-Statistic available | J8: =IF($BW8<>"",$BW8,"") -> 2003 | K8: =IF($BX8<>"",$BX8,"") -> 2018 | L8: =IF(AND(ISNUMBER($BW8),ISNUMBER($BX8)),($BW8+$BX8)/2,"") -> 2010.5 | M8: =IF($L8<>"",$L8,"") -> 2010.5 | N8: =IF(AND(ISNUMBER($BW8),ISNUMBER($BX8)),MIN(1,MAX(0,($BX8-2016+1)/($BX8-$BW8+1))),"") -> 0.1875 | O8: =IF(AND(ISNUMBER($BW8),ISNUMBER($BX8)),MIN(1,MAX(0,($BX8-2017+1)/($BX8-$BW8+1))),"") -> 0.125 | P8: =IF(AND(ISNUMBER($BW8),ISNUMBER($BX8)),MIN(1,MAX(0,($BX8-2018+1)/($BX8-$BW8+1))),"") -> 0.0625 | Q8: =IF(AND(ISNUMBER($BW8),ISNUMBER($BX8)),MIN(1,MAX(0,($BX8-2019+1)/($BX8-$BW8+1))),"") -> 0 | R8: =IF(AND(ISNUMBER($BW8),ISNUMBER($BX8)),MIN(1,MAX(0,($BX8-2016+1)/($BX8-$BW8+1))),"") -> 0.1875 | S8: =IF($L8<>"",IF($L8>=2015.5,1,0),"") -> 0 | T8: =IF($L8<>"",IF($L8>=2016,1,0),"") -> 0 | U8: =IF(ISNUMBER($BX8),IF($BX8>=2016,1,0),"") -> 1 | V8: =IF(ISNUMBER($BW8),IF($BW8>=2016,1,0),"") -> 0 | W8: =IF(AND(ISNUMBER($BW8),ISNUMBER($BX8)),IF($BW8>=2016,"post-only",IF($BX8<2016,"pre-only","mixed")),"") -> mixed | X8: =IF(AND(ISNUMBER($BW8),ISNUMBER($BX8)),MIN(1,MAX(0,($BX8-2017+1)/($BX8-$BW8+1))),"") -> 0.125 | Y8: =IF(AND(ISNUMBER($BW8),ISNUMBER($BX8)),MIN(1,MAX(0,($BX8-2018+1)/($BX8-$BW8+1))),"") -> 0.0625 | Z8: =IF(AND(ISNUMBER($BW8),ISNUMBER($BX8)),MIN(1,MAX(0,($BX8-2019+1)/($BX8-$BW8+1))),"") -> 0 | AA8: =IF(ISNUMBER($BX8),IF($BX8>=2017,1,0),"") -> 1 | AB8: =IF(ISNUMBER($BX8),IF($BX8>=2018,1,0),"") -> 1 | AC8: =IF(ISNUMBER($BX8),IF($BX8>=2019,1,0),"") -> 0 | AD8: =IF($L8<>"",IF($L8>2013,1,0),"") -> 0 | AE8: =IF($L8<>"",1+IF($L8>2011,1,0)+IF($L8>2014,1,0),"") -> 1 | AF8: loan (interest rate) | AG8: performance | AH8: non-sensitive | AI8: 99_NCE | AJ8: 99_NCE | AK8: =IF(AND($CF8<>"",IFERROR(INDEX(subsample_country_map!$B:$B,MATCH($CF8,subsample_country_map!$A:$A,0)),"")<>""),INDEX(subsample_country_map!$B:$B,MATCH($CF8,subsample_country_map!$A:$A,0)),INDEX(lookup!$AA:$AA,MATCH($A8,lookup!$A:$A,0))) -> 3_AsiaPac | AL8: =IF(AND($CF8<>"",IFERROR(INDEX(subsample_country_map!$C:$C,MATCH($CF8,subsample_country_map!$A:$A,0)),"")<>""),INDEX(subsample_country_map!$C:$C,MATCH($CF8,subsample_country_map!$A:$A,0)),INDEX(lookup!$AB:$AB,MATCH($A8,lookup!$A:$A,0))) -> 99_NCE | AM8: =IF(AND($CF8<>"",IFERROR(INDEX(subsample_country_map!$D:$D,MATCH($CF8,subsample_country_map!$A:$A,0)),"")<>""),INDEX(subsample_country_map!$D:$D,MATCH($CF8,subsample_country_map!$A:$A,0)),INDEX(lookup!$AC:$AC,MATCH($A8,lookup!$A:$A,0))) -> 99_NCE | AN8: =IF(AND($CF8<>"",IFERROR(INDEX(subsample_country_map!$E:$E,MATCH($CF8,subsample_country_map!$A:$A,0)),"")<>""),INDEX(subsample_country_map!$E:$E,MATCH($CF8,subsample_country_map!$A:$A,0)),INDEX(lookup!$AD:$AD,MATCH($A8,lookup!$A:$A,0))) -> 99_NCE | AO8: =INDEX(lookup!$Y:$Y,MATCH($A8,lookup!$A:$A,0)) -> 0_published | AP8: =INDEX(lookup!$Z:$Z,MATCH($A8,lookup!$A:$A,0)) -> 1_VHB high | AQ8: =INDEX(lookup!$W:$W,MATCH($A8,lookup!$A:$A,0)) -> 1_fin/acc/econ | AS8: staging | AT8: good-CER | AU8: cost | AV8: -0.022 | AX8: -2.45 | BA8: 3666 | BB8: 0 | BC8: OLS | BD8: firm | BE8: none | BI8: Table 5 | BJ8: Panel A col 3 | BK8: 8 | BL8: CCP3 -0.022** (-2.45) | BM8: CCP3 | BN8: COD | BO8: update | BP8: Al-Fakir Al Rabab'a et al (2023) | BQ8: computed | BT8: 0 | BU8: staging_Al-Fakir_Al_Rababa_et_al_2023.csv | BW8: 2003 | BX8: 2018 | BY8: multi: 14 Asia-Pacific countries (Australia, China, Hong Kong, India, Indonesia, Japan, Malaysia, New Zealand, Philippines, Singapore, South Korea, Sri Lanka, Taiwan, Thailand) | BZ8: 2010.5 | CA8: 0.1875 | CB8: 0 | CC8: 1 | CD8: -0.040453063 | CE8: 1
A9: Al-Fakir Al Rabab'a et al (2023) | B9: 1314 | C9: -0.03037534 | D9: 3666 | E9: =IF(ISNUMBER($BA9),$BA9,IF(AND(ISNUMBER($D9),ISNUMBER($BW9),ISNUMBER($BX9)),$D9*($BX9-$BW9+1),"")) -> 3666 | H9: partial | I9: T-Statistic available | J9: =IF($BW9<>"",$BW9,"") -> 2003 | K9: =IF($BX9<>"",$BX9,"") -> 2018 | L9: =IF(AND(ISNUMBER($BW9),ISNUMBER($BX9)),($BW9+$BX9)/2,"") -> 2010.5 | M9: =IF($L9<>"",$L9,"") -> 2010.5 | N9: =IF(AND(ISNUMBER($BW9),ISNUMBER($BX9)),MIN(1,MAX(0,($BX9-2016+1)/($BX9-$BW9+1))),"") -> 0.1875 | O9: =IF(AND(ISNUMBER($BW9),ISNUMBER($BX9)),MIN(1,MAX(0,($BX9-2017+1)/($BX9-$BW9+1))),"") -> 0.125 | P9: =IF(AND(ISNUMBER($BW9),ISNUMBER($BX9)),MIN(1,MAX(0,($BX9-2018+1)/($BX9-$BW9+1))),"") -> 0.0625 | Q9: =IF(AND(ISNUMBER($BW9),ISNUMBER($BX9)),MIN(1,MAX(0,($BX9-2019+1)/($BX9-$BW9+1))),"") -> 0 | R9: =IF(AND(ISNUMBER($BW9),ISNUMBER($BX9)),MIN(1,MAX(0,($BX9-2016+1)/($BX9-$BW9+1))),"") -> 0.1875 | S9: =IF($L9<>"",IF($L9>=2015.5,1,0),"") -> 0 | T9: =IF($L9<>"",IF($L9>=2016,1,0),"") -> 0 | U9: =IF(ISNUMBER($BX9),IF($BX9>=2016,1,0),"") -> 1 | V9: =IF(ISNUMBER($BW9),IF($BW9>=2016,1,0),"") -> 0 | W9: =IF(AND(ISNUMBER($BW9),ISNUMBER($BX9)),IF($BW9>=2016,"post-only",IF($BX9<2016,"pre-only","mixed")),"") -> mixed | X9: =IF(AND(ISNUMBER($BW9),ISNUMBER($BX9)),MIN(1,MAX(0,($BX9-2017+1)/($BX9-$BW9+1))),"") -> 0.125 | Y9: =IF(AND(ISNUMBER($BW9),ISNUMBER($BX9)),MIN(1,MAX(0,($BX9-2018+1)/($BX9-$BW9+1))),"") -> 0.0625 | Z9: =IF(AND(ISNUMBER($BW9),ISNUMBER($BX9)),MIN(1,MAX(0,($BX9-2019+1)/($BX9-$BW9+1))),"") -> 0 | AA9: =IF(ISNUMBER($BX9),IF($BX9>=2017,1,0),"") -> 1 | AB9: =IF(ISNUMBER($BX9),IF($BX9>=2018,1,0),"") -> 1 | AC9: =IF(ISNUMBER($BX9),IF($BX9>=2019,1,0),"") -> 0 | AD9: =IF($L9<>"",IF($L9>2013,1,0),"") -> 0 | AE9: =IF($L9<>"",1+IF($L9>2011,1,0)+IF($L9>2014,1,0),"") -> 1 | AF9: loan (interest rate) | AG9: performance | AH9: non-sensitive | AI9: 99_NCE | AJ9: 99_NCE | AK9: =IF(AND($CF9<>"",IFERROR(INDEX(subsample_country_map!$B:$B,MATCH($CF9,subsample_country_map!$A:$A,0)),"")<>""),INDEX(subsample_country_map!$B:$B,MATCH($CF9,subsample_country_map!$A:$A,0)),INDEX(lookup!$AA:$AA,MATCH($A9,lookup!$A:$A,0))) -> 3_AsiaPac | AL9: =IF(AND($CF9<>"",IFERROR(INDEX(subsample_country_map!$C:$C,MATCH($CF9,subsample_country_map!$A:$A,0)),"")<>""),INDEX(subsample_country_map!$C:$C,MATCH($CF9,subsample_country_map!$A:$A,0)),INDEX(lookup!$AB:$AB,MATCH($A9,lookup!$A:$A,0))) -> 99_NCE | AM9: =IF(AND($CF9<>"",IFERROR(INDEX(subsample_country_map!$D:$D,MATCH($CF9,subsample_country_map!$A:$A,0)),"")<>""),INDEX(subsample_country_map!$D:$D,MATCH($CF9,subsample_country_map!$A:$A,0)),INDEX(lookup!$AC:$AC,MATCH($A9,lookup!$A:$A,0))) -> 99_NCE | AN9: =IF(AND($CF9<>"",IFERROR(INDEX(subsample_country_map!$E:$E,MATCH($CF9,subsample_country_map!$A:$A,0)),"")<>""),INDEX(subsample_country_map!$E:$E,MATCH($CF9,subsample_country_map!$A:$A,0)),INDEX(lookup!$AD:$AD,MATCH($A9,lookup!$A:$A,0))) -> 99_NCE | AO9: =INDEX(lookup!$Y:$Y,MATCH($A9,lookup!$A:$A,0)) -> 0_published | AP9: =INDEX(lookup!$Z:$Z,MATCH($A9,lookup!$A:$A,0)) -> 1_VHB high | AQ9: =INDEX(lookup!$W:$W,MATCH($A9,lookup!$A:$A,0)) -> 1_fin/acc/econ | AS9: staging | AT9: good-CER | AU9: cost | AV9: -0.024 | AX9: -1.84 | BA9: 3666 | BB9: 0 | BC9: OLS | BD9: firm | BE9: none | BI9: Table 5 | BJ9: Panel A col 4 | BK9: 8 | BL9: CCP4 -0.024* (-1.84) | BM9: CCP4 | BN9: COD | BO9: update | BP9: Al-Fakir Al Rabab'a et al (2023) | BQ9: computed | BT9: 0 | BU9: staging_Al-Fakir_Al_Rababa_et_al_2023.csv | BW9: 2003 | BX9: 2018 | BY9: multi: 14 Asia-Pacific countries (Australia, China, Hong Kong, India, Indonesia, Japan, Malaysia, New Zealand, Philippines, Singapore, South Korea, Sri Lanka, Taiwan, Thailand) | BZ9: 2010.5 | CA9: 0.1875 | CB9: 0 | CC9: 1 | CD9: -0.030384687 | CE9: 1
A10: Al-Fakir Al Rabab'a et al (2023) | B10: 1315 | C10: -0.050638939 | D10: 3666 | E10: =IF(ISNUMBER($BA10),$BA10,IF(AND(ISNUMBER($D10),ISNUMBER($BW10),ISNUMBER($BX10)),$D10*($BX10-$BW10+1),"")) -> 3666 | H10: partial | I10: T-Statistic available | J10: =IF($BW10<>"",$BW10,"") -> 2003 | K10: =IF($BX10<>"",$BX10,"") -> 2018 | L10: =IF(AND(ISNUMBER($BW10),ISNUMBER($BX10)),($BW10+$BX10)/2,"") -> 2010.5 | M10: =IF($L10<>"",$L10,"") -> 2010.5 | N10: =IF(AND(ISNUMBER($BW10),ISNUMBER($BX10)),MIN(1,MAX(0,($BX10-2016+1)/($BX10-$BW10+1))),"") -> 0.1875 | O10: =IF(AND(ISNUMBER($BW10),ISNUMBER($BX10)),MIN(1,MAX(0,($BX10-2017+1)/($BX10-$BW10+1))),"") -> 0.125 | P10: =IF(AND(ISNUMBER($BW10),ISNUMBER($BX10)),MIN(1,MAX(0,($BX10-2018+1)/($BX10-$BW10+1))),"") -> 0.0625 | Q10: =IF(AND(ISNUMBER($BW10),ISNUMBER($BX10)),MIN(1,MAX(0,($BX10-2019+1)/($BX10-$BW10+1))),"") -> 0 | R10: =IF(AND(ISNUMBER($BW10),ISNUMBER($BX10)),MIN(1,MAX(0,($BX10-2016+1)/($BX10-$BW10+1))),"") -> 0.1875 | S10: =IF($L10<>"",IF($L10>=2015.5,1,0),"") -> 0 | T10: =IF($L10<>"",IF($L10>=2016,1,0),"") -> 0 | U10: =IF(ISNUMBER($BX10),IF($BX10>=2016,1,0),"") -> 1 | V10: =IF(ISNUMBER($BW10),IF($BW10>=2016,1,0),"") -> 0 | W10: =IF(AND(ISNUMBER($BW10),ISNUMBER($BX10)),IF($BW10>=2016,"post-only",IF($BX10<2016,"pre-only","mixed")),"") -> mixed | X10: =IF(AND(ISNUMBER($BW10),ISNUMBER($BX10)),MIN(1,MAX(0,($BX10-2017+1)/($BX10-$BW10+1))),"") -> 0.125 | Y10: =IF(AND(ISNUMBER($BW10),ISNUMBER($BX10)),MIN(1,MAX(0,($BX10-2018+1)/($BX10-$BW10+1))),"") -> 0.0625 | Z10: =IF(AND(ISNUMBER($BW10),ISNUMBER($BX10)),MIN(1,MAX(0,($BX10-2019+1)/($BX10-$BW10+1))),"") -> 0 | AA10: =IF(ISNUMBER($BX10),IF($BX10>=2017,1,0),"") -> 1 | AB10: =IF(ISNUMBER($BX10),IF($BX10>=2018,1,0),"") -> 1 | AC10: =IF(ISNUMBER($BX10),IF($BX10>=2019,1,0),"") -> 0 | AD10: =IF($L10<>"",IF($L10>2013,1,0),"") -> 0 | AE10: =IF($L10<>"",1+IF($L10>2011,1,0)+IF($L10>2014,1,0),"") -> 1 | AF10: loan (interest rate) | AG10: performance | AH10: non-sensitive | AI10: 99_NCE | AJ10: 99_NCE | AK10: =IF(AND($CF10<>"",IFERROR(INDEX(subsample_country_map!$B:$B,MATCH($CF10,subsample_country_map!$A:$A,0)),"")<>""),INDEX(subsample_country_map!$B:$B,MATCH($CF10,subsample_country_map!$A:$A,0)),INDEX(lookup!$AA:$AA,MATCH($A10,lookup!$A:$A,0))) -> 3_AsiaPac | AL10: =IF(AND($CF10<>"",IFERROR(INDEX(subsample_country_map!$C:$C,MATCH($CF10,subsample_country_map!$A:$A,0)),"")<>""),INDEX(subsample_country_map!$C:$C,MATCH($CF10,subsample_country_map!$A:$A,0)),INDEX(lookup!$AB:$AB,MATCH($A10,lookup!$A:$A,0))) -> 99_NCE | AM10: =IF(AND($CF10<>"",IFERROR(INDEX(subsample_country_map!$D:$D,MATCH($CF10,subsample_country_map!$A:$A,0)),"")<>""),INDEX(subsample_country_map!$D:$D,MATCH($CF10,subsample_country_map!$A:$A,0)),INDEX(lookup!$AC:$AC,MATCH($A10,lookup!$A:$A,0))) -> 99_NCE | AN10: =IF(AND($CF10<>"",IFERROR(INDEX(subsample_country_map!$E:$E,MATCH($CF10,subsample_country_map!$A:$A,0)),"")<>""),INDEX(subsample_country_map!$E:$E,MATCH($CF10,subsample_country_map!$A:$A,0)),INDEX(lookup!$AD:$AD,MATCH($A10,lookup!$A:$A,0))) -> 99_NCE | AO10: =INDEX(lookup!$Y:$Y,MATCH($A10,lookup!$A:$A,0)) -> 0_published | AP10: =INDEX(lookup!$Z:$Z,MATCH($A10,lookup!$A:$A,0)) -> 1_VHB high | AQ10: =INDEX(lookup!$W:$W,MATCH($A10,lookup!$A:$A,0)) -> 1_fin/acc/econ | AS10: staging | AT10: author-inverted-to-good | AU10: cost | AV10: -0.456 | AX10: -3.07 | BA10: 3666 | BB10: 0 | BC10: OLS | BD10: not stated | BE10: none | BI10: Table 6 | BJ10: Panel A col 1 | BK10: 9 | BL10: CCP1 -0.456*** (-3.07) | BM10: CCP1 | BN10: COD | BO10: update | BP10: Al-Fakir Al Rabab'a et al (2023) | BQ10: computed | BT10: 0 | BU10: staging_Al-Fakir_Al_Rababa_et_al_2023.csv | BW10: 2003 | BX10: 2018 | BY10: multi: 14 Asia-Pacific countries (Australia, China, Hong Kong, India, Indonesia, Japan, Malaysia, New Zealand, Philippines, Singapore, South Korea, Sri Lanka, Taiwan, Thailand) | BZ10: 2010.5 | CA10: 0.1875 | CB10: 0 | CC10: 1 | CD10: -0.05068229 | CE10: 1
A11: Al-Fakir Al Rabab'a et al (2023) | B11: 1316 | C11: -0.051461511 | D11: 3666 | E11: =IF(ISNUMBER($BA11),$BA11,IF(AND(ISNUMBER($D11),ISNUMBER($BW11),ISNUMBER($BX11)),$D11*($BX11-$BW11+1),"")) -> 3666 | H11: partial | I11: T-Statistic available | J11: =IF($BW11<>"",$BW11,"") -> 2003 | K11: =IF($BX11<>"",$BX11,"") -> 2018 | L11: =IF(AND(ISNUMBER($BW11),ISNUMBER($BX11)),($BW11+$BX11)/2,"") -> 2010.5 | M11: =IF($L11<>"",$L11,"") -> 2010.5 | N11: =IF(AND(ISNUMBER($BW11),ISNUMBER($BX11)),MIN(1,MAX(0,($BX11-2016+1)/($BX11-$BW11+1))),"") -> 0.1875 | O11: =IF(AND(ISNUMBER($BW11),ISNUMBER($BX11)),MIN(1,MAX(0,($BX11-2017+1)/($BX11-$BW11+1))),"") -> 0.125 | P11: =IF(AND(ISNUMBER($BW11),ISNUMBER($BX11)),MIN(1,MAX(0,($BX11-2018+1)/($BX11-$BW11+1))),"") -> 0.0625 | Q11: =IF(AND(ISNUMBER($BW11),ISNUMBER($BX11)),MIN(1,MAX(0,($BX11-2019+1)/($BX11-$BW11+1))),"") -> 0 | R11: =IF(AND(ISNUMBER($BW11),ISNUMBER($BX11)),MIN(1,MAX(0,($BX11-2016+1)/($BX11-$BW11+1))),"") -> 0.1875 | S11: =IF($L11<>"",IF($L11>=2015.5,1,0),"") -> 0 | T11: =IF($L11<>"",IF($L11>=2016,1,0),"") -> 0 | U11: =IF(ISNUMBER($BX11),IF($BX11>=2016,1,0),"") -> 1 | V11: =IF(ISNUMBER($BW11),IF($BW11>=2016,1,0),"") -> 0 | W11: =IF(AND(ISNUMBER($BW11),ISNUMBER($BX11)),IF($BW11>=2016,"post-only",IF($BX11<2016,"pre-only","mixed")),"") -> mixed | X11: =IF(AND(ISNUMBER($BW11),ISNUMBER($BX11)),MIN(1,MAX(0,($BX11-2017+1)/($BX11-$BW11+1))),"") -> 0.125 | Y11: =IF(AND(ISNUMBER($BW11),ISNUMBER($BX11)),MIN(1,MAX(0,($BX11-2018+1)/($BX11-$BW11+1))),"") -> 0.0625 | Z11: =IF(AND(ISNUMBER($BW11),ISNUMBER($BX11)),MIN(1,MAX(0,($BX11-2019+1)/($BX11-$BW11+1))),"") -> 0 | AA11: =IF(ISNUMBER($BX11),IF($BX11>=2017,1,0),"") -> 1 | AB11: =IF(ISNUMBER($BX11),IF($BX11>=2018,1,0),"") -> 1 | AC11: =IF(ISNUMBER($BX11),IF($BX11>=2019,1,0),"") -> 0 | AD11: =IF($L11<>"",IF($L11>2013,1,0),"") -> 0 | AE11: =IF($L11<>"",1+IF($L11>2011,1,0)+IF($L11>2014,1,0),"") -> 1 | AF11: loan (interest rate) | AG11: performance | AH11: non-sensitive | AI11: 99_NCE | AJ11: 99_NCE | AK11: =IF(AND($CF11<>"",IFERROR(INDEX(subsample_country_map!$B:$B,MATCH($CF11,subsample_country_map!$A:$A,0)),"")<>""),INDEX(subsample_country_map!$B:$B,MATCH($CF11,subsample_country_map!$A:$A,0)),INDEX(lookup!$AA:$AA,MATCH($A11,lookup!$A:$A,0))) -> 3_AsiaPac | AL11: =IF(AND($CF11<>"",IFERROR(INDEX(subsample_country_map!$C:$C,MATCH($CF11,subsample_country_map!$A:$A,0)),"")<>""),INDEX(subsample_country_map!$C:$C,MATCH($CF11,subsample_country_map!$A:$A,0)),INDEX(lookup!$AB:$AB,MATCH($A11,lookup!$A:$A,0))) -> 99_NCE | AM11: =IF(AND($CF11<>"",IFERROR(INDEX(subsample_country_map!$D:$D,MATCH($CF11,subsample_country_map!$A:$A,0)),"")<>""),INDEX(subsample_country_map!$D:$D,MATCH($CF11,subsample_country_map!$A:$A,0)),INDEX(lookup!$AC:$AC,MATCH($A11,lookup!$A:$A,0))) -> 99_NCE | AN11: =IF(AND($CF11<>"",IFERROR(INDEX(subsample_country_map!$E:$E,MATCH($CF11,subsample_country_map!$A:$A,0)),"")<>""),INDEX(subsample_country_map!$E:$E,MATCH($CF11,subsample_country_map!$A:$A,0)),INDEX(lookup!$AD:$AD,MATCH($A11,lookup!$A:$A,0))) -> 99_NCE | AO11: =INDEX(lookup!$Y:$Y,MATCH($A11,lookup!$A:$A,0)) -> 0_published | AP11: =INDEX(lookup!$Z:$Z,MATCH($A11,lookup!$A:$A,0)) -> 1_VHB high | AQ11: =INDEX(lookup!$W:$W,MATCH($A11,lookup!$A:$A,0)) -> 1_fin/acc/econ | AS11: staging | AT11: author-inverted-to-good | AU11: cost | AV11: -0.688 | AX11: -3.12 | BA11: 3666 | BB11: 0 | BC11: OLS | BD11: not stated | BE11: none | BI11: Table 6 | BJ11: Panel A col 2 | BK11: 9 | BL11: CCP2 -0.688*** (-3.12) | BM11: CCP2 | BN11: COD | BO11: update | BP11: Al-Fakir Al Rabab'a et al (2023) | BQ11: computed | BT11: 0 | BU11: staging_Al-Fakir_Al_Rababa_et_al_2023.csv | BW11: 2003 | BX11: 2018 | BY11: multi: 14 Asia-Pacific countries (Australia, China, Hong Kong, India, Indonesia, Japan, Malaysia, New Zealand, Philippines, Singapore, South Korea, Sri Lanka, Taiwan, Thailand) | BZ11: 2010.5 | CA11: 0.1875 | CB11: 0 | CC11: 1 | CD11: -0.051507011 | CE11: 1
A12: Al-Fakir Al Rabab'a et al (2023) | B12: 1317 | C12: -0.049322611 | D12: 3666 | E12: =IF(ISNUMBER($BA12),$BA12,IF(AND(ISNUMBER($D12),ISNUMBER($BW12),ISNUMBER($BX12)),$D12*($BX12-$BW12+1),"")) -> 3666 | H12: partial | I12: T-Statistic available | J12: =IF($BW12<>"",$BW12,"") -> 2003 | K12: =IF($BX12<>"",$BX12,"") -> 2018 | L12: =IF(AND(ISNUMBER($BW12),ISNUMBER($BX12)),($BW12+$BX12)/2,"") -> 2010.5 | M12: =IF($L12<>"",$L12,"") -> 2010.5 | N12: =IF(AND(ISNUMBER($BW12),ISNUMBER($BX12)),MIN(1,MAX(0,($BX12-2016+1)/($BX12-$BW12+1))),"") -> 0.1875 | O12: =IF(AND(ISNUMBER($BW12),ISNUMBER($BX12)),MIN(1,MAX(0,($BX12-2017+1)/($BX12-$BW12+1))),"") -> 0.125 | P12: =IF(AND(ISNUMBER($BW12),ISNUMBER($BX12)),MIN(1,MAX(0,($BX12-2018+1)/($BX12-$BW12+1))),"") -> 0.0625 | Q12: =IF(AND(ISNUMBER($BW12),ISNUMBER($BX12)),MIN(1,MAX(0,($BX12-2019+1)/($BX12-$BW12+1))),"") -> 0 | R12: =IF(AND(ISNUMBER($BW12),ISNUMBER($BX12)),MIN(1,MAX(0,($BX12-2016+1)/($BX12-$BW12+1))),"") -> 0.1875 | S12: =IF($L12<>"",IF($L12>=2015.5,1,0),"") -> 0 | T12: =IF($L12<>"",IF($L12>=2016,1,0),"") -> 0 | U12: =IF(ISNUMBER($BX12),IF($BX12>=2016,1,0),"") -> 1 | V12: =IF(ISNUMBER($BW12),IF($BW12>=2016,1,0),"") -> 0 | W12: =IF(AND(ISNUMBER($BW12),ISNUMBER($BX12)),IF($BW12>=2016,"post-only",IF($BX12<2016,"pre-only","mixed")),"") -> mixed | X12: =IF(AND(ISNUMBER($BW12),ISNUMBER($BX12)),MIN(1,MAX(0,($BX12-2017+1)/($BX12-$BW12+1))),"") -> 0.125 | Y12: =IF(AND(ISNUMBER($BW12),ISNUMBER($BX12)),MIN(1,MAX(0,($BX12-2018+1)/($BX12-$BW12+1))),"") -> 0.0625 | Z12: =IF(AND(ISNUMBER($BW12),ISNUMBER($BX12)),MIN(1,MAX(0,($BX12-2019+1)/($BX12-$BW12+1))),"") -> 0 | AA12: =IF(ISNUMBER($BX12),IF($BX12>=2017,1,0),"") -> 1 | AB12: =IF(ISNUMBER($BX12),IF($BX12>=2018,1,0),"") -> 1 | AC12: =IF(ISNUMBER($BX12),IF($BX12>=2019,1,0),"") -> 0 | AD12: =IF($L12<>"",IF($L12>2013,1,0),"") -> 0 | AE12: =IF($L12<>"",1+IF($L12>2011,1,0)+IF($L12>2014,1,0),"") -> 1 | AF12: loan (interest rate) | AG12: performance | AH12: non-sensitive | AI12: 99_NCE | AJ12: 99_NCE | AK12: =IF(AND($CF12<>"",IFERROR(INDEX(subsample_country_map!$B:$B,MATCH($CF12,subsample_country_map!$A:$A,0)),"")<>""),INDEX(subsample_country_map!$B:$B,MATCH($CF12,subsample_country_map!$A:$A,0)),INDEX(lookup!$AA:$AA,MATCH($A12,lookup!$A:$A,0))) -> 3_AsiaPac | AL12: =IF(AND($CF12<>"",IFERROR(INDEX(subsample_country_map!$C:$C,MATCH($CF12,subsample_country_map!$A:$A,0)),"")<>""),INDEX(subsample_country_map!$C:$C,MATCH($CF12,subsample_country_map!$A:$A,0)),INDEX(lookup!$AB:$AB,MATCH($A12,lookup!$A:$A,0))) -> 99_NCE | AM12: =IF(AND($CF12<>"",IFERROR(INDEX(subsample_country_map!$D:$D,MATCH($CF12,subsample_country_map!$A:$A,0)),"")<>""),INDEX(subsample_country_map!$D:$D,MATCH($CF12,subsample_country_map!$A:$A,0)),INDEX(lookup!$AC:$AC,MATCH($A12,lookup!$A:$A,0))) -> 99_NCE | AN12: =IF(AND($CF12<>"",IFERROR(INDEX(subsample_country_map!$E:$E,MATCH($CF12,subsample_country_map!$A:$A,0)),"")<>""),INDEX(subsample_country_map!$E:$E,MATCH($CF12,subsample_country_map!$A:$A,0)),INDEX(lookup!$AD:$AD,MATCH($A12,lookup!$A:$A,0))) -> 99_NCE | AO12: =INDEX(lookup!$Y:$Y,MATCH($A12,lookup!$A:$A,0)) -> 0_published | AP12: =INDEX(lookup!$Z:$Z,MATCH($A12,lookup!$A:$A,0)) -> 1_VHB high | AQ12: =INDEX(lookup!$W:$W,MATCH($A12,lookup!$A:$A,0)) -> 1_fin/acc/econ | AS12: staging | AT12: good-CER | AU12: cost | AV12: -0.195 | AX12: -2.99 | BA12: 3666 | BB12: 0 | BC12: OLS | BD12: not stated | BE12: none | BI12: Table 6 | BJ12: Panel A col 3 | BK12: 9 | BL12: CCP3 -0.195*** (-2.99) | BM12: CCP3 | BN12: COD | BO12: update | BP12: Al-Fakir Al Rabab'a et al (2023) | BQ12: computed | BT12: 0 | BU12: staging_Al-Fakir_Al_Rababa_et_al_2023.csv | BW12: 2003 | BX12: 2018 | BY12: multi: 14 Asia-Pacific countries (Australia, China, Hong Kong, India, Indonesia, Japan, Malaysia, New Zealand, Philippines, Singapore, South Korea, Sri Lanka, Taiwan, Thailand) | BZ12: 2010.5 | CA12: 0.1875 | CB12: 0 | CC12: 1 | CD12: -0.049362665 | CE12: 1
A13: Al-Fakir Al Rabab'a et al (2023) | B13: 1318 | C13: -0.041913669 | D13: 3666 | E13: =IF(ISNUMBER($BA13),$BA13,IF(AND(ISNUMBER($D13),ISNUMBER($BW13),ISNUMBER($BX13)),$D13*($BX13-$BW13+1),"")) -> 3666 | H13: partial | I13: T-Statistic available | J13: =IF($BW13<>"",$BW13,"") -> 2003 | K13: =IF($BX13<>"",$BX13,"") -> 2018 | L13: =IF(AND(ISNUMBER($BW13),ISNUMBER($BX13)),($BW13+$BX13)/2,"") -> 2010.5 | M13: =IF($L13<>"",$L13,"") -> 2010.5 | N13: =IF(AND(ISNUMBER($BW13),ISNUMBER($BX13)),MIN(1,MAX(0,($BX13-2016+1)/($BX13-$BW13+1))),"") -> 0.1875 | O13: =IF(AND(ISNUMBER($BW13),ISNUMBER($BX13)),MIN(1,MAX(0,($BX13-2017+1)/($BX13-$BW13+1))),"") -> 0.125 | P13: =IF(AND(ISNUMBER($BW13),ISNUMBER($BX13)),MIN(1,MAX(0,($BX13-2018+1)/($BX13-$BW13+1))),"") -> 0.0625 | Q13: =IF(AND(ISNUMBER($BW13),ISNUMBER($BX13)),MIN(1,MAX(0,($BX13-2019+1)/($BX13-$BW13+1))),"") -> 0 | R13: =IF(AND(ISNUMBER($BW13),ISNUMBER($BX13)),MIN(1,MAX(0,($BX13-2016+1)/($BX13-$BW13+1))),"") -> 0.1875 | S13: =IF($L13<>"",IF($L13>=2015.5,1,0),"") -> 0 | T13: =IF($L13<>"",IF($L13>=2016,1,0),"") -> 0 | U13: =IF(ISNUMBER($BX13),IF($BX13>=2016,1,0),"") -> 1 | V13: =IF(ISNUMBER($BW13),IF($BW13>=2016,1,0),"") -> 0 | W13: =IF(AND(ISNUMBER($BW13),ISNUMBER($BX13)),IF($BW13>=2016,"post-only",IF($BX13<2016,"pre-only","mixed")),"") -> mixed | X13: =IF(AND(ISNUMBER($BW13),ISNUMBER($BX13)),MIN(1,MAX(0,($BX13-2017+1)/($BX13-$BW13+1))),"") -> 0.125 | Y13: =IF(AND(ISNUMBER($BW13),ISNUMBER($BX13)),MIN(1,MAX(0,($BX13-2018+1)/($BX13-$BW13+1))),"") -> 0.0625 | Z13: =IF(AND(ISNUMBER($BW13),ISNUMBER($BX13)),MIN(1,MAX(0,($BX13-2019+1)/($BX13-$BW13+1))),"") -> 0 | AA13: =IF(ISNUMBER($BX13),IF($BX13>=2017,1,0),"") -> 1 | AB13: =IF(ISNUMBER($BX13),IF($BX13>=2018,1,0),"") -> 1 | AC13: =IF(ISNUMBER($BX13),IF($BX13>=2019,1,0),"") -> 0 | AD13: =IF($L13<>"",IF($L13>2013,1,0),"") -> 0 | AE13: =IF($L13<>"",1+IF($L13>2011,1,0)+IF($L13>2014,1,0),"") -> 1 | AF13: loan (interest rate) | AG13: performance | AH13: non-sensitive | AI13: 99_NCE | AJ13: 99_NCE | AK13: =IF(AND($CF13<>"",IFERROR(INDEX(subsample_country_map!$B:$B,MATCH($CF13,subsample_country_map!$A:$A,0)),"")<>""),INDEX(subsample_country_map!$B:$B,MATCH($CF13,subsample_country_map!$A:$A,0)),INDEX(lookup!$AA:$AA,MATCH($A13,lookup!$A:$A,0))) -> 3_AsiaPac | AL13: =IF(AND($CF13<>"",IFERROR(INDEX(subsample_country_map!$C:$C,MATCH($CF13,subsample_country_map!$A:$A,0)),"")<>""),INDEX(subsample_country_map!$C:$C,MATCH($CF13,subsample_country_map!$A:$A,0)),INDEX(lookup!$AB:$AB,MATCH($A13,lookup!$A:$A,0))) -> 99_NCE | AM13: =IF(AND($CF13<>"",IFERROR(INDEX(subsample_country_map!$D:$D,MATCH($CF13,subsample_country_map!$A:$A,0)),"")<>""),INDEX(subsample_country_map!$D:$D,MATCH($CF13,subsample_country_map!$A:$A,0)),INDEX(lookup!$AC:$AC,MATCH($A13,lookup!$A:$A,0))) -> 99_NCE | AN13: =IF(AND($CF13<>"",IFERROR(INDEX(subsample_country_map!$E:$E,MATCH($CF13,subsample_country_map!$A:$A,0)),"")<>""),INDEX(subsample_country_map!$E:$E,MATCH($CF13,subsample_country_map!$A:$A,0)),INDEX(lookup!$AD:$AD,MATCH($A13,lookup!$A:$A,0))) -> 99_NCE | AO13: =INDEX(lookup!$Y:$Y,MATCH($A13,lookup!$A:$A,0)) -> 0_published | AP13: =INDEX(lookup!$Z:$Z,MATCH($A13,lookup!$A:$A,0)) -> 1_VHB high | AQ13: =INDEX(lookup!$W:$W,MATCH($A13,lookup!$A:$A,0)) -> 1_fin/acc/econ | AS13: staging | AT13: good-CER | AU13: cost | AV13: -0.274 | AX13: -2.54 | BA13: 3666 | BB13: 0 | BC13: OLS | BD13: not stated | BE13: none | BI13: Table 6 | BJ13: Panel A col 4 | BK13: 9 | BL13: CCP4 -0.274** (-2.54) | BM13: CCP4 | BN13: COD | BO13: update | BP13: Al-Fakir Al Rabab'a et al (2023) | BQ13: computed | BT13: 0 | BU13: staging_Al-Fakir_Al_Rababa_et_al_2023.csv | BW13: 2003 | BX13: 2018 | BY13: multi: 14 Asia-Pacific countries (Australia, China, Hong Kong, India, Indonesia, Japan, Malaysia, New Zealand, Philippines, Singapore, South Korea, Sri Lanka, Taiwan, Thailand) | BZ13: 2010.5 | CA13: 0.1875 | CB13: 0 | CC13: 1 | CD13: -0.041938239 | CE13: 1
A14: Al-Fakir Al Rabab'a et al (2023) | B14: 1319 | C14: -0.039607196 | D14: 3666 | E14: =IF(ISNUMBER($BA14),$BA14,IF(AND(ISNUMBER($D14),ISNUMBER($BW14),ISNUMBER($BX14)),$D14*($BX14-$BW14+1),"")) -> 3666 | H14: partial | I14: T-Statistic available | J14: =IF($BW14<>"",$BW14,"") -> 2003 | K14: =IF($BX14<>"",$BX14,"") -> 2018 | L14: =IF(AND(ISNUMBER($BW14),ISNUMBER($BX14)),($BW14+$BX14)/2,"") -> 2010.5 | M14: =IF($L14<>"",$L14,"") -> 2010.5 | N14: =IF(AND(ISNUMBER($BW14),ISNUMBER($BX14)),MIN(1,MAX(0,($BX14-2016+1)/($BX14-$BW14+1))),"") -> 0.1875 | O14: =IF(AND(ISNUMBER($BW14),ISNUMBER($BX14)),MIN(1,MAX(0,($BX14-2017+1)/($BX14-$BW14+1))),"") -> 0.125 | P14: =IF(AND(ISNUMBER($BW14),ISNUMBER($BX14)),MIN(1,MAX(0,($BX14-2018+1)/($BX14-$BW14+1))),"") -> 0.0625 | Q14: =IF(AND(ISNUMBER($BW14),ISNUMBER($BX14)),MIN(1,MAX(0,($BX14-2019+1)/($BX14-$BW14+1))),"") -> 0 | R14: =IF(AND(ISNUMBER($BW14),ISNUMBER($BX14)),MIN(1,MAX(0,($BX14-2016+1)/($BX14-$BW14+1))),"") -> 0.1875 | S14: =IF($L14<>"",IF($L14>=2015.5,1,0),"") -> 0 | T14: =IF($L14<>"",IF($L14>=2016,1,0),"") -> 0 | U14: =IF(ISNUMBER($BX14),IF($BX14>=2016,1,0),"") -> 1 | V14: =IF(ISNUMBER($BW14),IF($BW14>=2016,1,0),"") -> 0 | W14: =IF(AND(ISNUMBER($BW14),ISNUMBER($BX14)),IF($BW14>=2016,"post-only",IF($BX14<2016,"pre-only","mixed")),"") -> mixed | X14: =IF(AND(ISNUMBER($BW14),ISNUMBER($BX14)),MIN(1,MAX(0,($BX14-2017+1)/($BX14-$BW14+1))),"") -> 0.125 | Y14: =IF(AND(ISNUMBER($BW14),ISNUMBER($BX14)),MIN(1,MAX(0,($BX14-2018+1)/($BX14-$BW14+1))),"") -> 0.0625 | Z14: =IF(AND(ISNUMBER($BW14),ISNUMBER($BX14)),MIN(1,MAX(0,($BX14-2019+1)/($BX14-$BW14+1))),"") -> 0 | AA14: =IF(ISNUMBER($BX14),IF($BX14>=2017,1,0),"") -> 1 | AB14: =IF(ISNUMBER($BX14),IF($BX14>=2018,1,0),"") -> 1 | AC14: =IF(ISNUMBER($BX14),IF($BX14>=2019,1,0),"") -> 0 | AD14: =IF($L14<>"",IF($L14>2013,1,0),"") -> 0 | AE14: =IF($L14<>"",1+IF($L14>2011,1,0)+IF($L14>2014,1,0),"") -> 1 | AF14: loan (interest rate) | AG14: performance | AH14: non-sensitive | AI14: 99_NCE | AJ14: 99_NCE | AK14: =IF(AND($CF14<>"",IFERROR(INDEX(subsample_country_map!$B:$B,MATCH($CF14,subsample_country_map!$A:$A,0)),"")<>""),INDEX(subsample_country_map!$B:$B,MATCH($CF14,subsample_country_map!$A:$A,0)),INDEX(lookup!$AA:$AA,MATCH($A14,lookup!$A:$A,0))) -> 3_AsiaPac | AL14: =IF(AND($CF14<>"",IFERROR(INDEX(subsample_country_map!$C:$C,MATCH($CF14,subsample_country_map!$A:$A,0)),"")<>""),INDEX(subsample_country_map!$C:$C,MATCH($CF14,subsample_country_map!$A:$A,0)),INDEX(lookup!$AB:$AB,MATCH($A14,lookup!$A:$A,0))) -> 99_NCE | AM14: =IF(AND($CF14<>"",IFERROR(INDEX(subsample_country_map!$D:$D,MATCH($CF14,subsample_country_map!$A:$A,0)),"")<>""),INDEX(subsample_country_map!$D:$D,MATCH($CF14,subsample_country_map!$A:$A,0)),INDEX(lookup!$AC:$AC,MATCH($A14,lookup!$A:$A,0))) -> 99_NCE | AN14: =IF(AND($CF14<>"",IFERROR(INDEX(subsample_country_map!$E:$E,MATCH($CF14,subsample_country_map!$A:$A,0)),"")<>""),INDEX(subsample_country_map!$E:$E,MATCH($CF14,subsample_country_map!$A:$A,0)),INDEX(lookup!$AD:$AD,MATCH($A14,lookup!$A:$A,0))) -> 99_NCE | AO14: =INDEX(lookup!$Y:$Y,MATCH($A14,lookup!$A:$A,0)) -> 0_published | AP14: =INDEX(lookup!$Z:$Z,MATCH($A14,lookup!$A:$A,0)) -> 1_VHB high | AQ14: =INDEX(lookup!$W:$W,MATCH($A14,lookup!$A:$A,0)) -> 1_fin/acc/econ | AS14: staging | AT14: author-inverted-to-good | AU14: cost | AV14: -0.397 | AX14: -2.40 | BA14: 3666 | BB14: 0 | BC14: OLS | BD14: not stated | BE14: none | BI14: Table 6 | BJ14: Panel B col 1 | BK14: 9 | BL14: CCP1 -0.397** (-2.40) | BM14: CCP1 | BN14: COD | BO14: update | BP14: Al-Fakir Al Rabab'a et al (2023) | BQ14: computed | BT14: 0 | BU14: staging_Al-Fakir_Al_Rababa_et_al_2023.csv | BW14: 2003 | BX14: 2018 | BY14: multi: 14 Asia-Pacific countries (Australia, China, Hong Kong, India, Indonesia, Japan, Malaysia, New Zealand, Philippines, Singapore, South Korea, Sri Lanka, Taiwan, Thailand) | BZ14: 2010.5 | CA14: 0.1875 | CB14: 0 | CC14: 1 | CD14: -0.039627927 | CE14: 1
A15: Al-Fakir Al Rabab'a et al (2023) | B15: 1320 | C15: -0.031694708 | D15: 3666 | E15: =IF(ISNUMBER($BA15),$BA15,IF(AND(ISNUMBER($D15),ISNUMBER($BW15),ISNUMBER($BX15)),$D15*($BX15-$BW15+1),"")) -> 3666 | H15: partial | I15: T-Statistic available | J15: =IF($BW15<>"",$BW15,"") -> 2003 | K15: =IF($BX15<>"",$BX15,"") -> 2018 | L15: =IF(AND(ISNUMBER($BW15),ISNUMBER($BX15)),($BW15+$BX15)/2,"") -> 2010.5 | M15: =IF($L15<>"",$L15,"") -> 2010.5 | N15: =IF(AND(ISNUMBER($BW15),ISNUMBER($BX15)),MIN(1,MAX(0,($BX15-2016+1)/($BX15-$BW15+1))),"") -> 0.1875 | O15: =IF(AND(ISNUMBER($BW15),ISNUMBER($BX15)),MIN(1,MAX(0,($BX15-2017+1)/($BX15-$BW15+1))),"") -> 0.125 | P15: =IF(AND(ISNUMBER($BW15),ISNUMBER($BX15)),MIN(1,MAX(0,($BX15-2018+1)/($BX15-$BW15+1))),"") -> 0.0625 | Q15: =IF(AND(ISNUMBER($BW15),ISNUMBER($BX15)),MIN(1,MAX(0,($BX15-2019+1)/($BX15-$BW15+1))),"") -> 0 | R15: =IF(AND(ISNUMBER($BW15),ISNUMBER($BX15)),MIN(1,MAX(0,($BX15-2016+1)/($BX15-$BW15+1))),"") -> 0.1875 | S15: =IF($L15<>"",IF($L15>=2015.5,1,0),"") -> 0 | T15: =IF($L15<>"",IF($L15>=2016,1,0),"") -> 0 | U15: =IF(ISNUMBER($BX15),IF($BX15>=2016,1,0),"") -> 1 | V15: =IF(ISNUMBER($BW15),IF($BW15>=2016,1,0),"") -> 0 | W15: =IF(AND(ISNUMBER($BW15),ISNUMBER($BX15)),IF($BW15>=2016,"post-only",IF($BX15<2016,"pre-only","mixed")),"") -> mixed | X15: =IF(AND(ISNUMBER($BW15),ISNUMBER($BX15)),MIN(1,MAX(0,($BX15-2017+1)/($BX15-$BW15+1))),"") -> 0.125 | Y15: =IF(AND(ISNUMBER($BW15),ISNUMBER($BX15)),MIN(1,MAX(0,($BX15-2018+1)/($BX15-$BW15+1))),"") -> 0.0625 | Z15: =IF(AND(ISNUMBER($BW15),ISNUMBER($BX15)),MIN(1,MAX(0,($BX15-2019+1)/($BX15-$BW15+1))),"") -> 0 | AA15: =IF(ISNUMBER($BX15),IF($BX15>=2017,1,0),"") -> 1 | AB15: =IF(ISNUMBER($BX15),IF($BX15>=2018,1,0),"") -> 1 | AC15: =IF(ISNUMBER($BX15),IF($BX15>=2019,1,0),"") -> 0 | AD15: =IF($L15<>"",IF($L15>2013,1,0),"") -> 0 | AE15: =IF($L15<>"",1+IF($L15>2011,1,0)+IF($L15>2014,1,0),"") -> 1 | AF15: loan (interest rate) | AG15: performance | AH15: non-sensitive | AI15: 99_NCE | AJ15: 99_NCE | AK15: =IF(AND($CF15<>"",IFERROR(INDEX(subsample_country_map!$B:$B,MATCH($CF15,subsample_country_map!$A:$A,0)),"")<>""),INDEX(subsample_country_map!$B:$B,MATCH($CF15,subsample_country_map!$A:$A,0)),INDEX(lookup!$AA:$AA,MATCH($A15,lookup!$A:$A,0))) -> 3_AsiaPac | AL15: =IF(AND($CF15<>"",IFERROR(INDEX(subsample_country_map!$C:$C,MATCH($CF15,subsample_country_map!$A:$A,0)),"")<>""),INDEX(subsample_country_map!$C:$C,MATCH($CF15,subsample_country_map!$A:$A,0)),INDEX(lookup!$AB:$AB,MATCH($A15,lookup!$A:$A,0))) -> 99_NCE | AM15: =IF(AND($CF15<>"",IFERROR(INDEX(subsample_country_map!$D:$D,MATCH($CF15,subsample_country_map!$A:$A,0)),"")<>""),INDEX(subsample_country_map!$D:$D,MATCH($CF15,subsample_country_map!$A:$A,0)),INDEX(lookup!$AC:$AC,MATCH($A15,lookup!$A:$A,0))) -> 99_NCE | AN15: =IF(AND($CF15<>"",IFERROR(INDEX(subsample_country_map!$E:$E,MATCH($CF15,subsample_country_map!$A:$A,0)),"")<>""),INDEX(subsample_country_map!$E:$E,MATCH($CF15,subsample_country_map!$A:$A,0)),INDEX(lookup!$AD:$AD,MATCH($A15,lookup!$A:$A,0))) -> 99_NCE | AO15: =INDEX(lookup!$Y:$Y,MATCH($A15,lookup!$A:$A,0)) -> 0_published | AP15: =INDEX(lookup!$Z:$Z,MATCH($A15,lookup!$A:$A,0)) -> 1_VHB high | AQ15: =INDEX(lookup!$W:$W,MATCH($A15,lookup!$A:$A,0)) -> 1_fin/acc/econ | AS15: staging | AT15: author-inverted-to-good | AU15: cost | AV15: -0.509 | AX15: -1.92 | BA15: 3666 | BB15: 0 | BC15: OLS | BD15: not stated | BE15: none | BI15: Table 6 | BJ15: Panel B col 2 | BK15: 9 | BL15: CCP2 -0.509* (-1.92) | BM15: CCP2 | BN15: COD | BO15: update | BP15: Al-Fakir Al Rabab'a et al (2023) | BQ15: computed | BT15: 0 | BU15: staging_Al-Fakir_Al_Rababa_et_al_2023.csv | BW15: 2003 | BX15: 2018 | BY15: multi: 14 Asia-Pacific countries (Australia, China, Hong Kong, India, Indonesia, Japan, Malaysia, New Zealand, Philippines, Singapore, South Korea, Sri Lanka, Taiwan, Thailand) | BZ15: 2010.5 | CA15: 0.1875 | CB15: 0 | CC15: 1 | CD15: -0.031705327 | CE15: 1
A16: Al-Fakir Al Rabab'a et al (2023) | B16: 1321 | C16: -0.048499774 | D16: 3666 | E16: =IF(ISNUMBER($BA16),$BA16,IF(AND(ISNUMBER($D16),ISNUMBER($BW16),ISNUMBER($BX16)),$D16*($BX16-$BW16+1),"")) -> 3666 | H16: partial | I16: T-Statistic available | J16: =IF($BW16<>"",$BW16,"") -> 2003 | K16: =IF($BX16<>"",$BX16,"") -> 2018 | L16: =IF(AND(ISNUMBER($BW16),ISNUMBER($BX16)),($BW16+$BX16)/2,"") -> 2010.5 | M16: =IF($L16<>"",$L16,"") -> 2010.5 | N16: =IF(AND(ISNUMBER($BW16),ISNUMBER($BX16)),MIN(1,MAX(0,($BX16-2016+1)/($BX16-$BW16+1))),"") -> 0.1875 | O16: =IF(AND(ISNUMBER($BW16),ISNUMBER($BX16)),MIN(1,MAX(0,($BX16-2017+1)/($BX16-$BW16+1))),"") -> 0.125 | P16: =IF(AND(ISNUMBER($BW16),ISNUMBER($BX16)),MIN(1,MAX(0,($BX16-2018+1)/($BX16-$BW16+1))),"") -> 0.0625 | Q16: =IF(AND(ISNUMBER($BW16),ISNUMBER($BX16)),MIN(1,MAX(0,($BX16-2019+1)/($BX16-$BW16+1))),"") -> 0 | R16: =IF(AND(ISNUMBER($BW16),ISNUMBER($BX16)),MIN(1,MAX(0,($BX16-2016+1)/($BX16-$BW16+1))),"") -> 0.1875 | S16: =IF($L16<>"",IF($L16>=2015.5,1,0),"") -> 0 | T16: =IF($L16<>"",IF($L16>=2016,1,0),"") -> 0 | U16: =IF(ISNUMBER($BX16),IF($BX16>=2016,1,0),"") -> 1 | V16: =IF(ISNUMBER($BW16),IF($BW16>=2016,1,0),"") -> 0 | W16: =IF(AND(ISNUMBER($BW16),ISNUMBER($BX16)),IF($BW16>=2016,"post-only",IF($BX16<2016,"pre-only","mixed")),"") -> mixed | X16: =IF(AND(ISNUMBER($BW16),ISNUMBER($BX16)),MIN(1,MAX(0,($BX16-2017+1)/($BX16-$BW16+1))),"") -> 0.125 | Y16: =IF(AND(ISNUMBER($BW16),ISNUMBER($BX16)),MIN(1,MAX(0,($BX16-2018+1)/($BX16-$BW16+1))),"") -> 0.0625 | Z16: =IF(AND(ISNUMBER($BW16),ISNUMBER($BX16)),MIN(1,MAX(0,($BX16-2019+1)/($BX16-$BW16+1))),"") -> 0 | AA16: =IF(ISNUMBER($BX16),IF($BX16>=2017,1,0),"") -> 1 | AB16: =IF(ISNUMBER($BX16),IF($BX16>=2018,1,0),"") -> 1 | AC16: =IF(ISNUMBER($BX16),IF($BX16>=2019,1,0),"") -> 0 | AD16: =IF($L16<>"",IF($L16>2013,1,0),"") -> 0 | AE16: =IF($L16<>"",1+IF($L16>2011,1,0)+IF($L16>2014,1,0),"") -> 1 | AF16: loan (interest rate) | AG16: performance | AH16: non-sensitive | AI16: 99_NCE | AJ16: 99_NCE | AK16: =IF(AND($CF16<>"",IFERROR(INDEX(subsample_country_map!$B:$B,MATCH($CF16,subsample_country_map!$A:$A,0)),"")<>""),INDEX(subsample_country_map!$B:$B,MATCH($CF16,subsample_country_map!$A:$A,0)),INDEX(lookup!$AA:$AA,MATCH($A16,lookup!$A:$A,0))) -> 3_AsiaPac | AL16: =IF(AND($CF16<>"",IFERROR(INDEX(subsample_country_map!$C:$C,MATCH($CF16,subsample_country_map!$A:$A,0)),"")<>""),INDEX(subsample_country_map!$C:$C,MATCH($CF16,subsample_country_map!$A:$A,0)),INDEX(lookup!$AB:$AB,MATCH($A16,lookup!$A:$A,0))) -> 99_NCE | AM16: =IF(AND($CF16<>"",IFERROR(INDEX(subsample_country_map!$D:$D,MATCH($CF16,subsample_country_map!$A:$A,0)),"")<>""),INDEX(subsample_country_map!$D:$D,MATCH($CF16,subsample_country_map!$A:$A,0)),INDEX(lookup!$AC:$AC,MATCH($A16,lookup!$A:$A,0))) -> 99_NCE | AN16: =IF(AND($CF16<>"",IFERROR(INDEX(subsample_country_map!$E:$E,MATCH($CF16,subsample_country_map!$A:$A,0)),"")<>""),INDEX(subsample_country_map!$E:$E,MATCH($CF16,subsample_country_map!$A:$A,0)),INDEX(lookup!$AD:$AD,MATCH($A16,lookup!$A:$A,0))) -> 99_NCE | AO16: =INDEX(lookup!$Y:$Y,MATCH($A16,lookup!$A:$A,0)) -> 0_published | AP16: =INDEX(lookup!$Z:$Z,MATCH($A16,lookup!$A:$A,0)) -> 1_VHB high | AQ16: =INDEX(lookup!$W:$W,MATCH($A16,lookup!$A:$A,0)) -> 1_fin/acc/econ | AS16: staging | AT16: good-CER | AU16: cost | AV16: -0.157 | AX16: -2.94 | BA16: 3666 | BB16: 0 | BC16: OLS | BD16: not stated | BE16: none | BI16: Table 6 | BJ16: Panel B col 3 | BK16: 9 | BL16: CCP3 -0.157*** (-2.94) | BM16: CCP3 | BN16: COD | BO16: update | BP16: Al-Fakir Al Rabab'a et al (2023) | BQ16: computed | BT16: 0 | BU16: staging_Al-Fakir_Al_Rababa_et_al_2023.csv | BW16: 2003 | BX16: 2018 | BY16: multi: 14 Asia-Pacific countries (Australia, China, Hong Kong, India, Indonesia, Japan, Malaysia, New Zealand, Philippines, Singapore, South Korea, Sri Lanka, Taiwan, Thailand) | BZ16: 2010.5 | CA16: 0.1875 | CB16: 0 | CC16: 1 | CD16: -0.048537856 | CE16: 1
