Workbook

Sheet data
A1: study | B1: outcome | C1: ES (corr_coeff) | D1: sample_size no_firms_rounded | E1: sample_size no_firm-years_rounded | F1: sample_size no_firms_source | G1: sample_size no_firm-years_source | H1: ES_measure | I1: ES_source | J1: sample_start | K1: sample_end | L1: sample_mid | M1: sample_median | N1: sample_post share_2016 | O1: sample_post share_2017 | P1: sample_post share_2018 | Q1: sample_post share_2019 | R1: pp_share_lag0 | S1: pp_mid_lag0 | T1: pp_median_lag0 | U1: pp_end_lag0 | V1: pp_start_lag0 | W1: pp_window_class | X1: pp_share_lag1 | Y1: pp_share_lag2 | Z1: pp_share_lag3 | AA1: pp_end_lag1 | AB1: pp_end_lag2 | AC1: pp_end_lag3 | AD1: pp_median split | AE1: pp_tertial split | AF1: COD_instrument | AG1: CER_measure | AH1: industry | AI1: regulation_sample_start | AJ1: regulation_sample_end | AK1: country_region | AL1: country_econ | AM1: country_culture | AN1: country_legal | AO1: q_status | AP1: q_VHB | AQ1: field | AR1: country | AS1: source
A2: Atif, Ali (2021) | B2: 1 | C2: -0.057746584 | D2: 170 | E2: 2036 | F2: calculated | G2: coded | H2: partial | I2: T-Statistic available | J2: 2006 | K2: 2017 | L2: =ROUND(AVERAGE(J2:K2),100) -> 2011.5 | M2: =ROUND(MEDIAN(J2:K2),100) -> 2011.5 | N2: =MAX(0,$K2-MAX($J2,2016)+1)/($K2-$J2+1) -> 0.16666667 | O2: =MAX(0,$K2-MAX($J2,2017)+1)/($K2-$J2+1) -> 0.083333333 | P2: =MAX(0,$K2-MAX($J2,2018)+1)/($K2-$J2+1) -> 0 | Q2: =MAX(0,$K2-MAX($J2,2019)+1)/($K2-$J2+1) -> 0 | R2: =IF(N2>=0.5,"1_Post","0_Pre") -> 0_Pre | S2: =IF($L2>=2016,"1_Post","0_Pre") -> 0_Pre | T2: =IF($M2>=2016,"1_Post","0_Pre") -> 0_Pre | U2: =IF($K2>=2016,"1_Post","0_Pre") -> 1_Post | V2: =IF($J2<=2017,"0_Pre","1_Post") -> 0_Pre | W2: =IF($K2<=2015,"clean_pre",IF($J2>=2016,"clean_post","straddle")) -> straddle | X2: =IF(O2>=0.5,"1_Post","0_Pre") -> 0_Pre | Y2: =IF(P2>=0.5,"1_Post","0_Pre") -> 0_Pre | Z2: =IF(Q2>=0.5,"1_Post","0_Pre") -> 0_Pre | AA2: =IF($K2>=2017,"1_Post","0_Pre") -> 1_Post | AB2: =IF($K2>=2018,"1_Post","0_Pre") -> 0_Pre | AC2: =IF($K2>=2019,"1_Post","0_Pre") -> 0_Pre | AD2: =IF(L2<MEDIAN($L$2:$L$1307),"1_pre sample median","2_post sample median") -> 1_pre sample median | AE2: =IF(L2<=PERCENTILE($L$2:$L$1307,0.33),"1_pre sample first tertile",IF(L2>=PERCENTILE($L$2:$L$1307,0.67),"3_post sample third tertile","2_in sample second tertile")) -> 2_in sample second tertile | AF2: derivativ (CDS spread) | AG2: performance | AH2: non-sensitive | AI2: with ETS/CT | AJ2: without ETS/CT | AK2: =VLOOKUP(MID($AR2,1,255),country_lookup!$B:$F,2,FALSE) -> 1_US | AL2: =VLOOKUP(MID($AR2,1,255),country_lookup!$B:$F,3,FALSE) -> 1_developed | AM2: =VLOOKUP(MID($AR2,1,255),country_lookup!$B:$F,4,FALSE) -> 1_western | AN2: =VLOOKUP(MID($AR2,1,255),country_lookup!$B:$F,5,FALSE) -> 1_common law | AO2: =VLOOKUP(MID($AS2,1,255),source_lookup!$B:$K,4,FALSE) -> 0_published | AP2: =VLOOKUP(MID($AS2,1,255),source_lookup!$B:$K,6,FALSE) -> 1_VHB high | AQ2: =VLOOKUP(MID($AS2,1,255),source_lookup!$B:$K,10,FALSE) -> 2_sust | AR2: United States | AS2: Atif, M., and Searat Ali (2021). Environmental, social and governance disclosure and default risk. In Business Strategy and the Environment, 30, 8, 3937–3959. https://doi.org/10.1002/bse.2850.
A3: Azmi et al (2021) | B3: 2 | C3: 0.10885031 | D3: 36 | E3: 251 | F3: coded | G3: calculated | H3: partial | I3: p-Value available | J3: 2011 | K3: 2017 | L3: =ROUND(AVERAGE(J3:K3),100) -> 2014 | M3: =ROUND(MEDIAN(J3:K3),100) -> 2014 | N3: =MAX(0,$K3-MAX($J3,2016)+1)/($K3-$J3+1) -> 0.28571429 | O3: =MAX(0,$K3-MAX($J3,2017)+1)/($K3-$J3+1) -> 0.14285714 | P3: =MAX(0,$K3-MAX($J3,2018)+1)/($K3-$J3+1) -> 0 | Q3: =MAX(0,$K3-MAX($J3,2019)+1)/($K3-$J3+1) -> 0 | R3: =IF(N3>=0.5,"1_Post","0_Pre") -> 0_Pre | S3: =IF($L3>=2016,"1_Post","0_Pre") -> 0_Pre | T3: =IF($M3>=2016,"1_Post","0_Pre") -> 0_Pre | U3: =IF($K3>=2016,"1_Post","0_Pre") -> 1_Post | V3: =IF($J3<=2017,"0_Pre","1_Post") -> 0_Pre | W3: =IF($K3<=2015,"clean_pre",IF($J3>=2016,"clean_post","straddle")) -> straddle | X3: =IF(O3>=0.5,"1_Post","0_Pre") -> 0_Pre | Y3: =IF(P3>=0.5,"1_Post","0_Pre") -> 0_Pre | Z3: =IF(Q3>=0.5,"1_Post","0_Pre") -> 0_Pre | AA3: =IF($K3>=2017,"1_Post","0_Pre") -> 1_Post | AB3: =IF($K3>=2018,"1_Post","0_Pre") -> 0_Pre | AC3: =IF($K3>=2019,"1_Post","0_Pre") -> 0_Pre | AD3: =IF(L3<MEDIAN($L$2:$L$1307),"1_pre sample median","2_post sample median") -> 2_post sample median | AE3: =IF(L3<=PERCENTILE($L$2:$L$1307,0.33),"1_pre sample first tertile",IF(L3>=PERCENTILE($L$2:$L$1307,0.67),"3_post sample third tertile","2_in sample second tertile")) -> 3_post sample third tertile | AF3: loand (interest rate) | AG3: performance | AH3: non-sensitive | AI3: NA | AJ3: NA | AK3: =VLOOKUP(MID($AR3,1,255),country_lookup!$B:$F,2,FALSE) -> 99_NCE | AL3: =VLOOKUP(MID($AR3,1,255),country_lookup!$B:$F,3,FALSE) -> 99_NCE | AM3: =VLOOKUP(MID($AR3,1,255),country_lookup!$B:$F,4,FALSE) -> 99_NCE | AN3: =VLOOKUP(MID($AR3,1,255),country_lookup!$B:$F,5,FALSE) -> 99_NCE | AO3: =VLOOKUP(MID($AS3,1,255),source_lookup!$B:$K,4,FALSE) -> 0_published | AP3: =VLOOKUP(MID($AS3,1,255),source_lookup!$B:$K,6,FALSE) -> 1_VHB high | AQ3: =VLOOKUP(MID($AS3,1,255),source_lookup!$B:$K,10,FALSE) -> 1_fin/acc/econ | AR3: Argentina,Bahrain,Botswana,Brazil,Chile,China,Colombia,Croatia,Czechia,Egypt,Hungary,India,Jordan,Kazakhstan,Kenya,Kuwait,Lebanon,Malaysia,Mauritius,Mexico,Morocco,Namibia,Indonesia,Nigeria,Oman,Pakistan,Panama,Peru,Philippines,Poland,Qatar,Romania,Russian Federation,Saudi Arabia,Slovak Republic,South Africa,Sri Lanka,Thailand,Turkiye,Uganda,Ukraine,United Arab Emirates,Viet Nam,Zambia | AS3: Azmi, W., Hassan, M. K., Houston, R. & Karim, M. S. (2021). ESG activities and Banking Performance: International Evidence from Emerging Economies. In Journal of International Financial Markets, Institutions and Money, 70, 101277. https://doi.org/10.1016/j.intfin.2020.101277
A4: Azmi et al (2021) | B4: 3 | C4: 0.061742838 | D4: 36 | E4: 251 | F4: coded | G4: calculated | H4: partial | I4: p-Value available | J4: 2011 | K4: 2017 | L4: =ROUND(AVERAGE(J4:K4),100) -> 2014 | M4: =ROUND(MEDIAN(J4:K4),100) -> 2014 | N4: =MAX(0,$K4-MAX($J4,2016)+1)/($K4-$J4+1) -> 0.28571429 | O4: =MAX(0,$K4-MAX($J4,2017)+1)/($K4-$J4+1) -> 0.14285714 | P4: =MAX(0,$K4-MAX($J4,2018)+1)/($K4-$J4+1) -> 0 | Q4: =MAX(0,$K4-MAX($J4,2019)+1)/($K4-$J4+1) -> 0 | R4: =IF(N4>=0.5,"1_Post","0_Pre") -> 0_Pre | S4: =IF($L4>=2016,"1_Post","0_Pre") -> 0_Pre | T4: =IF($M4>=2016,"1_Post","0_Pre") -> 0_Pre | U4: =IF($K4>=2016,"1_Post","0_Pre") -> 1_Post | V4: =IF($J4<=2017,"0_Pre","1_Post") -> 0_Pre | W4: =IF($K4<=2015,"clean_pre",IF($J4>=2016,"clean_post","straddle")) -> straddle | X4: =IF(O4>=0.5,"1_Post","0_Pre") -> 0_Pre | Y4: =IF(P4>=0.5,"1_Post","0_Pre") -> 0_Pre | Z4: =IF(Q4>=0.5,"1_Post","0_Pre") -> 0_Pre | AA4: =IF($K4>=2017,"1_Post","0_Pre") -> 1_Post | AB4: =IF($K4>=2018,"1_Post","0_Pre") -> 0_Pre | AC4: =IF($K4>=2019,"1_Post","0_Pre") -> 0_Pre | AD4: =IF(L4<MEDIAN($L$2:$L$1307),"1_pre sample median","2_post sample median") -> 2_post sample median | AE4: =IF(L4<=PERCENTILE($L$2:$L$1307,0.33),"1_pre sample first tertile",IF(L4>=PERCENTILE($L$2:$L$1307,0.67),"3_post sample third tertile","2_in sample second tertile")) -> 3_post sample third tertile | AF4: loand (interest rate) | AG4: performance | AH4: non-sensitive | AI4: NA | AJ4: NA | AK4: =VLOOKUP(MID($AR4,1,255),country_lookup!$B:$F,2,FALSE) -> 99_NCE | AL4: =VLOOKUP(MID($AR4,1,255),country_lookup!$B:$F,3,FALSE) -> 99_NCE | AM4: =VLOOKUP(MID($AR4,1,255),country_lookup!$B:$F,4,FALSE) -> 99_NCE | AN4: =VLOOKUP(MID($AR4,1,255),country_lookup!$B:$F,5,FALSE) -> 99_NCE | AO4: =VLOOKUP(MID($AS4,1,255),source_lookup!$B:$K,4,FALSE) -> 0_published | AP4: =VLOOKUP(MID($AS4,1,255),source_lookup!$B:$K,6,FALSE) -> 1_VHB high | AQ4: =VLOOKUP(MID($AS4,1,255),source_lookup!$B:$K,10,FALSE) -> 1_fin/acc/econ | AR4: Argentina,Bahrain,Botswana,Brazil,Chile,China,Colombia,Croatia,Czechia,Egypt,Hungary,India,Jordan,Kazakhstan,Kenya,Kuwait,Lebanon,Malaysia,Mauritius,Mexico,Morocco,Namibia,Indonesia,Nigeria,Oman,Pakistan,Panama,Peru,Philippines,Poland,Qatar,Romania,Russian Federation,Saudi Arabia,Slovak Republic,South Africa,Sri Lanka,Thailand,Turkiye,Uganda,Ukraine,United Arab Emirates,Viet Nam,Zambia | AS4: Azmi, W., Hassan, M. K., Houston, R. & Karim, M. S. (2021). ESG activities and Banking Performance: International Evidence from Emerging Economies. In Journal of International Financial Markets, Institutions and Money, 70, 101277. https://doi.org/10.1016/j.intfin.2020.101277
A5: Bannier et al (2022) | B5: 4 | C5: -0.025709775 | D5: 1300 | E5: 20806 | F5: calculated | G5: coded | H5: partial | I5: Regression Cofficient and Standard Error available | J5: 2003 | K5: 2018 | L5: =ROUND(AVERAGE(J5:K5),100) -> 2010.5 | M5: =ROUND(MEDIAN(J5:K5),100) -> 2010.5 | N5: =MAX(0,$K5-MAX($J5,2016)+1)/($K5-$J5+1) -> 0.1875 | O5: =MAX(0,$K5-MAX($J5,2017)+1)/($K5-$J5+1) -> 0.125 | P5: =MAX(0,$K5-MAX($J5,2018)+1)/($K5-$J5+1) -> 0.0625 | Q5: =MAX(0,$K5-MAX($J5,2019)+1)/($K5-$J5+1) -> 0 | R5: =IF(N5>=0.5,"1_Post","0_Pre") -> 0_Pre | S5: =IF($L5>=2016,"1_Post","0_Pre") -> 0_Pre | T5: =IF($M5>=2016,"1_Post","0_Pre") -> 0_Pre | U5: =IF($K5>=2016,"1_Post","0_Pre") -> 1_Post | V5: =IF($J5<=2017,"0_Pre","1_Post") -> 0_Pre | W5: =IF($K5<=2015,"clean_pre",IF($J5>=2016,"clean_post","straddle")) -> straddle | X5: =IF(O5>=0.5,"1_Post","0_Pre") -> 0_Pre | Y5: =IF(P5>=0.5,"1_Post","0_Pre") -> 0_Pre | Z5: =IF(Q5>=0.5,"1_Post","0_Pre") -> 0_Pre | AA5: =IF($K5>=2017,"1_Post","0_Pre") -> 1_Post | AB5: =IF($K5>=2018,"1_Post","0_Pre") -> 1_Post | AC5: =IF($K5>=2019,"1_Post","0_Pre") -> 0_Pre | AD5: =IF(L5<MEDIAN($L$2:$L$1307),"1_pre sample median","2_post sample median") -> 1_pre sample median | AE5: =IF(L5<=PERCENTILE($L$2:$L$1307,0.33),"1_pre sample first tertile",IF(L5>=PERCENTILE($L$2:$L$1307,0.67),"3_post sample third tertile","2_in sample second tertile")) -> 1_pre sample first tertile | AF5: derivativ (CDS spread) | AG5: performance | AH5: non-sensitive | AI5: with ETS/CT | AJ5: NA | AK5: =VLOOKUP(MID($AR5,1,255),country_lookup!$B:$F,2,FALSE) -> 99_NCE | AL5: =VLOOKUP(MID($AR5,1,255),country_lookup!$B:$F,3,FALSE) -> 99_NCE | AM5: =VLOOKUP(MID($AR5,1,255),country_lookup!$B:$F,4,FALSE) -> 1_western | AN5: =VLOOKUP(MID($AR5,1,255),country_lookup!$B:$F,5,FALSE) -> 99_NCE | AO5: =VLOOKUP(MID($AS5,1,255),source_lookup!$B:$K,4,FALSE) -> 0_published | AP5: =VLOOKUP(MID($AS5,1,255),source_lookup!$B:$K,6,FALSE) -> 1_VHB high | AQ5: =VLOOKUP(MID($AS5,1,255),source_lookup!$B:$K,10,FALSE) -> 1_fin/acc/econ | AR5: United States,Austria,Belgium,Bulgaria,Croatia,Cyprus,Czechia,Denmark,Estonia,Finland,France,Germany,Greece,Hungary,Ireland,Italy,Latvia,Lithuania,Luxembourg,Malta,Netherlands,Poland,Portugal,Romania,Slovak Republic,Slovenia,Spain,Sweden | AS5: Bannier, C., et al (2020). Corporate Social Responsibility and Credit Risk. In SSRN Electronic Journal. https://doi.org/10.2139/ssrn.3686025.
A6: Bannier et al (2022) | B6: 5 | C6: -0.019358559 | D6: 1300 | E6: 20806 | F6: calculated | G6: coded | H6: partial | I6: Regression Cofficient and Standard Error available | J6: 2003 | K6: 2018 | L6: =ROUND(AVERAGE(J6:K6),100) -> 2010.5 | M6: =ROUND(MEDIAN(J6:K6),100) -> 2010.5 | N6: =MAX(0,$K6-MAX($J6,2016)+1)/($K6-$J6+1) -> 0.1875 | O6: =MAX(0,$K6-MAX($J6,2017)+1)/($K6-$J6+1) -> 0.125 | P6: =MAX(0,$K6-MAX($J6,2018)+1)/($K6-$J6+1) -> 0.0625 | Q6: =MAX(0,$K6-MAX($J6,2019)+1)/($K6-$J6+1) -> 0 | R6: =IF(N6>=0.5,"1_Post","0_Pre") -> 0_Pre | S6: =IF($L6>=2016,"1_Post","0_Pre") -> 0_Pre | T6: =IF($M6>=2016,"1_Post","0_Pre") -> 0_Pre | U6: =IF($K6>=2016,"1_Post","0_Pre") -> 1_Post | V6: =IF($J6<=2017,"0_Pre","1_Post") -> 0_Pre | W6: =IF($K6<=2015,"clean_pre",IF($J6>=2016,"clean_post","straddle")) -> straddle | X6: =IF(O6>=0.5,"1_Post","0_Pre") -> 0_Pre | Y6: =IF(P6>=0.5,"1_Post","0_Pre") -> 0_Pre | Z6: =IF(Q6>=0.5,"1_Post","0_Pre") -> 0_Pre | AA6: =IF($K6>=2017,"1_Post","0_Pre") -> 1_Post | AB6: =IF($K6>=2018,"1_Post","0_Pre") -> 1_Post | AC6: =IF($K6>=2019,"1_Post","0_Pre") -> 0_Pre | AD6: =IF(L6<MEDIAN($L$2:$L$1307),"1_pre sample median","2_post sample median") -> 1_pre sample median | AE6: =IF(L6<=PERCENTILE($L$2:$L$1307,0.33),"1_pre sample first tertile",IF(L6>=PERCENTILE($L$2:$L$1307,0.67),"3_post sample third tertile","2_in sample second tertile")) -> 1_pre sample first tertile | AF6: derivativ (CDS spread) | AG6: performance | AH6: non-sensitive | AI6: with ETS/CT | AJ6: NA | AK6: =VLOOKUP(MID($AR6,1,255),country_lookup!$B:$F,2,FALSE) -> 99_NCE | AL6: =VLOOKUP(MID($AR6,1,255),country_lookup!$B:$F,3,FALSE) -> 99_NCE | AM6: =VLOOKUP(MID($AR6,1,255),country_lookup!$B:$F,4,FALSE) -> 1_western | AN6: =VLOOKUP(MID($AR6,1,255),country_lookup!$B:$F,5,FALSE) -> 99_NCE | AO6: =VLOOKUP(MID($AS6,1,255),source_lookup!$B:$K,4,FALSE) -> 0_published | AP6: =VLOOKUP(MID($AS6,1,255),source_lookup!$B:$K,6,FALSE) -> 1_VHB high | AQ6: =VLOOKUP(MID($AS6,1,255),source_lookup!$B:$K,10,FALSE) -> 1_fin/acc/econ | AR6: United States,Austria,Belgium,Bulgaria,Croatia,Cyprus,Czechia,Denmark,Estonia,Finland,France,Germany,Greece,Hungary,Ireland,Italy,Latvia,Lithuania,Luxembourg,Malta,Netherlands,Poland,Portugal,Romania,Slovak Republic,Slovenia,Spain,Sweden | AS6: Bannier, C., et al (2020). Corporate Social Responsibility and Credit Risk. In SSRN Electronic Journal. https://doi.org/10.2139/ssrn.3686025.
A7: Bannier et al (2022) | B7: 6 | C7: 0.020468975 | D7: 687 | E7: 10998 | F7: calculated | G7: coded | H7: partial | I7: Regression Cofficient and Standard Error available | J7: 2003 | K7: 2018 | L7: =ROUND(AVERAGE(J7:K7),100) -> 2010.5 | M7: =ROUND(MEDIAN(J7:K7),100) -> 2010.5 | N7: =MAX(0,$K7-MAX($J7,2016)+1)/($K7-$J7+1) -> 0.1875 | O7: =MAX(0,$K7-MAX($J7,2017)+1)/($K7-$J7+1) -> 0.125 | P7: =MAX(0,$K7-MAX($J7,2018)+1)/($K7-$J7+1) -> 0.0625 | Q7: =MAX(0,$K7-MAX($J7,2019)+1)/($K7-$J7+1) -> 0 | R7: =IF(N7>=0.5,"1_Post","0_Pre") -> 0_Pre | S7: =IF($L7>=2016,"1_Post","0_Pre") -> 0_Pre | T7: =IF($M7>=2016,"1_Post","0_Pre") -> 0_Pre | U7: =IF($K7>=2016,"1_Post","0_Pre") -> 1_Post | V7: =IF($J7<=2017,"0_Pre","1_Post") -> 0_Pre | W7: =IF($K7<=2015,"clean_pre",IF($J7>=2016,"clean_post","straddle")) -> straddle | X7: =IF(O7>=0.5,"1_Post","0_Pre") -> 0_Pre | Y7: =IF(P7>=0.5,"1_Post","0_Pre") -> 0_Pre | Z7: =IF(Q7>=0.5,"1_Post","0_Pre") -> 0_Pre | AA7: =IF($K7>=2017,"1_Post","0_Pre") -> 1_Post | AB7: =IF($K7>=2018,"1_Post","0_Pre") -> 1_Post | AC7: =IF($K7>=2019,"1_Post","0_Pre") -> 0_Pre | AD7: =IF(L7<MEDIAN($L$2:$L$1307),"1_pre sample median","2_post sample median") -> 1_pre sample median | AE7: =IF(L7<=PERCENTILE($L$2:$L$1307,0.33),"1_pre sample first tertile",IF(L7>=PERCENTILE($L$2:$L$1307,0.67),"3_post sample third tertile","2_in sample second tertile")) -> 1_pre sample first tertile | AF7: rating | AG7: performance | AH7: non-sensitive | AI7: with ETS/CT | AJ7: NA | AK7: =VLOOKUP(MID($AR7,1,255),country_lookup!$B:$F,2,FALSE) -> 99_NCE | AL7: =VLOOKUP(MID($AR7,1,255),country_lookup!$B:$F,3,FALSE) -> 99_NCE | AM7: =VLOOKUP(MID($AR7,1,255),country_lookup!$B:$F,4,FALSE) -> 1_western | AN7: =VLOOKUP(MID($AR7,1,255),country_lookup!$B:$F,5,FALSE) -> 99_NCE | AO7: =VLOOKUP(MID($AS7,1,255),source_lookup!$B:$K,4,FALSE) -> 0_published | AP7: =VLOOKUP(MID($AS7,1,255),source_lookup!$B:$K,6,FALSE) -> 1_VHB high | AQ7: =VLOOKUP(MID($AS7,1,255),source_lookup!$B:$K,10,FALSE) -> 1_fin/acc/econ | AR7: United States,Austria,Belgium,Bulgaria,Croatia,Cyprus,Czechia,Denmark,Estonia,Finland,France,Germany,Greece,Hungary,Ireland,Italy,Latvia,Lithuania,Luxembourg,Malta,Netherlands,Poland,Portugal,Romania,Slovak Republic,Slovenia,Spain,Sweden | AS7: Bannier, C., et al (2020). Corporate Social Responsibility and Credit Risk. In SSRN Electronic Journal. https://doi.org/10.2139/ssrn.3686025.
A8: Bannier et al (2022) | B8: 7 | C8: -0.0048716062 | D8: 1300 | E8: 20806 | F8: calculated | G8: coded | H8: partial | I8: Regression Cofficient and Standard Error available | J8: 2003 | K8: 2018 | L8: =ROUND(AVERAGE(J8:K8),100) -> 2010.5 | M8: =ROUND(MEDIAN(J8:K8),100) -> 2010.5 | N8: =MAX(0,$K8-MAX($J8,2016)+1)/($K8-$J8+1) -> 0.1875 | O8: =MAX(0,$K8-MAX($J8,2017)+1)/($K8-$J8+1) -> 0.125 | P8: =MAX(0,$K8-MAX($J8,2018)+1)/($K8-$J8+1) -> 0.0625 | Q8: =MAX(0,$K8-MAX($J8,2019)+1)/($K8-$J8+1) -> 0 | R8: =IF(N8>=0.5,"1_Post","0_Pre") -> 0_Pre | S8: =IF($L8>=2016,"1_Post","0_Pre") -> 0_Pre | T8: =IF($M8>=2016,"1_Post","0_Pre") -> 0_Pre | U8: =IF($K8>=2016,"1_Post","0_Pre") -> 1_Post | V8: =IF($J8<=2017,"0_Pre","1_Post") -> 0_Pre | W8: =IF($K8<=2015,"clean_pre",IF($J8>=2016,"clean_post","straddle")) -> straddle | X8: =IF(O8>=0.5,"1_Post","0_Pre") -> 0_Pre | Y8: =IF(P8>=0.5,"1_Post","0_Pre") -> 0_Pre | Z8: =IF(Q8>=0.5,"1_Post","0_Pre") -> 0_Pre | AA8: =IF($K8>=2017,"1_Post","0_Pre") -> 1_Post | AB8: =IF($K8>=2018,"1_Post","0_Pre") -> 1_Post | AC8: =IF($K8>=2019,"1_Post","0_Pre") -> 0_Pre | AD8: =IF(L8<MEDIAN($L$2:$L$1307),"1_pre sample median","2_post sample median") -> 1_pre sample median | AE8: =IF(L8<=PERCENTILE($L$2:$L$1307,0.33),"1_pre sample first tertile",IF(L8>=PERCENTILE($L$2:$L$1307,0.67),"3_post sample third tertile","2_in sample second tertile")) -> 1_pre sample first tertile | AF8: derivativ (CDS spread) | AG8: performance | AH8: non-sensitive | AI8: with ETS/CT | AJ8: NA | AK8: =VLOOKUP(MID($AR8,1,255),country_lookup!$B:$F,2,FALSE) -> 99_NCE | AL8: =VLOOKUP(MID($AR8,1,255),country_lookup!$B:$F,3,FALSE) -> 99_NCE | AM8: =VLOOKUP(MID($AR8,1,255),country_lookup!$B:$F,4,FALSE) -> 1_western | AN8: =VLOOKUP(MID($AR8,1,255),country_lookup!$B:$F,5,FALSE) -> 99_NCE | AO8: =VLOOKUP(MID($AS8,1,255),source_lookup!$B:$K,4,FALSE) -> 0_published | AP8: =VLOOKUP(MID($AS8,1,255),source_lookup!$B:$K,6,FALSE) -> 1_VHB high | AQ8: =VLOOKUP(MID($AS8,1,255),source_lookup!$B:$K,10,FALSE) -> 1_fin/acc/econ | AR8: United States,Austria,Belgium,Bulgaria,Croatia,Cyprus,Czechia,Denmark,Estonia,Finland,France,Germany,Greece,Hungary,Ireland,Italy,Latvia,Lithuania,Luxembourg,Malta,Netherlands,Poland,Portugal,Romania,Slovak Republic,Slovenia,Spain,Sweden | AS8: Bannier, C., et al (2020). Corporate Social Responsibility and Credit Risk. In SSRN Electronic Journal. https://doi.org/10.2139/ssrn.3686025.
A9: Bannier et al (2022) | B9: 8 | C9: -0.012456323 | D9: 1300 | E9: 20806 | F9: calculated | G9: coded | H9: partial | I9: Regression Cofficient and Standard Error available | J9: 2003 | K9: 2018 | L9: =ROUND(AVERAGE(J9:K9),100) -> 2010.5 | M9: =ROUND(MEDIAN(J9:K9),100) -> 2010.5 | N9: =MAX(0,$K9-MAX($J9,2016)+1)/($K9-$J9+1) -> 0.1875 | O9: =MAX(0,$K9-MAX($J9,2017)+1)/($K9-$J9+1) -> 0.125 | P9: =MAX(0,$K9-MAX($J9,2018)+1)/($K9-$J9+1) -> 0.0625 | Q9: =MAX(0,$K9-MAX($J9,2019)+1)/($K9-$J9+1) -> 0 | R9: =IF(N9>=0.5,"1_Post","0_Pre") -> 0_Pre | S9: =IF($L9>=2016,"1_Post","0_Pre") -> 0_Pre | T9: =IF($M9>=2016,"1_Post","0_Pre") -> 0_Pre | U9: =IF($K9>=2016,"1_Post","0_Pre") -> 1_Post | V9: =IF($J9<=2017,"0_Pre","1_Post") -> 0_Pre | W9: =IF($K9<=2015,"clean_pre",IF($J9>=2016,"clean_post","straddle")) -> straddle | X9: =IF(O9>=0.5,"1_Post","0_Pre") -> 0_Pre | Y9: =IF(P9>=0.5,"1_Post","0_Pre") -> 0_Pre | Z9: =IF(Q9>=0.5,"1_Post","0_Pre") -> 0_Pre | AA9: =IF($K9>=2017,"1_Post","0_Pre") -> 1_Post | AB9: =IF($K9>=2018,"1_Post","0_Pre") -> 1_Post | AC9: =IF($K9>=2019,"1_Post","0_Pre") -> 0_Pre | AD9: =IF(L9<MEDIAN($L$2:$L$1307),"1_pre sample median","2_post sample median") -> 1_pre sample median | AE9: =IF(L9<=PERCENTILE($L$2:$L$1307,0.33),"1_pre sample first tertile",IF(L9>=PERCENTILE($L$2:$L$1307,0.67),"3_post sample third tertile","2_in sample second tertile")) -> 1_pre sample first tertile | AF9: derivativ (CDS spread) | AG9: performance | AH9: non-sensitive | AI9: with ETS/CT | AJ9: NA | AK9: =VLOOKUP(MID($AR9,1,255),country_lookup!$B:$F,2,FALSE) -> 99_NCE | AL9: =VLOOKUP(MID($AR9,1,255),country_lookup!$B:$F,3,FALSE) -> 99_NCE | AM9: =VLOOKUP(MID($AR9,1,255),country_lookup!$B:$F,4,FALSE) -> 1_western | AN9: =VLOOKUP(MID($AR9,1,255),country_lookup!$B:$F,5,FALSE) -> 99_NCE | AO9: =VLOOKUP(MID($AS9,1,255),source_lookup!$B:$K,4,FALSE) -> 0_published | AP9: =VLOOKUP(MID($AS9,1,255),source_lookup!$B:$K,6,FALSE) -> 1_VHB high | AQ9: =VLOOKUP(MID($AS9,1,255),source_lookup!$B:$K,10,FALSE) -> 1_fin/acc/econ | AR9: United States,Austria,Belgium,Bulgaria,Croatia,Cyprus,Czechia,Denmark,Estonia,Finland,France,Germany,Greece,Hungary,Ireland,Italy,Latvia,Lithuania,Luxembourg,Malta,Netherlands,Poland,Portugal,Romania,Slovak Republic,Slovenia,Spain,Sweden | AS9: Bannier, C., et al (2020). Corporate Social Responsibility and Credit Risk. In SSRN Electronic Journal. https://doi.org/10.2139/ssrn.3686025.
A10: Bannier et al (2022) | B10: 9 | C10: -0.011441842 | D10: 687 | E10: 10998 | F10: calculated | G10: coded | H10: partial | I10: Regression Cofficient and Standard Error available | J10: 2003 | K10: 2018 | L10: =ROUND(AVERAGE(J10:K10),100) -> 2010.5 | M10: =ROUND(MEDIAN(J10:K10),100) -> 2010.5 | N10: =MAX(0,$K10-MAX($J10,2016)+1)/($K10-$J10+1) -> 0.1875 | O10: =MAX(0,$K10-MAX($J10,2017)+1)/($K10-$J10+1) -> 0.125 | P10: =MAX(0,$K10-MAX($J10,2018)+1)/($K10-$J10+1) -> 0.0625 | Q10: =MAX(0,$K10-MAX($J10,2019)+1)/($K10-$J10+1) -> 0 | R10: =IF(N10>=0.5,"1_Post","0_Pre") -> 0_Pre | S10: =IF($L10>=2016,"1_Post","0_Pre") -> 0_Pre | T10: =IF($M10>=2016,"1_Post","0_Pre") -> 0_Pre | U10: =IF($K10>=2016,"1_Post","0_Pre") -> 1_Post | V10: =IF($J10<=2017,"0_Pre","1_Post") -> 0_Pre | W10: =IF($K10<=2015,"clean_pre",IF($J10>=2016,"clean_post","straddle")) -> straddle | X10: =IF(O10>=0.5,"1_Post","0_Pre") -> 0_Pre | Y10: =IF(P10>=0.5,"1_Post","0_Pre") -> 0_Pre | Z10: =IF(Q10>=0.5,"1_Post","0_Pre") -> 0_Pre | AA10: =IF($K10>=2017,"1_Post","0_Pre") -> 1_Post | AB10: =IF($K10>=2018,"1_Post","0_Pre") -> 1_Post | AC10: =IF($K10>=2019,"1_Post","0_Pre") -> 0_Pre | AD10: =IF(L10<MEDIAN($L$2:$L$1307),"1_pre sample median","2_post sample median") -> 1_pre sample median | AE10: =IF(L10<=PERCENTILE($L$2:$L$1307,0.33),"1_pre sample first tertile",IF(L10>=PERCENTILE($L$2:$L$1307,0.67),"3_post sample third tertile","2_in sample second tertile")) -> 1_pre sample first tertile | AF10: rating | AG10: performance | AH10: non-sensitive | AI10: with ETS/CT | AJ10: NA | AK10: =VLOOKUP(MID($AR10,1,255),country_lookup!$B:$F,2,FALSE) -> 99_NCE | AL10: =VLOOKUP(MID($AR10,1,255),country_lookup!$B:$F,3,FALSE) -> 99_NCE | AM10: =VLOOKUP(MID($AR10,1,255),country_lookup!$B:$F,4,FALSE) -> 1_western | AN10: =VLOOKUP(MID($AR10,1,255),country_lookup!$B:$F,5,FALSE) -> 99_NCE | AO10: =VLOOKUP(MID($AS10,1,255),source_lookup!$B:$K,4,FALSE) -> 0_published | AP10: =VLOOKUP(MID($AS10,1,255),source_lookup!$B:$K,6,FALSE) -> 1_VHB high | AQ10: =VLOOKUP(MID($AS10,1,255),source_lookup!$B:$K,10,FALSE) -> 1_fin/acc/econ | AR10: United States,Austria,Belgium,Bulgaria,Croatia,Cyprus,Czechia,Denmark,Estonia,Finland,France,Germany,Greece,Hungary,Ireland,Italy,Latvia,Lithuania,Luxembourg,Malta,Netherlands,Poland,Portugal,Romania,Slovak Republic,Slovenia,Spain,Sweden | AS10: Bannier, C., et al (2020). Corporate Social Responsibility and Credit Risk. In SSRN Electronic Journal. https://doi.org/10.2139/ssrn.3686025.
A11: Bannier et al (2022) | B11: 10 | C11: -0.029447088 | D11: 695 | E11: 11124 | F11: calculated | G11: coded | H11: partial | I11: Regression Cofficient and Standard Error available | J11: 2003 | K11: 2018 | L11: =ROUND(AVERAGE(J11:K11),100) -> 2010.5 | M11: =ROUND(MEDIAN(J11:K11),100) -> 2010.5 | N11: =MAX(0,$K11-MAX($J11,2016)+1)/($K11-$J11+1) -> 0.1875 | O11: =MAX(0,$K11-MAX($J11,2017)+1)/($K11-$J11+1) -> 0.125 | P11: =MAX(0,$K11-MAX($J11,2018)+1)/($K11-$J11+1) -> 0.0625 | Q11: =MAX(0,$K11-MAX($J11,2019)+1)/($K11-$J11+1) -> 0 | R11: =IF(N11>=0.5,"1_Post","0_Pre") -> 0_Pre | S11: =IF($L11>=2016,"1_Post","0_Pre") -> 0_Pre | T11: =IF($M11>=2016,"1_Post","0_Pre") -> 0_Pre | U11: =IF($K11>=2016,"1_Post","0_Pre") -> 1_Post | V11: =IF($J11<=2017,"0_Pre","1_Post") -> 0_Pre | W11: =IF($K11<=2015,"clean_pre",IF($J11>=2016,"clean_post","straddle")) -> straddle | X11: =IF(O11>=0.5,"1_Post","0_Pre") -> 0_Pre | Y11: =IF(P11>=0.5,"1_Post","0_Pre") -> 0_Pre | Z11: =IF(Q11>=0.5,"1_Post","0_Pre") -> 0_Pre | AA11: =IF($K11>=2017,"1_Post","0_Pre") -> 1_Post | AB11: =IF($K11>=2018,"1_Post","0_Pre") -> 1_Post | AC11: =IF($K11>=2019,"1_Post","0_Pre") -> 0_Pre | AD11: =IF(L11<MEDIAN($L$2:$L$1307),"1_pre sample median","2_post sample median") -> 1_pre sample median | AE11: =IF(L11<=PERCENTILE($L$2:$L$1307,0.33),"1_pre sample first tertile",IF(L11>=PERCENTILE($L$2:$L$1307,0.67),"3_post sample third tertile","2_in sample second tertile")) -> 1_pre sample first tertile | AF11: derivativ (CDS spread) | AG11: performance | AH11: non-sensitive | AI11: with ETS/CT | AJ11: without ETS/CT | AK11: =VLOOKUP(MID($AR11,1,255),country_lookup!$B:$F,2,FALSE) -> 1_US | AL11: =VLOOKUP(MID($AR11,1,255),country_lookup!$B:$F,3,FALSE) -> 1_developed | AM11: =VLOOKUP(MID($AR11,1,255),country_lookup!$B:$F,4,FALSE) -> 1_western | AN11: =VLOOKUP(MID($AR11,1,255),country_lookup!$B:$F,5,FALSE) -> 1_common law | AO11: =VLOOKUP(MID($AS11,1,255),source_lookup!$B:$K,4,FALSE) -> 0_published | AP11: =VLOOKUP(MID($AS11,1,255),source_lookup!$B:$K,6,FALSE) -> 1_VHB high | AQ11: =VLOOKUP(MID($AS11,1,255),source_lookup!$B:$K,10,FALSE) -> 1_fin/acc/econ | AR11: United States | AS11: Bannier, C., et al (2020). Corporate Social Responsibility and Credit Risk. In SSRN Electronic Journal. https://doi.org/10.2139/ssrn.3686025.
A12: Bannier et al (2022) | B12: 11 | C12: -0.03178591 | D12: 695 | E12: 11124 | F12: calculated | G12: coded | H12: partial | I12: Regression Cofficient and Standard Error available | J12: 2003 | K12: 2018 | L12: =ROUND(AVERAGE(J12:K12),100) -> 2010.5 | M12: =ROUND(MEDIAN(J12:K12),100) -> 2010.5 | N12: =MAX(0,$K12-MAX($J12,2016)+1)/($K12-$J12+1) -> 0.1875 | O12: =MAX(0,$K12-MAX($J12,2017)+1)/($K12-$J12+1) -> 0.125 | P12: =MAX(0,$K12-MAX($J12,2018)+1)/($K12-$J12+1) -> 0.0625 | Q12: =MAX(0,$K12-MAX($J12,2019)+1)/($K12-$J12+1) -> 0 | R12: =IF(N12>=0.5,"1_Post","0_Pre") -> 0_Pre | S12: =IF($L12>=2016,"1_Post","0_Pre") -> 0_Pre | T12: =IF($M12>=2016,"1_Post","0_Pre") -> 0_Pre | U12: =IF($K12>=2016,"1_Post","0_Pre") -> 1_Post | V12: =IF($J12<=2017,"0_Pre","1_Post") -> 0_Pre | W12: =IF($K12<=2015,"clean_pre",IF($J12>=2016,"clean_post","straddle")) -> straddle | X12: =IF(O12>=0.5,"1_Post","0_Pre") -> 0_Pre | Y12: =IF(P12>=0.5,"1_Post","0_Pre") -> 0_Pre | Z12: =IF(Q12>=0.5,"1_Post","0_Pre") -> 0_Pre | AA12: =IF($K12>=2017,"1_Post","0_Pre") -> 1_Post | AB12: =IF($K12>=2018,"1_Post","0_Pre") -> 1_Post | AC12: =IF($K12>=2019,"1_Post","0_Pre") -> 0_Pre | AD12: =IF(L12<MEDIAN($L$2:$L$1307),"1_pre sample median","2_post sample median") -> 1_pre sample median | AE12: =IF(L12<=PERCENTILE($L$2:$L$1307,0.33),"1_pre sample first tertile",IF(L12>=PERCENTILE($L$2:$L$1307,0.67),"3_post sample third tertile","2_in sample second tertile")) -> 1_pre sample first tertile | AF12: derivativ (CDS spread) | AG12: performance | AH12: non-sensitive | AI12: with ETS/CT | AJ12: without ETS/CT | AK12: =VLOOKUP(MID($AR12,1,255),country_lookup!$B:$F,2,FALSE) -> 1_US | AL12: =VLOOKUP(MID($AR12,1,255),country_lookup!$B:$F,3,FALSE) -> 1_developed | AM12: =VLOOKUP(MID($AR12,1,255),country_lookup!$B:$F,4,FALSE) -> 1_western | AN12: =VLOOKUP(MID($AR12,1,255),country_lookup!$B:$F,5,FALSE) -> 1_common law | AO12: =VLOOKUP(MID($AS12,1,255),source_lookup!$B:$K,4,FALSE) -> 0_published | AP12: =VLOOKUP(MID($AS12,1,255),source_lookup!$B:$K,6,FALSE) -> 1_VHB high | AQ12: =VLOOKUP(MID($AS12,1,255),source_lookup!$B:$K,10,FALSE) -> 1_fin/acc/econ | AR12: United States | AS12: Bannier, C., et al (2020). Corporate Social Responsibility and Credit Risk. In SSRN Electronic Journal. https://doi.org/10.2139/ssrn.3686025.
A13: Bannier et al (2022) | B13: 12 | C13: 0.015250182 | D13: 454 | E13: 7265 | F13: calculated | G13: coded | H13: partial | I13: Regression Cofficient and Standard Error available | J13: 2003 | K13: 2018 | L13: =ROUND(AVERAGE(J13:K13),100) -> 2010.5 | M13: =ROUND(MEDIAN(J13:K13),100) -> 2010.5 | N13: =MAX(0,$K13-MAX($J13,2016)+1)/($K13-$J13+1) -> 0.1875 | O13: =MAX(0,$K13-MAX($J13,2017)+1)/($K13-$J13+1) -> 0.125 | P13: =MAX(0,$K13-MAX($J13,2018)+1)/($K13-$J13+1) -> 0.0625 | Q13: =MAX(0,$K13-MAX($J13,2019)+1)/($K13-$J13+1) -> 0 | R13: =IF(N13>=0.5,"1_Post","0_Pre") -> 0_Pre | S13: =IF($L13>=2016,"1_Post","0_Pre") -> 0_Pre | T13: =IF($M13>=2016,"1_Post","0_Pre") -> 0_Pre | U13: =IF($K13>=2016,"1_Post","0_Pre") -> 1_Post | V13: =IF($J13<=2017,"0_Pre","1_Post") -> 0_Pre | W13: =IF($K13<=2015,"clean_pre",IF($J13>=2016,"clean_post","straddle")) -> straddle | X13: =IF(O13>=0.5,"1_Post","0_Pre") -> 0_Pre | Y13: =IF(P13>=0.5,"1_Post","0_Pre") -> 0_Pre | Z13: =IF(Q13>=0.5,"1_Post","0_Pre") -> 0_Pre | AA13: =IF($K13>=2017,"1_Post","0_Pre") -> 1_Post | AB13: =IF($K13>=2018,"1_Post","0_Pre") -> 1_Post | AC13: =IF($K13>=2019,"1_Post","0_Pre") -> 0_Pre | AD13: =IF(L13<MEDIAN($L$2:$L$1307),"1_pre sample median","2_post sample median") -> 1_pre sample median | AE13: =IF(L13<=PERCENTILE($L$2:$L$1307,0.33),"1_pre sample first tertile",IF(L13>=PERCENTILE($L$2:$L$1307,0.67),"3_post sample third tertile","2_in sample second tertile")) -> 1_pre sample first tertile | AF13: rating | AG13: performance | AH13: non-sensitive | AI13: with ETS/CT | AJ13: without ETS/CT | AK13: =VLOOKUP(MID($AR13,1,255),country_lookup!$B:$F,2,FALSE) -> 1_US | AL13: =VLOOKUP(MID($AR13,1,255),country_lookup!$B:$F,3,FALSE) -> 1_developed | AM13: =VLOOKUP(MID($AR13,1,255),country_lookup!$B:$F,4,FALSE) -> 1_western | AN13: =VLOOKUP(MID($AR13,1,255),country_lookup!$B:$F,5,FALSE) -> 1_common law | AO13: =VLOOKUP(MID($AS13,1,255),source_lookup!$B:$K,4,FALSE) -> 0_published | AP13: =VLOOKUP(MID($AS13,1,255),source_lookup!$B:$K,6,FALSE) -> 1_VHB high | AQ13: =VLOOKUP(MID($AS13,1,255),source_lookup!$B:$K,10,FALSE) -> 1_fin/acc/econ | AR13: United States | AS13: Bannier, C., et al (2020). Corporate Social Responsibility and Credit Risk. In SSRN Electronic Journal. https://doi.org/10.2139/ssrn.3686025.
... A1307: Zhu, Zhao (2022) | B1307: 1306 | C1307: -0.028467605 | D1307: 717 | E1307: 7892 | F1307: coded | G1307: calculated | H1307: partial | I1307: T-Statistic available | J1307: 2009 | K1307: 2019 | L1307: =ROUND(AVERAGE(J1307:K1307),100) -> 2014 | M1307: =ROUND(MEDIAN(J1307:K1307),100) -> 2014 | N1307: =MAX(0,$K1307-MAX($J1307,2016)+1)/($K1307-$J1307+1) -> 0.36363636 | O1307: =MAX(0,$K1307-MAX($J1307,2017)+1)/($K1307-$J1307+1) -> 0.27272727 | P1307: =MAX(0,$K1307-MAX($J1307,2018)+1)/($K1307-$J1307+1) -> 0.18181818 | Q1307: =MAX(0,$K1307-MAX($J1307,2019)+1)/($K1307-$J1307+1) -> 0.090909091 | R1307: =IF(N1307>=0.5,"1_Post","0_Pre") -> 0_Pre | S1307: =IF($L1307>=2016,"1_Post","0_Pre") -> 0_Pre | T1307: =IF($M1307>=2016,"1_Post","0_Pre") -> 0_Pre | U1307: =IF($K1307>=2016,"1_Post","0_Pre") -> 1_Post | V1307: =IF($J1307<=2017,"0_Pre","1_Post") -> 0_Pre | W1307: =IF($K1307<=2015,"clean_pre",IF($J1307>=2016,"clean_post","straddle")) -> straddle | X1307: =IF(O1307>=0.5,"1_Post","0_Pre") -> 0_Pre | Y1307: =IF(P1307>=0.5,"1_Post","0_Pre") -> 0_Pre | Z1307: =IF(Q1307>=0.5,"1_Post","0_Pre") -> 0_Pre | AA1307: =IF($K1307>=2017,"1_Post","0_Pre") -> 1_Post | AB1307: =IF($K1307>=2018,"1_Post","0_Pre") -> 1_Post | AC1307: =IF($K1307>=2019,"1_Post","0_Pre") -> 1_Post | AD1307: =IF(L1307<MEDIAN($L$2:$L$1307),"1_pre sample median","2_post sample median") -> 2_post sample median | AE1307: =IF(L1307<=PERCENTILE($L$2:$L$1307,0.33),"1_pre sample first tertile",IF(L1307>=PERCENTILE($L$2:$L$1307,0.67),"3_post sample third tertile","2_in sample second tertile")) -> 3_post sample third tertile | AF1307: loand (interest rate) | AG1307: performance | AH1307: non-sensitive | AI1307: with ETS/CT | AJ1307: without ETS/CT | AK1307: =VLOOKUP(MID($AR1307,1,255),country_lookup!$B:$F,2,FALSE) -> 3_AsiaPac | AL1307: =VLOOKUP(MID($AR1307,1,255),country_lookup!$B:$F,3,FALSE) -> 2_developing | AM1307: =VLOOKUP(MID($AR1307,1,255),country_lookup!$B:$F,4,FALSE) -> 2_non_western | AN1307: =VLOOKUP(MID($AR1307,1,255),country_lookup!$B:$F,5,FALSE) -> 2_civil law | AO1307: =VLOOKUP(MID($AS1307,1,255),source_lookup!$B:$K,4,FALSE) -> 0_published | AP1307: =VLOOKUP(MID($AS1307,1,255),source_lookup!$B:$K,6,FALSE) -> 1_VHB high | AQ1307: =VLOOKUP(MID($AS1307,1,255),source_lookup!$B:$K,10,FALSE) -> 3_mgmt | AR1307: China | AS1307: Zhu, B. & Zhao, Y. (2022). Carbon risk and the cost of bank loans: Evidence from China. In Technological Forecasting and Social Change, 180, 121741. https://doi.org/10.1016/j.techfore.2022.121741.

Sheet country_lookup
A1: country | B1: country_short | C1: region | D1: development | E1: culture | F1: law | G1: note
A2: United States | B2: =MID(A2,1,255) -> United States | C2: 1_US | D2: 1_developed | E2: 1_western | F2: 1_common law | G2: single
A3: Argentina,Bahrain,Botswana,Brazil,Chile,China,Colombia,Croatia,Czechia,Egypt,Hungary,India,Jordan,Kazakhstan,Kenya,Kuwait,Lebanon,Malaysia,Mauritius,Mexico,Morocco,Namibia,Indonesia,Nigeria,Oman,Pakistan,Panama,Peru,Philippines,Poland,Qatar,Romania,Russian Federation,Saudi Arabia,Slovak Republic,South Africa,Sri Lanka,Thailand,Turkiye,Uganda,Ukraine,United Arab Emirates,Viet Nam,Zambia | B3: =MID(A3,1,255) -> Argentina,Bahrain,Botswana,Brazil,Chile,China,Colombia,Croatia,Czechia,Egypt,Hungary,India,Jordan,Kazakhstan,Kenya,Kuwait,Lebanon,Malaysia,Mauritius,Mexico,Morocco,Namibia,Indonesia,Nigeria,Oman,Pakistan,Panama,Peru,Philippines,Poland,Qatar,Romania,Russia | C3: 99_NCE | D3: 99_NCE | E3: 99_NCE | F3: 99_NCE | G3: multi (44)
A4: United States,Austria,Belgium,Bulgaria,Croatia,Cyprus,Czechia,Denmark,Estonia,Finland,France,Germany,Greece,Hungary,Ireland,Italy,Latvia,Lithuania,Luxembourg,Malta,Netherlands,Poland,Portugal,Romania,Slovak Republic,Slovenia,Spain,Sweden | B4: =MID(A4,1,255) -> United States,Austria,Belgium,Bulgaria,Croatia,Cyprus,Czechia,Denmark,Estonia,Finland,France,Germany,Greece,Hungary,Ireland,Italy,Latvia,Lithuania,Luxembourg,Malta,Netherlands,Poland,Portugal,Romania,Slovak Republic,Slovenia,Spain,Sweden | C4: 99_NCE | D4: 99_NCE | E4: 1_western | F4: 99_NCE | G4: multi (28)
A5: Austria,Belgium,Bulgaria,Croatia,Cyprus,Czechia,Denmark,Estonia,Finland,France,Germany,Greece,Hungary,Ireland,Italy,Latvia,Lithuania,Luxembourg,Malta,Netherlands,Poland,Portugal,Romania,Slovak Republic,Slovenia,Spain,Sweden | B5: =MID(A5,1,255) -> Austria,Belgium,Bulgaria,Croatia,Cyprus,Czechia,Denmark,Estonia,Finland,France,Germany,Greece,Hungary,Ireland,Italy,Latvia,Lithuania,Luxembourg,Malta,Netherlands,Poland,Portugal,Romania,Slovak Republic,Slovenia,Spain,Sweden | C5: 2_Europe | D5: 99_NCE | E5: 1_western | F5: 2_civil law | G5: multi (27)
A6: Norway,New Zealand,Sweden,Finland,Canada,Austria,Switzerland,Denmark,Netherlands,Australia,Japan,United Kingdom,Germany,France,Belgium,Spain,Portugal,Italy,Ireland,Greece | B6: =MID(A6,1,255) -> Norway,New Zealand,Sweden,Finland,Canada,Austria,Switzerland,Denmark,Netherlands,Australia,Japan,United Kingdom,Germany,France,Belgium,Spain,Portugal,Italy,Ireland,Greece | C6: 99_NCE | D6: 1_developed | E6: 99_NCE | F6: 2_civil law | G6: multi (20)
A7: Worldwide | B7: =MID(A7,1,255) -> Worldwide | C7: 99_NCE | D7: 99_NCE | E7: 99_NCE | F7: 99_NCE | G7: global
A8: Austria,Belgium,Bulgaria,Croatia,Cyprus,Czechia,Denmark,Estonia,Finland,France,Germany,Greece,Hungary,Ireland,Italy,Latvia,Lithuania,Luxembourg,Malta,Netherlands,Poland,Portugal,Romania,Slovak Republic,Slovenia,Spain,Sweden,United Kingdom | B8: =MID(A8,1,255) -> Austria,Belgium,Bulgaria,Croatia,Cyprus,Czechia,Denmark,Estonia,Finland,France,Germany,Greece,Hungary,Ireland,Italy,Latvia,Lithuania,Luxembourg,Malta,Netherlands,Poland,Portugal,Romania,Slovak Republic,Slovenia,Spain,Sweden,United Kingdom | C8: 2_Europe | D8: 99_NCE | E8: 1_western | F8: 2_civil law | G8: multi (28)
A9: Argentina, Australia, Brazil, Bulgaria, Canada, China, Colombia, Croatia, Czechia, Denmark, Ecuador, Egypt, France, Germany, India, Indonesia, Iraq, Ireland, Israel, Italy, Kazakhstan, Libya, Malaysia, Mexico, Mongolia, Morocco, Netherlands, New Zealand, Nigeria, Norway, Oman, Pakistan, Peru, Poland, Romania, Russian Federation, Saudi Arabia, South Africa, Thailand, Turkiye, United Kingdom, United States, Venezuela, Viet Nam | B9: =MID(A9,1,255) -> Argentina, Australia, Brazil, Bulgaria, Canada, China, Colombia, Croatia, Czechia, Denmark, Ecuador, Egypt, France, Germany, India, Indonesia, Iraq, Ireland, Israel, Italy, Kazakhstan, Libya, Malaysia, Mexico, Mongolia, Morocco, Netherlands, New Zealand, | C9: 99_NCE | D9: 99_NCE | E9: 99_NCE | F9: 99_NCE | G9: multi (44)
A10: Spain,Italy | B10: =MID(A10,1,255) -> Spain,Italy | C10: 2_Europe | D10: 1_developed | E10: 1_western | F10: 2_civil law | G10: multi (2)
A11: China | B11: =MID(A11,1,255) -> China | C11: 3_AsiaPac | D11: 2_developing | E11: 2_non_western | F11: 2_civil law | G11: single
A12: Austria,Belgium,Czechia,Denmark,Finland,France,Germany,Greece,Hungary,Italy,Netherlands,Norway,Poland,Portugal,Spain,Sweden,Switzerland,United Kingdom | B12: =MID(A12,1,255) -> Austria,Belgium,Czechia,Denmark,Finland,France,Germany,Greece,Hungary,Italy,Netherlands,Norway,Poland,Portugal,Spain,Sweden,Switzerland,United Kingdom | C12: 2_Europe | D12: 99_NCE | E12: 1_western | F12: 1_common law | G12: multi (18)
A13: Austria,Belgium,Cyprus,Czechia,Denmark,Finland,France,Germany,Greece,Ireland,Italy,Netherlands,Poland,Portugal,Spain,Sweden,United Kingdom | B13: =MID(A13,1,255) -> Austria,Belgium,Cyprus,Czechia,Denmark,Finland,France,Germany,Greece,Ireland,Italy,Netherlands,Poland,Portugal,Spain,Sweden,United Kingdom | C13: 2_Europe | D13: 99_NCE | E13: 1_western | F13: 1_common law | G13: multi (17)
... A36: Australia,Austria,Belgium,Canada,Denmark,Finland,France,Germany,Greece,Hungary,Ireland,Italy,Japan,Luxembourg,Netherlands,Norway,Poland,Portugal,Russian Federation,Spain,Sweden,Switzerland,United Kingdom,United States | B36: =MID(A36,1,255) -> Australia,Austria,Belgium,Canada,Denmark,Finland,France,Germany,Greece,Hungary,Ireland,Italy,Japan,Luxembourg,Netherlands,Norway,Poland,Portugal,Russian Federation,Spain,Sweden,Switzerland,United Kingdom,United States | C36: 99_NCE | D36: 99_NCE | E36: 99_NCE | F36: 99_NCE | G36: multi (24)

Sheet source_lookup
A1: source | B1: source_short | C1: journal | D1: publication year | E1: publication status | F1: journal vhb ranking | G1: journal VHB ranking_moderator | H1: jounal Journal impact factor | I1: journal vhb ranking_moderator | J1: jounal field | K1: journal field_moderator | L1: note | M1: source_verfified
A2: Atif, M., and Searat Ali (2021). Environmental, social and governance disclosure and default risk. In Business Strategy and the Environment, 30, 8, 3937–3959. https://doi.org/10.1002/bse.2850. | B2: =MID(A2,1,255) -> Atif, M., and Searat Ali (2021). Environmental, social and governance disclosure and default risk. In Business Strategy and the Environment, 30, 8, 3937–3959. https://doi.org/10.1002/bse.2850. | C2: Business Strategy and the Environment | D2: 2021 | E2: 0_published | F2: B | G2: 1_VHB high | H2: 12.5 | I2: =IF(H2>MEDIAN($H$2:$H$66),"1_JIF high","0_JIF low") -> 1_JIF high | J2: Nachhaltigkeit | K2: 2_sust | L2: - | M2: =A2 -> Atif, M., and Searat Ali (2021). Environmental, social and governance disclosure and default risk. In Business Strategy and the Environment, 30, 8, 3937–3959. https://doi.org/10.1002/bse.2850.
A3: Azmi, W., Hassan, M. K., Houston, R. & Karim, M. S. (2021). ESG activities and Banking Performance: International Evidence from Emerging Economies. In Journal of International Financial Markets, Institutions and Money, 70, 101277. https://doi.org/10.1016/j.intfin.2020.101277 | B3: =MID(A3,1,255) -> Azmi, W., Hassan, M. K., Houston, R. & Karim, M. S. (2021). ESG activities and Banking Performance: International Evidence from Emerging Economies. In Journal of International Financial Markets, Institutions and Money, 70, 101277. https://doi.org/10.1016/ | C3: Journal of International Financial Markets, Institutions and Money | D3: 2021 | E3: 0_published | F3: B | G3: 1_VHB high | H3: 4.9 | I3: =IF(H3>MEDIAN($H$2:$H$66),"1_JIF high","0_JIF low") -> 0_JIF low | J3: Finance | K3: 1_fin/acc/econ | L3: - | M3: =A3 -> Azmi, W., Hassan, M. K., Houston, R. & Karim, M. S. (2021). ESG activities and Banking Performance: International Evidence from Emerging Economies. In Journal of International Financial Markets, Institutions and Money, 70, 101277. https://doi.org/10.1016/j.intfin.2020.101277
A4: Bannier, C., et al (2020). Corporate Social Responsibility and Credit Risk. In SSRN Electronic Journal. https://doi.org/10.2139/ssrn.3686025. | B4: =MID(A4,1,255) -> Bannier, C., et al (2020). Corporate Social Responsibility and Credit Risk. In SSRN Electronic Journal. https://doi.org/10.2139/ssrn.3686025. | C4: SSRN Working Paper | D4: 2020 | E4: 0_published | F4: B | G4: 1_VHB high | H4: n/a | I4: 99_NA | J4: Finance | K4: 1_fin/acc/econ | L4: Finance Research Letters, 44 (2021/22), 102052 | M4: Bannier, C. E., Bofinger, Y., & Rock, B. (2022). Corporate social responsibility and credit risk. Finance Research Letters, 44, 102052.
A5: Bauer, R. & Hann, D. (2010). Corporate Environmental Management and Credit Risk. In SSRN Electronic Journal. https://doi.org/10.2139/ssrn.1660470. | B5: =MID(A5,1,255) -> Bauer, R. & Hann, D. (2010). Corporate Environmental Management and Credit Risk. In SSRN Electronic Journal. https://doi.org/10.2139/ssrn.1660470. | C5: SSRN Working Paper | D5: 2010 | E5: 1_not published | F5: - | G5: 99_NA | H5: n/a | I5: 99_NA | J5: Finance | K5: 1_fin/acc/econ | L5: - | M5: =A5 -> Bauer, R. & Hann, D. (2010). Corporate Environmental Management and Credit Risk. In SSRN Electronic Journal. https://doi.org/10.2139/ssrn.1660470.
A6: Capelle-Blancard, G., et al (2019). Sovereign bond yield spreads and sustainability: An empirical analysis of OECD countries. In Journal of Banking and Finance, 98, 156–169. https://doi.org/10.1016/j.jbankfin.2018.11.011. | B6: =MID(A6,1,255) -> Capelle-Blancard, G., et al (2019). Sovereign bond yield spreads and sustainability: An empirical analysis of OECD countries. In Journal of Banking and Finance, 98, 156–169. https://doi.org/10.1016/j.jbankfin.2018.11.011. | C6: Journal of Banking & Finance | D6: 2019 | E6: 0_published | F6: A | G6: 1_VHB high | H6: 3.6 | I6: =IF(H6>MEDIAN($H$2:$H$66),"1_JIF high","0_JIF low") -> 0_JIF low | J6: Finance | K6: 1_fin/acc/econ | L6: - | M6: =A6 -> Capelle-Blancard, G., et al (2019). Sovereign bond yield spreads and sustainability: An empirical analysis of OECD countries. In Journal of Banking and Finance, 98, 156–169. https://doi.org/10.1016/j.jbankfin.2018.11.011.
A7: Chava, S. (2010). Do Environmental Concerns Affect the Cost of Bank Loans? (Mays Business School, Texas A&M University, Texas, US) | B7: =MID(A7,1,255) -> Chava, S. (2010). Do Environmental Concerns Affect the Cost of Bank Loans? (Mays Business School, Texas A&M University, Texas, US) | C7: Working Paper (Mays Business School, Texas A&M) | D7: 2010 | E7: 1_not published | F7: - | G7: 99_NA | H7: n/a | I7: 99_NA | J7: Finance | K7: 1_fin/acc/econ | L7: - | M7: =A7 -> Chava, S. (2010). Do Environmental Concerns Affect the Cost of Bank Loans? (Mays Business School, Texas A&M University, Texas, US)
A8: Chava, S. (2014). Environmental externalities and cost of capital. In Management Science, 60/9, 2223–2247. https://doi.org/10.1287/mnsc.2013.1863. | B8: =MID(A8,1,255) -> Chava, S. (2014). Environmental externalities and cost of capital. In Management Science, 60/9, 2223–2247. https://doi.org/10.1287/mnsc.2013.1863. | C8: Management Science | D8: 2014 | E8: 0_published | F8: A+ | G8: 1_VHB high | H8: 4.6 | I8: =IF(H8>MEDIAN($H$2:$H$66),"1_JIF high","0_JIF low") -> 0_JIF low | J8: Management | K8: 3_mgmt | L8: - | M8: =A8 -> Chava, S. (2014). Environmental externalities and cost of capital. In Management Science, 60/9, 2223–2247. https://doi.org/10.1287/mnsc.2013.1863.
A9: Chen, I., et al (2020). Do banks value borrowers’ environmental record? evidence from financial contracts. In Journal of Business Ethics, 174/3, 687–713. https://doi.org/10.1007/s10551-020-04621-2. | B9: =MID(A9,1,255) -> Chen, I., et al (2020). Do banks value borrowers’ environmental record? evidence from financial contracts. In Journal of Business Ethics, 174/3, 687–713. https://doi.org/10.1007/s10551-020-04621-2. | C9: Journal of Business Ethics | D9: 2020 | E9: 0_published | F9: B | G9: 1_VHB high | H9: 6.1 | I9: =IF(H9>MEDIAN($H$2:$H$66),"1_JIF high","0_JIF low") -> 1_JIF high | J9: Management | K9: 3_mgmt | L9: - | M9: =A9 -> Chen, I., et al (2020). Do banks value borrowers’ environmental record? evidence from financial contracts. In Journal of Business Ethics, 174/3, 687–713. https://doi.org/10.1007/s10551-020-04621-2.
A10: Chen, Li. & Gao, L. S. (2011). The pricing of climate risk. In SSRN Electronic Journal. https://doi.org/10.2139/ssrn.1940727. | B10: =MID(A10,1,255) -> Chen, Li. & Gao, L. S. (2011). The pricing of climate risk. In SSRN Electronic Journal. https://doi.org/10.2139/ssrn.1940727. | C10: SSRN Working Paper | D10: 2011 | E10: 0_published | F10: nicht gelistet | G10: 0_VHB low | H10: n/a | I10: 99_NA | J10: Finance | K10: 1_fin/acc/econ | L10: Journal of Financial and Economic Practice, 12(2), 2012, 115–131 | M10: Chen, L. H., & Silva Gao, L. (2012). The pricing of climate risk. Journal of Financial and Economic Practice, Vol12 (2), Spring, 115-131.
A11: Chodnicka-Jaworska, P. (2022). Environmental, social, and governance impact on energy sector default risk—long-term issuer credit ratings perspective. In Frontiers in Energy Research, 10. https://doi.org/10.3389/fenrg.2022.817679. | B11: =MID(A11,1,255) -> Chodnicka-Jaworska, P. (2022). Environmental, social, and governance impact on energy sector default risk—long-term issuer credit ratings perspective. In Frontiers in Energy Research, 10. https://doi.org/10.3389/fenrg.2022.817679. | C11: Frontiers in Energy Research | D11: 2022 | E11: 0_published | F11: nicht gelistet (VHB-2024) | G11: 0_VHB low | H11: 2.6 | I11: =IF(H11>MEDIAN($H$2:$H$66),"1_JIF high","0_JIF low") -> 0_JIF low | J11: Umweltwissenschaften | K11: 2_sust | L11: - | M11: =A11 -> Chodnicka-Jaworska, P. (2022). Environmental, social, and governance impact on energy sector default risk—long-term issuer credit ratings perspective. In Frontiers in Energy Research, 10. https://doi.org/10.3389/fenrg.2022.817679.
A12: Christ, J., et al (2022). Corporate Sustainability Performance and the cost of debt – an analysis of the impact of country- and industry-specific climate risk exposures. In SSRN Electronic Journal. https://doi.org/10.2139/ssrn.4135247. | B12: =MID(A12,1,255) -> Christ, J., et al (2022). Corporate Sustainability Performance and the cost of debt – an analysis of the impact of country- and industry-specific climate risk exposures. In SSRN Electronic Journal. https://doi.org/10.2139/ssrn.4135247. | C12: SSRN Working Paper | D12: 2022 | E12: 1_not published | F12: - | G12: 99_NA | H12: n/a | I12: 99_NA | J12: Finance | K12: 1_fin/acc/econ | L12: - | M12: =A12 -> Christ, J., et al (2022). Corporate Sustainability Performance and the cost of debt – an analysis of the impact of country- and industry-specific climate risk exposures. In SSRN Electronic Journal. https://doi.org/10.2139/ssrn.4135247.
A13: Cubas-Díaz, M. & Sedano M.A.M. (2018). Do credit ratings take into account the sustainability performance of companies? In Sustainability, 10/11, 4272. https://doi.org/10.3390/su10114272. | B13: =MID(A13,1,255) -> Cubas-Díaz, M. & Sedano M.A.M. (2018). Do credit ratings take into account the sustainability performance of companies? In Sustainability, 10/11, 4272. https://doi.org/10.3390/su10114272. | C13: Sustainability (MDPI) | D13: 2018 | E13: 0_published | F13: nicht in VHB-2024 (JQ3: C) | G13: 0_VHB low | H13: 3.3 | I13: =IF(H13>MEDIAN($H$2:$H$66),"1_JIF high","0_JIF low") -> 0_JIF low | J13: Nachhaltigkeit | K13: 2_sust | L13: - | M13: =A13 -> Cubas-Díaz, M. & Sedano M.A.M. (2018). Do credit ratings take into account the sustainability performance of companies? In Sustainability, 10/11, 4272. https://doi.org/10.3390/su10114272.
A14: Delis, M., et al (2021). Being stranded with fossil fuel reserves? climate policy risk and the pricing of Bank Loans. In Swiss Finance InstituteResearch Paper Series, 18/10. https://doi.org/10.2139/ssrn.3451335. | B14: =MID(A14,1,255) -> Delis, M., et al (2021). Being stranded with fossil fuel reserves? climate policy risk and the pricing of Bank Loans. In Swiss Finance InstituteResearch Paper Series, 18/10. https://doi.org/10.2139/ssrn.3451335. | C14: Swiss Finance Institute Research Paper 18-10 | D14: 2021 | E14: 0_published | F14: B | G14: 1_VHB high | H14: n/a | I14: 99_NA | J14: Finance | K14: 1_fin/acc/econ | L14: Financial Markets, Institutions & Instruments, 33 (2024), 239–265 | M14: Delis, M. D., Greiff, K. D., Iosifidi, M., & Ongena, S. (2024). Being stranded with fossil fuel reserves? Climate policy risk and the pricing of bank loans. Financial markets, institutions & instruments, 33(3), 239-265.
A15: Devalle, A., et al (2017). The linkage between ESG performance and Credit Ratings: A firm-level perspective analysis. In International Journal of Business and Management, 12/9, 53. https://doi.org/10.5539/ijbm.v12n9p53. | B15: =MID(A15,1,255) -> Devalle, A., et al (2017). The linkage between ESG performance and Credit Ratings: A firm-level perspective analysis. In International Journal of Business and Management, 12/9, 53. https://doi.org/10.5539/ijbm.v12n9p53. | C15: International Journal of Business and Management (CCSE) | D15: 2017 | E15: 0_published | F15: nicht gelistet | G15: 0_VHB low | H15: n/a | I15: 99_NA | J15: Management | K15: 3_mgmt | L15: - | M15: =A15 -> Devalle, A., et al (2017). The linkage between ESG performance and Credit Ratings: A firm-level perspective analysis. In International Journal of Business and Management, 12/9, 53. https://doi.org/10.5539/ijbm.v12n9p53.
A16: Ding, X., et al (2022). Environmental administrative penalty, corporate environmental disclosures and the cost of debt. In Journal of Cleaner Production, 332, 2022, 129919. https://doi.org/10.1016/j.jclepro.2021.129919. | B16: =MID(A16,1,255) -> Ding, X., et al (2022). Environmental administrative penalty, corporate environmental disclosures and the cost of debt. In Journal of Cleaner Production, 332, 2022, 129919. https://doi.org/10.1016/j.jclepro.2021.129919. | C16: Journal of Cleaner Production | D16: 2022 | E16: 0_published | F16: B | G16: 1_VHB high | H16: 11.1 | I16: =IF(H16>MEDIAN($H$2:$H$66),"1_JIF high","0_JIF low") -> 1_JIF high | J16: Nachhaltigkeit | K16: 2_sust | L16: - | M16: =A16 -> Ding, X., et al (2022). Environmental administrative penalty, corporate environmental disclosures and the cost of debt. In Journal of Cleaner Production, 332, 2022, 129919. https://doi.org/10.1016/j.jclepro.2021.129919.
A17: Drago, D., et al (2018). Do corporate social responsibility ratings affect credit default swap spreads? In Corporate Social Responsibility and Environmental Management, 26/3, 644–652. https://doi.org/10.1002/csr.1709. | B17: =MID(A17,1,255) -> Drago, D., et al (2018). Do corporate social responsibility ratings affect credit default swap spreads? In Corporate Social Responsibility and Environmental Management, 26/3, 644–652. https://doi.org/10.1002/csr.1709. | C17: Corporate Social Responsibility and Environmental Management | D17: 2018 | E17: 0_published | F17: B | G17: 1_VHB high | H17: 9.8 | I17: =IF(H17>MEDIAN($H$2:$H$66),"1_JIF high","0_JIF low") -> 1_JIF high | J17: Nachhaltigkeit | K17: 2_sust | L17: - | M17: =A17 -> Drago, D., et al (2018). Do corporate social responsibility ratings affect credit default swap spreads? In Corporate Social Responsibility and Environmental Management, 26/3, 644–652. https://doi.org/10.1002/csr.1709.
A18: Drago, D. &Carnevale, C. (2020). Do CSR ratings affect loan spreads? evidence from European syndicated loan market. In Sustainability, 12/18, 7639. https://doi.org/10.3390/su12187639. | B18: =MID(A18,1,255) -> Drago, D. &Carnevale, C. (2020). Do CSR ratings affect loan spreads? evidence from European syndicated loan market. In Sustainability, 12/18, 7639. https://doi.org/10.3390/su12187639. | C18: Sustainability (MDPI) | D18: 2020 | E18: 0_published | F18: nicht in VHB-2024 (JQ3: C) | G18: 0_VHB low | H18: 3.3 | I18: =IF(H18>MEDIAN($H$2:$H$66),"1_JIF high","0_JIF low") -> 0_JIF low | J18: Nachhaltigkeit | K18: 2_sust | L18: - | M18: =A18 -> Drago, D. &Carnevale, C. (2020). Do CSR ratings affect loan spreads? evidence from European syndicated loan market. In Sustainability, 12/18, 7639. https://doi.org/10.3390/su12187639.
A19: Du, X., et al (2015). Do lenders applaud corporate environmental performance? evidence from Chinese private-owned firms. In Journal of Business Ethics, 143/1, 179–207. https://doi.org/10.1007/s10551-015-2758-2. | B19: =MID(A19,1,255) -> Du, X., et al (2015). Do lenders applaud corporate environmental performance? evidence from Chinese private-owned firms. In Journal of Business Ethics, 143/1, 179–207. https://doi.org/10.1007/s10551-015-2758-2. | C19: Journal of Business Ethics | D19: 2015 | E19: 0_published | F19: B | G19: 1_VHB high | H19: 6.1 | I19: =IF(H19>MEDIAN($H$2:$H$66),"1_JIF high","0_JIF low") -> 1_JIF high | J19: Management | K19: 3_mgmt | L19: - | M19: =A19 -> Du, X., et al (2015). Do lenders applaud corporate environmental performance? evidence from Chinese private-owned firms. In Journal of Business Ethics, 143/1, 179–207. https://doi.org/10.1007/s10551-015-2758-2.
A20: Du, M, et al (2022). Will environmental information disclosure affect bank credit decisions and corporate debt financing costs? evidence from China’s heavily polluting industries. In Environmental Science and Pollution Research, 29/31, 47661–47672. https://doi.org/10.1007/s11356-022-19229-4. | B20: =MID(A20,1,255) -> Du, M, et al (2022). Will environmental information disclosure affect bank credit decisions and corporate debt financing costs? evidence from China’s heavily polluting industries. In Environmental Science and Pollution Research, 29/31, 47661–47672. https: | C20: Environmental Science and Pollution Research | D20: 2022 | E20: 0_published | F20: nicht gelistet | G20: 0_VHB low | H20: 5.8 | I20: =IF(H20>MEDIAN($H$2:$H$66),"1_JIF high","0_JIF low") -> 1_JIF high | J20: Umweltwissenschaften | K20: 2_sust | L20: - | M20: =A20 -> Du, M, et al (2022). Will environmental information disclosure affect bank credit decisions and corporate debt financing costs? evidence from China’s heavily polluting industries. In Environmental Science and Pollution Research, 29/31, 47661–47672. https://doi.org/10.1007/s11356-022-19229-4.
A21: Eichholtz, P., et al (2019). Environmental performance and the cost of debt: Evidence from commercial mortgages and REIT bonds. In Journal of Banking & Finance, 102, 19–32. https://doi.org/10.1016/j.jbankfin.2019.02.015. | B21: =MID(A21,1,255) -> Eichholtz, P., et al (2019). Environmental performance and the cost of debt: Evidence from commercial mortgages and REIT bonds. In Journal of Banking & Finance, 102, 19–32. https://doi.org/10.1016/j.jbankfin.2019.02.015. | C21: Journal of Banking & Finance | D21: 2019 | E21: 0_published | F21: A | G21: 1_VHB high | H21: 3.6 | I21: =IF(H21>MEDIAN($H$2:$H$66),"1_JIF high","0_JIF low") -> 0_JIF low | J21: Finance | K21: 1_fin/acc/econ | L21: - | M21: =A21 -> Eichholtz, P., et al (2019). Environmental performance and the cost of debt: Evidence from commercial mortgages and REIT bonds. In Journal of Banking & Finance, 102, 19–32. https://doi.org/10.1016/j.jbankfin.2019.02.015.
A22: Eliwa, Y., et al (2021). ESG practices and the cost of debt: Evidence from EU countries. In Critical Perspectives on Accounting, 79, 102097. https://doi.org/10.1016/j.cpa.2019.102097. | B22: =MID(A22,1,255) -> Eliwa, Y., et al (2021). ESG practices and the cost of debt: Evidence from EU countries. In Critical Perspectives on Accounting, 79, 102097. https://doi.org/10.1016/j.cpa.2019.102097. | C22: Critical Perspectives on Accounting | D22: 2021 | E22: 0_published | F22: B | G22: 1_VHB high | H22: 5 | I22: =IF(H22>MEDIAN($H$2:$H$66),"1_JIF high","0_JIF low") -> 0_JIF low | J22: Accounting | K22: 1_fin/acc/econ | L22: - | M22: =A22 -> Eliwa, Y., et al (2021). ESG practices and the cost of debt: Evidence from EU countries. In Critical Perspectives on Accounting, 79, 102097. https://doi.org/10.1016/j.cpa.2019.102097.
A23: Fard, A., et al (2020). Environmental regulation and the cost of Bank Loans: International Evidence. In Journal of Financial Stability, 51, 100797. https://doi.org/10.1016/j.jfs.2020.100797. | B23: =MID(A23,1,255) -> Fard, A., et al (2020). Environmental regulation and the cost of Bank Loans: International Evidence. In Journal of Financial Stability, 51, 100797. https://doi.org/10.1016/j.jfs.2020.100797. | C23: Journal of Financial Stability | D23: 2020 | E23: 0_published | F23: A | G23: 1_VHB high | H23: 6.1 | I23: =IF(H23>MEDIAN($H$2:$H$66),"1_JIF high","0_JIF low") -> 1_JIF high | J23: Finance | K23: 1_fin/acc/econ | L23: - | M23: =A23 -> Fard, A., et al (2020). Environmental regulation and the cost of Bank Loans: International Evidence. In Journal of Financial Stability, 51, 100797. https://doi.org/10.1016/j.jfs.2020.100797.
A24: Ferriani, F. (2022). Issuing bonds during the covid-19 pandemic: Is there an ESG premium? In SSRN Electronic Journal. https://doi.org/10.2139/ssrn.4042802. | B24: =MID(A24,1,255) -> Ferriani, F. (2022). Issuing bonds during the covid-19 pandemic: Is there an ESG premium? In SSRN Electronic Journal. https://doi.org/10.2139/ssrn.4042802. | C24: SSRN Working Paper | D24: 2022 | E24: 0_published | F24: B | G24: 1_VHB high | H24: n/a | I24: 99_NA | J24: Finance | K24: 1_fin/acc/econ | L24: International Review of Financial Analysis, 88 (2023) | M24: Ferriani, F. (2023). Issuing bonds during the Covid-19 pandemic: Was there an ESG premium?. International Review of Financial Analysis, 88, 102653.
A25: Fonseka, M., et al (2019). The effect of environmental information disclosure and energy product type on the cost of debt: Evidence from energy firms in China. In Pacific-Basin Finance Journal, 54, 159–182. https://doi.org/10.1016/j.pacfin.2018.05.001. | B25: =MID(A25,1,255) -> Fonseka, M., et al (2019). The effect of environmental information disclosure and energy product type on the cost of debt: Evidence from energy firms in China. In Pacific-Basin Finance Journal, 54, 159–182. https://doi.org/10.1016/j.pacfin.2018.05.001. | C25: Pacific-Basin Finance Journal | D25: 2019 | E25: 0_published | F25: C | G25: 1_VHB high | H25: 4.8 | I25: =IF(H25>MEDIAN($H$2:$H$66),"1_JIF high","0_JIF low") -> 0_JIF low | J25: Finance | K25: 1_fin/acc/econ | L25: - | M25: =A25 -> Fonseka, M., et al (2019). The effect of environmental information disclosure and energy product type on the cost of debt: Evidence from energy firms in China. In Pacific-Basin Finance Journal, 54, 159–182. https://doi.org/10.1016/j.pacfin.2018.05.001.
